File: src/xpsdeeplearning/data/measured/mno gas-phase removed.vms
VAMAS Surface Chemical Analysis Standard Data Transfer Format 1988 May 4
Not Specified
Not Specified
Not Specified
Not Specified
7
Casa Info Follows CasaXPS Version 2.3.20rev1.2G
0
SourceAnalyserAngle: Not Specified
CasaRowLabel:afer reduction, 100 C, H2, gas-bg removed, MnO
CasaRowLabel:550 C, 0.1 mbar O2
CasaRowLabel:750 C, 0.1 mbar O2 (Mn2O3)
CasaRowLabel:Heating 100 C in vacuum, MnO2
NORM
REGULAR
1
1
Exp Variable
d
0
0
0
0
4
Mn2p
afer reduction, 100 C, H2, gas-bg removed, MnO
2026
2021
1
15
21
20
0
10
Casa Info Follows
0
0
0
0
none
Group: none
Analyzer Lens: none
Analyzer Slit: none
Scan Mode: none
XPS
0
Al
1486.61
0
0
0
56.5
180
FAT
0
1
0
0
0
0
0
0
Mn2p

-1
kinetic energy
eV
798.71
0.1
2
counts
d
Transmission
d
pulse counting
1
1
0
0
0
0
2
ESCAPE DEPTH TYPE
d
0
MFP Exponent
d
0
1260
373.84
4712.77
1
1
1512.04
1
1506.29
1
1516.94
1
1528.17
1
1508.33
1
1511.96
1
1483.83
1
1519.24
1
1517.5
1
1521.35
1
1539.19
1
1524.47
1
1523.92
1
1535.91
1
1531.88
1
1508.73
1
1521.76
1
1532.45
1
1515.55
1
1523.62
1
1535.56
1
1557.24
1
1546.27
1
1527.49
1
1532.27
1
1549.36
1
1537.27
1
1530.49
1
1544.95
1
1552.81
1
1537.59
1
1541.57
1
1536.79
1
1509.23
1
1560.1
1
1558
1
1524.57
1
1545.72
1
1544.9
1
1552.39
1
1539.12
1
1544.74
1
1561.65
1
1517.12
1
1570.42
1
1573.32
1
1527.26
1
1529
1
1530.36
1
1546.35
1
1572.27
1
1562.58
1
1579.74
1
1552.81
1
1560.39
1
1596.45
1
1577.85
1
1543.6
1
1578.77
1
1580.26
1
1557.46
1
1560.34
1
1581.15
1
1554.86
1
1561.96
1
1557.93
1
1532.03
1
1563.62
1
1535.57
1
1538.06
1
1553.3
1
1559.38
1
1588.63
1
1597.41
1
1582.63
1
1561.61
1
1530.12
1
1559.31
1
1574.45
1
1556.08
1
1563.5
1
1576.6
1
1566.26
1
1590.28
1
1594.43
1
1592.21
1
1605.95
1
1579.3
1
1560.45
1
1579.81
1
1567.16
1
1606.97
1
1589.82
1
1603.71
1
1593.62
1
1614.77
1
1601.71
1
1600.29
1
1605.04
1
1565.62
1
1607.21
1
1616.68
1
1582.06
1
1618.04
1
1622.67
1
1619.49
1
1643.25
1
1648.85
1
1653.87
1
1654.64
1
1624.32
1
1648.51
1
1640.01
1
1632.31
1
1661.2
1
1656.31
1
1661.69
1
1659.53
1
1644.75
1
1650.8
1
1629.1
1
1625.74
1
1641.54
1
1660.39
1
1626.02
1
1635.78
1
1660.59
1
1667.51
1
1611.8
1
1650.84
1
1682.14
1
1672.77
1
1674.76
1
1659.61
1
1660.59
1
1652.29
1
1640.67
1
1681.88
1
1666.45
1
1647.62
1
1634.85
1
1634.5
1
1653.83
1
1656.1
1
1662.76
1
1647.48
1
1655.26
1
1645.96
1
1632.47
1
1623.3
1
1613.61
1
1602.34
1
1638.08
1
1631.16
1
1626.27
1
1614.42
1
1633.85
1
1624.3
1
1632.36
1
1655.06
1
1643.59
1
1638.88
1
1615.73
1
1625.44
1
1615.57
1
1613.69
1
1624.75
1
1618.25
1
1604.5
1
1601.51
1
1649.14
1
1655.08
1
1648.18
1
1594.25
1
1594.35
1
1581.96
1
1614.1
1
1615.87
1
1615.66
1
1586.62
1
1597.57
1
1606.38
1
1613.42
1
1593.07
1
1592.21
1
1567.51
1
1604.07
1
1598.41
1
1576.64
1
1617.51
1
1598.18
1
1616.51
1
1599.02
1
1552.67
1
1568.92
1
1626.29
1
1549.05
1
1570.76
1
1591.63
1
1584.95
1
1570.32
1
1577.37
1
1575.6
1
1548.91
1
1541.84
1
1566.63
1
1559.64
1
1556.28
1
1567.38
1
1534.72
1
1571.23
1
1557.35
1
1586.1
1
1592.36
1
1587.58
1
1628.82
1
1597.33
1
1588.35
1
1560.21
1
1569.1
1
1607.3
1
1615.32
1
1596.72
1
1609.98
1
1586.35
1
1600.92
1
1606.09
1
1632.21
1
1622.13
1
1631.87
1
1619.32
1
1620.52
1
1624.74
1
1619.88
1
1625.58
1
1630.08
1
1624.54
1
1587.56
1
1613.13
1
1624.13
1
1609.81
1
1640.17
1
1659.37
1
1670.39
1
1654.79
1
1603.95
1
1629.55
1
1655.6
1
1650
1
1659.73
1
1667.3
1
1697.5
1
1673.62
1
1664.46
1
1645.13
1
1668.16
1
1697.29
1
1704.65
1
1675.8
1
1721.59
1
1696.22
1
1680.68
1
1679.79
1
1698.27
1
1726.4
1
1735.45
1
1736.44
1
1772.98
1
1766.95
1
1789.4
1
1795.22
1
1786.99
1
1834.82
1
1824.78
1
1836.09
1
1861.98
1
1903.23
1
1924.22
1
1914.03
1
1881.21
1
1879.07
1
1925.9
1
1940.23
1
1955.56
1
1960.58
1
1957.17
1
1955.64
1
1952.44
1
1938.76
1
1947.36
1
1947.41
1
1904.06
1
1915.53
1
1905.83
1
1915.16
1
1910.23
1
1834.9
1
1816.8
1
1854.87
1
1850.24
1
1860.91
1
1812.37
1
1856.49
1
1825.73
1
1844.97
1
1815.1
1
1845.06
1
1864.61
1
1820.57
1
1807.34
1
1806.49
1
1837.61
1
1857.46
1
1855.95
1
1892.78
1
1877.66
1
1880.52
1
1930.96
1
1915.04
1
1952.63
1
1995.3
1
2016.97
1
2064.65
1
2103.03
1
2179.32
1
2183.51
1
2230.24
1
2282.84
1
2330.09
1
2370.37
1
2381.12
1
2445.35
1
2480.66
1
2571.12
1
2619
1
2671.79
1
2758.5
1
2824.96
1
2901.84
1
2995.44
1
3045.14
1
3132.21
1
3184.02
1
3209.62
1
3240.24
1
3307.85
1
3347.18
1
3297.5
1
3292.72
1
3254.59
1
3220.72
1
3188.73
1
3119.14
1
3057.74
1
3032.02
1
2990.32
1
2921.42
1
2904.96
1
2879.66
1
2823.21
1
2753.24
1
2659.17
1
2538.62
1
2480.08
1
2397.04
1
2239.95
1
2160.09
1
2047.98
1
1948.75
1
1867.26
1
1774.6
1
1717.51
1
1657.38
1
1627.07
1
1575.62
1
1566.34
1
1528.5
1
1540.72
1
1533.87
1
1527.78
1
1527.79
1
1533.57
1
1532.21
1
1531.65
1
1535.76
1
1536.87
1
1581.42
1
1594.55
1
1655.32
1
1640.63
1
1698.67
1
1696.61
1
1714.59
1
1732.25
1
1753.66
1
1801.36
1
1802.61
1
1839.51
1
1850.18
1
1814.17
1
1911.27
1
1888.62
1
1918.31
1
1924.93
1
1927.68
1
1943.94
1
1941.74
1
1947.6
1
2000.6
1
1984.71
1
1968.12
1
1972.4
1
1922.89
1
1912.12
1
1894.6
1
1887.77
1
1879.12
1
1870.06
1
1889.23
1
1848.05
1
1816.33
1
1830.11
1
1850.5
1
1857.08
1
1825.45
1
1852.31
1
1878.59
1
1868.99
1
1901.07
1
1940.06
1
1973.86
1
1972.81
1
1984.57
1
2025.21
1
2032.01
1
2072.53
1
2059.86
1
2172.77
1
2178.01
1
2234.32
1
2301.29
1
2291.49
1
2390.91
1
2506.6
1
2605.37
1
2669.98
1
2754.02
1
2885.62
1
3017.98
1
3116.15
1
3226.07
1
3407.09
1
3546.17
1
3648.18
1
3775.3
1
3880.2
1
3983.37
1
4066.46
1
4254.89
1
4385.39
1
4464.4
1
4638.8
1
4673.25
1
4702.17
1
4701.88
1
4712.77
1
4705.02
1
4687.64
1
4621.2
1
4586.95
1
4619.81
1
4646.73
1
4654.69
1
4638.2
1
4680.31
1
4708.13
1
4630.98
1
4403.31
1
4129.95
1
3715.33
1
3271.52
1
2740.53
1
2238.49
1
1817.65
1
1467.99
1
1193.78
1
991.937
1
861.416
1
736.676
1
668.387
1
627.526
1
581.631
1
540.379
1
549.455
1
525.124
1
514.23
1
490.9
1
484.485
1
481.915
1
470.749
1
462.034
1
452.342
1
444.836
1
436.903
1
427.106
1
405.349
1
420.07
1
436.228
1
439.067
1
438.551
1
433.258
1
423.995
1
413.577
1
433.679
1
410.412
1
412.707
1
419.261
1
411.575
1
415.596
1
413.165
1
411.911
1
405.095
1
402.616
1
410.669
1
405.236
1
397.417
1
395.535
1
395.922
1
408.295
1
413.302
1
391.707
1
406.485
1
396.42
1
380.196
1
380.551
1
402.465
1
400.056
1
391.543
1
399.777
1
400.143
1
387.055
1
408.657
1
399.474
1
387.085
1
389.168
1
391.726
1
382.769
1
378.703
1
402.188
1
400.332
1
396.667
1
408.72
1
396.462
1
399.466
1
384.801
1
384.028
1
385.096
1
375.654
1
381.015
1
388.16
1
376.761
1
386.908
1
389.838
1
386.057
1
408.789
1
407.766
1
388.954
1
379.76
1
376.553
1
390.911
1
383.267
1
394.392
1
387.699
1
398.059
1
401.573
1
379.212
1
384.448
1
387.389
1
385.572
1
397.435
1
393.833
1
387.97
1
382.196
1
384.555
1
380.459
1
373.84
1
396.346
1
393.972
1
401.314
1
386.363
1
391.64
1
390.629
1
387.726
1
377.496
1
398.217
1
393.532
1
401.23
1
384.462
1
380.652
1
373.986
1
387.788
1
385.798
1
383.07
1
395.588
1
380.176
1
397.441
1
393.452
1
398.25
1
378.742
1
382.71
1
385.789
1
382.44
1
381.512
1
382.092
1
385.548
1
381.277
1
401.593
1
385.831
1
377.531
1
380.215
1
385.307
1
382.416
1
401.117
1
400.894
1
388.924
1
386.604
1
384.84
1
390.528
1
388.157
1
389.71
1
Mn2p
550 C, 0.1 mbar O2
2026
2021
1
15
37
36
0
11
Casa Info Follows
0
0
0
0
none
Group: none
Analyzer Lens: none
Analyzer Slit: none
Scan Mode: none
c:\users\mark\desktop\ex165 - extract - mn2o3 in o2 2.vms
XPS
0
Al
1486.61
0
0
0
56.5
180
FAT
0
1
0
0
0
0
0
0
Mn2p

-1
kinetic energy
eV
816.61
0.1
2
counts
d
Transmission
d
pulse counting
1
1
0
0
0
0
2
ESCAPE DEPTH TYPE
d
0
MFP Exponent
d
0
802
187.069
1706.89
1
1
656.97
1
645.023
1
648.761
1
657.536
1
660.604
1
656.017
1
652.344
1
655.527
1
658.617
1
651.477
1
655.388
1
662.538
1
659.265
1
672.308
1
669.306
1
661.601
1
663.249
1
661.906
1
663.494
1
663.309
1
674.289
1
665.929
1
677.713
1
670.395
1
657.497
1
667.276
1
675.825
1
665.217
1
675.484
1
678.07
1
677.36
1
676.303
1
683.473
1
684.226
1
675.088
1
682.334
1
695.208
1
689.559
1
688.163
1
693.38
1
691.729
1
693.047
1
692.065
1
709.073
1
707.749
1
709.261
1
709.629
1
705.986
1
709.973
1
713.243
1
722.944
1
716.856
1
717.426
1
724.787
1
725.186
1
725.306
1
720.985
1
727.822
1
736.042
1
744.328
1
732.654
1
743.315
1
747.471
1
754.997
1
749.435
1
738.93
1
750.779
1
750.796
1
760.329
1
751.332
1
763.214
1
752.985
1
751.073
1
766.369
1
758.368
1
760.835
1
754.122
1
758.887
1
750.531
1
756.025
1
744.359
1
738.599
1
735.871
1
734.421
1
738.705
1
739.199
1
728.945
1
725.441
1
719.683
1
719.096
1
721.477
1
727.199
1
716.424
1
717.036
1
724.234
1
714.08
1
713.685
1
705.264
1
713.188
1
705.144
1
710.149
1
715.088
1
718.364
1
699.149
1
696.604
1
702.296
1
703.601
1
703.203
1
700.735
1
715.319
1
697.831
1
695.517
1
708.155
1
713.089
1
714.954
1
712.046
1
711.789
1
723.904
1
711.947
1
711.877
1
717.951
1
726.532
1
732.797
1
729.752
1
729.065
1
730.785
1
739.959
1
744.791
1
752.375
1
769.037
1
762.052
1
760.464
1
762.412
1
773.872
1
788.347
1
795.663
1
798.847
1
809.896
1
821.274
1
824.914
1
842.237
1
844.717
1
861.851
1
873.96
1
874.452
1
883.36
1
892.605
1
920.555
1
951.335
1
954.419
1
972.047
1
984.975
1
1004.61
1
1015.03
1
1040.28
1
1068.36
1
1082.37
1
1112.4
1
1142.1
1
1165.1
1
1197.37
1
1224.23
1
1241.98
1
1270.84
1
1276.15
1
1306.14
1
1319.15
1
1342.78
1
1341.09
1
1341
1
1345.24
1
1342.74
1
1353.02
1
1354.43
1
1313.7
1
1290.97
1
1275.11
1
1246.7
1
1231.73
1
1202.48
1
1165.1
1
1129.51
1
1101.45
1
1056
1
1025.14
1
990.276
1
953.112
1
922.618
1
887.556
1
878.554
1
853.763
1
826.264
1
806.391
1
789.64
1
779.625
1
753.546
1
737.417
1
734.023
1
721.777
1
712.425
1
702.045
1
703.942
1
689.105
1
682.606
1
684.949
1
666.783
1
664.202
1
655.409
1
650.98
1
650.751
1
647.603
1
640.958
1
638.376
1
627.681
1
625.747
1
619.57
1
620.183
1
622.504
1
613.901
1
612.989
1
613.961
1
615.608
1
613.541
1
609.374
1
608.724
1
616.591
1
611.256
1
618.088
1
616.192
1
622.366
1
623.086
1
629.994
1
635.987
1
632.314
1
642.235
1
635.861
1
646.07
1
664.269
1
654.268
1
668.307
1
669.068
1
670.433
1
680.463
1
690.317
1
699.498
1
701.853
1
704.964
1
709.155
1
722.107
1
730.054
1
741.379
1
751.527
1
764.219
1
776.245
1
793.744
1
806.01
1
823.514
1
838.546
1
843.753
1
853.923
1
881.516
1
883.559
1
914.327
1
954.344
1
977.483
1
1003.18
1
1038
1
1063.71
1
1107.91
1
1147.29
1
1177.01
1
1231.53
1
1269.97
1
1314.46
1
1357.43
1
1395.25
1
1452.37
1
1487.42
1
1517.14
1
1566.31
1
1597.71
1
1615.04
1
1621.14
1
1665.36
1
1662.88
1
1677.12
1
1689.89
1
1699.82
1
1706.89
1
1703.74
1
1674.74
1
1651.96
1
1626.05
1
1568.65
1
1506.64
1
1449.76
1
1367.1
1
1263.26
1
1170.6
1
1054.55
1
944.256
1
834.777
1
735.477
1
646.483
1
564.386
1
511.772
1
446.394
1
398.264
1
360.699
1
328.086
1
302.654
1
273.919
1
264.316
1
250.393
1
246.693
1
237.059
1
232.311
1
228.082
1
228.039
1
227.551
1
216.672
1
213.512
1
208.512
1
211.238
1
209.113
1
211.195
1
209.028
1
207.227
1
208.49
1
206.118
1
210.326
1
204.716
1
200.402
1
202.451
1
202.265
1
199.309
1
197.897
1
198.313
1
201.383
1
200.724
1
202.179
1
197.561
1
194.055
1
197.24
1
200.542
1
195.507
1
194.471
1
197.068
1
200.29
1
194.116
1
197.85
1
191.489
1
194.218
1
191.262
1
190.827
1
198.698
1
195.744
1
189.299
1
196.756
1
195.952
1
198.925
1
194.278
1
190.538
1
192.832
1
195.649
1
194.832
1
197.058
1
193.231
1
193.994
1
193.11
1
193.902
1
197.892
1
200.446
1
189.494
1
188.483
1
190.197
1
195.622
1
192.466
1
191.936
1
188.993
1
187.069
1
197.598
1
189.661
1
190.01
1
193.542
1
189.61
1
193.26
1
187.264
1
189.385
1
189.616
1
196.269
1
193.223
1
194.841
1
193.254
1
188.906
1
193.968
1
196.709
1
191.424
1
188.02
1
190.098
1
189.197
1
Mn2p
750 C, 0.1 mbar O2 (Mn2O3)
2026
2021
1
15
37
54
0
11
Casa Info Follows
0
0
0
0
none
Group: none
Analyzer Lens: none
Analyzer Slit: none
Scan Mode: none
c:\users\mark\desktop\ex165 - extract - mn2o3 in o2 1.vms
XPS
0
Al
1486.61
0
0
0
56.5
180
FAT
0
1
0
0
0
0
0
0
Mn2p

-1
kinetic energy
eV
816.61
0.1
2
counts
d
Transmission
d
pulse counting
1
1
0
0
0
0
2
ESCAPE DEPTH TYPE
d
0
MFP Exponent
d
0
802
142.96
1419.54
1
1
514.139
1
515.628
1
515.692
1
520.968
1
522.458
1
521.747
1
519.825
1
520.226
1
522.865
1
521.351
1
520.285
1
521.566
1
524.171
1
525.211
1
524.999
1
526.919
1
516.531
1
524.852
1
527.522
1
532.36
1
532.399
1
530.584
1
531.145
1
530.752
1
528.3
1
528.553
1
528.624
1
531.595
1
533.37
1
533.135
1
536.089
1
538.361
1
539.288
1
539.896
1
532.739
1
535.614
1
538.782
1
544.401
1
542.178
1
544.445
1
548.891
1
549.878
1
547.515
1
554.311
1
554.195
1
553.321
1
556.877
1
558.671
1
559.207
1
559.955
1
559.411
1
563.167
1
566.699
1
566.724
1
562.971
1
567.004
1
567.059
1
573.341
1
576.756
1
576.204
1
578.781
1
581.591
1
581.529
1
579.051
1
584.019
1
578.678
1
578.191
1
585.389
1
585.168
1
587.021
1
588.802
1
585.282
1
586.113
1
585.282
1
587.362
1
588.069
1
586.251
1
587.964
1
584.927
1
583.245
1
589.122
1
584.772
1
582.071
1
578.026
1
582.575
1
580.607
1
576.852
1
573.183
1
570.869
1
575.729
1
576.441
1
571.155
1
567.594
1
573.526
1
570.803
1
566.716
1
575.026
1
573.719
1
572.151
1
577.016
1
573.468
1
576.102
1
574.699
1
576.178
1
579.248
1
580.013
1
581.694
1
583.631
1
583.758
1
583.389
1
579.691
1
583.931
1
587.128
1
586.204
1
591.364
1
591.715
1
596.139
1
594.344
1
593.894
1
592.46
1
599.082
1
597.141
1
593.785
1
597.923
1
609.17
1
610.902
1
603.01
1
609.286
1
616.398
1
620.818
1
620.499
1
630.468
1
628.59
1
633.245
1
636.79
1
633.531
1
643.875
1
652.08
1
662.606
1
669.198
1
677.59
1
682.895
1
693.641
1
697.158
1
705.185
1
721.016
1
726.459
1
735.857
1
747.769
1
760.143
1
771.177
1
787.827
1
808.55
1
824.439
1
840.733
1
858.841
1
868.716
1
885.889
1
905.945
1
927.771
1
949.748
1
967.765
1
983.515
1
1009.36
1
1036.59
1
1042.61
1
1054.58
1
1056.63
1
1077.25
1
1081.15
1
1081.02
1
1078.76
1
1075.21
1
1069.31
1
1059.39
1
1056.25
1
1041.12
1
1023.15
1
1001.58
1
993.674
1
966.202
1
929.591
1
903.506
1
873.319
1
854.143
1
831.69
1
801.309
1
769.476
1
755.069
1
731.752
1
702.278
1
687.706
1
675.591
1
656.29
1
636.106
1
624.451
1
608.53
1
595.491
1
581.427
1
581.78
1
572.065
1
565.514
1
556.113
1
545.548
1
540.952
1
534.955
1
529.129
1
520.715
1
521.784
1
525.694
1
521.815
1
520.367
1
517.508
1
519.097
1
519.504
1
522.052
1
519.028
1
521.709
1
524.088
1
526.723
1
527.645
1
530.577
1
523.997
1
533.108
1
531.711
1
540.179
1
536.357
1
539.983
1
537.939
1
538.628
1
550.668
1
554.169
1
553.075
1
556.627
1
559.495
1
563.091
1
570.108
1
574.941
1
569.659
1
574.129
1
576.564
1
577.453
1
577.874
1
587.023
1
592.976
1
602.337
1
605.683
1
605.895
1
614.875
1
624.064
1
628.235
1
639.71
1
649.282
1
652.413
1
660.514
1
676.549
1
689.769
1
695.96
1
705.47
1
730.104
1
736.643
1
754.164
1
773.306
1
792.946
1
810.659
1
824.105
1
852.946
1
876.745
1
908.004
1
933.747
1
974.447
1
999.339
1
1037.49
1
1069.01
1
1102.2
1
1136.62
1
1170.15
1
1207.57
1
1249.45
1
1270.33
1
1293.3
1
1328.72
1
1363.84
1
1371.98
1
1384.99
1
1392.71
1
1403.44
1
1414.07
1
1413.67
1
1414.47
1
1419.54
1
1414.7
1
1393.17
1
1376.01
1
1340.48
1
1298.82
1
1231.97
1
1156.85
1
1077.12
1
998.224
1
921.149
1
850.191
1
771.484
1
702.439
1
639.565
1
573.187
1
514.789
1
462.82
1
414.923
1
364.148
1
320.508
1
285.195
1
259.049
1
236.321
1
217.68
1
204.817
1
201.551
1
190.976
1
180.585
1
177.133
1
173.981
1
172.869
1
168.862
1
168.795
1
167.151
1
163.08
1
161.958
1
162.399
1
158.214
1
158.495
1
160.552
1
157.455
1
157.934
1
156.698
1
157.005
1
155.235
1
151.276
1
154.976
1
155.754
1
153.594
1
150.876
1
150.707
1
152.492
1
149.029
1
147.919
1
150.905
1
148.817
1
151.203
1
149.112
1
150.226
1
150.761
1
147.375
1
152.243
1
150.86
1
152.261
1
147.482
1
148.784
1
148.55
1
147.15
1
147.057
1
144.898
1
145.818
1
149.184
1
149.588
1
148.38
1
145.953
1
147.222
1
145.149
1
147.781
1
148.895
1
150.388
1
145.663
1
147.854
1
145.266
1
142.96
1
145.541
1
146.936
1
148.289
1
147.34
1
147.861
1
149.87
1
148.708
1
147.347
1
146.947
1
146.058
1
147.895
1
146.806
1
145.923
1
147.296
1
146.314
1
146.355
1
145.821
1
148.149
1
145.809
1
143.338
1
147.536
1
148.552
1
147.738
1
147.326
1
150.298
1
146.724
1
Mn2p
Heating 100 C in vacuum, MnO2
2018
2
3
0
55
31
0
18
Casa Info Follows
0
0
0
0
File = C:/Users/Public/Documents/SpecsLab Prodigy/Experiments/Experiment 2018-02-02_MnO in H2.sle
Group = Heating 100 C in vacuum
First of group = 0
Analyzer lens = SmallArea:3.5kV
Analyzer slit = 4:7x20c\C:mesh
Scan mode = FixedAnalyzerTransmission
Kinetic energy start = 798.71
Kinetic energy base = 0
PCA Coefs = 38186.9, -240.926, 1267.03, -362.764, -6.96917,
PCA Coefs = 38186.1, 244.237, 1340.87, 66.9934,
PCA Coefs = 38186.1, 244.237, 1340.87, 66.9934,
C:\Users\Mark\ownCloud\Muelheim Group\Projects\MnOx references\Experiment 2018-02-02_MnO in H2 - removed bad spectra.vms
C:\Users\Mark\Desktop\MnO in H2-extract.vms
XPS
1
Al
1486.61
0
0
0
54.5
180
FAT
20
1
3.808
0
0
0
0
0
Mn2p

-1
kinetic energy
eV
798.71
0.1
2
counts
d
Transmission
d
pulse counting
0.4
2
0
0
0
0
2
ESCAPE DEPTH TYPE
d
1
MFP Exponent
d
0
1260
358.347
3750.34
2.09831
2.17975
1291.22
2.17975
1285.47
2.17961
1302.93
2.17947
1316.28
2.17934
1298.02
2.1792
1312.71
2.17906
1302.82
2.17893
1314.55
2.17879
1312.59
2.17865
1302.42
2.17851
1306.53
2.17838
1298.71
2.17824
1308.34
2.1781
1303.98
2.17797
1308.66
2.17783
1309.89
2.17769
1309.68
2.17756
1315.78
2.17742
1321.16
2.17728
1306.03
2.17715
1310.28
2.17701
1297.66
2.17687
1296.74
2.17674
1319.32
2.1766
1307.72
2.17646
1320.46
2.17633
1319.78
2.17619
1321.9
2.17606
1336.18
2.17592
1327.41
2.17578
1337.88
2.17565
1325.54
2.17551
1323.94
2.17537
1333.14
2.17524
1326.21
2.1751
1325.62
2.17496
1328.91
2.17483
1320.33
2.17469
1347.05
2.17456
1325.99
2.17442
1320.68
2.17428
1321.17
2.17415
1323.93
2.17401
1333.44
2.17388
1343.52
2.17374
1345.55
2.1736
1337.15
2.17347
1338.94
2.17333
1340.1
2.1732
1349.21
2.17306
1322.9
2.17292
1326.75
2.17279
1352.45
2.17265
1340.75
2.17252
1353.08
2.17238
1339.14
2.17225
1331.99
2.17211
1339.45
2.17197
1349.22
2.17184
1353.03
2.1717
1349.68
2.17157
1347.85
2.17143
1340.52
2.1713
1348.24
2.17116
1348.45
2.17103
1374.34
2.17089
1381.66
2.17075
1383.36
2.17062
1359.52
2.17048
1344.9
2.17035
1344.32
2.17021
1370.13
2.17008
1363.21
2.16994
1350.8
2.16981
1358.51
2.16967
1375
2.16954
1376.47
2.1694
1381.8
2.16927
1372.24
2.16913
1373.11
2.169
1373.55
2.16886
1367.87
2.16873
1364.46
2.16859
1369.01
2.16846
1386.19
2.16832
1387.12
2.16819
1372.78
2.16805
1365.38
2.16792
1380.01
2.16778
1384.7
2.16765
1378.39
2.16751
1383.75
2.16738
1387.02
2.16724
1385.84
2.16711
1390.42
2.16697
1390.57
2.16684
1383.48
2.1667
1382.18
2.16657
1388.1
2.16643
1391.42
2.1663
1401.27
2.16616
1387.16
2.16603
1382.66
2.1659
1398.44
2.16576
1402.65
2.16563
1394.23
2.16549
1416.62
2.16536
1412.14
2.16522
1417.45
2.16509
1406.32
2.16495
1400.7
2.16482
1404.12
2.16469
1393.36
2.16455
1393.92
2.16442
1396.49
2.16428
1389.39
2.16415
1416.57
2.16402
1393.16
2.16388
1407.31
2.16375
1429.27
2.16361
1408.51
2.16348
1404.76
2.16334
1405.13
2.16321
1409.44
2.16308
1401.05
2.16294
1421.44
2.16281
1427.96
2.16267
1403.16
2.16254
1408.67
2.16241
1407.61
2.16227
1406.77
2.16214
1420.8
2.16201
1429.54
2.16187
1419.68
2.16174
1416.48
2.1616
1405.79
2.16147
1406.79
2.16134
1410.24
2.1612
1400
2.16107
1403.13
2.16094
1408.92
2.1608
1399.56
2.16067
1395.07
2.16054
1395.24
2.1604
1403.25
2.16027
1399.36
2.16013
1408.02
2.16
1414.26
2.15987
1400.47
2.15973
1394.26
2.1596
1393.51
2.15947
1386.41
2.15933
1386.78
2.1592
1415.98
2.15907
1396.77
2.15893
1403.38
2.1588
1386.53
2.15867
1396.87
2.15854
1403.85
2.1584
1402.58
2.15827
1403.84
2.15814
1389.51
2.158
1384.84
2.15787
1406.75
2.15774
1392.61
2.1576
1389.57
2.15747
1384.01
2.15734
1403.89
2.15721
1401.08
2.15707
1381.03
2.15694
1386.54
2.15681
1393.2
2.15667
1384.19
2.15654
1393.09
2.15641
1388.65
2.15628
1387.1
2.15614
1390.98
2.15601
1376.76
2.15588
1379.95
2.15574
1389.96
2.15561
1380.75
2.15548
1396.28
2.15535
1407.15
2.15521
1396.71
2.15508
1396.6
2.15495
1388.95
2.15482
1410.27
2.15468
1402.19
2.15455
1412.72
2.15442
1420.3
2.15429
1407.85
2.15416
1402.24
2.15402
1408.47
2.15389
1395.35
2.15376
1402.15
2.15363
1395.39
2.15349
1402.75
2.15336
1408.93
2.15323
1398.37
2.1531
1404.71
2.15297
1404.46
2.15283
1411.54
2.1527
1429.01
2.15257
1408.11
2.15244
1417.94
2.1523
1420.72
2.15217
1432.5
2.15204
1426.73
2.15191
1426.07
2.15178
1439.41
2.15165
1436.02
2.15151
1432.04
2.15138
1438.66
2.15125
1436.78
2.15112
1436.96
2.15099
1448.37
2.15085
1426.43
2.15072
1447.69
2.15059
1436.8
2.15046
1442.3
2.15033
1444.37
2.1502
1452.55
2.15006
1471.99
2.14993
1458.51
2.1498
1469.7
2.14967
1461.73
2.14954
1474.2
2.14941
1493.24
2.14928
1477.4
2.14914
1490.99
2.14901
1490.58
2.14888
1483.31
2.14875
1475.05
2.14862
1503.82
2.14849
1494.78
2.14836
1496.35
2.14822
1508.67
2.14809
1509.01
2.14796
1522.82
2.14783
1518.62
2.1477
1513.87
2.14757
1524.66
2.14744
1534.23
2.14731
1534.41
2.14718
1524.1
2.14704
1529
2.14691
1540.45
2.14678
1541.04
2.14665
1531.12
2.14652
1532.05
2.14639
1528.83
2.14626
1523.76
2.14613
1519.16
2.146
1517.29
2.14587
1508.55
2.14574
1512.44
2.1456
1513.43
2.14547
1504.76
2.14534
1519.39
2.14521
1502.45
2.14508
1493.41
2.14495
1484.6
2.14482
1481.26
2.14469
1468.95
2.14456
1490.22
2.14443
1454.88
2.1443
1452.5
2.14417
1478.72
2.14404
1467.23
2.14391
1463.22
2.14378
1453.59
2.14365
1454
2.14352
1480.77
2.14338
1454.97
2.14325
1465.9
2.14312
1450.69
2.14299
1461.88
2.14286
1457.21
2.14273
1469.73
2.1426
1464.34
2.14247
1456.17
2.14234
1472.2
2.14221
1459.3
2.14208
1480.05
2.14195
1479.29
2.14182
1484.19
2.14169
1469.3
2.14156
1463.44
2.14143
1490.34
2.1413
1495.43
2.14117
1493.08
2.14104
1483.64
2.14091
1510.51
2.14078
1512.53
2.14065
1502.67
2.14052
1509.34
2.14039
1505.45
2.14026
1514.78
2.14013
1512.63
2.14
1482.63
2.13987
1482.41
2.13974
1509.49
2.13961
1530.03
2.13948
1512.96
2.13936
1535.67
2.13923
1528.71
2.1391
1550.16
2.13897
1546.92
2.13884
1563.24
2.13871
1577.44
2.13858
1587.63
2.13845
1596.87
2.13832
1586.69
2.13819
1607.82
2.13806
1620.1
2.13793
1646.12
2.1378
1659.39
2.13767
1685.18
2.13754
1716.44
2.13741
1713.48
2.13728
1744.67
2.13715
1765.64
2.13703
1783.08
2.1369
1836.48
2.13677
1844.22
2.13664
1858.37
2.13651
1894.5
2.13638
1937.34
2.13625
1954.63
2.13612
2022.16
2.13599
2051.2
2.13586
2094.11
2.13573
2142.12
2.13561
2180.16
2.13548
2245.17
2.13535
2287.65
2.13522
2327.7
2.13509
2388.21
2.13496
2466.05
2.13483
2499.91
2.1347
2556.33
2.13458
2592.81
2.13445
2659.85
2.13432
2690.5
2.13419
2716.24
2.13406
2738.09
2.13393
2749.37
2.1338
2771.23
2.13367
2750.32
2.13355
2729.88
2.13342
2731.96
2.13329
2725.26
2.13316
2694.79
2.13303
2676.5
2.1329
2607.56
2.13277
2562.12
2.13265
2506.38
2.13252
2449.59
2.13239
2350.71
2.13226
2286.01
2.13213
2207.47
2.132
2163.33
2.13188
2079.33
2.13175
2022.63
2.13162
1969.68
2.13149
1903.56
2.13136
1858.98
2.13124
1802.04
2.13111
1735.28
2.13098
1697.79
2.13085
1620.56
2.13072
1590.62
2.13059
1558.08
2.13047
1511.61
2.13034
1483.72
2.13021
1450.82
2.13008
1400.16
2.12995
1397.57
2.12983
1364.86
2.1297
1355.88
2.12957
1335.05
2.12944
1308.06
2.12932
1321.08
2.12919
1301.41
2.12906
1274.47
2.12893
1288.43
2.1288
1272.24
2.12868
1264.08
2.12855
1272.5
2.12842
1266.98
2.12829
1264.5
2.12817
1267.53
2.12804
1268.93
2.12791
1291.97
2.12778
1290.78
2.12766
1277.27
2.12753
1266.3
2.1274
1290.38
2.12727
1309.56
2.12715
1312.85
2.12702
1309.25
2.12689
1315.93
2.12676
1314.07
2.12664
1342.59
2.12651
1327.06
2.12638
1332.56
2.12625
1348.31
2.12613
1345.39
2.126
1329.13
2.12587
1355.66
2.12575
1382.83
2.12562
1401.67
2.12549
1387.92
2.12536
1384.02
2.12524
1423.15
2.12511
1413.09
2.12498
1418.66
2.12486
1411.99
2.12473
1448.46
2.1246
1446.91
2.12448
1433.62
2.12435
1458.03
2.12422
1462.42
2.12409
1480.21
2.12397
1492.84
2.12384
1515.72
2.12371
1526.6
2.12359
1540.1
2.12346
1571.23
2.12333
1574.07
2.12321
1609.82
2.12308
1634.82
2.12295
1670.6
2.12283
1680.7
2.1227
1711.56
2.12257
1752.45
2.12245
1794.21
2.12232
1830.03
2.12219
1887.57
2.12207
1914.28
2.12194
1958.7
2.12181
2006.9
2.12169
2074.38
2.12156
2126.7
2.12144
2182.86
2.12131
2253.68
2.12118
2328.59
2.12106
2416.59
2.12093
2517.11
2.1208
2607.77
2.12068
2689.76
2.12055
2788.68
2.12042
2890.42
2.1203
2978.16
2.12017
3046.7
2.12005
3134.36
2.11992
3248.28
2.11979
3333.83
2.11967
3407.19
2.11954
3473.86
2.11942
3501.78
2.11929
3509.56
2.11916
3570.5
2.11904
3586.64
2.11891
3567.66
2.11879
3579.09
2.11866
3578.48
2.11853
3636.26
2.11841
3683.65
2.11828
3718.92
2.11816
3704.54
2.11803
3650.14
2.1179
3500.44
2.11778
3283.38
2.11765
3058.8
2.11753
2803.76
2.1174
2580.74
2.11728
2365.77
2.11715
2179.93
2.11703
2035.75
2.1169
1934.85
2.11677
1806.62
2.11665
1640.04
2.11652
1473.44
2.1164
1294.37
2.11627
1111.69
2.11615
956.873
2.11602
829.039
2.1159
732.444
2.11577
651.776
2.11564
592.472
2.11552
554.556
2.11539
515.107
2.11527
503.714
2.11514
500.549
2.11502
474.273
2.11489
460.026
2.11477
468.327
2.11464
456.224
2.11452
444.473
2.11439
442.059
2.11427
426.718
2.11414
435.446
2.11402
435.848
2.11389
423.285
2.11377
420.493
2.11364
426.748
2.11352
421.907
2.11339
421.719
2.11327
415.479
2.11314
408.656
2.11302
423.023
2.11289
417.931
2.11277
413.812
2.11264
411.356
2.11252
412.562
2.11239
404.316
2.11227
409.503
2.11214
403.83
2.11202
399.285
2.11189
387.936
2.11177
398.108
2.11164
398.073
2.11152
411.749
2.1114
407.033
2.11127
395.767
2.11115
393.164
2.11102
392.143
2.1109
404.465
2.11077
401.294
2.11065
399.875
2.11052
406.964
2.1104
384.301
2.11027
387.594
2.11015
388.192
2.11003
400.702
2.1099
398.567
2.10978
400.688
2.10965
394.044
2.10953
396.464
2.1094
394.682
2.10928
401.56
2.10916
396.228
2.10903
399.826
2.10891
390.444
2.10878
388.881
2.10866
389.857
2.10853
381.154
2.10841
380.003
2.10829
395.712
2.10816
392.854
2.10804
392.493
2.10791
383.734
2.10779
380.275
2.10767
396.006
2.10754
392.411
2.10742
394.765
2.10729
392.069
2.10717
392.668
2.10705
390.444
2.10692
386.748
2.1068
381.459
2.10668
390.636
2.10655
388.913
2.10643
394.897
2.1063
396.1
2.10618
392.024
2.10606
390.459
2.10593
393.961
2.10581
393.465
2.10569
386.454
2.10556
393.891
2.10544
389.526
2.10532
394.476
2.10519
385.972
2.10507
384.703
2.10495
373.845
2.10482
384.99
2.1047
390.217
2.10457
389.436
2.10445
384.692
2.10433
377.532
2.1042
389.43
2.10408
386.637
2.10396
385.165
2.10383
394.176
2.10371
380.107
2.10359
382.928
2.10347
385.876
2.10334
389.506
2.10322
382.496
2.1031
388.935
2.10297
380.802
2.10285
391.889
2.10273
383.108
2.1026
385.027
2.10248
390.626
2.10236
388.368
2.10223
383.452
2.10211
388.866
2.10199
390.751
2.10187
382.982
2.10174
388.919
2.10162
385.111
2.1015
393.897
2.10137
384.792
2.10125
390.831
2.10113
383.798
2.10101
390.335
2.10088
388.098
2.10076
388.355
2.10064
391.104
2.10051
389.779
2.10039
382.069
2.10027
387.182
2.10015
387.866
2.10002
379.022
2.0999
385.94
2.09978
389.597
2.09966
390.197
2.09953
398.15
2.09941
402.222
2.09929
391.945
2.09917
391.381
2.09904
389.776
2.09892
395.653
2.0988
388.574
2.09868
383.725
2.09855
386.758
2.09843
381.456
2.09831
end of experiment