File: xpsdeeplearning/data/references/Co_references.vms
VAMAS Surface Chemical Analysis Standard Data Transfer Format 1988 May 4
Not Specified
Not Specified
Not Specified
Not Specified
7
Casa Info Follows CasaXPS Version 2.3.24PR1.0
0
Created by SpecsLab Prodigy, Version 4.73.2-r95032
SourceAnalyserAngle: Not Specified
CasaRowLabel:Co metal
CasaRowLabel:CoO
CasaRowLabel:Co3O4
NORM
REGULAR
1
1
Exp Variable
d
0
0
0
0
3
Co2p
Co metal
2021
4
27
18
36
14
0
17
Casa Info Follows
0
0
0
0
File = E:/OwnCloud/XPS lab/EX491_S745_Co.sle
Group = RT in vacuum, #Treatments:4h sputter, #Temp:RT , #Pressure:vacuum , #Atmosphere:{:}, #Comments:
First of group = 0
Spectrum ID = 15
Analyzer lens = AngleResolvedMode22:1.5kV
Analyzer slit = 4:7x20c\C:mesh
Scan mode = FixedAnalyzerTransmission
Kinetic energy start = 646.61
PCA Coefs = 117821, -21153.7, -1403.13, 970.754, 1743.34,
C:\Users\Mark\Downloads\EX491_S745_Co (1).vms
c:\users\pielsticker\lukas\mpi-cec\projects\deepxps\xpsdeeplearning\data\references\nicofe\ex491-495 fe, ni, co oxide references.vms
C:\Users\pielsticker\Lukas\MPI-CEC\Projects\deepxps\xpsdeeplearning\data\references\NiCoFe\EX491-495 FeCo summed.vms
XPS
1
Al
1486.61
0
0
0
54.5
180
FAT
20
1
4.1408
0
0
0
0
0
Co
2p
-1
kinetic energy
eV
646.61
0.1
2
counts
d
Transmission
d
pulse counting
0.1
2
0
0
0
0
2
ESCAPE DEPTH TYPE
d
1
MFP Exponent
d
0
1402
2120.19
13889.6
1
1
4565.58
1
4573.78
1
4592.52
1
4594.61
1
4589.69
1
4625.72
1
4632.34
1
4631.83
1
4617.53
1
4622.36
1
4628.75
1
4610.33
1
4632.59
1
4652.39
1
4642.18
1
4638.13
1
4638.33
1
4636.05
1
4663.47
1
4659.32
1
4661.18
1
4667.98
1
4662.28
1
4655.87
1
4634.72
1
4634.58
1
4621.88
1
4640.71
1
4643.94
1
4641.59
1
4631.49
1
4605.81
1
4636.11
1
4633.43
1
4611.44
1
4623.11
1
4605.16
1
4584.81
1
4595.82
1
4589.15
1
4578.12
1
4587.29
1
4580.29
1
4540.5
1
4526.17
1
4526.69
1
4532.22
1
4489.65
1
4503.42
1
4509.74
1
4497.77
1
4503.13
1
4497.29
1
4512.85
1
4485.34
1
4494.74
1
4483.6
1
4474.39
1
4469.59
1
4451.37
1
4425.91
1
4467.92
1
4467.25
1
4444.25
1
4463.18
1
4484.65
1
4500.96
1
4465.22
1
4441.89
1
4448.85
1
4476.73
1
4486.37
1
4491.61
1
4511.35
1
4526.53
1
4512.47
1
4515.82
1
4521.5
1
4519.35
1
4519.94
1
4541.25
1
4560.45
1
4612.8
1
4626.28
1
4638.57
1
4605.67
1
4629.09
1
4643.45
1
4655.13
1
4652.27
1
4667.74
1
4654.73
1
4691.46
1
4699.84
1
4681.69
1
4657.73
1
4685.2
1
4652.53
1
4660.02
1
4649.62
1
4616.76
1
4623.6
1
4618.29
1
4610.17
1
4578.82
1
4569.14
1
4515.38
1
4510.69
1
4484.02
1
4465.77
1
4433.52
1
4385.32
1
4354.16
1
4367.07
1
4324.94
1
4286.76
1
4258.85
1
4232.18
1
4189.11
1
4181.66
1
4174.6
1
4162.63
1
4147.71
1
4100.91
1
4083.54
1
4068.67
1
4055.87
1
4063.55
1
4036.66
1
4038.03
1
4002.93
1
4013.89
1
3994.06
1
3977.06
1
3986.67
1
3986.11
1
3961.77
1
3941.76
1
3968.53
1
3960.37
1
3954.85
1
3917.05
1
3915.17
1
3928.73
1
3917.22
1
3947.12
1
3931.18
1
3917.23
1
3902.98
1
3872
1
3911.59
1
3914.28
1
3908.09
1
3940.57
1
3932.52
1
3892.21
1
3920.19
1
3939.9
1
3910.85
1
3890.28
1
3878
1
3907.75
1
3899.35
1
3867.71
1
3884.25
1
3891.64
1
3893.9
1
3913.15
1
3901.38
1
3914.45
1
3882.95
1
3893.55
1
3911.72
1
3884.93
1
3902.85
1
3912.22
1
3885.39
1
3878.58
1
3909.17
1
3928.02
1
3910.91
1
3916.38
1
3923.95
1
3932.93
1
3886.43
1
3887.47
1
3892.57
1
3925.69
1
3912.36
1
3891.64
1
3900.66
1
3902.32
1
3930.83
1
3916.06
1
3909.01
1
3932.12
1
3931.42
1
3899.78
1
3895.55
1
3898.03
1
3918.04
1
3911.14
1
3898.61
1
3916.07
1
3938.36
1
3929.22
1
3925.19
1
3918.33
1
3940.54
1
3972.24
1
3966.15
1
3932.3
1
3921.75
1
3952.09
1
3946.19
1
3953.93
1
3964.75
1
3978.08
1
3943.78
1
3975.15
1
3966.39
1
3953.27
1
3981.42
1
3951.86
1
3978.86
1
3985.28
1
3985.37
1
3973.32
1
3986.93
1
3951.53
1
3955.54
1
3980.08
1
3993.82
1
4006.91
1
4013.88
1
4012.95
1
4004.59
1
3996.62
1
4014.7
1
4018.43
1
4011.66
1
4024.78
1
4008.87
1
4027.81
1
4022.19
1
4028.99
1
4039.46
1
4033.2
1
4063.18
1
4049.45
1
4039.69
1
4061.92
1
4065.55
1
4095.46
1
4069.28
1
4068.61
1
4057.23
1
4059.45
1
4085.93
1
4083.34
1
4055.85
1
4065.13
1
4051.45
1
4058.02
1
4064.88
1
4068.04
1
4055.55
1
4055.36
1
4047.27
1
4053.44
1
4045.58
1
4048.7
1
4022.46
1
4064.16
1
4058.76
1
4031.75
1
4029.82
1
4037.41
1
4010.65
1
4031.14
1
4028.63
1
4022.63
1
4041.42
1
4022.72
1
4043.11
1
4027.42
1
4054.13
1
4028.87
1
4024.91
1
4033.74
1
4041.64
1
4020.82
1
4054.24
1
4054.77
1
4040.36
1
4027.76
1
4036.72
1
4051.28
1
4027.17
1
4038.59
1
4053.37
1
4051.15
1
4053.17
1
4061.02
1
4055.42
1
4048.65
1
4074.19
1
4067.43
1
4091.31
1
4098.42
1
4093.23
1
4056.82
1
4064.68
1
4075.78
1
4089.18
1
4080.15
1
4100.41
1
4073.47
1
4069.8
1
4098.24
1
4089.62
1
4080.22
1
4071.68
1
4090.51
1
4115.9
1
4121.8
1
4112.85
1
4104.45
1
4149.54
1
4124.48
1
4138.13
1
4148.64
1
4170.52
1
4164.72
1
4188.67
1
4180.95
1
4165.31
1
4181.17
1
4187.54
1
4178.91
1
4180.78
1
4170.71
1
4227.2
1
4204.86
1
4202.67
1
4193.58
1
4197.05
1
4206.8
1
4199.6
1
4190.95
1
4209.2
1
4203.65
1
4226.81
1
4216.54
1
4217.43
1
4223.24
1
4229.41
1
4207.41
1
4240.63
1
4227.9
1
4233.24
1
4233.87
1
4252.25
1
4245.27
1
4257.93
1
4271.98
1
4245.85
1
4271.46
1
4273.98
1
4270.29
1
4272.6
1
4269.69
1
4281.04
1
4281.05
1
4311.61
1
4310.13
1
4282.84
1
4300.29
1
4320.27
1
4322.87
1
4341.28
1
4316.74
1
4316.45
1
4353.22
1
4329.21
1
4297.05
1
4319.06
1
4356.98
1
4376.28
1
4332.61
1
4350.19
1
4331.19
1
4359.29
1
4372.86
1
4362.28
1
4350.3
1
4377.97
1
4384.89
1
4408.84
1
4374.81
1
4374.07
1
4391.63
1
4399.03
1
4430.32
1
4450.77
1
4432.11
1
4436.09
1
4435.21
1
4448.8
1
4467.75
1
4474.36
1
4483.76
1
4497.12
1
4507.46
1
4527.36
1
4554.93
1
4544.55
1
4537.73
1
4556.31
1
4579.77
1
4577.42
1
4561.8
1
4623.04
1
4629.61
1
4633.98
1
4655.1
1
4667.86
1
4705.97
1
4730.06
1
4735.01
1
4752.94
1
4762.72
1
4792.45
1
4828.71
1
4828.7
1
4886.79
1
4913.73
1
4912.83
1
4935.49
1
4970.35
1
5023.92
1
5003.6
1
5051.46
1
5095.98
1
5137.54
1
5176.99
1
5229.74
1
5275.57
1
5304.85
1
5395.1
1
5429.72
1
5489.65
1
5540.86
1
5613.38
1
5699.42
1
5753.3
1
5831.5
1
5898.96
1
5980.26
1
6059.09
1
6178.68
1
6314.94
1
6411.18
1
6580.71
1
6699.06
1
6811.43
1
6936.81
1
7019.51
1
7041.27
1
7002.25
1
6864.2
1
6666.02
1
6434.5
1
6160.47
1
5878.15
1
5568.63
1
5279.12
1
5042.33
1
4837.55
1
4678.37
1
4510.26
1
4388.43
1
4303.01
1
4220.3
1
4147.16
1
4148.13
1
4054.21
1
4026.64
1
4015.76
1
4003.33
1
3955.86
1
3933.92
1
3904.73
1
3885.48
1
3875.89
1
3872.25
1
3829.81
1
3833.4
1
3830.76
1
3818.97
1
3824.02
1
3833.07
1
3813.13
1
3829
1
3808.58
1
3816.19
1
3820.59
1
3836.14
1
3851.1
1
3846.77
1
3837.17
1
3852.67
1
3853.64
1
3858.56
1
3896.86
1
3906.7
1
3901.95
1
3898.55
1
3884.65
1
3907.55
1
3933.9
1
3938.84
1
3931.22
1
3945.38
1
3945.76
1
3973.09
1
3988.31
1
3951.12
1
3970.79
1
3978
1
4011.65
1
4007.99
1
4008.87
1
4017.56
1
4024.89
1
4042.1
1
4070.59
1
4075.64
1
4066.28
1
4088.84
1
4091.6
1
4120.27
1
4107.12
1
4119.94
1
4126.51
1
4146.41
1
4135.17
1
4189.59
1
4216.82
1
4203.09
1
4203.86
1
4211.39
1
4242.9
1
4239.47
1
4277.85
1
4321.15
1
4327.86
1
4336.87
1
4344.37
1
4350.66
1
4360.84
1
4415.33
1
4399.67
1
4435.12
1
4454.85
1
4492.73
1
4494.65
1
4496.45
1
4550.34
1
4589.65
1
4615.25
1
4643.2
1
4683.1
1
4683.46
1
4720.65
1
4736.58
1
4789.94
1
4824.6
1
4822.89
1
4823.44
1
4875.44
1
4914.05
1
4888.3
1
4912.45
1
4905.75
1
4944.81
1
4961.19
1
4943.26
1
4970.8
1
5034.78
1
5025.78
1
5072.26
1
5151.96
1
5199.74
1
5242.44
1
5270.47
1
5403.71
1
5465.66
1
5529.36
1
5661.11
1
5744.31
1
5868.5
1
5997.12
1
6158.41
1
6342.74
1
6468.35
1
6720.09
1
6931.28
1
7225.09
1
7534.2
1
7946.21
1
8467.86
1
9085.86
1
9874.31
1
10799.3
1
11826.9
1
12812.9
1
13570.3
1
13923.1
1
13602.9
1
12656.8
1
11198.9
1
9520.84
1
7833.75
1
6439.82
1
5397.08
1
4667.5
1
4182.13
1
3815.72
1
3572.46
1
3406.33
1
3281.26
1
3175.14
1
3117.13
1
3049.81
1
2975.06
1
2948.42
1
2919.17
1
2884.24
1
2855.6
1
2843.81
1
2808.89
1
2803.59
1
2775.38
1
2766.78
1
2740.08
1
2693.98
1
2668.73
1
2657.65
1
2618.4
1
2593.98
1
2578.61
1
2536.15
1
2501.95
1
2483.01
1
2464.76
1
2433.08
1
2389.5
1
2370.49
1
2349.62
1
2376.13
1
2339.65
1
2307.94
1
2300.04
1
2282.35
1
2290.45
1
2300.01
1
2269.94
1
2253.01
1
2262.6
1
2265.68
1
2273.46
1
2271.7
1
2273.8
1
2264.05
1
2274.8
1
2272.8
1
2267.31
1
2259.87
1
2260.94
1
2283.3
1
2301.67
1
2283.84
1
2283.05
1
2300.14
1
2298.28
1
2283.51
1
2277.61
1
2288.35
1
2286.29
1
2286.73
1
2266.66
1
2255.9
1
2258.2
1
2230.89
1
2209.46
1
2186.02
1
2179.3
1
2177.35
1
2160.91
1
2138.65
1
Co2p
CoO
2021
4
29
9
50
16
0
17
Casa Info Follows
0
0
0
0
File = E:/OwnCloud/XPS lab/EX491_S745_Co.sle
Group = Loop 11_ RT in vacuum, #Treatments: , #Temp:RT , #Pressure:vacuum , #Atmosphere: , #Comments:
First of group = 0
Spectrum ID = 61
Analyzer lens = AngleResolvedMode22:1.5kV
Analyzer slit = 4:7x20c\C:mesh
Scan mode = FixedAnalyzerTransmission
Kinetic energy start = 646.61
PCA Coefs = 146858, 18127.4, -14522.3, -1131.5, -938.021,
C:\Users\Mark\Downloads\EX491_S745_Co (1).vms
c:\users\pielsticker\lukas\mpi-cec\projects\deepxps\xpsdeeplearning\data\references\nicofe\ex491-495 fe, ni, co oxide references.vms
C:\Users\pielsticker\Lukas\MPI-CEC\Projects\deepxps\xpsdeeplearning\data\references\NiCoFe\EX491-495 FeCo summed.vms
XPS
8
Al
1486.61
0
0
0
54.5
180
FAT
20
1
4.1408
0
0
0
0
0
Co
2p
-1
kinetic energy
eV
646.61
0.1
2
counts
d
Transmission
d
pulse counting
0.1
3
0
0
0
0
2
ESCAPE DEPTH TYPE
d
1
MFP Exponent
d
0
1402
2556.35
10658.9
1
1
5793.49
1
5769.83
1
5778.71
1
5793.63
1
5824.14
1
5800.77
1
5775.7
1
5779.5
1
5824.43
1
5771.05
1
5757.64
1
5800.48
1
5809.69
1
5781.79
1
5762.01
1
5820.93
1
5789.52
1
5789.72
1
5788.65
1
5747.62
1
5713.6
1
5735.09
1
5758.97
1
5782.19
1
5755.33
1
5754
1
5749.84
1
5760.21
1
5714.93
1
5730.73
1
5717.53
1
5733.84
1
5783.62
1
5764.39
1
5750.08
1
5706.17
1
5710.57
1
5775.05
1
5732.2
1
5732.33
1
5777.68
1
5752.96
1
5718.55
1
5719.85
1
5742.52
1
5758.4
1
5746.43
1
5736.17
1
5752.67
1
5776.23
1
5773.43
1
5773.14
1
5754.87
1
5717.55
1
5746.9
1
5749.14
1
5815.13
1
5783.64
1
5791.97
1
5801.8
1
5844.23
1
5776.14
1
5786.45
1
5787.41
1
5816.46
1
5779.54
1
5800.57
1
5833.82
1
5806.85
1
5810.39
1
5790.78
1
5766.05
1
5754.93
1
5803.2
1
5761.97
1
5762.91
1
5754.17
1
5784.2
1
5782.09
1
5750.94
1
5713.89
1
5714.6
1
5689.32
1
5687.11
1
5664.86
1
5622.49
1
5617.77
1
5622.64
1
5629.93
1
5591.64
1
5564.16
1
5495.03
1
5482.19
1
5499.92
1
5457.85
1
5396.59
1
5389.73
1
5393.43
1
5373.73
1
5359.55
1
5325.33
1
5311.19
1
5261.36
1
5226.56
1
5209.16
1
5250.1
1
5220.74
1
5187.71
1
5195.49
1
5147.97
1
5142.86
1
5137.96
1
5143.73
1
5071.07
1
5055.82
1
5061.95
1
5050.19
1
5084.71
1
5093.97
1
5024.79
1
5028.16
1
5022.74
1
4982
1
5011.43
1
4999.29
1
5000.47
1
4988.08
1
4978
1
4947.82
1
4990.69
1
4976.88
1
4985.71
1
4961.71
1
4955.57
1
4943.25
1
4928.93
1
4926.53
1
4905.66
1
4920.49
1
4930.85
1
4939.62
1
4921.31
1
4928.34
1
4902.63
1
4938.92
1
4917.99
1
4941.64
1
4939.42
1
4893.49
1
4892.88
1
4944.97
1
4896.84
1
4909.48
1
4881.53
1
4871.26
1
4919.57
1
4885.68
1
4846
1
4888.58
1
4911.27
1
4920.47
1
4925.96
1
4941.63
1
4917.94
1
4920.7
1
4906.33
1
4906.68
1
4931.43
1
4904.64
1
4922.6
1
4941.17
1
4914.76
1
4918.11
1
4946.79
1
4945.94
1
4897.61
1
4931.64
1
4952.05
1
4932
1
4918.49
1
4923.74
1
4933.57
1
4926.89
1
4898.44
1
4951.9
1
4938.59
1
4935
1
4967.75
1
4987.1
1
4979.03
1
4898.93
1
4958.6
1
4958.07
1
4954.99
1
4919.84
1
4935.87
1
4932
1
4956.8
1
4976.97
1
4943.39
1
4937.77
1
4967.86
1
4951.02
1
4962.1
1
4931.93
1
4946.7
1
4945.08
1
4941.64
1
4911.94
1
4886.15
1
4941.61
1
4917.3
1
4950.51
1
4915.77
1
4921.33
1
4939.12
1
4960.52
1
4934.6
1
4926.02
1
4893.77
1
4930.18
1
4896.72
1
4875.85
1
4914.02
1
4906.59
1
4914.23
1
4871.98
1
4861.96
1
4885.18
1
4896.42
1
4890.41
1
4859.55
1
4825.29
1
4845.6
1
4856.34
1
4841.85
1
4848.07
1
4842.62
1
4813.11
1
4793.02
1
4801.65
1
4775.01
1
4805.73
1
4779
1
4782.77
1
4734.47
1
4708.07
1
4729.81
1
4725.29
1
4705.84
1
4743
1
4715.95
1
4725.42
1
4701.5
1
4707.99
1
4698.6
1
4678.59
1
4621.68
1
4612.6
1
4634.59
1
4651.45
1
4615.01
1
4607.39
1
4609.12
1
4606.3
1
4621.14
1
4624.87
1
4592.67
1
4606.97
1
4570.15
1
4583.4
1
4594.43
1
4565.83
1
4563.91
1
4509.29
1
4551.23
1
4536.8
1
4521.57
1
4519.04
1
4528.22
1
4528.2
1
4514.42
1
4514.77
1
4525.51
1
4502.34
1
4496.64
1
4474.79
1
4480.22
1
4453.43
1
4444.93
1
4471.44
1
4469.89
1
4466.88
1
4465.54
1
4466.6
1
4458.35
1
4486.88
1
4488.34
1
4532.02
1
4475.85
1
4480.26
1
4494.58
1
4465.39
1
4464.14
1
4470.03
1
4487.05
1
4481.48
1
4488.48
1
4470
1
4460.89
1
4500.81
1
4553.73
1
4517.95
1
4529.47
1
4528.81
1
4573.75
1
4579.93
1
4608.2
1
4598.7
1
4640.74
1
4639.3
1
4634.6
1
4676.24
1
4739.9
1
4755.43
1
4710.06
1
4743.32
1
4774.89
1
4783.31
1
4758.91
1
4808.5
1
4837.09
1
4876.9
1
4866.84
1
4868.18
1
4913.6
1
4973.16
1
5006.32
1
5031.18
1
5094.28
1
5075.39
1
5124.06
1
5138.35
1
5157.11
1
5211.01
1
5253.13
1
5327.67
1
5353.55
1
5386.65
1
5418.48
1
5467.19
1
5527.44
1
5603.21
1
5638.88
1
5721.5
1
5788.28
1
5880.47
1
5949.27
1
6008.12
1
6089.39
1
6115.14
1
6213.68
1
6304.39
1
6342.57
1
6400.14
1
6535.83
1
6509.01
1
6550.05
1
6644.98
1
6655.68
1
6648.49
1
6623.17
1
6626.63
1
6589.09
1
6583.64
1
6552.61
1
6572.91
1
6441.04
1
6387.56
1
6362.13
1
6260.24
1
6213.49
1
6158.92
1
6114.09
1
6074.97
1
6000.26
1
5929.25
1
5851.27
1
5770.74
1
5760.73
1
5710.76
1
5667.82
1
5590.33
1
5554.29
1
5507.89
1
5494.05
1
5467.73
1
5443.64
1
5433.62
1
5405.48
1
5433.82
1
5417.93
1
5428.88
1
5445.45
1
5456.05
1
5488.54
1
5526.37
1
5547.86
1
5608.75
1
5667.34
1
5721.86
1
5774.46
1
5827.32
1
5902.81
1
6030.63
1
6105.55
1
6171.92
1
6227.55
1
6378.61
1
6460.31
1
6591.71
1
6670.09
1
6750.79
1
6777.2
1
6918.69
1
7056.07
1
7085.33
1
7121.49
1
7161.43
1
7222.61
1
7326.94
1
7344.73
1
7357.04
1
7385.39
1
7454.66
1
7461.28
1
7452.56
1
7464.74
1
7416.4
1
7403.89
1
7340.47
1
7331.99
1
7242.78
1
7131.03
1
7032.57
1
6991.16
1
6838.79
1
6660.16
1
6542.54
1
6354.83
1
6214.31
1
6054.99
1
5929.5
1
5718.51
1
5512.59
1
5345.22
1
5207.94
1
5051.97
1
4967.01
1
4882.2
1
4722.67
1
4660.17
1
4631.1
1
4591.16
1
4516.73
1
4494.35
1
4481.47
1
4454.85
1
4428.37
1
4416.59
1
4462.29
1
4432.81
1
4445.67
1
4462.12
1
4474.55
1
4516.75
1
4539.79
1
4517.93
1
4560.66
1
4585.08
1
4673.1
1
4696.88
1
4711.66
1
4727.76
1
4776.91
1
4765.07
1
4821.82
1
4874.11
1
4898.68
1
4907.77
1
4927.68
1
4969.74
1
4971.48
1
5018.38
1
5067.95
1
5056.2
1
5078.07
1
5098.25
1
5165.26
1
5182.56
1
5219.14
1
5245.78
1
5327.71
1
5341.41
1
5406.1
1
5434.44
1
5517.26
1
5602.97
1
5653.28
1
5735.73
1
5841.38
1
5884.38
1
5935.56
1
6026.6
1
6140.52
1
6243.54
1
6314.72
1
6337.17
1
6419.21
1
6501.65
1
6587.89
1
6626.41
1
6646.42
1
6740.91
1
6817.7
1
6846.04
1
6953.91
1
6953.9
1
7015.85
1
7047.98
1
7101.75
1
7165.33
1
7218.87
1
7266.27
1
7348
1
7371.05
1
7316.21
1
7382.63
1
7324.9
1
7293.03
1
7245.04
1
7177.46
1
7142.49
1
7045.02
1
7023.8
1
6895.23
1
6830.41
1
6739.48
1
6643.74
1
6632.25
1
6630.32
1
6591.83
1
6598.33
1
6575.15
1
6531.98
1
6613.92
1
6640.59
1
6651.93
1
6703.61
1
6743.4
1
6836.81
1
6923.2
1
6988.41
1
7081.4
1
7184.37
1
7309.88
1
7444.86
1
7566.28
1
7690.3
1
7807.2
1
7891.8
1
7959.14
1
8091.18
1
8233.31
1
8334.37
1
8417.31
1
8509.89
1
8613.45
1
8740.49
1
8852.38
1
8954.2
1
9055.61
1
9244.31
1
9333.22
1
9423.61
1
9568.04
1
9720.64
1
9835.06
1
9957.61
1
10032.5
1
10123.1
1
10254.2
1
10362.2
1
10486.6
1
10495.8
1
10500.9
1
10547.4
1
10490
1
10496.6
1
10331.7
1
10209.8
1
10073.6
1
9854.09
1
9648.25
1
9457.95
1
9177.54
1
8819.24
1
8416.77
1
8038.94
1
7675.15
1
7209.58
1
6694.9
1
6258.65
1
5863.55
1
5465.44
1
5114.25
1
4748.5
1
4484.21
1
4248.08
1
4071.84
1
3928.19
1
3848.2
1
3749.03
1
3687.68
1
3642.69
1
3563.91
1
3545.61
1
3541.72
1
3480.46
1
3484.22
1
3494.43
1
3428.99
1
3402.28
1
3393.13
1
3349.96
1
3340.49
1
3301.33
1
3313.93
1
3300.39
1
3295.76
1
3260.03
1
3221.01
1
3217.27
1
3215.73
1
3197.69
1
3178
1
3171.31
1
3186.18
1
3144.98
1
3147
1
3139.48
1
3094.96
1
3104.28
1
3102.71
1
3080.88
1
3092.66
1
3068.87
1
3061.28
1
3054.32
1
3047.58
1
3008.9
1
3022.82
1
3022.41
1
3026.81
1
3022.62
1
3013.82
1
2983.56
1
2994.07
1
3002.59
1
2952.01
1
2993.31
1
2985.52
1
2957.78
1
2975.44
1
2935.4
1
2942.52
1
2932.42
1
2944.54
1
2954.26
1
2946.27
1
2923.9
1
2912.64
1
2924.42
1
2942.57
1
2896.78
1
2881.23
1
2856.98
1
2848.07
1
2836.05
1
2813.23
1
2826.89
1
2817.17
1
2786.8
1
2732.04
1
2750.86
1
2744.78
1
2710.28
1
2679.96
1
2629.85
1
2620.59
1
2572.15
1
Co2p
Co3O4
2021
4
28
14
3
32
0
18
Casa Info Follows
0
0
0
0
File = E:/OwnCloud/XPS lab/EX491_S745_Co.sle
Group = Loop 5_ RT in vacuum, #Treatments: , #Temp:RT , #Pressure:vacuum , #Atmosphere: , #Comments:
First of group = 0
Spectrum ID = 35
Analyzer lens = AngleResolvedMode22:1.5kV
Analyzer slit = 4:7x20c\C:mesh
Scan mode = FixedAnalyzerTransmission
Kinetic energy start = 646.61
PCA Coefs = 121097, 10503.5, 4030.21, -1208.61, 399.219,
C:\Users\Mark\Downloads\EX491_S745_Co (1).vms
c:\users\pielsticker\lukas\mpi-cec\projects\deepxps\xpsdeeplearning\data\references\nicofe\ex491-495 fe, ni, co oxide references.vms
C:\Users\pielsticker\Lukas\MPI-CEC\Projects\deepxps\xpsdeeplearning\data\references\NiCoFe\EX491-495 FeCo summed.vms
CasaXP2
XPS
2
Al
1486.61
0
0
0
54.5
180
FAT
20
1
4.1408
0
0
0
0
0
Co
2p
-1
kinetic energy
eV
646.61
0.1
2
counts
d
Transmission
d
pulse counting
0.1
3
0
0
0
0
2
ESCAPE DEPTH TYPE
d
1
MFP Exponent
d
0
1402
2338.41
9790.8
1
1
4874.31
1
4899.15
1
4906.93
1
4914.08
1
4923.15
1
4897.92
1
4907
1
4928.19
1
4927.38
1
4947.5
1
4931.35
1
4913.69
1
4931.09
1
4936.01
1
4933.23
1
4935.56
1
4923.07
1
4909.71
1
4931.01
1
4933.03
1
4921.09
1
4904.73
1
4928.58
1
4916.7
1
4914.77
1
4922.88
1
4918.25
1
4918
1
4905.29
1
4910.8
1
4893.82
1
4890.32
1
4916.98
1
4909.28
1
4897.06
1
4900.35
1
4881.96
1
4878.58
1
4874.58
1
4868.89
1
4859.94
1
4872.63
1
4875.84
1
4859.41
1
4856.38
1
4866.25
1
4863.03
1
4872.76
1
4874.43
1
4862.53
1
4863.39
1
4878.97
1
4871.59
1
4866.55
1
4879.81
1
4872.64
1
4862.51
1
4866
1
4887.22
1
4866.54
1
4875.13
1
4880.45
1
4884.2
1
4885.64
1
4911.21
1
4895.37
1
4893.96
1
4892.06
1
4879.67
1
4885.18
1
4898.59
1
4879.6
1
4895.94
1
4892.78
1
4904.13
1
4899.4
1
4912.61
1
4905.63
1
4906.53
1
4898.28
1
4889.43
1
4876.57
1
4886.18
1
4885.57
1
4869.18
1
4865.32
1
4859.71
1
4886.91
1
4850.27
1
4859.12
1
4853.83
1
4833.74
1
4810.63
1
4819.77
1
4783.83
1
4775.12
1
4779.85
1
4765.22
1
4741.95
1
4709.28
1
4709.57
1
4680.19
1
4677.36
1
4646.65
1
4635.91
1
4618.38
1
4601.06
1
4588.43
1
4579.29
1
4568.01
1
4547.84
1
4529.83
1
4504.66
1
4494.87
1
4472.73
1
4472.21
1
4447.87
1
4431.17
1
4411.71
1
4397.97
1
4401.1
1
4393.04
1
4366.72
1
4368.73
1
4355.94
1
4357.21
1
4346.01
1
4324.82
1
4337.11
1
4327.33
1
4327.34
1
4324.08
1
4307.18
1
4300.96
1
4305.88
1
4302.02
1
4280.74
1
4281.88
1
4261.55
1
4277.74
1
4287
1
4287.11
1
4283.06
1
4270.49
1
4264.07
1
4274.99
1
4280.63
1
4279.19
1
4259.87
1
4263.41
1
4270.62
1
4264.62
1
4288.64
1
4272.78
1
4268.18
1
4255.22
1
4255.89
1
4264.57
1
4261.38
1
4264.49
1
4269
1
4272.93
1
4266.43
1
4262.87
1
4264.77
1
4266.04
1
4259.46
1
4252.46
1
4266.86
1
4269.63
1
4249.45
1
4274.79
1
4257.9
1
4270.52
1
4262.44
1
4253.34
1
4252.18
1
4255.8
1
4256.1
1
4268.83
1
4266.45
1
4262.11
1
4249.59
1
4245.01
1
4251.15
1
4250.65
1
4230.82
1
4241.03
1
4230.47
1
4242.17
1
4235.59
1
4234.01
1
4232.32
1
4226.46
1
4237.5
1
4233.36
1
4221.24
1
4215.75
1
4226.08
1
4221.33
1
4218.31
1
4194.32
1
4193.69
1
4222.88
1
4206.47
1
4210.82
1
4209.14
1
4190.1
1
4202.72
1
4213.22
1
4197.28
1
4202.51
1
4198.43
1
4198.24
1
4174.86
1
4205.3
1
4188.78
1
4213.26
1
4195.94
1
4175.4
1
4180.73
1
4194.95
1
4200.21
1
4179.21
1
4171.22
1
4182.66
1
4174.57
1
4179.69
1
4182.3
1
4176.19
1
4170.34
1
4160.72
1
4161.9
1
4155.85
1
4148.16
1
4143.33
1
4163.24
1
4160.28
1
4150.58
1
4130.58
1
4148.63
1
4138.35
1
4119.16
1
4132.09
1
4130.89
1
4122.1
1
4112.57
1
4126.78
1
4128.76
1
4122.8
1
4106.94
1
4122.81
1
4108.75
1
4080.16
1
4082.61
1
4092.82
1
4101.54
1
4095.26
1
4092.09
1
4089.29
1
4103.81
1
4101.88
1
4066.33
1
4077.52
1
4082.57
1
4079.97
1
4072.21
1
4061.75
1
4059.76
1
4084.85
1
4087.77
1
4069.49
1
4050.3
1
4044.91
1
4028.05
1
4035.71
1
4031.63
1
4035.52
1
4038.22
1
4054.74
1
4050.15
1
4038.64
1
4032.06
1
4049.43
1
4066.04
1
4048.56
1
4048.15
1
4046.02
1
4057.15
1
4043.91
1
4039.32
1
4025.58
1
4031.26
1
4052.58
1
4049.91
1
4051.36
1
4041.61
1
4050.99
1
4051.17
1
4041.52
1
4045.76
1
4055.7
1
4057.68
1
4067.44
1
4067.58
1
4085.2
1
4058.9
1
4072.51
1
4065.12
1
4062.82
1
4070.23
1
4081.36
1
4086.62
1
4094.61
1
4098
1
4109.49
1
4110.18
1
4112.97
1
4125.26
1
4131.37
1
4129.82
1
4135.6
1
4139.11
1
4168.39
1
4173.6
1
4176.69
1
4180.51
1
4202.47
1
4224.5
1
4234.54
1
4250.62
1
4240.57
1
4274.75
1
4292.37
1
4313.79
1
4300.02
1
4307.72
1
4324.11
1
4339.06
1
4355.56
1
4368.93
1
4391.69
1
4394.09
1
4410.25
1
4411.09
1
4416.37
1
4435.45
1
4437.73
1
4444.36
1
4443.04
1
4463.29
1
4468.71
1
4483.88
1
4498.57
1
4493.55
1
4488.97
1
4485.23
1
4509.55
1
4496.9
1
4499.54
1
4493.29
1
4511.05
1
4485.14
1
4477.99
1
4492.92
1
4462
1
4463.13
1
4454.8
1
4457.56
1
4496.3
1
4465.78
1
4448.27
1
4445.75
1
4422.14
1
4417.93
1
4430.44
1
4411.52
1
4394.04
1
4388.04
1
4396.1
1
4368.86
1
4344.1
1
4328.66
1
4328.53
1
4323.9
1
4320.32
1
4310.36
1
4294.49
1
4279.33
1
4285.18
1
4264.6
1
4254.3
1
4260.26
1
4266.56
1
4250.34
1
4259.19
1
4222.73
1
4233.84
1
4243.42
1
4227.15
1
4240.16
1
4232.69
1
4249.78
1
4270.57
1
4257.24
1
4257.31
1
4297.98
1
4296.09
1
4317.76
1
4324.68
1
4348.62
1
4364.09
1
4398.79
1
4434.87
1
4461.77
1
4476.97
1
4534.53
1
4550.6
1
4593.12
1
4641.15
1
4692.36
1
4734.51
1
4798.94
1
4849.38
1
4906.09
1
4949.11
1
5024.6
1
5074.91
1
5142.5
1
5218.83
1
5298.92
1
5356.14
1
5417.11
1
5477.49
1
5552.38
1
5613.86
1
5683.78
1
5719.11
1
5783.45
1
5834.78
1
5873.96
1
5927.19
1
5957.87
1
6001.83
1
6036.13
1
6066.22
1
6085.84
1
6098.26
1
6118.13
1
6171.88
1
6208.49
1
6286.47
1
6359.09
1
6454.42
1
6498.75
1
6530.91
1
6502.89
1
6390.96
1
6199.28
1
5917.75
1
5629.04
1
5330.71
1
5033.71
1
4779.03
1
4579.33
1
4415.86
1
4294.43
1
4166.49
1
4084.86
1
4029.51
1
3972.13
1
3934.55
1
3909.31
1
3897.8
1
3883.61
1
3887.62
1
3890.26
1
3903.02
1
3903.27
1
3910.82
1
3924.78
1
3952.53
1
3977.47
1
4003.03
1
4020.01
1
4048.03
1
4077.04
1
4100.84
1
4135.59
1
4141.37
1
4165.67
1
4203.83
1
4231.55
1
4252.87
1
4269.62
1
4284.29
1
4287.87
1
4312.89
1
4353.23
1
4354.76
1
4357.38
1
4390.48
1
4385.98
1
4383.54
1
4376.09
1
4388.08
1
4419.72
1
4430.92
1
4422.59
1
4419.68
1
4428.82
1
4438.57
1
4417.75
1
4427.88
1
4410.86
1
4397.29
1
4386.68
1
4387.34
1
4367.17
1
4359.31
1
4362.92
1
4341.28
1
4346.8
1
4352.16
1
4335.05
1
4313.14
1
4326.59
1
4323.22
1
4311.38
1
4313.79
1
4354.23
1
4345.21
1
4331.29
1
4353.98
1
4346.32
1
4335.09
1
4328.45
1
4352.2
1
4351.18
1
4351.28
1
4355.18
1
4342.83
1
4388.3
1
4381.54
1
4367.99
1
4362.96
1
4370.83
1
4363.65
1
4374.72
1
4358.86
1
4347.83
1
4373.41
1
4381.21
1
4392.96
1
4396.55
1
4408.13
1
4423.04
1
4419.83
1
4432.86
1
4446.5
1
4480.98
1
4523.46
1
4547.07
1
4588.3
1
4643.98
1
4681.43
1
4715.67
1
4780.82
1
4852.2
1
4921.26
1
4981.57
1
5042.33
1
5149.32
1
5239.38
1
5342.77
1
5451.05
1
5561.95
1
5682.33
1
5800.56
1
5954.24
1
6116.08
1
6232.67
1
6389.51
1
6572.71
1
6732.83
1
6880.6
1
7041.13
1
7201.61
1
7363.26
1
7552.24
1
7710.33
1
7869.82
1
8061.76
1
8221.06
1
8351.72
1
8494.8
1
8586.38
1
8655.17
1
8748.39
1
8778.47
1
8930.03
1
9060.56
1
9202.25
1
9430.15
1
9637.46
1
9777.93
1
9762.67
1
9542.68
1
9061.49
1
8419.58
1
7660.66
1
6875.64
1
6185.17
1
5625.52
1
5170.82
1
4825.73
1
4535.96
1
4251.39
1
3997.96
1
3782.67
1
3580.5
1
3422.18
1
3282.22
1
3203.44
1
3143.96
1
3072.56
1
3022.36
1
3007.79
1
2966.76
1
2954.79
1
2926.19
1
2922.46
1
2891.52
1
2870.36
1
2858.07
1
2848.05
1
2820.37
1
2804.29
1
2792.29
1
2771.25
1
2766.01
1
2757.26
1
2739.59
1
2724.12
1
2715.66
1
2710.67
1
2696.93
1
2668.03
1
2662.11
1
2660.77
1
2653.28
1
2643.89
1
2623.28
1
2630.83
1
2616.75
1
2619.83
1
2606.83
1
2593.88
1
2594.84
1
2595.47
1
2580.89
1
2575.78
1
2574.82
1
2559.33
1
2557.45
1
2558.59
1
2544.08
1
2550.95
1
2538.87
1
2534.03
1
2519.94
1
2506.31
1
2514.19
1
2514.21
1
2501.68
1
2502.88
1
2495.23
1
2494.96
1
2496.17
1
2484.58
1
2489.46
1
2481.78
1
2503.19
1
2493.2
1
2469.32
1
2479.95
1
2479.42
1
2486.47
1
2474.39
1
2465.76
1
2472.4
1
2462.19
1
2458.47
1
2444.63
1
2432.51
1
2428
1
2430.73
1
2437.06
1
2427.84
1
2415.98
1
2401.99
1
end of experiment