File: data/measured/Cu(111) oxidation.vms
VAMAS Surface Chemical Analysis Standard Data Transfer Format 1988 May 4
Not Specified
Not Specified
Not Specified
Not Specified
7
Casa Info Follows CasaXPS Version 2.3.24rev1.0W
0
SourceAnalyserAngle: 56.500000 d
CasaRowLabel:1. Cu metal, Vacuum, room temp.
CasaRowLabel:2. Cu metal, in 0.1mbar O2, room temp.
CasaRowLabel:3. Cu2O, in 0.1 mbar O2, 200 C
CasaRowLabel:4. CuO, in 0.1 mbar O2, 300 C
NORM
REGULAR
4
1
Sample Identifier
d
0
0
0
0
14
Cu2p
1. Cu metal, Vacuum, room temp.
2006
2018
2
6
17
18
0
6
Casa Info Follows
0
0
0
0
Sum of 6 spectra in column containing 6 scans
XPS
1
Al
1486.61
0
0
0
56.5
180
FAT
20
1
3.808
0
0
0
0
0
Cu
2p
-1
kinetic energy
eV
514.66
0.05
2
counts
d
Transmission
d
pulse counting
0.6
1
0
0
0
0
2
ESCAPE DEPTH TYPE
d
0
MFP Exponent
d
0
243.592
1
359.381
361.632
358.01
350.174
357.996
361.042
358.251
370.476
364.022
355.938
360.482
360.746
357.443
353.195
355.467
364.591
365.842
357.023
355.702
345.378
356.217
349.574
353.298
350.876
353.574
360.246
366.465
372.717
366.013
360.017
357.779
357.169
356.628
347.819
351.79
350.373
355.344
351.021
360.399
360.501
361.394
358.048
354.066
357.701
355.308
361.053
357.704
357.932
358.018
359.601
357.389
356.473
363.074
372.954
357.459
355.192
363.972
352.894
364.073
365.154
359.225
357.229
354.288
359.683
358.297
356.694
362.185
358.261
353.384
352.227
359.153
348.827
358.338
372.994
365.478
351.502
353.99
361.831
364.004
359.908
362.57
363.544
362.796
360.052
354.12
352.858
357.881
370.541
352.989
355.499
366.254
363.853
357.242
362.906
361.527
360.423
362.185
365.656
357.192
349.108
356.782
351.227
361.476
367.984
363.747
359.316
357.142
368.077
364.338
358.507
357.55
360.285
361.575
359.474
354.526
362.748
367.075
366.627
363.245
363.316
361.367
359.044
364.66
372.123
368.47
368.312
366.852
376.334
361.296
363.872
374.137
371.44
370.507
364.006
363.983
377.24
370.846
373.992
369.709
366.514
372.615
369.42
372.248
374.662
377.056
367.426
367.38
366.694
362.193
372.492
370.916
368.4
357.404
351.263
358.21
356.976
360.642
362.375
361.651
359.514
355.279
349.046
360.502
366.873
359.871
344.953
357.37
357.939
356.118
351.81
357.306
355.079
355.491
350.145
353.151
347.652
352.538
351.306
350.09
349.265
342.78
340.206
351.859
351.739
346.632
346.952
354.504
357.009
349.577
345.806
353.486
343.608
344.762
354.856
345.769
343.774
350.676
347.981
345.335
340.591
345.848
340.089
348.3
346.464
349.847
345.67
341.313
347.127
341.754
350.684
340.562
350.53
344.21
349.173
346.8
344.043
343.619
347.636
349.907
357.115
360.935
354.364
340.748
342.125
353.357
345.604
352.023
355.766
355.733
345.179
339.758
340.005
348.874
347.498
347.357
356.118
347.793
348.344
340.859
345.433
353.115
343.5
350.417
350.146
346.528
347.905
343.314
344.32
341.275
346.774
352.033
352.449
356.469
352.467
354.416
358.509
352.682
349.223
350.569
351.646
351.423
346.909
347.475
347.735
353.404
348.063
347.281
344.428
352.05
358.079
350.197
353.2
352.977
359.936
353.369
348.583
350.034
356.017
352.132
345.626
347.923
345.694
354.094
354.794
346.738
346.316
354.326
349.247
346.095
347.557
357.384
355.503
364.816
354.985
354.088
356.386
351.53
364.342
362.152
367.631
365.139
353.846
357.771
357.374
364.105
366.013
361.691
359.366
361.093
364.159
362.858
363.995
363.973
363.754
368.241
369.258
368.55
379.801
373.93
366.347
368.79
369.82
369.508
374.868
372.547
373.647
380.839
377.039
384.533
385.088
380.577
382.969
382.015
379.772
385.925
387.929
381.522
389.441
393.99
392.311
400.543
404.86
396.182
407.005
405.889
402.128
408.757
415.274
407.21
426.015
432.57
436.088
438.611
432.886
439.137
446.267
449.089
457.057
462.6
470.224
470.828
482.066
493.379
499.69
512.619
522.254
534.728
545.775
555.368
572.781
585.175
611.965
633.705
656.77
676.975
699.582
722.093
749.026
768.178
804.195
830.242
863.46
883.251
911.474
928.741
955.748
964.814
980.866
996.391
988.24
993.483
976.124
940.648
935.82
921.059
891.864
846.634
811.741
800.196
752.967
713.457
697.74
667.093
649.776
625.538
598.376
579.397
572.07
540.014
536.219
512.121
499.161
485.983
467.105
462.967
451.688
447.622
437.247
436.046
421.357
414.268
416.146
410.442
403.574
403.164
392.433
387.741
398.013
382.637
383.129
381.781
370.475
379.438
370.01
369.781
365.791
364.744
352.823
363.099
362.216
355.579
350.261
351.273
348.177
348.564
348.086
339.961
345.639
346.401
338.779
332.353
335.972
339.73
337.877
332.704
334.508
324.287
330.368
327.586
315.472
325.85
322.143
327.588
318.575
319.242
321.459
322.478
319.682
320.768
320.994
322.504
321.642
324.111
320.704
323.267
330.143
325.72
328.103
322.258
315.948
322.289
326.108
325.205
327.445
315.82
318.966
321.168
321.03
324.211
321.238
315.495
320.985
321.87
320.923
313.841
314.883
316.415
313.493
309.768
316.519
320.874
323.644
312.272
316.059
312.599
318.429
318.383
315.442
310.898
315.48
321.843
312.048
309.661
315.963
322.17
318.267
310.709
314.389
318.441
308.165
315.262
314.433
320.006
316.529
312.128
313.433
316.812
313.532
310.914
304.836
299.857
295.644
309.896
304.558
299.201
294.006
298.612
301.692
303.475
293.955
301.807
303.029
306.084
298.385
297.204
300.081
292.046
294.053
295.866
297.687
300.401
297.707
304.285
297.726
290.278
286.36
299.239
299.779
300.403
290.593
298.603
288.385
284.66
292.678
296.618
299.862
291.15
288.338
282.936
284.159
285.745
279.036
285.158
285.068
285.324
286.191
276.884
281.409
284.283
281.056
280.014
276.644
280.155
275.223
272.377
270.629
276.966
278.837
274.968
274.522
273.619
275.866
270.588
269.064
271.604
272.728
268.9
271.999
264.174
266.124
265.796
262.599
263.09
253.248
258.394
260.139
263.396
258.825
251.493
258.369
258.393
263.258
251.909
257.775
258.867
258.331
248.454
250.666
249.339
253.603
261.152
260.128
256.703
261.073
254.282
259.636
255.579
253.418
254.358
253.814
249.938
248.154
252.248
252.591
260.36
255.625
265.043
268.254
255.917
257.923
263.337
254.812
258.306
262.369
256.801
262.439
254.657
247.442
249.66
257.657
258.798
255.516
253.547
256.295
259.372
250.363
253.414
252.301
252.055
253.649
250.725
250.492
252.649
250.483
252.089
255.488
244.382
257.434
254.374
250.416
260.647
252.101
256.492
252.838
259.731
253.823
258.211
261.444
254.983
252.14
257.611
256.194
259.753
261.906
256.204
262.024
268.113
259.749
263.775
262.795
263.584
263.958
264.526
261.811
256.6
262.301
266.745
258.49
265.256
262.15
264.036
265.165
261.905
266.163
262.34
268.022
272.768
262.065
263.683
270.088
268.645
263.1
264.075
271.227
267.63
268.486
269.33
266.869
275.468
275.614
274.422
271.301
265.388
266.235
275.669
276.469
273.177
264.249
275.955
278.606
274.653
271.176
284.883
276.405
278.469
278.295
278.707
279.168
285.978
283.393
288.806
291.777
291.92
289.963
300.972
306.073
304.987
306.113
308.571
314.177
327.424
330.892
332.137
339.602
344.793
349.591
375.767
374.345
395.468
403.994
413.353
434.269
455.307
483.397
505.124
528.35
558.019
592.542
635.773
682.442
736.326
809.789
888.799
992.173
1086.1
1185.94
1308.62
1467.76
1639.92
1802.91
1965.3
2137.95
2283.79
2376.61
2426.91
2456.56
2443.57
2367.56
2238.52
2080.55
1906.64
1725.44
1532.84
1385.43
1232.24
1092.8
965.783
868.882
780.266
712.202
666.52
610.755
546.122
511.915
478.063
445.418
415.052
398.788
375.918
353.061
351.508
337.282
315.047
307.633
294.696
290.833
274.564
271.901
263.568
263.88
258.412
252.528
247.709
241.296
236.98
232.699
228.446
224.521
219.385
220.881
225.575
214.402
208.07
209.423
205.298
207.289
204.688
203.353
200.463
200.931
206.956
196.591
188.963
198.868
190.863
195.414
188.31
186.237
185.963
190.559
182.928
190.759
184.665
191.58
185.367
183.271
181.623
179.881
183.233
182.661
181.746
180.295
183.083
180.71
180.136
180.221
173.907
171.27
173.947
170.6
174.413
177.864
177.611
171.386
177.611
171.557
177.595
176.204
171.323
170.067
172.802
166.946
167.623
168.388
168.323
170.113
166.214
165.373
169.504
171.274
166.512
172.413
172.688
168.195
169.307
170.815
168.224
160.557
165.708
163.108
165.865
167.945
165.385
168.763
169.603
167.199
169.191
166.904
171.57
168.184
160.666
164.065
156.15
162.791
159.495
167.023
160.811
160.063
162.581
162.119
160.155
165.49
167.325
169.533
165.907
167.267
163.344
163.601
165.563
163.299
163.784
161.559
163.001
166.853
167.428
160.972
164.765
161.828
168.953
169.69
165.403
169.132
163.428
165.366
165.936
163.245
165.887
163.856
167.829
164.867
170.761
156.176
156.081
162.041
164.551
163.527
162.65
166.709
160.265
161.027
157.417
163.654
162.751
159.173
161.934
163.022
162.068
161.397
161.415
156.079
157.895
164.947
169.313
164.571
159.898
160.174
161.943
162.757
163.114
169.003
163.995
159.442
161.42
157.415
158.557
159.41
158.51
161.417
164.592
157.902
156.71
162.298
161.835
164.546
162.678
161.016
162.387
167.066
163.318
160.102
163.068
165.482
168.793
166.55
160.226
162.295
162.381
163.599
163.428
163.034
166.13
166.517
161.492
160.915
162.838
162.864
162.738
162.67
167.808
164.499
161.71
161.83
162.888
165.604
157.373
157.18
161.619
163.853
160.95
163.639
163.802
160.508
161.244
166.322
160.157
160.13
159.359
156.943
161.772
159.76
1
Cu LMM
1. Cu metal, Vacuum, room temp.
2006
2018
2
6
17
18
0
6
Casa Info Follows
0
0
0
0
Sum of 6 spectra in column containing 6 scans
XPS
1
Al
1486.61
0
0
0
56.5
180
FAT
20
1
3.808
0
0
0
0
0
Cu LMM

-1
kinetic energy
eV
906.71
0.1
2
counts
d
Transmission
d
pulse counting
0.6
1
0
0
0
0
2
ESCAPE DEPTH TYPE
d
0
MFP Exponent
d
0
500
103.969
1084.5
1
1
176.06
1
175.639
1
170.222
1
168.706
1
168.807
1
172.944
1
175.191
1
174.21
1
176.749
1
172.9
1
171.503
1
174.207
1
176.233
1
182.821
1
178.618
1
178.076
1
173.831
1
178.271
1
185.909
1
181.948
1
180.428
1
182.525
1
181.407
1
181.274
1
178.202
1
180.005
1
185.336
1
181.319
1
189.834
1
186.309
1
186.141
1
180.186
1
183.87
1
186.012
1
187.505
1
192.606
1
193.391
1
189.528
1
188.883
1
193.601
1
197.649
1
188.177
1
192.178
1
199.985
1
201.565
1
197.493
1
193.764
1
188.677
1
192.79
1
196.339
1
193.365
1
189.179
1
190.408
1
198.96
1
201.836
1
204.691
1
203.339
1
212.551
1
215.617
1
223.683
1
220.68
1
221.755
1
226.814
1
238.527
1
232.526
1
232.309
1
238.264
1
241.798
1
250.9
1
246.557
1
250.616
1
255.987
1
254.694
1
257.287
1
255.314
1
257.814
1
260.746
1
254.789
1
248.177
1
245.019
1
244.364
1
232.097
1
232.817
1
237.162
1
237.164
1
236.68
1
239.182
1
250.853
1
251.991
1
259.589
1
260.977
1
272.974
1
275.107
1
282.63
1
281.748
1
277.244
1
271.882
1
269.232
1
264.224
1
267.848
1
273.184
1
268.859
1
271.882
1
270.448
1
267.522
1
270.18
1
289.231
1
297.047
1
300.257
1
318.838
1
341.18
1
363.835
1
402.123
1
450.073
1
494.146
1
559.451
1
602.737
1
626.832
1
619.532
1
578.268
1
542.06
1
476.653
1
420.97
1
382.504
1
346.261
1
325.166
1
308.383
1
302.829
1
285.314
1
268.97
1
270.119
1
247.944
1
233.391
1
216.423
1
200.659
1
188.793
1
186.708
1
189.833
1
190.25
1
194.725
1
208.281
1
206.981
1
215.163
1
224.498
1
232.332
1
226.012
1
220.777
1
216.145
1
199.434
1
185.197
1
175.563
1
163.047
1
148.458
1
141.097
1
128.792
1
124.771
1
122.963
1
116.351
1
109.583
1
108.525
1
109.441
1
107.916
1
109.93
1
106.113
1
101.526
1
97.7022
1
99.7563
1
102.126
1
99.5891
1
99.9501
1
100.722
1
102.415
1
100.545
1
98.5399
1
97.9815
1
101.434
1
98.2199
1
96.6161
1
96.4176
1
94.749
1
91.8074
1
92.8633
1
97.246
1
97.0297
1
94.3896
1
93.9718
1
96.8608
1
94.8502
1
94.895
1
92.8011
1
91.9848
1
92.4718
1
92.8982
1
94.4083
1
91.2908
1
90.3564
1
88.2809
1
93.1085
1
91.9537
1
91.4175
1
90.006
1
91.7958
1
91.3512
1
87.0984
1
91.3502
1
92.5704
1
90.0655
1
87.0793
1
84.4384
1
86.8476
1
87.3187
1
87.3562
1
84.3405
1
84.9244
1
86.4717
1
85.028
1
85.194
1
84.7898
1
88.2223
1
85.1722
1
83.8297
1
86.8617
1
83.4916
1
82.1316
1
85.102
1
83.9467
1
81.0492
1
78.3638
1
82.1755
1
76.3945
1
74.9852
1
74.6594
1
74.3622
1
77.9152
1
76.676
1
72.2939
1
71.8039
1
73.4648
1
74.9364
1
73.272
1
71.8762
1
73.9608
1
73.6555
1
74.6263
1
75.7706
1
75.0258
1
71.5153
1
70.9967
1
70.2968
1
71.8444
1
O1s
1. Cu metal, Vacuum, room temp.
2005
2018
2
16
13
31
0
6
Casa Info Follows
0
0
0
0
Sum of 6 spectra in column containing 6 scans
XPS
1
Al
1486.61
0
0
0
56.5
180
FAT
20
1
3.808
0
0
0
0
0
O
1s
-1
kinetic energy
eV
946.61
0.1
2
counts
d
Transmission
d
pulse counting
0.6
1
0
0
0
0
2
ESCAPE DEPTH TYPE
d
0
MFP Exponent
d
0
402
22.7619
64.3284
1
1
30.4085
1
34.256
1
31.111
1
30.7652
1
31.7428
1
30.8185
1
31.0328
1
30.8644
1
29.8682
1
28.8569
1
30.4167
1
30.8707
1
31.7831
1
31
1
31.9923
1
33.1069
1
28.4222
1
29.7025
1
32.7683
1
30.3335
1
30.1209
1
29.4538
1
29.4902
1
28.2974
1
27.9446
1
30.0371
1
29.771
1
29.8672
1
30.4445
1
28.3941
1
27.3167
1
31.4216
1
29.3095
1
27.8245
1
29.7858
1
30.6972
1
27.8866
1
28.3476
1
27.3081
1
27.1963
1
29.366
1
25.4776
1
26.9027
1
27.7223
1
28.2988
1
26.5544
1
28.3218
1
27.8883
1
25.7646
1
27.6052
1
28.4488
1
27.9955
1
28.9149
1
27.8566
1
26.2418
1
28.5436
1
29.7864
1
29.3669
1
27.826
1
26.6391
1
29.6952
1
28.1548
1
28.2716
1
28.4629
1
29.1371
1
27.9194
1
26.8585
1
30.9974
1
27.188
1
26.531
1
27.7426
1
27.8562
1
27.2172
1
27.3877
1
25.6592
1
28.8317
1
29.5353
1
28.32
1
26.8146
1
28.448
1
29.6098
1
28.0549
1
27.5145
1
27.819
1
29.4938
1
31.5172
1
29.5997
1
33.1189
1
32.9828
1
30.6839
1
30.5667
1
29.0874
1
31.3196
1
30.1012
1
28.7132
1
29.6999
1
29.1209
1
30.0147
1
29.6289
1
28.3562
1
27.2426
1
28.1219
1
26.6051
1
27.6199
1
24.7355
1
26.8961
1
26.7674
1
26.7667
1
27.4167
1
26.22
1
26.3333
1
25.8506
1
26.6584
1
27.4598
1
26.0659
1
26.2024
1
23.7685
1
25.2478
1
27.4532
1
27.1358
1
26.1978
1
25.8488
1
26.0885
1
26.1078
1
24.0845
1
27.737
1
25.7481
1
26.0917
1
25.0615
1
27.4454
1
25.943
1
24.9491
1
24.3966
1
24.0505
1
25.9204
1
24.3627
1
26.6995
1
27.6017
1
27.3166
1
28.083
1
27.0648
1
24.9911
1
24.6864
1
25.0021
1
24.6769
1
25.1934
1
25.2551
1
25.2869
1
24.6925
1
25.6167
1
27.6013
1
25.6275
1
26.0619
1
26.2505
1
25.2314
1
25.0253
1
25.2869
1
25.264
1
24.6958
1
26.0054
1
24.269
1
27.0472
1
25.6447
1
25.4471
1
26.6556
1
26.7541
1
27.1567
1
27.1558
1
27.4608
1
26.1059
1
23.8365
1
25.6202
1
27.1514
1
24.7688
1
24.8992
1
25.8544
1
24.0701
1
24.716
1
24.3626
1
24.6182
1
24.3231
1
24.1318
1
25.2456
1
26.7998
1
25.7357
1
24.951
1
23.6557
1
25.266
1
25.1177
1
24.226
1
22.8785
1
23.7972
1
24.8669
1
25.1961
1
23.4786
1
24.5251
1
24.5554
1
23.1421
1
23.6194
1
22.8574
1
24.74
1
Cu2p
2. Cu metal, in 0.1mbar O2, room temp.
2006
2018
2
6
17
18
0
6
Casa Info Follows
0
0
0
0
Sum of 2 spectra in column containing 2 scans
XPS
2
Al
1486.61
0
0
0
56.5
180
FAT
20
1
3.808
0
0
0
0
0
Cu
2p
-1
kinetic energy
eV
514.66
0.05
2
counts
d
Transmission
d
pulse counting
0.2
1
0
0
0
0
2
ESCAPE DEPTH TYPE
d
0
MFP Exponent
d
0
224.6
1
114.821
114.327
110.596
110.355
107.962
112.934
115.062
112.613
105.522
110.662
112.21
107.876
111.804
107.29
110.246
108.238
109.817
110.755
111.345
109.516
111.125
110.446
106.089
111.411
111.259
112.637
109.282
110.206
108.28
105.677
109.901
111.828
108.49
108.252
112.069
111.521
112.249
109.806
112.087
107.035
109.429
115.365
113.165
114.433
113.274
113.581
109.985
112.005
112.039
104.744
109.378
107.796
113.458
115.368
112.91
108.503
109.468
109.164
110.194
113.213
112.767
112.309
111.46
109.128
110.97
109.513
115.036
114.879
111.185
107.578
116.232
110.757
105.603
109.205
111.216
110.981
113.145
112.287
112.949
109.922
112.396
109.667
111.832
109.915
109.927
112.805
110.123
106.727
106.447
112.817
113.128
110.535
110.494
106.795
111.819
113.098
109.224
105.643
110.136
107.087
109.885
110.636
108.804
112.02
111.067
111.825
106.86
108.198
112.749
112.27
108.758
110.076
112.767
108.163
107.869
112.196
110.752
110.913
109.552
109.447
115.445
106.354
115.576
114.385
111.608
113.389
116.717
112.469
116.553
119.86
113.62
111.902
110.688
110.29
113.495
109.605
113.81
113.122
113.534
112.748
113.148
113.562
114.076
117.288
117.306
115.455
111.619
112.22
112.716
115.215
115.383
112.559
114.431
111.23
108.554
106.559
110.267
115.09
110.087
109.882
111.511
110.905
113.646
114.6
111.093
105.67
107.875
108.426
108.571
105.779
104.931
110.201
107.357
106.166
109.785
110.908
107.273
108.574
107.266
111.063
109.005
106.557
104.671
106.836
106.139
104.064
105.626
106.32
106.34
106.006
103.66
105.134
104.85
105.126
110.464
105.177
104.174
100.886
100.638
101.69
105.752
104.015
109.654
107.615
106.035
104.104
105.272
104.562
103.651
104.9
104.01
105.111
107.113
106.238
103.61
104.012
106.916
109.687
105.405
105.966
105.365
104.594
103.393
108.139
110.066
107.33
105.015
105.308
103.4
107.352
109.352
109.171
107.873
106.258
103.086
104.706
103.701
107.257
101.413
104.683
109.625
105.788
103.253
101.001
102.998
110.067
106.904
103.041
104.201
108.786
108.896
111.217
109.52
108.214
104.305
100.907
106.354
103.266
105.523
110.375
108.159
103.815
106.943
107.916
104.998
103.488
104.833
99.377
101.146
105.097
105.313
104.676
105.15
105.539
101.341
109.74
107.78
102.875
104.844
108.936
105.582
106.587
103.533
107.99
107.132
108.898
105.779
104.864
108.8
104.087
104.216
101.352
103.346
108.004
110.928
108.637
108.157
110.361
109.304
110.304
104.272
105.97
109.171
106.36
106.771
103.831
104.345
111.929
111.074
108.562
110.118
113.761
112.5
107.352
114.968
115.012
109.668
111.764
108.501
108.385
108.367
115.46
111.69
119.315
112.841
112.349
112.023
117.228
116.385
116.68
119.349
116.042
111.593
112.072
119.381
117.113
118.137
116.267
114.606
112.102
116.641
114.859
112.905
120.07
118.135
115.35
117.943
119.786
115.211
125.189
123.449
125.015
126.149
123.691
127.189
130.383
133.064
131.905
132.774
128.175
130.774
138.01
141.793
139.721
144.449
146.06
146.404
154.583
152.016
158.507
163.346
168.619
168.686
167.249
178.053
194.882
195.45
199.911
201.39
206.93
223.792
218.47
233.374
241.127
243.59
249.547
257.685
256.964
255.413
257.178
267.905
257.351
256.689
254.88
256.164
252.384
244.005
235.618
227.324
215.46
209.591
200.093
202.832
187.082
186.338
186.405
172.993
156.492
163.199
162.435
154.685
151.879
151.261
146.529
142.749
134.478
134.865
130.121
128.764
123.388
121.531
121.077
123.738
116.927
114.714
119.362
117.616
118.865
118.635
115.497
111.923
103.913
111.347
108.713
108.623
106.622
109.411
109.605
106.962
103.567
107.706
104.718
106.985
110.739
107.45
104.808
107.186
102.648
99.5959
105.125
100.923
103.978
102.014
99.3225
100.939
102.338
101.157
101.523
101.412
99.581
100.911
99.5878
93.9625
93.3609
93.9107
98.8353
98.1517
97.231
93.1593
95.9979
95.0343
96.6612
101.855
99.2342
97.8407
97.7402
95.4641
97.7305
93.3673
96.3634
92.7017
93.2064
96.6196
95.9129
95.5512
95.8144
95.706
96.2101
95.0815
94.1545
94.809
93.1029
98.872
96.1068
96.3063
97.8586
97.9077
91.6464
93.3591
95.9548
94.3115
94.4137
94.8852
97.5909
95.9662
96.4925
98.1522
99.5441
96.33
95.5326
95.8844
93.9829
92.2194
95.7144
99.2137
94.3104
95.0708
97.7861
97.0619
101.891
103.812
99.9704
93.742
94.4492
96.7666
94.4152
95.4264
98.2176
95.8176
95.1264
92.8855
91.2184
93.3133
91.2109
93.8379
89.8388
90.2452
88.3678
88.1235
91.0398
92.8608
88.7911
87.9902
90.7434
89.2187
88.2759
90.2481
87.8183
90.0446
92.6022
90.7472
87.0243
89.2612
89.1448
88.7338
87.0766
93.0035
84.7193
84.5301
86.1628
90.5041
90.05
85.847
88.995
88.0096
86.3937
90.6152
89.4805
88.1726
87.766
82.9854
88.443
86.4824
88.0693
85.655
87.0795
86.6226
86.3127
85.884
88.8328
80.2393
83.1558
87.2421
83.2691
81.4341
82.7827
79.8833
80.8497
82.1894
83.7222
83.2502
82.5585
83.5187
84.9263
79.7709
81.089
83.7326
83.9429
84.5387
82.945
82.5559
81.0603
80.2081
78.9195
84.1265
77.6064
80.0591
81.6795
77.9169
75.6314
76.097
79.1071
80.2627
79.8312
78.5112
78.3308
81.3413
81.2516
81.3174
80.2788
75.9892
80.5834
77.8032
75.6524
80.8668
81.2136
78.4448
79.014
79.5157
73.5809
73.9463
73.6636
77.3124
76.7194
76.9535
76.5535
77.4018
73.4946
79.021
76.7491
78.7135
79.4035
80.5073
75.7171
73.9995
76.1974
74.8311
78.7827
75.469
81.9916
78.6424
76.0071
77.251
77.7454
74.4484
73.096
77.9728
76.3882
74.9131
76.4525
76.9885
74.4594
75.7696
75.492
73.2281
74.2878
77.669
74.3302
74.4178
79.6498
78.4676
77.3438
72.952
73.4838
77.3595
77.2074
81.0787
76.4061
76.5299
77.3096
77.205
76.0883
75.6629
75.3023
73.6723
77.7254
78.7866
78.3914
80.5338
78.2542
77.0355
77.0282
76.1894
75.8962
78.1446
80.7159
82.629
82.1213
78.2363
79.7101
79.7027
78.3424
80.999
86.4385
79.4942
77.1659
77.952
76.7287
77.1862
79.6824
78.4833
81.3719
81.8069
81.8123
80.5374
82.2171
80.8356
79.8207
86.2208
82.8526
79.8269
85.1461
86.4907
81.2715
77.86
83.3273
86.5068
83.8217
81.5071
85.6785
83.9141
84.2931
79.2721
83.5828
85.9839
89.494
87.4321
86.4329
85.7737
84.5013
87.1684
88.438
90.6964
87.8526
90.3628
89.5493
95.1379
93.3782
94.0762
94.1711
97.8446
99.8178
100.414
101.392
99.8384
105.936
108.161
103.957
109.264
115.755
114.858
118.982
124.276
132.326
141.327
149.102
155.165
153.832
166.457
180.381
191.011
207.758
229.135
242.461
267.301
291.84
331.092
368.913
401.152
439.847
478.963
518.789
545.05
566.757
579.351
609.913
606.197
604.346
569.288
540.116
522.655
482.718
438.262
410.872
379.226
346.16
311.595
272.508
253.13
235.095
218.619
194.24
182.87
166.614
158.4
145.902
140.035
126.282
114.586
110.211
108.872
105.025
104.108
99.5575
91.6166
87.5179
87.7517
88.8353
84.8368
77.7407
77.7804
78.5363
75.7
75.184
75.3413
70.1244
69.992
65.6749
65.428
67.5371
70.249
69.4111
69.897
64.6455
67.3723
64.508
63.2831
66.4938
63.4825
65.1151
65.8795
58.8995
60.7454
62.5806
61.9996
58.2559
59.2348
60.7085
62.6443
56.4953
55.9469
57.811
59.0214
59.731
53.5501
59.2704
57.2102
55.0445
56.3613
57.3407
56.5694
54.0819
52.8959
60.2689
56.2487
55.8959
56.5831
55.6302
56.486
54.896
56.9913
54.1713
53.231
52.5247
51.79
55.8661
54.6042
52.6075
54.3152
53.9605
55.1194
54.3092
53.5498
51.7661
55.5222
53.226
54.2564
54.8387
57.3
55.0368
49.8683
54.5987
54.1241
52.1257
50.2583
50.9996
48.5874
51.4607
51.8812
54.8688
54.7456
51.3249
52.9538
54.4501
54.4872
52.2981
52.8731
50.6471
49.3611
51.3261
55.4965
54.0259
54.8899
52.7908
52.9856
53.1096
56.0656
55.5322
53.2612
52.1518
52.2462
49.2357
51.2431
52.2311
52.7164
52.2549
52.1437
52.7454
52.0303
50.2921
54.1635
51.8705
47.2424
46.9625
49.253
48.4747
52.9442
54.1815
50.5667
51.086
52.2559
49.9702
51.2707
52.6872
49.6656
52.6114
50.8823
51.5055
52.1067
50.8474
52.5869
55.3152
50.1746
51.9435
52.5811
51.9888
54.0953
51.9792
49.4093
51.3613
53.1334
51.3392
48.8811
49.9479
51.8084
54.3908
51.9128
48.9805
49.8419
50.4677
51.567
51.1964
52.4191
51.6819
52.7855
48.2877
52.0101
52.2296
52.8535
49.7666
47.049
52.2395
51.4801
48.7894
51.309
51.7171
52.0223
47.6544
52.2357
52.6153
52.4154
50.7362
52.2463
50.3416
50.928
54.372
51.5034
50.1407
51.4525
54.9006
54.2909
51.8095
52.1059
47.4803
49.9231
46.7465
49.3266
52.0559
51.4716
48.2978
53.7017
50.9919
53.6595
52.5739
52.7309
51.5874
51.366
50.9133
49.9621
51.6288
52.2575
50.5519
51.2104
52.2593
57.4466
51.1753
51.1609
50.2319
51.8697
53.0436
50.9746
52.4041
52.6351
51.6125
50.2343
54.6676
52.463
51.4064
52.1116
50.2251
1
Cu LMM
2. Cu metal, in 0.1mbar O2, room temp.
2006
2018
2
6
17
18
0
6
Casa Info Follows
0
0
0
0
Sum of 2 spectra in column containing 2 scans
XPS
2
Al
1486.61
0
0
0
56.5
180
FAT
20
1
3.808
0
0
0
0
0
Cu LMM

-1
kinetic energy
eV
906.71
0.1
2
counts
d
Transmission
d
pulse counting
0.2
1
0
0
0
0
2
ESCAPE DEPTH TYPE
d
0
MFP Exponent
d
0
500
88.9804
824.73
1
1
49.1536
1
51.8621
1
48.2977
1
50.4761
1
49.7912
1
51.878
1
51.3348
1
52.0757
1
52.5951
1
50.5583
1
48.9401
1
49.5375
1
49.4083
1
54.6018
1
50.507
1
49.6294
1
51.4858
1
53.6108
1
50.2463
1
52.9135
1
53.3806
1
55.6117
1
54.8061
1
56.0946
1
55.7393
1
54.0073
1
51.8083
1
53.7353
1
55.1697
1
55.4415
1
57.1623
1
56.5309
1
54.8632
1
56.4321
1
57.6102
1
59.729
1
55.9477
1
54.5201
1
59.3973
1
59.6257
1
58.476
1
59.4265
1
54.9277
1
56.4985
1
57.8248
1
56.0948
1
57.6596
1
55.3445
1
59.0889
1
57.1247
1
56.8897
1
59.2575
1
60.3631
1
60.3668
1
60.9523
1
63.103
1
64.7079
1
64.267
1
62.2764
1
64.1556
1
64.328
1
63.5192
1
65.5663
1
69.8298
1
66.6683
1
66.2926
1
72.5307
1
71.4743
1
72.6449
1
68.4723
1
71.1497
1
73.5516
1
72.0906
1
70.214
1
70.8388
1
74.3443
1
74.879
1
73.6405
1
75.9816
1
73.7581
1
73.7755
1
68.3334
1
74.4394
1
73.2034
1
72.3862
1
72.1536
1
70.7787
1
73.9577
1
71.4713
1
76.5483
1
80.3915
1
81.236
1
80.6506
1
79.8987
1
77.2566
1
78.5596
1
78.7849
1
74.5787
1
72.4517
1
86.0531
1
82.5075
1
80.4373
1
81.4526
1
83.1803
1
84.9953
1
84.235
1
90.8868
1
89.0044
1
93.3782
1
92.513
1
103.576
1
111.872
1
122.947
1
132.644
1
141.235
1
146.797
1
157.12
1
165.3
1
157.942
1
151.586
1
134.357
1
121.852
1
112.859
1
97.5958
1
91.1691
1
89.2736
1
87.8696
1
78.6164
1
76.5726
1
75.8679
1
71.6332
1
67.6198
1
66.4412
1
62.2487
1
59.2604
1
53.187
1
54.3092
1
57.4518
1
54.4053
1
57.2565
1
57.8005
1
59.9428
1
60.6024
1
62.945
1
63.4415
1
60.4255
1
61.0616
1
58.2954
1
58.2018
1
52.9259
1
49.1755
1
45.1677
1
43.9136
1
42.1214
1
38.2184
1
35.5481
1
36.5615
1
33.6976
1
34.7486
1
32.6717
1
31.62
1
30.9223
1
31.994
1
32.2928
1
31.0068
1
30.3844
1
31.4075
1
29.7338
1
33.6041
1
32.002
1
30.6653
1
32.2641
1
31.1078
1
28.3611
1
30.6466
1
31.035
1
29.9106
1
26.8137
1
28.64
1
29.2911
1
29.9454
1
29.2261
1
29.6807
1
30.0409
1
29.1724
1
29.7043
1
28.2254
1
26.7413
1
30.0483
1
29.7384
1
27.4707
1
29.6883
1
29.1877
1
27.2514
1
28.4307
1
28.8456
1
28.3149
1
28.1413
1
28.1431
1
26.0731
1
28.8675
1
26.4628
1
28.7124
1
27.8165
1
27.577
1
26.8547
1
26.807
1
25.3189
1
26.6592
1
28.2929
1
24.9923
1
24.3102
1
25.4613
1
26.6399
1
26.1713
1
26.299
1
26.7103
1
26.2425
1
25.9755
1
26.1421
1
25.7636
1
25.5922
1
23.5705
1
24.3473
1
25.0794
1
25.5038
1
24.5
1
25.0051
1
24.6998
1
24.5818
1
22.5487
1
24.1224
1
26.0223
1
23.5361
1
23.0745
1
21.45
1
22.9809
1
22.9245
1
22.4536
1
24.7349
1
20.7
1
24.176
1
22.719
1
22.1017
1
21.8104
1
22.3151
1
21.3924
1
22.263
1
24.1397
1
20.9888
1
O1s
2. Cu metal, in 0.1mbar O2, room temp.
2005
2018
2
16
7
8
0
6
Casa Info Follows
0
0
0
0
Sum of 2 spectra in column containing 2 scans
XPS
2
Al
1486.61
0
0
0
56.5
180
FAT
20
1
3.808
0
0
0
0
0
O
1s
-1
kinetic energy
eV
946.61
0.1
2
counts
d
Transmission
d
pulse counting
0.2
1
0
0
0
0
2
ESCAPE DEPTH TYPE
d
0
MFP Exponent
d
0
402
28.6172
84.5893
1
1
11.1002
1
10.2083
1
12.2
1
11.7773
1
12.3884
1
11.013
1
11.4958
1
12.4499
1
10.7479
1
10.3066
1
11.7042
1
11.7275
1
11.5737
1
10.8616
1
9.87686
1
10.6753
1
10.5574
1
10.3295
1
8.58694
1
10.3691
1
9.63559
1
9.28032
1
9.89628
1
9.45081
1
9.10569
1
8.41705
1
9.63108
1
9.10599
1
10.8511
1
10.8476
1
8.4181
1
8.48038
1
10.4043
1
8.83521
1
8.05772
1
8.56617
1
9.93483
1
10.2367
1
9.86255
1
10.2782
1
10.0002
1
8.8255
1
10.2261
1
8.54513
1
8.90793
1
9.11523
1
9.87542
1
9.38191
1
8.52763
1
10.4616
1
9.7373
1
9.81926
1
10.0871
1
10.0227
1
9.54267
1
10.0884
1
8.14891
1
9.03762
1
9.49414
1
10.1084
1
8.54673
1
9.48896
1
10.1805
1
9.22702
1
10.5603
1
10.6161
1
10.6239
1
10.8207
1
10.9432
1
10.0994
1
8.56937
1
10.8133
1
12.1084
1
9.65039
1
9.65674
1
9.88987
1
11.2263
1
11.5173
1
12.7019
1
11.5365
1
13.3563
1
12.9054
1
11.5921
1
11.7545
1
14.5115
1
12.7803
1
13.0433
1
11.7618
1
12.5721
1
13.8133
1
14.3462
1
13.5771
1
14.2312
1
14.9084
1
15.0206
1
15.8055
1
14.7246
1
16.2192
1
16.6723
1
14.9101
1
16.411
1
14.6963
1
16.9705
1
17.6217
1
14.4277
1
13.5388
1
15.1145
1
13.5204
1
13.9063
1
12.9296
1
10.1325
1
9.47031
1
9.53275
1
8.44627
1
7.82224
1
9.11693
1
7.99289
1
9.80178
1
9.18067
1
9.98269
1
9.42959
1
8.8529
1
8.92107
1
8.61427
1
7.42192
1
8.26561
1
10.5693
1
9.6329
1
9.28016
1
8.03908
1
7.9771
1
7.77814
1
7.94191
1
7.38551
1
8.2343
1
7.97983
1
8.46826
1
8.35752
1
8.28085
1
8.93322
1
6.63141
1
8.04354
1
8.4494
1
8.61058
1
8.61708
1
7.36189
1
7.65541
1
9.14178
1
9.65492
1
7.78023
1
7.47413
1
8.4851
1
8.59162
1
8.64348
1
6.63208
1
8.24282
1
9.13529
1
8.92781
1
8.86214
1
8.43468
1
8.32233
1
8.8146
1
8.42908
1
6.74121
1
6.91797
1
6.47428
1
8.10254
1
7.82263
1
6.561
1
8.53138
1
8.4233
1
7.81823
1
8.78412
1
8.77258
1
8.65744
1
8.39671
1
8.06356
1
8.5016
1
8.53302
1
7.23247
1
7.09188
1
8.9616
1
7.79717
1
8.66864
1
8.20076
1
8.16022
1
7.87462
1
7.37212
1
8.36542
1
7.47719
1
8.41526
1
8.10143
1
8.82584
1
8.68027
1
7.8539
1
7.96903
1
8.16372
1
7.14907
1
8.25622
1
7.9042
1
8.08556
1
Cu2p
3. Cu2O, in 0.1 mbar O2, 200 C
2006
2018
2
6
17
18
0
6
Casa Info Follows
0
0
0
0
Sum of 38 spectra in column containing 38 scans
XPS
3
Al
1486.61
0
0
0
56.5
180
FAT
20
1
3.808
0
0
0
0
0
Cu 2p

-1
kinetic energy
eV
514.66
0.05
2
counts
d
Transmission
d
pulse counting
1.9
1
0
0
0
0
2
ESCAPE DEPTH TYPE
d
0
MFP Exponent
d
0
105.265
1
495.084
495.921
502.237
498.909
492.712
493.809
493.005
490.209
486.13
488.322
490.567
498.134
503.75
502.118
502.208
494.206
495.136
497.136
491.821
499.949
491.322
495.091
496.279
494.604
491.337
493.795
498.247
496.921
492.768
491.978
490.515
498.096
488.367
491.496
494.834
495.818
502.378
497.081
493.449
497.608
496.89
486.46
488.837
493.367
491.35
498.595
495.674
490.087
486.643
487.972
492.202
494.695
497.49
492.143
489.328
488.014
492.762
500.811
500.741
498.075
491.641
491.639
496.187
496.659
498.506
498.57
494.479
496.583
496.389
508.032
495.394
498.733
497.149
496.819
496.641
499.526
495.383
497.434
503.606
501.48
501.093
500.654
506.188
504.013
499.772
506.828
510
505.514
508.912
503.081
502.757
506.727
505.482
502.575
508.06
510.703
514.025
512.267
502.835
510.544
510.788
515.394
513.004
512.335
513.495
515.402
513.826
508.987
508.865
513.295
520.558
521.453
515.061
519.917
515.612
521.611
522.888
518.892
513.065
527.621
522.411
529.483
539.647
534.403
532.824
525.61
530.698
533.736
531.531
539.655
538.054
542.338
537.028
541.211
544.041
551.143
549.938
544.983
546.488
553.127
549.334
547.071
543.86
548
543.517
542.766
537.73
541.731
541.99
539.354
534.935
542.422
534.864
526.869
528.866
522.758
518.133
517.887
516.58
521.378
514.557
519.838
508.748
509.306
509.058
507.515
509.187
510.476
506.061
506.948
501.031
497.456
492.764
495.506
491.756
491.56
493.603
494.086
490.81
492.376
487.056
489.311
492.867
494.197
486.407
492.311
484.793
482.856
475.234
483.81
478.265
480.031
479.809
474.751
480.801
479.552
479.787
474.181
472.409
477.139
478.971
477.7
476.674
476.222
470.274
473.504
478.034
478.174
476.911
478.077
468.403
481.683
473.503
477.938
476.053
476.28
478.188
479.016
472.371
482.086
482.723
478.852
476.811
478.933
475.375
480.052
476.176
476.053
479.806
483.354
471.569
476.267
478.66
471.661
470.137
476.066
475.701
465.762
471.152
483.757
480.02
485.419
484.462
489.021
478.88
482.361
474.956
476.862
476.322
485.437
485.492
474.776
478.409
482.153
484.746
479.276
483.206
476.763
474.315
480.303
478.645
478.108
473.127
489.747
486.196
486.385
487.932
484.082
483.08
486.016
488.56
492.181
490.704
480.209
482.625
480.541
484.522
483.709
489.043
493.993
486.389
480.892
484.293
486.122
483.562
483.503
494.197
490.274
479.141
484.07
487.415
487.775
488.006
490.605
490.392
489.483
492.289
494.97
493.044
490.727
491.561
492.292
491.749
491.706
488.087
487.376
487.59
491.762
485.105
486.987
497.711
490.856
489.009
487.867
489.362
489.249
494.271
492.955
494.667
493.471
493.197
496.245
494.193
490.184
493.526
488.932
486.628
489.526
488.175
490.69
491.823
498.173
484.216
492.913
487.337
491.459
491.932
497.379
497.134
487.335
483.166
487.364
493.378
497.777
490.605
493.198
497.997
502.976
506.649
502.947
503.263
501.348
503.892
505.271
506.338
520.878
518.536
520.342
518.937
529.63
527.091
541.03
537.806
548.975
559.419
563.223
577.127
588.881
595.056
600.709
616.789
635.061
648.982
678.671
697.936
704.66
724.742
758.11
794.474
819.455
864.455
899.3
936.411
970.1
1019.17
1062.5
1114.96
1155.69
1197.59
1249.9
1303.92
1343.69
1386.49
1408.46
1446.45
1447.99
1450.6
1449.89
1432.51
1402.28
1383.5
1343.35
1315.8
1258.34
1207.83
1144.48
1103.42
1045.77
1003.78
958.491
915.761
872.322
832.671
799.852
767.589
733.987
705.981
682.68
665.392
641.982
639.663
617.16
601.513
592.983
569.18
560.11
560.218
546.421
551.024
542.892
529.51
521.074
522.286
513.909
503.878
503.558
503.91
491.483
487.525
491.886
499.021
487.512
478.404
468.578
477.244
469.453
472.939
469.012
468.737
470.369
463.093
467.55
459.954
458.489
458.164
458.568
463.329
462.534
459.524
454.846
460.755
459.002
457.85
455.601
454.272
460.452
452.761
455.506
452.435
447.486
455.527
456.252
452.158
456.214
452.629
449.732
451.465
448.999
451.988
452.97
455.892
451.878
452.5
457.553
461.739
465.908
459.294
460.437
454.897
451.863
453.635
464.736
462.897
465.327
472.513
466.953
467.837
473.649
477.64
477.514
486.137
489.903
488.245
490.234
500.314
495.674
506.231
516.807
510.872
511.47
513
515.435
515.512
516.022
520.421
517.433
515.744
510.787
505.205
506.464
499.564
492.628
486.328
496.532
489.204
489.453
489.136
481.69
479.653
469.717
469.178
465.613
476.495
470.961
470.213
462.049
465.495
471.7
463.503
468.203
473.44
462.385
463.633
465.156
460.739
461.122
457.906
459.677
454.925
453.56
451.613
458.316
448.089
443.692
451.074
450.506
452.693
451.723
449.329
451.401
454.739
446.557
440.544
444.847
451.978
455.148
452.896
449.477
445.644
444.367
441.156
443.109
445.541
440.274
439.832
446.217
441.704
444.907
443.077
436.847
438.667
431.457
428.486
426.811
427.856
416.731
413.358
422.472
408.967
407.337
407.078
407.381
404.664
399.243
399.242
401.348
403.519
404.822
398.979
393.475
387.783
389.444
393.185
391.201
385.903
384.677
387.246
390.023
390.855
385.575
384.653
389.559
389.493
383.319
383.052
386.056
385.01
384.232
381.71
386.92
384.408
378.571
382.593
378.771
385.742
391.472
391.838
387.144
379.894
390.147
389.163
378.358
386.821
390.849
383.744
388.395
391.051
386.571
385.907
384.147
386.334
387.007
381.79
383.047
381.626
385.208
388.812
387.852
384.644
391.173
384.702
386.177
387.855
384.208
389.216
392.286
389.749
384.448
386.674
390.572
389.099
388.151
387.304
394.863
389.447
390.685
400.117
397.055
401.33
397.954
399.374
390.538
391.316
393.497
403.321
399.632
404.258
406.229
399.63
398.912
398.65
398.245
398.411
395.587
391.418
395.354
397.12
405.882
405.351
402.093
394.169
395.382
397.839
396.606
396.924
398.484
399.069
399.801
403.23
398.72
399.894
402.142
396.769
400.814
399.813
404.347
404.279
399.279
396.889
397.896
396.195
396.047
387.494
392.725
393.474
390.945
394.242
394.695
385.677
385.786
385.261
388.221
391.986
392.863
387.167
386.418
388.482
378.45
383.162
383.08
383.207
382.013
383.158
386.124
383.111
382.962
376.094
377.047
372.576
374.174
370.266
371.262
367.75
371.103
366.797
366.985
371.449
372.978
378.928
373.599
374.968
378.512
373.712
377.076
384.024
385.935
397.794
401.456
405.889
412.647
430.197
437.336
447.748
459.473
481.808
502.882
520.041
543.494
567.232
593.039
627.271
663.682
705.447
754.679
811.137
866.145
951.348
1040.02
1128.21
1241.15
1359.05
1486.95
1633.14
1775.25
1942.99
2129.7
2306.13
2471.11
2636.96
2782.72
2894.5
3007.03
3075.15
3082.32
3060.9
2996.11
2891.98
2750.06
2587.43
2399.8
2249.67
2045.16
1840.1
1669.95
1515.34
1365.01
1214.51
1105.26
1010.07
925.245
836.199
775.377
729.024
671.35
622.608
582.086
553.204
532.175
508.703
477.739
459.669
443.708
434.325
410.789
397.651
384.47
379.423
367.076
358.849
354.773
354.921
342.771
329.903
327.894
328.941
324.935
322.928
312.381
307.374
308.693
299.49
292.668
294.541
291.054
287.063
285.469
285.607
280.038
280.833
277.22
278.896
274.521
267.541
270.447
270.642
269.865
267.562
262.983
264.393
265.709
263.042
259.363
263.173
264.055
262.493
253.92
255.698
255.854
254.046
256.632
252.677
251.88
251.196
251.794
251.129
251.446
253.762
248.78
252.4
244.315
247.342
249.582
250.099
246.779
247.217
245.215
244.934
244.898
244.361
245.406
246.441
244.991
245.074
235.812
240.157
241.182
237.262
240.097
239.322
244.6
241.743
238.511
237.793
236.696
239.414
240.589
235.002
234.075
235.742
235.262
239.742
239.307
236.347
232.37
239.382
239.148
239.429
237.334
234.583
239.992
239.006
237.639
238.223
237.142
236.986
236.934
232.348
235.697
233.877
237.109
242.358
239.983
239.803
234.678
236.819
236.871
237.157
237.816
235.282
238.249
236.543
235.042
233.848
239.166
233.712
233.257
236.02
233.818
234.615
232.355
231.827
236.446
239.217
238.744
235.374
235.806
232.32
234.844
233.639
236.085
233.176
230.395
229.009
237.059
229.742
233.935
234.598
235.729
235.6
230.15
231.835
233.379
232.301
231.323
231.075
233.562
233.819
237.83
234.984
234.406
230.153
227.947
229.656
237.532
235.515
236.882
232.59
231.022
235.272
237.716
239.941
233.484
234.799
235.62
232.77
230.179
227.68
229.992
231.685
230.557
235.688
239.037
235.943
239.096
238.596
235.012
233.414
228.756
229.85
232.019
233.314
227.346
229.605
228.754
228.705
227.848
235.134
232.654
229.85
230.952
233.897
231.266
225.546
230.988
232.079
233.072
235.505
237.139
233.087
228.246
226.708
234.437
233.287
228.153
230.688
228.862
231.186
230.121
236.263
233.508
1
Cu LMM
3. Cu2O, in 0.1 mbar O2, 200 C
2005
2018
2
20
15
47
0
6
Casa Info Follows
0
0
0
0
Sum of 38 spectra in column containing 38 scans
XPS
3
Al
1486.61
0
0
0
56.5
180
FAT
20
1
3.808
0
0
0
0
0
Cu LMM

-1
kinetic energy
eV
906.71
0.1
2
counts
d
Transmission
d
pulse counting
1.9
1
0
0
0
0
2
ESCAPE DEPTH TYPE
d
0
MFP Exponent
d
0
500
49.7144
337.196
1
1
258.614
1
251.98
1
261.312
1
256.706
1
261.1
1
262.62
1
258.06
1
259.564
1
260.577
1
261.283
1
263.367
1
263.182
1
267.801
1
268.259
1
270.557
1
265.644
1
268.256
1
269.191
1
273.568
1
270.796
1
271.407
1
272.886
1
271.545
1
274.466
1
274.129
1
275.571
1
279.116
1
276.023
1
279.432
1
286.976
1
281.357
1
286.219
1
286.728
1
285.954
1
287.153
1
288.831
1
287.344
1
289.985
1
292.48
1
298.827
1
303.565
1
304.158
1
304.56
1
302.553
1
305.635
1
305.045
1
304.839
1
311.536
1
321.376
1
315.777
1
313.338
1
313.723
1
320.996
1
321.317
1
319.326
1
328.303
1
330.628
1
329.878
1
330.959
1
333.419
1
333.065
1
335.028
1
330.123
1
332.023
1
332.581
1
327.311
1
331.099
1
333.28
1
328.624
1
332.989
1
340.808
1
328.324
1
333.1
1
342.675
1
346.412
1
337.477
1
344.541
1
346.192
1
345.224
1
350.186
1
347.407
1
357.857
1
360.178
1
369.747
1
374.941
1
383.001
1
392.841
1
402.036
1
418.998
1
431.31
1
441.023
1
462.322
1
495.214
1
511.42
1
526.843
1
556.34
1
568.19
1
585.769
1
595.802
1
590.09
1
596.253
1
582.835
1
566.401
1
547.835
1
526.267
1
509.934
1
487.122
1
463.332
1
446.775
1
425.398
1
412.675
1
403.112
1
393.217
1
382.187
1
364.187
1
356.083
1
344.828
1
334.661
1
325.437
1
321.533
1
315.479
1
306.483
1
302.04
1
299.354
1
301.089
1
287.546
1
285.49
1
281.118
1
270.944
1
267.978
1
258.72
1
251.757
1
245.879
1
244.573
1
236.863
1
232.758
1
229.77
1
227.066
1
223.44
1
214.66
1
217.139
1
211.903
1
213.754
1
213.973
1
211.061
1
208.776
1
205.081
1
203.223
1
200.285
1
198.704
1
202.252
1
198.256
1
197.057
1
191.364
1
191.528
1
186.018
1
184.629
1
181.231
1
178.92
1
176.328
1
177.678
1
174.16
1
171.735
1
164.059
1
158.599
1
162.039
1
159.315
1
156.58
1
152.778
1
149.523
1
145.497
1
148.824
1
148.444
1
148.155
1
151.291
1
141.918
1
138.364
1
143.244
1
145.136
1
146.388
1
145.12
1
141.923
1
142.299
1
144.589
1
142.301
1
141.291
1
139.864
1
138.533
1
140.536
1
138.648
1
141.042
1
139.719
1
137.064
1
137.195
1
137.759
1
137
1
137.086
1
136.135
1
133.902
1
137.983
1
134.784
1
133.772
1
136.806
1
136.702
1
136.119
1
134.516
1
131.518
1
127.507
1
131.504
1
130.68
1
129.574
1
128.186
1
125.417
1
129.507
1
125.012
1
124.904
1
124.41
1
125.96
1
126.093
1
125.803
1
127.697
1
121.169
1
121.939
1
124.948
1
120.554
1
121.468
1
122.519
1
121.355
1
121.423
1
122.542
1
125.811
1
123.937
1
121.121
1
120.426
1
126.792
1
127.61
1
124.291
1
121.729
1
124.085
1
123.071
1
127.081
1
124.208
1
122.258
1
128.341
1
125.319
1
129.252
1
127.288
1
127.378
1
128.655
1
128.452
1
O1s
3. Cu2O, in 0.1 mbar O2, 200 C
2005
2018
2
19
32
18
0
7
Casa Info Follows
0
0
0
0
Sum of 38 spectra in column containing 38 scans

XPS
3
Al
1486.61
0
0
0
56.5
180
FAT
20
1
3.808
0
0
0
0
0
O 1s

-1
kinetic energy
eV
946.61
0.1
2
counts
d
Transmission
d
pulse counting
1.9
1
0
0
0
0
2
ESCAPE DEPTH TYPE
d
0
MFP Exponent
d
0
402
12.1566
204.73
1
1
63.3072
1
61.9162
1
61.3964
1
61.0797
1
60.1196
1
58.3574
1
59.5925
1
60.4829
1
61.6927
1
59.1139
1
57.3578
1
57.6496
1
58.2062
1
57.6232
1
56.5106
1
59.2276
1
58.0327
1
58.3029
1
56.5581
1
56.4405
1
57.5591
1
55.4171
1
56.2945
1
53.7721
1
54.8544
1
55.5653
1
60.193
1
58.0177
1
57.1485
1
54.1784
1
56.8806
1
55.2005
1
55.5369
1
56.0337
1
57.0535
1
55.795
1
57.8591
1
56.6514
1
57.578
1
58.3391
1
57.8174
1
59.2748
1
62.8061
1
58.3774
1
60.1603
1
[...]
1
300.17
1
302.662
1
307.779
1
305.956
1
299.589
1
297.624
1
302.598
1
307.737
1
309.967
1
311.782
1
314.506
1
312.649
1
317.999
1
329.982
1
337.044
1
337.233
1
350.224
1
363.47
1
374.581
1
389.21
1
400.702
1
415.008
1
426.969
1
441.352
1
448.255
1
462.82
1
475.13
1
489.312
1
493.636
1
493.528
1
490.553
1
482.622
1
472.614
1
460.238
1
444.493
1
427.549
1
415.284
1
398.743
1
379.565
1
369.647
1
358.933
1
345.573
1
333.212
1
323.411
1
318.604
1
311.134
1
299.863
1
290.411
1
285.389
1
283.357
1
282.498
1
274.676
1
269.67
1
269.558
1
265.161
1
265.825
1
263.329
1
256.134
1
259.752
1
250.983
1
243.722
1
241.521
1
237.778
1
231.623
1
233.056
1
229.333
1
223.828
1
220.458
1
217.512
1
215.58
1
211.859
1
204.873
1
203.147
1
202.485
1
203.709
1
200.704
1
198.937
1
199.184
1
196.002
1
193.438
1
189.897
1
189.11
1
192.362
1
186.215
1
184.656
1
183.624
1
184.552
1
179.68
1
180.385
1
181.949
1
172.305
1
172.115
1
175.371
1
174.383
1
174.125
1
175.165
1
174.784
1
174.186
1
171.524
1
170.939
1
169.661
1
172.857
1
168.164
1
165.113
1
167.463
1
169.97
1
168.96
1
168.366
1
166.49
1
166.24
1
163.797
1
158.813
1
164.936
1
159.926
1
157.943
1
162.491
1
159.721
1
155.677
1
152.975
1
155.854
1
155.024
1
157.991
1
154.429
1
152.556
1
147.999
1
148.55
1
144.135
1
144.983
1
148.64
1
145.392
1
140.335
1
143.982
1
140.208
1
139.709
1
136.649
1
133.464
1
135.719
1
133.864
1
134.34
1
133.921
1
134.999
1
131.47
1
132.521
1
130.247
1
130.444
1
132.707
1
130.45
1
128.839
1
130.482
1
128.053
1
131.268
1
131.775
1
136.262
1
132.001
1
128.959
1
131.933
1
134.486
1
134.757
1
136.604
1
137.697
1
136.537
1
138.208
1
140.562
1
135.826
1
137.46
1
141.528
1
139.025
1
O1s
4. CuO, in 0.1 mbar O2, 300 C
2006
2018
2
7
31
32
0
7
Casa Info Follows
0
0
0
0
Sum of 43 spectra in column containing 43 scans

XPS
4
Al
1486.61
0
0
0
56.5
180
FAT
20
1
3.808
0
0
0
0
0
O 1s

-1
kinetic energy
eV
946.61
0.1
2
counts
d
Transmission
d
pulse counting
2.15
1
0
0
0
0
2
ESCAPE DEPTH TYPE
d
0
MFP Exponent
d
0
402
7.30304
286.567
1
1
75.6189
1
78.3553
1
77.2469
1
74.0311
1
74.8343
1
74.8689
1
72.5596
1
72.1124
1
70.7395
1
70.6745
1
71.1402
1
69.5402
1
70.4369
1
73.6458
1
68.4267
1
68.3089
1
66.8737
1
67.6996
1
66.9152
1
68.1612
1
64.0221
1
63.2446
1
61.9821
1
61.754
1
63.6597
1
60.7669
1
60.6417
1
60.5864
1
60.6935
1
60.8121
1
61.0482
1
59.3073
1
58.41
1
57.979
1
57.2597
1
57.5439
1
56.3608
1
57.0951
1
57.571
1
56.8825
1
58.6615
1
57.9107
1
58.6714
1
56.9108
1
56.0123
1
58.177
1
58.4467
1
59.3652
1
58.8741
1
59.2108
1
62.241
1
58.2623
1
59.9347
1
57.0067
1
61.2252
1
58.9051
1
62.3306
1
63.8036
1
63.7483
1
63.4192
1
61.7928
1
62.772
1
62.7043
1
64.8545
1
64.7629
1
64.5501
1
65.3237
1
67.7428
1
69.539
1
67.8257
1
69.147
1
68.3173
1
68.4253
1
68.0212
1
67.6748
1
70.3665
1
71.0669
1
71.3539
1
73.6364
1
76.8029
1
77.4949
1
79.2785
1
85.3777
1
86.1962
1
91.4623
1
94.6358
1
97.6271
1
100.002
1
100.419
1
104.482
1
106.981
1
109.36
1
107.189
1
110.273
1
110.925
1
118.915
1
128.778
1
148.678
1
175.519
1
216.391
1
266.772
1
322.606
1
390.595
1
476.301
1
525.651
1
577.567
1
594.211
1
578.99
1
546.263
1
490.52
1
411.709
1
333.755
1
267.879
1
212.382
1
163.66
1
132.564
1
107.046
1
89.3767
1
74.3858
1
65.809
1
57.7779
1
51.2741
1
47.8722
1
45.2826
1
43.7934
1
41.8437
1
39.9669
1
41.0005
1
41.3929
1
38.0217
1
36.8735
1
39.9026
1
39.1054
1
36.3125
1
37.678
1
36.562
1
35.5846
1
36.0939
1
36.2625
1
35.5267
1
35.6649
1
35.3602
1
37.4223
1
35.4632
1
34.7641
1
35.1275
1
35.7889
1
34.9162
1
35.4501
1
33.904
1
34.5848
1
35.5198
1
34.8822
1
36.4113
1
35.3914
1
34.823
1
34.4587
1
38.1953
1
37.3613
1
36.3398
1
35.9673
1
36.4052
1
35.8963
1
34.5003
1
34.6988
1
34.9078
1
35.4176
1
34.0524
1
33.9091
1
33.3593
1
34.6576
1
37.0007
1
34.9766
1
33.6583
1
34.5632
1
34.2212
1
35.0464
1
35.3462
1
34.5007
1
33.4498
1
32.7378
1
33.7229
1
33.7248
1
33.8668
1
33.7461
1
32.0812
1
33.2511
1
33.1929
1
31.8947
1
33.8768
1
34.0777
1
34.2797
1
32.1901
1
33.374
1
32.6419
1
31.1142
1
33.1222
1
34.3858
1
31.8281
1
31.578
1
35.9976
1
Survey
4. CuO, in 0.1 mbar O2, 300 C
2006
2018
2
10
32
17
0
6
Casa Info Follows
0
0
0
0
corrected with calibrated transmission function
XPS
4
Al
1486.61
0
0
0
56.5
180
FAT
150
1
3.808
0
0
0
0
0
Survey

-1
kinetic energy
eV
286.61
0.4
2
counts
d
Transmission
d
pulse counting
0.1
1
0
0
0
0
2
ESCAPE DEPTH TYPE
d
0
MFP Exponent
d
0
1
19474.9
1
18883.5
1
18897.8
1
18525.5
1
19368.8
1
18536.2
1
18680
1
19901.4
1
19059.7
1
19333.4
1
19280
1
18896.9
1
19841.7
1
19340.9
1
19616.4
1
19919.7
1
19694.2
1
20047.3
1
20050.1
1
19403.7
1
20357.4
1
20042.2
1
20525.2
1
19881.5
1
21147
1
19937.7
1
20365.4
1
21317.3
1
20280
1
20550.6
1
20893.9
1
20890.4
1
20021.9
1
21115.1
1
20948.2
1
21054.4
1
20306
1
21264.7
1
21460.3
1
22181.3
1
21151.5
1
21097.4
1
22612.7
1
21951.9
1
21719.4
1
23878.7
1
22509.6
1
22666.5
1
23595
1
23593.9
1
24378.3
1
23492.4
1
23723.5
1
21812.4
1
21370.7
1
20470.6
1
21097.7
1
20759.5
1
20736.3
1
21204
1
20219.4
1
21166.8
1
20961.9
1
20508.8
1
20377.9
1
20094
1
20739.2
1
20376.7
1
21613.5
1
21322.4
1
21779.3
1
21410.5
1
21013.2
1
20782.6
1
21839.6
1
21502.9
1
21710.3
1
21366.1
1
21093.3
1
21919.6
1
21925.2
1
22104.5
1
22206.1
1
22157.3
1
21405.8
1
21699.8
1
22356
1
22959.2
1
22031.9
1
22873.2
1
23034.2
1
21957.3
1
23587.2
1
24093.9
1
24247.1
1
24219.3
1
24340
1
24689.3
1
24012
1
24825.9
1
24444.1
1
23721.6
1
25845.8
1
25365.3
1
23692.5
1
24948.1
1
25824.7
1
25547
1
24785.7
1
25302.1
1
25646.2
1
26757.5
1
28002.9
1
28776
1
26714
1
26815.7
1
26008.2
1
26807.7
1
30635.9
1
33396.1
1
26860.1
1
26173.1
1
29884.5
1
33960.2
1
27882.6
1
23033.3
1
22213.9
1
25877.8
1
31964.5
1
32815.5
1
26349.2
1
24479.4
1
35507.9
1
43834.5
1
25809.8
1
15982.2
1
13976.9
1
13845.6
1
13581.8
1
13785.2
1
13433.8
1
12832.8
1
13527.3
1
13461.6
1
13369.1
1
12726.9
1
13731.4
1
13387.9
1
13390.2
1
13293.1
1
13465.3
1
13188
1
13125.5
1
13650.7
1
13186
1
13854.7
1
12920.1
1
14141.1
1
13907
1
13835.5
1
13983.5
1
13509.3
1
14107.2
1
14486.7
1
14201.9
1
13654.8
1
14095.8
1
13834.2
1
14244.1
1
14249.4
1
14140.7
1
14824.6
1
14664.6
1
15086.4
1
14529.1
1
14331.9
1
14415.4
1
14701.5
1
14857
1
14671.6
1
14805.4
1
15686.5
1
14561.1
1
15228.1
1
15237
1
15137.1
1
14837.7
1
15687.4
1
15176
1
15357.4
1
15686.5
1
15954.9
1
15723.4
1
15696.4
1
15778.3
1
15859.6
1
15828.9
1
15757.8
1
16515
1
16186
1
16436.3
1
16259.2
1
16526.8
1
16315.5
1
16662
1
16372.7
1
16551.7
1
16509.6
1
17250.2
1
17426.8
1
16989
1
17655.4
1
17730.6
1
17641.7
1
17810
1
17864.4
1
17732.8
1
17921.5
1
18203.1
1
17937.5
1
18266.2
1
18308.3
1
18482.3
1
18087.4
1
18208.6
1
17966.9
1
17671.8
1
18289.5
1
18620.9
1
18157.8
1
18994.2
1
18711
1
18977.6
1
19284.9
1
19114.3
1
20055.8
1
19297.6
1
20111.3
1
20641
1
21310.5
1
21778.5
1
21131.8
1
20541.3
1
20668.1
1
19577.7
1
18616
1
17439.1
1
16864.1
1
16937.5
1
17244.5
1
16869.9
1
16562.2
1
15821.9
1
16016.4
1
15825.2
1
15991.8
1
15587.4
1
15641.3
1
15240.3
1
15662.6
1
15529.8
1
15481
1
15870.1
1
15955.4
1
16488.5
1
16618.1
1
16337
1
16652
1
16701.9
1
17458
1
18164.6
1
18170.2
1
18364.9
1
19119.6
1
19867.5
1
21795.6
1
21368.2
1
19348.4
1
18517.5
1
18618.9
1
17897.8
1
15937
1
14423.9
1
14238.1
1
14111.9
1
14213.8
1
13583.1
1
13696.4
1
11848.7
1
12576.9
1
11691.1
1
11879.2
1
10993.2
1
11410.7
1
11601.5
1
11100.8
1
11926.2
1
11719.3
1
11672.7
1
11866.5
1
11838.2
1
12198.6
1
12034.6
1
12219.2
1
12655.6
1
12616.7
1
13012.4
1
13064.8
1
13793
1
14015.5
1
15244.5
1
16343.6
1
18217.7
1
18789.8
1
20152.9
1
25148.6
1
21520.8
1
15016.6
1
12443
1
10581.1
1
9975.97
1
8848.23
1
8712.9
1
8892.44
1
8734.46
1
9670.82
1
8410.88
1
6423.54
1
5651.61
1
4975.69
1
4821.79
1
3871.14
1
3932.17
1
4494.29
1
8459.91
1
16253
1
5130.39
1
2520.38
1
2336.85
1
2119.17
1
2293.28
1
2344.91
1
2324.92
1
2149.04
1
2228.08
1
2170.16
1
2130.98
1
2048.75
1
2206.63
1
2275.11
1
2005.31
1
2274.72
1
2254.36
1
2083.64
1
1868.54
1
2021.49
1
2241.96
1
2243.81
1
2240.68
1
2007.26
1
2030.24
1
2295.03
1
2080.35
1
2194.78
1
2167.39
1
2109.2
1
2196.11
1
2129.11
1
2183.39
1
2030.84
1
2182.68
1
2116.59
1
2093.89
1
2141.5
1
2463.75
1
2186.57
1
2275.6
1
2173.83
1
2344.43
1
2118.7
1
2205.86
1
2242.29
1
2232.07
1
2503.17
1
2237.58
1
2229.21
1
2383.63
1
2345.11
1
2300.45
1
2119.77
1
2407.55
1
2185.53
1
2423.2
1
2318.93
1
2358.58
1
2320.7
1
2443.5
1
2302.72
1
2308.93
1
2444.78
1
2206.98
1
2282.9
1
2210.31
1
2399.58
1
2134.8
1
2247.64
1
2256.67
1
2363.19
1
2394.76
1
2175.08
1
2267.35
1
2562.4
1
2515.06
1
2314.24
1
2321.3
1
2283.06
1
2489.25
1
2413.74
1
2402.42
1
2504.2
1
2500.39
1
2729.8
1
2379.96
1
2280.97
1
2428.65
1
2497.6
1
2623.38
1
2597.23
1
2501.31
1
2416.9
1
2476.93
1
2367.14
1
2543.37
1
2431.8
1
2515.8
1
2612.86
1
2627.82
1
2519.19
1
2449.83
1
2481.42
1
2700.23
1
2688.18
1
2472.13
1
2792.57
1
2447.7
1
2792.05
1
2523.07
1
2330.67
1
2652.95
1
2494.97
1
2580.18
1
2761.51
1
2583.38
1
2691.79
1
2672.09
1
2728.85
1
2794.24
1
2694.9
1
2772.05
1
2740.44
1
2606.06
1
2603.03
1
2656.06
1
2809.48
1
2804.44
1
2595.22
1
2721.95
1
2764.05
1
2871.69
1
2794.55
1
2976.21
1
2860.55
1
2803.53
1
2953.27
1
3056.7
1
3007.27
1
2742.49
1
2738.56
1
2767.82
1
3021.68
1
2897.81
1
2853.27
1
3096.34
1
3154.15
1
3000.66
1
3060.75
1
3161.56
1
3052.76
1
3102.81
1
3152.69
1
3033.33
1
3138.6
1
2971.95
1
3031.29
1
3254.72
1
3180.51
1
3223.46
1
3186.37
1
2930.97
1
3277.08
1
3239.18
1
3299.64
1
3089.48
1
3093.89
1
3119.97
1
3363.9
1
3214.8
1
3416.25
1
3348.24
1
3311.84
1
3411.79
1
3380.27
1
3535.61
1
3682.49
1
3497.77
1
3540.64
1
3618.65
1
3593.37
1
3373.61
1
3668.43
1
3699.53
1
3616.25
1
3538.9
1
3599.41
1
3670.44
1
3776.44
1
3649.68
1
3850.27
1
3748.11
1
4077.1
1
3969.94
1
4142.39
1
4209.58
1
4515.67
1
4850.44
1
5025.31
1
4736.45
1
5863.94
1
6594.84
1
5018.86
1
3938.01
1
3584.5
1
3577.27
1
3577.78
1
3292.88
1
3454.94
1
3329.59
1
3469.28
1
3558.37
1
3310.73
1
3397.67
1
3711.89
1
3663.28
1
4117.42
1
4142.06
1
3952.23
1
3981.74
1
4490.11
1
4913.61
1
5148.94
1
8425.08
1
10067.6
1
8532.19
1
3908.32
1
1772.01
1
1447.79
1
1162.3
1
1001.43
1
999.583
1
891.859
1
969.998
1
862.067
1
889.463
1
1090.8
1
906.758
1
884.245
1
1004.81
1
1001.54
1
1028.75
1
901.094
1
971.787
1
886.871
1
1060.79
1
935.638
1
1058
1
1131.09
1
1092.29
1
980.423
1
1199.32
1
1559.08
1
1219.21
1
929.243
1
832.33
1
1569.67
1
1787.14
1
1500.91
1
1910.57
1
3138.25
1
3950.88
1
1288.17
1
204.075
1
1
Survey
1. Cu metal, Vacuum, room temp.
2005
2018
2
14
31
39
0
6
Casa Info Follows
0
0
0
0
corrected by calibrated transmission function
XPS
1e+037
Al
1486.61
0
0
0
56.5
180
FAT
150
1
3.808
0
0
0
0
0
Survey

-1
kinetic energy
eV
266.61
0.5
2
counts
d
Transmission
d
pulse counting
0.1
1
0
0
0
0
2
ESCAPE DEPTH TYPE
d
0
MFP Exponent
d
0
1
26964.7
26105.1
26060.4
26879.4
26586.3
27294.1
28111
27780.4
26939.9
26578.2
27478.5
27321.4
27389.7
27000.8
27513.1
27549.4
26933.2
27119.1
27803.1
27857.6
27032.1
28414.2
27207.3
27889.7
28579.4
27511.5
28383.7
27760.4
28356.4
27593.8
27955.4
28078.2
28071.3
27684.9
28097
27734.9
29457.3
28358.3
28389.4
28603.6
28717.7
28998.4
29108.3
29050.8
27967.1
28725.4
28081.6
29163.7
29533.1
28777.6
29319.2
29881.3
28695.2
28067.2
29490.3
28869.4
29073.8
28135.6
29155.4
29894.7
28795.1
29130.3
29451.1
29778.2
29202.4
29776.2
29585.3
29202.4
29298.9
28742.5
29396.6
29156
28779.2
30034.2
29964.2
30221.8
30380.4
30277.8
30227.9
30042.1
29278.6
30555.7
29565.2
31363.2
30388
29672.2
30450.3
30916.3
30997.1
30886.8
30568.9
31128.6
30943.3
30948.3
31761.8
31405.6
31113.3
30592.6
31129.8
31783.2
32666.5
31251.5
32154.8
32094.5
31679.7
30863.2
32418.2
32430.7
32154.9
32012.3
32849
32832.9
32015.4
31648.8
32364.3
30554.4
33331
32858.5
34024.8
34512.4
35512.3
35456
37079.3
38115.4
36905.4
35236.5
33502.2
32726.5
31625.1
31055.6
29640.1
30459.7
29197
29315.7
29465.8
29851.1
29111.1
29950.7
29711.7
29588.5
29110.4
28998.1
29824.4
29228.4
28002.6
29087.6
29595.4
29439
30367.1
29323.9
29317.1
29620.7
29721.8
29788.8
28813
30190.3
29466
30127.8
29479.7
29302.9
29495.2
30458.5
30664.1
31167.1
30536.3
30797.7
30747
29264.5
30962.7
30080.4
31001.3
30632.9
29487.3
31157.4
31308.5
30083.5
31188.5
31417.3
31314.8
30658.8
31825.2
31728.8
30625.2
31273
31462.6
31301.2
31664.2
30948
31400.1
31331.9
31796.3
31989.9
31328.8
31746.4
31995.8
32577.5
32934.4
32417.1
31943.2
31617.7
32257.8
33838.2
32551.9
32477.7
32969
33546.8
32803.3
32673.4
33463.6
33510.9
33410.5
34707.8
33252.4
33678
34139.8
34352.1
34687.9
34054
35499.2
34773.1
34424.2
34397.9
35801.8
35168.6
35582.7
35516.9
35493.7
36501
36402.4
36424
36120.5
35533.9
36814.4
36781.2
37725.4
37546.7
37021.5
38070.2
37653.3
37746.9
38078
38980.6
38905.5
39314.9
38651.1
39506.4
39757.4
40735
39843.8
40750.4
40061.5
40728.5
40091.9
41909.7
41187.4
41227.6
39730.4
39896.1
40060.7
41291.1
40267.2
40453.2
41892.3
41426.5
46210
56143.3
70359.6
74608.1
66391.6
52282.3
42784.4
38167.5
37111.3
35810.2
35928.9
35094.3
33779.1
33693.5
32001.6
31375.2
29943.8
31669.7
31874.8
32378.4
39999.8
62195.6
102071
105579
78603.2
44875.4
25472.2
22026.5
20335.4
19667
18684.8
18855.6
19357
19029.2
18397.8
18907.3
18385.8
18445.3
18819.6
17753.6
18285.9
17886.5
17774.7
17936.2
18276
17814
17819.5
17726.2
17910.3
18407.7
18651.5
18010.8
18487.7
18417.8
17875.3
19049.1
18594.5
18397.5
19086.5
18473.5
18449.9
19302.8
18438.7
18947.7
19574.6
18815.9
18878
19074.5
18314.5
18578.5
18317.2
19237.9
18907
18435.5
18567.1
18881.5
18426.8
18871.2
18748.2
18997.4
19648
19747.6
19274
18436.5
18988.6
19729.5
19004.8
19199.5
19304.9
19343.1
19985.3
19864.7
19730.4
20502.9
19594
19661.8
19398.3
20054.2
19630.4
19396.1
18826
19808.6
19815.7
19706.2
20043.1
20964.9
19524.6
19941.8
19859.2
20544.6
20710.3
20469.6
20512.4
20594.1
20165.2
20178.7
20521.3
20834.1
21016.8
20023.1
20152.4
20867.3
21164.9
21124.7
21212.5
20473.3
20623.4
21775.7
20896.8
20931.9
21671.9
21625.4
21660
21429.8
21897.4
20786.6
21065.1
21613.9
22617
21107.4
21082.8
22424.3
21798.2
21744.7
22596.7
22097.9
22662.8
21779.4
23069.9
22640.1
22493.2
22401
22150.6
22042
22190
23699.9
23231.4
22745
22323.1
22615.6
22971.5
22612
22768
23165.8
22854
23731.6
23712.6
23996.9
23899.8
23820.4
23408.1
24651.4
24105.6
24346
24361.5
24361
25093.2
24780.2
24824
25281.1
25656.5
24371.6
25642.3
25312
25865.5
26176
26360.5
25470.8
25992.3
26477.4
25850.2
26162
26181.9
25388.9
25603.1
26457
26687.7
26838.5
27806.8
26587.6
26304.3
26303.3
26607.5
26050.7
25999
24779.6
25890.7
26371.8
26864.4
26183.5
27364
27234.5
26747.2
26840.4
26285.3
27394.3
26791.9
27225.5
27235.7
27529
28321.9
28695.2
28545.3
28750.8
28134.7
29194.2
30027.2
30442.5
30098.5
30246.5
30193.1
30060.1
30318.9
31729.8
31748
31834
32258.1
33111
31747.3
31276.9
31093.3
31609.4
30625.2
31249.5
30527.9
29515.3
27319.1
26035.3
24908.9
24308
24081.4
24145.9
23888.1
23789.6
24475.8
23803.3
23707.1
23185.2
22547.3
23147.3
22826.6
22919.1
23159.5
23117
23275.2
23197.6
23417.8
22398.5
21985.9
21782.4
21784.9
21642.6
21544.1
22352.3
22236.5
22460.4
22228.8
21487.2
22103.2
22442.1
22790.2
22740.9
22446
23026.3
22687
23868.1
23706
23324.4
24064.3
23832
24785.5
23975.9
24569.3
24308.7
25359.3
25256.3
25873.8
26944.7
26532.2
27789.8
28101.3
27842.6
28046.5
28294.9
28860.9
30568.4
32042.2
34482.2
34983.8
32087
30025.9
28708.8
27182
26725.6
26875.1
27025.5
27346.7
26449
24036.9
22752.9
21716
19640.1
19531.5
18917.4
19169.2
18360.2
19258.3
18738
18471.8
17694.1
17406.4
16657.4
16452.1
15885.6
15816.8
15623.5
15512.4
15076
15262.3
14737.5
14549.5
14860.8
15011.5
14706.7
15257.1
15349.8
15182.5
15291.5
15660.5
15117.4
15740.4
15676
15718.3
16514.7
15951.7
16531.2
16547.5
16778.6
16671.5
16937.2
17713.4
17269.5
17862.2
17442
17935.3
18141.2
18878.9
18523.6
18912.9
18848
18379.4
19256.5
19107.8
19488.2
19009.3
20553.5
20924.3
21358.2
22404.3
23026.5
24594.3
25618.5
28273.2
29688.2
30981.8
33961.1
39896
46087
39940
33521.3
24154.1
19022.8
14861.3
13137.9
11976.7
11614.3
10487.1
10087.8
9759.58
9689.28
9298.62
9550.55
9656.87
9920.2
9465.25
9217.26
9698.71
10012.8
9376.26
7628.43
6234.5
4950.43
4839.16
4150.88
4121.79
3936.36
3550.74
3382.85
3254.23
3606.11
3206.09
3226.66
3295.77
3334.82
2952.1
3167.84
3021.01
3018.72
3179.96
2849.3
2972.37
3029.67
2854.28
2697.09
3008.63
3061.94
2893.36
2860.97
2745.91
2860.81
2990.48
2858.18
2767.78
2905.3
2801.67
2681.01
2854.72
2898.24
2894.42
2798.05
3106.58
2879.92
2721.73
2645.29
2824.86
2953.2
2891.3
3028.34
2992.94
2784.92
2611.96
2965.33
3016.87
3062.82
2889.82
2682.07
2958.45
2866.24
3005.89
2787.95
3017.9
3142.49
3196.45
2815.03
3102.21
2983.65
2664.99
2789.72
2878.67
3013.49
2884.25
2925.07
2998.56
2707.11
2697.74
2867.78
2997.8
2707.1
2673.33
3059.49
2830.29
2999.17
2811.92
2862.64
2944.55
2705.57
2908.41
2835.42
2952.27
3020.34
3088.78
2933.88
2804.72
3069.27
2820.81
2832.21
3002.12
2933.73
3052.59
2968.69
2932.08
2881.08
3040.14
2931.56
3178.08
2832.21
2900.98
3028.81
2938.76
3071.24
2924.64
3196.44
2935.24
3088.6
3130.86
2981.17
3150.86
3442.14
3209.68
3007.78
2989.8
3211.03
2913.81
3207.75
2988.48
3073.11
3039.32
3094.85
3037.67
3273.98
3251.08
2955.46
3221.84
3227.21
3037.17
3067.25
3030.17
3217.53
3188.71
3378.65
3250.61
3142.83
3076.76
3278.35
3295.31
3243.68
3168.97
3157.64
3068.26
3198.96
3116.44
3027.63
2925.74
3166.02
3138.1
2881.14
3086.86
3375.27
3142.77
3277.56
3129.51
2952.04
3024.65
3080.49
2962.58
3180.58
3374.23
3314.24
3314.22
3378.17
2895.73
3196.92
3100.07
3241.02
3136.16
3382.38
3317.97
3038.89
3213.55
3170.99
3219.21
3175.58
3060.43
3275.54
3135.18
3309.48
3266.38
3195.56
3293.76
3327.1
2975.61
3355.76
3261.62
3014.73
3033.75
3302.96
3172.03
3271.28
3438.86
3291.07
3585.81
3310.28
3352.09
3166.83
3419.46
3617.93
3422.89
3361.27
3457.68
3273.89
3142.81
3522.9
3187.84
3301.21
3379.62
3535.75
3108.33
3187.99
3335.79
3401.54
3175.21
3400.24
3258.86
3251.31
3578.14
3405.69
3442.84
3452.21
3466.96
3499.16
3205.97
3404.58
3704.76
3488.47
3367.84
3278.1
3607.36
3584.63
3671.61
3644.87
3481.01
3933.38
3408.06
3621.27
3551.87
3516.26
3725.79
3593.27
3606.29
3669.19
3470.71
3602.3
3716.37
3714.05
3539.72
3797.97
3568.57
3705.98
3997.18
3870.93
4368.64
4377.57
4177.7
3796.74
3454.74
3450.14
3545.38
3477.41
3503.24
3789.3
3522.18
3432.44
3631.66
4112.91
3789.24
3367.97
3655.63
3558.4
3826.6
3496.74
3415.16
4033.4
3672.25
3927.31
3700.02
3871.85
3851.17
3677.15
3717.01
3830.19
3959.71
3983.65
3808.26
3758.52
3713.5
3643.48
3829.92
3705.51
4014.69
3734.97
3892.38
3926.86
3475.93
3732.78
3741.12
3644.91
3929.23
4093.21
3940.19
4052.21
3673.46
4057.75
3805.19
3924.5
3979.66
3858.53
3958.88
4305.79
4009.37
4125.46
4020.16
3958.5
3904.05
3958.13
3874.34
4060
4024.48
3795.9
4123.92
4084.36
3785.91
4084.35
3957.02
4363.89
3598.77
4030.94
4117.13
4148.32
4007.22
4030.56
4441.53
4254.22
4218.2
4265.19
4286.63
4287.97
3932.21
4031.5
4016.81
4332.69
4295.24
4038.51
4191.14
4213.48
4138
4382.88
4239.02
4046.64
4497.31
4190.76
4461.14
4601.89
4553.22
4451.57
4224.94
4557.66
4664.85
4666.1
4571.25
4652.21
4663.29
4836.34
4687.9
4585.94
4680.75
4692.26
4823.24
4721.82
4741.23
4615.13
4797.02
4545.31
5262.42
5019.27
4903.74
4634.91
5151.65
5065.06
5175.55
5210.01
4947.45
5223.82
4952.68
5144.06
5271.13
5654.21
5460.96
5427.44
5445.98
5504.08
5576.73
5488.42
5756.5
5732.89
5653.97
5438.66
5807.66
5599.96
5883.05
5462.49
6065.37
5870.09
6043.52
6050.05
6080.6
5874.11
5630.44
6013.27
5846.77
6825.75
7333.96
8657.3
11085.8
11964.8
10597.2
8293.62
6541.56
5834.61
5189.66
5224.39
5338.37
5241.34
5222.96
5308.81
4804.46
5128.63
5000.91
5175.42
5151.17
5297.66
5709.49
5357.93
5612.37
5751.06
5847.32
5611.45
5771.4
5910.78
6044.87
5882.55
5975.13
6108.94
5640.99
5523.31
5632.93
5689.92
5351.4
5411.09
5697.83
5431.89
5506.62
5342.41
5524.79
5960.75
6178.05
7050.14
9030.98
11837.6
15205.4
17879.4
19154.9
16109.2
11428.6
6503.6
3877.89
3081.58
2397.46
1938.74
1714.09
1661.71
1498.59
1319.2
1417.09
1207.77
1303.75
1202.03
1240.46
1184.22
1133.09
1165.21
1035.15
1167.16
1258.28
1254.71
1098.29
1192.22
1102.6
1221.3
1021.08
1233.56
1320.02
1083.03
1284.83
1117.42
1305.25
1462.31
1195.79
1278.89
1220.05
1299.06
1186.22
1420.72
1453.01
1204.68
1459.67
1422.29
1477.2
1334.75
1424.15
1459.4
1352.02
1632.32
1469.27
1625.13
1682.97
1449.45
1
end of experiment