File: data/measured/EX502-506 Fe, Ni, Co mixed oxides.vms
VAMAS Surface Chemical Analysis Standard Data Transfer Format 1988 May 4
Not Specified
Not Specified
Not Specified
Not Specified
35
Casa Info Follows CasaXPS Version 2.3.24PR1.0
9
Co
Co
Co3O4
Co3O4
CoO
CoO
Fe
Fe
Fe2O3
Fe2O3
Fe3O4
Fe3O4
FeO
FeO
Ni
Ni
NiO
NiO
Created by SpecsLab Prodigy, Version 4.75.1-r96360
SourceAnalyserAngle: Not Specified
CasaRowLabel:FeNiCo
CasaRowLabel:NiCo
CasaRowLabel:FeCo
CasaRowLabel:NiFe
CasaRowLabel:Co
CasaRowLabel:Co3O4
CasaRowLabel:CoO
CasaRowLabel:Fe
CasaRowLabel:Fe2O3
CasaRowLabel:Fe3O4
CasaRowLabel:FeO
CasaRowLabel:Ni
CasaRowLabel:NiO
NORM
REGULAR
9
1
Exp Variable
d
0
0
0
0
67
FeNiCo
FeNiCo
2021
6
1
15
32
52
0
28
Casa Info Follows
0
0
1
CASA region (*Ni 2p-Co 2p-Fe 2p*) (*Min Limits*) 596.74342 801.81 1 2 0 0 0 -1643 0 0 (*NoTag*) 0 0 0
9
CASA comp (*Co*) (*%&<>CO*) Area 8840.4062 0 25031010 -1 1 MFWHM 1 1 1 -1 1 Position 701.76866 696.61 716.61 -1 1 RSF 1 MASS 0 INDEX 0 (*NoTag*) CONST (**) UNCORRECTEDRSF 0
CASA comp (*Co3O4*) (*%&<>CO3O4*) Area 13155.67 1e-020 1743731.7 -1 1 MFWHM 1 1 1 -1 1 Position 700.55964 696.61 716.61 -1 1 RSF 1 MASS 0 INDEX 1 (*NoTag*) CONST (**) UNCORRECTEDRSF 0
CASA comp (*CoO*) (*%&<>COO*) Area 136435.75 0 1.7430073e+008 -1 1 MFWHM 1 1 1 -1 1 Position 705.67863 701.61 716.61 -1 1 RSF 1 MASS 0 INDEX 2 (*NoTag*) CONST (**) UNCORRECTEDRSF 0
CASA comp (*Fe*) (*%&<>FE*) Area 426.3953 1e-020 943278.97 -1 1 MFWHM 1 1 1 -1 1 Position 776.189 776.61 801.81 -1 1 RSF 1 MASS 0 INDEX 0 (*NoTag*) CONST (**) UNCORRECTEDRSF 0
CASA comp (*FeO*) (*%&<>FEO*) Area 11948.88 1e-020 943278.97 -1 1 MFWHM 1 1 1 -1 1 Position 774.61 774.61 801.81 -1 1 RSF 1 MASS 0 INDEX 1 (*NoTag*) CONST (**) UNCORRECTEDRSF 0
CASA comp (*Fe3O4*) (*%&<>FE3O4*) Area 425.23558 1e-020 943278.97 -1 1 MFWHM 1 1 1 -1 1 Position 777.25675 774.61 801.81 -1 1 RSF 1 MASS 0 INDEX 2 (*NoTag*) CONST (**) UNCORRECTEDRSF 0
CASA comp (*Fe2O3*) (*%&<>FE2O3*) Area 107116.7 1e-020 943278.97 -1 1 MFWHM 1 1 1 -1 1 Position 775.46493 774.61 801.81 -1 1 RSF 1 MASS 0 INDEX 3 (*NoTag*) CONST (**) UNCORRECTEDRSF 0
CASA comp (*Ni*) (*%&<>NI*) Area 6586.5274 1e-020 943278.97 -1 1 MFWHM 1 1 1 -1 1 Position 632.5385 628.61 636.61 -1 1 RSF 1 MASS 0 INDEX 0 (*NoTag*) CONST (**) UNCORRECTEDRSF 0
CASA comp (*NiO*) (*%&<>NIO*) Area 86812.936 1e-020 943278.97 -1 1 MFWHM 1 1 1 -1 1 Position 631.44195 628.61 636.61 -1 1 RSF 1 MASS 0 INDEX 1 (*NoTag*) CONST (**) UNCORRECTEDRSF 0
File = C:/Users/Mark/Downloads/EX506_S788_FeNiCo.sle
Group = Loop 2_UHV at 200C, #Treatments:, #Temp:200C , #Pressure:0.1mbar , #Atmosphere:O2, #Comments:
First of group = 0
Spectrum ID = 25
Analyzer lens = AngleResolvedMode22:1.5kV
Analyzer slit = 4:7x20c\C:mesh
Scan mode = FixedAnalyzerTransmission
Kinetic energy start = 596.61
PCA Coefs = 86557.3, 578.657,
Energy offsets:  1:0 2:0
PCA Coefs = 133652, 709.231,
PCA Coefs = 133652, 709.231, 268.058,
C:\Users\Mark\Downloads\EX506_S788_FeNiCo.vms
XPS
20
Al
1486.61
0
0
0
54.5
180
FAT
20
1
4.1408
0
0
0
0
0
Ni 2p-Co 2p-Fe 2p

-1
kinetic energy
eV
596.61
0.1
2
counts
d
Transmission
d
pulse counting
1
1
0
0
0
0
3
MFP Exponent
d
0
ESCAPE DEPTH TYPE
d
0
PROPAGATION_CONVERGED
d
1
1
3890.65
0.3
3876.85
0.3
3863.87
0.3
3869.35
0.3
3827.93
0.3
3834.8
0.3
3821.31
0.3
3798
0.3
3768.31
0.3
3780.72
0.3
3783.84
0.3
3774.56
0.3
3748.98
0.3
3773.45
0.3
3772.28
0.3
3766.45
0.3
3769.43
0.3
3802.91
0.3
3838.05
0.3
3844.79
0.3
3874.53
0.3
3868.61
0.3
3889.38
0.3
3944.84
0.3
3947.1
0.3
4000.69
0.3
4047.49
0.3
4087.62
0.3
4080.62
0.3
4099.63
0.3
4070.92
0.3
4087.46
0.3
4079.2
0.3
4097.92
0.3
4066.39
0.3
4069.79
0.3
4061.41
0.3
4040.71
0.3
4014.85
0.3
4002.21
0.3
3956.63
0.3
3943.56
0.3
3924
0.3
3916.79
0.3
3905.57
0.3
3917.34
0.3
3911.66
0.3
3940.98
0.3
3947.81
0.3
3992.79
0.3
4020.17
0.3
4085.81
0.3
4105.05
0.3
4172.59
0.3
4216.87
0.3
4254.03
0.3
4249.87
0.3
4229.62
0.3
4173.4
0.3
4113.5
0.3
3998.92
0.3
3887.47
0.3
3749.85
0.3
3661.41
0.3
3593.28
0.3
3580.91
0.3
3571.95
0.3
3573.86
0.3
3585.47
0.3
3583.87
0.3
3614.91
0.3
3610.14
0.3
3658.47
0.3
3675.58
0.3
3685.42
0.3
3725.56
0.3
3734.06
0.3
3729.91
0.3
3731.98
0.3
3747.73
0.3
3766.42
0.3
3809.91
0.3
3857.94
0.3
3886.14
0.3
3918.47
0.3
3983.97
0.3
3985.45
0.3
4024.95
0.3
4065.65
0.3
4116.55
0.3
4186.52
0.3
4239.2
0.3
4281.12
0.3
4318.91
0.3
4317.04
0.3
4320.46
0.3
4261.27
0.3
4212.29
0.3
4126.06
0.3
4056.49
0.3
4005.55
0.3
3955.36
0.3
3911.31
0.3
3938.81
0.3
3957.38
0.3
3999.88
0.3
4059.25
0.3
4152.6
0.3
4262.59
0.3
4396.4
0.3
4546.69
0.3
4696.4
0.3
4832.93
0.3
4903.7
0.3
4946.55
0.3
4975.96
0.3
4974.69
0.3
4806.01
0.3
4466.73
0.3
4050.55
0.3
3730.11
0.3
3579.35
0.3
3494.04
0.3
3474.4
0.3
3442.31
0.3
3440.19
0.3
3423.18
0.3
3417.19
0.3
3412.5
0.3
3428.65
0.3
3415.65
0.3
3442.88
0.3
3427.85
0.3
3455.45
0.3
3442.17
0.3
3456.94
0.3
3465.83
0.3
3455.3
0.3
3480.27
0.3
3466.85
0.3
3471.67
0.3
3480.05
0.3
3466.02
0.3
3464.15
0.3
3471.49
0.3
3465.06
0.3
3492.31
0.3
3460.16
0.3
3477.72
0.3
3484.42
0.3
3465.32
0.3
3460.6
0.3
3480.98
0.3
3459.91
0.3
3471.71
0.3
3487.04
0.3
3472.87
0.3
3484.27
0.3
3466.57
0.3
3484.39
0.3
3514
0.3
3484.01
0.3
3495.07
0.3
3503.41
0.3
3489.31
0.3
3487.41
0.3
3474.88
0.3
3467.95
0.3
3463.57
0.3
3459.54
0.3
3444.72
0.3
3461.59
0.3
3430.7
0.3
3437.22
0.3
3442.01
0.3
3426.97
0.3
3433.23
0.3
3432.07
0.3
3431.01
0.3
3436.76
0.3
3404.87
0.3
3398.11
0.3
3392.87
0.3
3399.71
0.3
3360.89
0.3
3355.74
0.3
3335.01
0.3
3310.63
0.3
3298.02
0.3
3295.87
0.3
3250.72
0.3
3232.17
0.3
3215.17
0.3
3204.75
0.3
3164.37
0.3
3141.68
0.3
3127.51
0.3
3103.06
0.3
3099.95
0.3
3083.99
0.3
3084.66
0.3
3059.17
0.3
3040.72
0.3
3048.8
0.3
3029.83
0.3
3022.56
0.3
3028.67
0.3
3005.92
0.3
3005.53
0.3
3017.06
0.3
3006.96
0.3
2991.41
0.3
3009.43
0.3
3014.17
0.3
3007.05
0.3
2994.24
0.3
2997.3
0.3
2988.95
0.3
3005.53
0.3
2994.68
0.3
2977.96
0.3
2988.01
0.3
2985.29
0.3
2968.46
0.3
2987.2
0.3
2968.38
0.3
2987.54
0.3
2973.68
0.3
2979.04
0.3
2971.07
0.3
2975.51
0.3
2979.49
0.3
2966.96
0.3
2983.13
0.3
2969.94
0.3
2972.56
0.3
2973.1
0.3
2961.9
0.3
2982.63
0.3
2951.04
0.3
2956.28
0.3
2976.19
0.3
2970.37
0.3
2973.54
0.3
2960.55
0.3
2957.15
0.3
2964.37
0.3
2957.75
0.3
2970.72
0.3
2967.45
0.3
2955.52
0.3
2946.75
0.3
2956.77
0.3
2935.77
0.3
2940.75
0.3
2923.17
0.3
2940.96
0.3
2933.52
0.3
2925.19
0.3
2935.92
0.3
2928.1
0.3
2940.08
0.3
2922.88
0.3
2927.64
0.3
2921.03
0.3
2906.36
0.3
2918.3
0.3
2912.47
0.3
2924.93
0.3
2936.57
0.3
2941.58
0.3
2952.44
0.3
2950.92
0.3
2954.86
0.3
2970.54
0.3
2987.77
0.3
3007.1
0.3
2987.54
0.3
3027.15
0.3
3050.13
0.3
3052.98
0.3
3118.33
0.3
3118.43
0.3
3156.38
0.3
3199.42
0.3
3221.06
0.3
3252.03
0.3
3277.42
0.3
3304.16
0.3
3326.58
0.3
3320.49
0.3
3318.14
0.3
3331.76
0.3
3290.89
0.3
3265.45
0.3
3245.06
0.3
3191.33
0.3
3172.2
0.3
3150.64
0.3
3154.44
0.3
3150.99
0.3
3177.59
0.3
3189.65
0.3
3226.25
0.3
3276.34
0.3
3335.99
0.3
3367.26
0.3
3433.6
0.3
3505.33
0.3
3533.62
0.3
3570.17
0.3
3588.21
0.3
3556.5
0.3
3513.94
0.3
3432.13
0.3
3347.86
0.3
3238.29
0.3
3132.5
0.3
3055.3
0.3
2996.85
0.3
2989.96
0.3
2972.84
0.3
2973.39
0.3
2982.93
0.3
2995.73
0.3
3025.32
0.3
3055.73
0.3
3065.1
0.3
3103.14
0.3
3110.87
0.3
3134.89
0.3
3195.38
0.3
3213.51
0.3
3254.44
0.3
3292.74
0.3
3350.1
0.3
3397.84
0.3
3436.41
0.3
3489.21
0.3
3540.06
0.3
3584.3
0.3
3622.02
0.3
3658.42
0.3
3677.81
0.3
3711.98
0.3
3726.62
0.3
3716.01
0.3
3711.67
0.3
3679.95
0.3
3650.18
0.3
3669.44
0.3
3658
0.3
3675.85
0.3
3713.34
0.3
3783.7
0.3
3843.5
0.3
3911.36
0.3
3988.2
0.3
4055.47
0.3
4157.25
0.3
4213.51
0.3
4308.48
0.3
4391.61
0.3
4418.64
0.3
4419.86
0.3
4312.9
0.3
4112.7
0.3
3854.13
0.3
3589.98
0.3
3324.62
0.3
3060.52
0.3
2890.85
0.3
2796.32
0.3
2753.79
0.3
2692.42
0.3
2680.4
0.3
2671.44
0.3
2655.45
0.3
2634.77
0.3
2633.51
0.3
2616.79
0.3
2595.71
0.3
2593.81
0.3
2596.93
0.3
2581.86
0.3
2563.74
0.3
2558.13
0.3
2538.75
0.3
2534.4
0.3
2525.46
0.3
2530.26
0.3
2505.45
0.3
2479.97
0.3
2467.26
0.3
2437.74
0.3
2424.12
0.3
2382.1
0.3
2370.29
0.3
2328.7
0.3
2321.16
0.3
2285.98
0.3
2247.45
0.3
2222.26
0.3
2190.47
0.3
2182.8
0.3
2154.89
0.3
2127.42
0.3
2107.51
0.3
2097.71
0.3
2097.35
0.3
2083.44
0.3
2071.89
0.3
2059.38
0.3
2044.26
0.3
2041.83
0.3
2032.5
0.3
2036.47
0.3
2021.79
0.3
2023.98
0.3
2023.58
0.3
2009.79
0.3
1998.4
0.3
2012.93
0.3
1999.61
0.3
2001.83
0.3
2000.17
0.3
1991.31
0.3
2004.8
0.3
1979.22
0.3
1964.06
0.3
1969.69
0.3
1963.75
0.3
1980.54
0.3
1976.8
0.3
1979.2
0.3
1963.37
0.3
1977.78
0.3
1979.92
0.3
1968.88
0.3
1976.33
0.3
1968.09
0.3
1968.12
0.3
1958.19
0.3
1960.9
0.3
1958.23
0.3
1957.4
0.3
1945.21
0.3
1952.23
0.3
1943.5
0.3
1944.9
0.3
1937.95
0.3
1946.39
0.3
1943.41
0.3
1932.09
0.3
1944.02
0.3
1933.99
0.3
1940.57
0.3
1921.23
0.3
1932.87
0.3
1936.66
0.3
1946.3
0.3
1930.4
0.3
1950.62
0.3
1946.81
0.3
1941.36
0.3
1930.68
0.3
1944.26
0.3
1948.27
0.3
1934.46
0.3
1940.1
0.3
1946.11
0.3
1947.29
0.3
1945.23
0.3
1951.07
0.3
1956.29
0.3
1958.86
0.3
1951.42
0.3
1949.31
0.3
1959.58
0.3
1967.01
0.3
1963.45
0.3
1977.32
0.3
1962.01
0.3
1989.24
0.3
1990.57
0.3
1987.51
0.3
2009.11
0.3
2008.57
0.3
2032.97
0.3
2028.2
0.3
2032.77
0.3
2035.89
0.3
2039.26
0.3
2038.89
0.3
2028.45
0.3
2031.48
0.3
2014.09
0.3
2023.01
0.3
2023.73
0.3
2024.64
0.3
2022.64
0.3
2008.2
0.3
2010.24
0.3
2022.78
0.3
2018.91
0.3
2026.33
0.3
2034.89
0.3
2047.95
0.3
2031.12
0.3
2048.73
0.3
2070.16
0.3
2077.01
0.3
2082.43
0.3
2091.49
0.3
2085.6
0.3
2099.27
0.3
2094.78
0.3
2123.05
0.3
2125.86
0.3
2136.12
0.3
2134.5
0.3
2141.05
0.3
2160.59
0.3
2148.57
0.3
2159.6
0.3
2168.75
0.3
2159.59
0.3
2158.76
0.3
2179.99
0.3
2182.44
0.3
2158.89
0.3
2164.26
0.3
2166.51
0.3
2184.69
0.3
2190.54
0.3
2183.06
0.3
2192.11
0.3
2195.88
0.3
2238.78
0.3
2242.67
0.3
2271.15
0.3
2288.39
0.3
2319.83
0.3
2337.03
0.3
2387.09
0.3
2407
0.3
2437.88
0.3
2469.68
0.3
2489.29
0.3
2533.44
0.3
2548.03
0.3
2564.82
0.3
2573.6
0.3
2578.2
0.3
2559.72
0.3
2528.57
0.3
2509.65
0.3
2442.35
0.3
2400.62
0.3
2351.23
0.3
2333
0.3
2326.99
0.3
2302.82
0.3
2323.57
0.3
2323.17
0.3
2347.13
0.3
2375.85
0.3
2391.51
0.3
2396.16
0.3
2410.08
0.3
2397.44
0.3
2412.72
0.3
2415.85
0.3
2391.73
0.3
2414.94
0.3
2392.91
0.3
2387.91
0.3
2386.91
0.3
2391.47
0.3
2402.16
0.3
2405.56
0.3
2423.54
0.3
2461.52
0.3
2464.24
0.3
2516.94
0.3
2545.76
0.3
2603.59
0.3
2640.89
0.3
2675.5
0.3
2728.96
0.3
2759.17
0.3
2814.38
0.3
2832.02
0.3
2841.27
0.3
2896.56
0.3
2912.18
0.3
2902.87
0.3
2861.78
0.3
2781.1
0.3
2661.66
0.3
2507.08
0.3
2310.12
0.3
2093.22
0.3
1874.8
0.3
1720.26
0.3
1618.19
0.3
1553.05
0.3
1523.72
0.3
1493.35
0.3
1458.31
0.3
1453
0.3
1447.09
0.3
1435.77
0.3
1412.7
0.3
1405.49
0.3
1400.9
0.3
1390.18
0.3
1378.1
0.3
1366.05
0.3
1365.6
0.3
1352.23
0.3
1330.02
0.3
1325.46
0.3
1303.54
0.3
1288.72
0.3
1275.02
0.3
1270.91
0.3
1247.99
0.3
1239.86
0.3
1224.9
0.3
1228.52
0.3
1207.7
0.3
1219.41
0.3
1193.96
0.3
1200.96
0.3
1187.32
0.3
1202.08
0.3
1190.64
0.3
1191.98
0.3
1178.65
0.3
1181.55
0.3
1166.14
0.3
1157.79
0.3
1159.84
0.3
1153.06
0.3
1142.33
0.3
1122.67
0.3
1119.35
0.3
1104.95
0.3
1102.2
0.3
1088.62
0.3
1082.31
0.3
1073.71
0.3
1076.97
0.3
1065.53
0.3
1045.58
0.3
1057.19
0.3
1050.94
0.3
1047.78
0.3
1048.79
0.3
1037.42
0.3
1041.97
0.3
1042.76
0.3
1031.58
0.3
1033.02
0.3
1033.9
0.3
1033.38
0.3
1032.07
0.3
1030.38
0.3
1020.4
0.3
1031.27
0.3
1019.61
0.3
1019.45
0.3
1026.7
0.3
1016.41
0.3
1019.53
0.3
1016.31
0.3
1003.34
0.3
1015.19
0.3
1012.22
0.3
1012.27
0.3
1003.45
0.3
1010.69
0.3
998.185
0.3
1003.27
0.3
FeNiCo
FeNiCo
2021
6
1
15
29
19
0
16
Casa Info Follows
0
0
0
0
File = C:/Users/Mark/Downloads/EX506_S788_FeNiCo.sle
Group = Loop 2_UHV at 200C, #Treatments:, #Temp:200C , #Pressure:0.1mbar , #Atmosphere:O2, #Comments:
First of group = 1
Spectrum ID = 24
Analyzer lens = LargeArea:1.5kV
Analyzer slit = 4:7x20c\C:mesh
Scan mode = FixedAnalyzerTransmission
Kinetic energy start = 286.61
PCA Coefs = 101874, 710.71,
PCA Coefs = 101874, 710.71, -253.77,
C:\Users\Mark\Downloads\EX506_S788_FeNiCo.vms
XPS
29
Al
1486.61
0
0
0
54.5
180
FAT
100
1
4.1408
0
0
0
0
0
Survey

-1
kinetic energy
eV
286.61
1
2
counts
d
Transmission
d
pulse counting
0.1
0
0
0
11.1633
1
2921.69
2934.88
2953.55
2969.51
2971.99
2954.41
2990.89
2969.8
2984.52
2992.57
2993.93
3005
3023.4
3032.15
3018.9
3048.67
3052.05
3040.5
3050.91
3054.57
3067.81
3063.05
3103.47
3124.06
3130.24
3113.87
3119.86
3128.27
3129.41
3142.6
3160.52
3175.1
3171.3
3181.08
3163.87
3190.99
3194.48
3212.78
3227.94
3246.36
3239.45
3246.69
3271.19
3288.65
3297.17
3273.38
3287.66
3314.3
3324.88
3307.2
3314.48
3325.3
3349.21
3326.55
3334.76
3374.95
3376.78
3404.01
3398.94
3410.82
3407.41
3412.97
3453.47
3470.98
3454.83
3450.07
3480.4
3479.54
3529.14
3515.98
3481.05
3484.02
3504.18
3523.34
3524.66
3555.91
3563.01
3538.68
3574.49
3577.76
3609
3631.86
3615.68
3622.03
3647.36
3641.84
3626.13
3656.91
3663.75
3692.52
3668.96
3679.32
3726.67
3710.37
3728.9
3747.61
3737.97
3728.92
3765.85
3776.95
3810.12
3792.96
3803.3
3826.32
3827.29
3839.59
3869.17
3872.57
3875.06
3860.12
3871.18
3883.85
3891.23
3908.43
3922.46
3920.42
3955.89
3980.13
3990.1
3987.79
3989.37
4010.73
4008.08
4034.77
4031.4
4023.78
4086.8
4091.49
4078.91
4084.62
4076.73
4093.08
4114.48
4137.88
4144.93
4169.9
4166.32
4174.63
4174.96
4175.29
4197.58
4216.33
4213.3
4232.23
4255.6
4266.18
4275.48
4291.15
4302.41
4314.09
4303.86
4302.26
4338.36
4355.11
4349.28
4381.39
4355.37
4384.77
4397.93
4410.2
4451.86
4459.33
4461.09
4466.38
4477.27
4498.86
4494.41
4501.7
4519.16
4547.72
4542.94
4517.16
4545.46
4564.72
4600.56
4613.28
4662.58
4712.85
4684.05
4722.6
4783.28
4815.89
4845.14
4849.77
4876.98
4907.77
4938.75
4933.48
4970.58
4946.72
4908.95
4891.96
4871.56
4842.06
4823.74
4811.63
4797.15
4831.47
4862.48
4871.41
4899.1
4976.68
5002.46
4994.9
5015.24
5016.62
4968.18
4911.13
4876.36
4895.4
4893.46
4898.07
4918.46
4901.95
4897.14
4914.06
4948.87
5001.38
5050.37
5130.31
5239.21
5408.08
5565.34
5692.75
5730.76
5632.24
5469
5313.84
5198.23
5127.36
5052.86
4991.2
4928.53
4873.17
4825.23
4809.68
4792.17
4788.12
4759.48
4749.57
4769.88
4786.4
4787.05
4818.84
4823.24
4831.53
4841.98
4853.1
4844.95
4861.67
4882.28
4907.98
4941.06
4940.23
4945.36
4967.46
4993.47
4993.44
5038.56
5039.33
5100.84
5109.66
5152.44
5177.66
5165
5230.83
5224.95
5277.01
5307.76
5296.66
5320.91
5360.5
5378.49
5388.71
5324.39
5285.12
5271.06
5193.33
5178.82
5159.1
5168.63
5167.68
5185.63
5187.45
5198.32
5221.88
5233.92
5277.86
5290.12
5305.39
5316.45
5340.21
5358.42
5410.04
5398.63
5416.46
5434.45
5462.77
5444.36
5481.78
5509.99
5539.7
5512.05
5528.34
5541.31
5546.88
5516.46
5533.68
5550.98
5545.47
5519.44
5460.95
5409.69
5385.33
5450.12
5494.7
5565.58
5697.01
5780.52
5817.45
5832.96
5776.34
5689.91
5665.83
5691.18
5834.72
5928.35
5810.6
5560.45
5292.73
5203.37
5257.97
5341.86
5424.68
5539.58
5686.24
5864.33
6047.77
6108.91
5963.63
5806.3
5861.95
6226.44
6620.04
6752.08
6204.84
5477.25
5088.09
4989.27
5008.85
5021.37
5042.79
5030.94
5029.48
5031.83
5035.85
5037.06
5044.66
5059.7
5075.58
5021.04
5016.27
4968.66
4933.11
4920.91
4877.59
4796.76
4679.11
4572.94
4506.22
4448.96
4413.59
4414.24
4374.64
4380.94
4383.49
4350.44
4359.34
4338.73
4335.18
4347.51
4323.38
4311.69
4318.18
4319.67
4313.85
4295.36
4273.57
4275.73
4268.35
4317.86
4322.48
4398
4473.4
4583.39
4721.28
4807.78
4821.15
4738.16
4685.92
4723.6
4896.09
5060.46
5064.79
4834.73
4559.14
4460.88
4477.95
4545.21
4748.38
4956.31
5188.95
5326.98
5412.49
5428.55
5521.28
5700.36
5975.5
6138.15
5862.33
5122.58
4393.42
4044.16
3902.8
3837.75
3826.5
3728.93
3658.34
3555.56
3413.46
3297.75
3186.68
3100.33
3060.98
3011.5
2966.51
2963.64
2946.99
2947.57
2927.31
2936.97
2933.97
2925.36
2896.68
2908.23
2909.55
2908.94
2901.61
2880.98
2900.13
2888.29
2882.87
2897.57
2906.19
2931.36
2952.07
3007.35
3003.17
3005.01
2996.13
2991.38
3025.01
3048.35
3087.47
3130.19
3153.36
3202.17
3211.06
3229.87
3258.27
3312.45
3364.42
3490.03
3620.28
3709.19
3771.64
3713.23
3606.05
3519.66
3528.6
3567.18
3578.33
3587.01
3627.37
3709.73
3852.46
4024.93
4166.8
4141.5
3776.35
3141.15
2555.56
2283.77
2169.41
2098.6
2060.88
1973.76
1920.96
1854.91
1812.48
1784.84
1766.82
1752.01
1694
1678.87
1636.67
1604.47
1583.08
1566.58
1545.41
1557.31
1551.81
1538.21
1528.1
1530.78
1522.82
1513.64
1507.86
1512.2
1510.66
1526.67
1535.07
1536.16
1539.66
1538.35
1535.2
1561.47
1560.62
1569.32
1587.83
1585.15
1571.31
1574.47
1593.72
1602.48
1603.62
1609.06
1625.84
1615.35
1607.35
1604.04
1618.69
1597.39
1589.3
1620.92
1654.81
1652.48
1674.87
1725.21
1759.86
1821.86
1897.64
1977
2025.57
2071.44
2089.18
2090.7
2086.87
2061.89
2021.42
1971.28
1912.02
1798.99
1635.23
1505.07
1406.08
1359.54
1341.38
1330.47
1340.53
1348.75
1355.82
1368.48
1355.89
1350.62
1365.94
1370.44
1345.37
1314.14
1298.74
1265.93
1229.12
1209.34
1193.36
1200.81
1202.14
1205.24
1204.65
1208.26
1203.65
1220.94
1219.48
1209.01
1222.6
1225.7
1215.85
1211.28
1219.99
1238.65
1235.95
1244.66
1238.48
1240.88
1249.75
1260.63
1254.47
1253.3
1253.05
1247.25
1250.42
1271.46
1268.74
1267.71
1257.44
1253.39
1254.37
1267.31
1274.41
1282.39
1285.4
1295.35
1289.25
1292.6
1290.68
1300.38
1318.83
1326.85
1330.66
1314.92
1328.34
1314.16
1319.47
1309.1
1312.93
1325.93
1319.16
1314.07
1317.3
1324.93
1337.03
1341.91
1372.06
1393.37
1409.53
1445.72
1463.54
1468.71
1455.72
1418.23
1376.86
1358.19
1306.55
1267.33
1231.39
1213.34
1199.9
1161.52
1125.78
1092.46
1070.11
1049.99
1045.81
1025.94
1051.57
1078.97
1264.56
1942.38
3447.37
5431.9
5966.07
3909.01
1596.77
757.664
608.93
567.644
560.746
533.41
528.602
526.432
527.15
521.815
520.095
533.159
521.468
524.781
527.492
520.079
527.199
523.465
529.464
527.585
526.647
526.405
527.462
536.11
543.474
532.118
536.44
537.005
539.919
541.635
549.147
548.681
551.314
544.513
543.46
544.328
542.672
536.82
539.178
535.456
541.835
546.041
538.21
537.718
537.766
544.33
539.077
540.911
541.484
540.918
541.997
540.094
538.354
540.977
534.292
541.988
552.457
546.896
546.365
546.944
544.778
554.964
547.028
535.896
537.601
546.59
558.479
551.579
555.214
553.71
553.312
554.06
550.844
555.986
556.979
556.376
557.072
553.359
555.504
552.652
558.754
563.528
559.723
575.458
564.707
556.474
558.986
567.046
569.736
573.386
576.14
570.549
582.526
577.379
564.541
569.393
577.459
574.048
578.928
579.946
573.58
573.951
569.559
573.744
584.142
586.943
579.908
584.259
587.648
586.413
582.846
579.993
587.632
589.017
572.42
586.446
589.617
588.884
583.376
593.586
591.367
590.503
589.743
601.649
601.145
596.731
602.507
604.881
614.099
622.589
616.654
600.265
601.656
613.365
602.636
607.421
608.672
602.657
601.894
606.871
613.755
618.022
608.465
603.071
606.881
610.781
619.673
610.202
606.006
617.638
613.031
625.849
625.661
635.134
642.016
623.241
621.889
626.496
633.244
655.497
655.388
642.539
634.155
628.2
625.323
628.559
636.425
642.964
628.846
624.038
633.285
639.019
634.292
639.91
646.112
642.573
648.827
653.576
649.379
646.122
647.482
643.686
647.496
650.786
651.515
646.624
652.966
652.354
659.418
663.455
653.035
666.543
659.599
659.46
662.921
668.01
672.341
670.062
671.701
677.417
671.443
673.678
684.175
683.906
681.566
685.78
684.381
686.522
689.967
684.594
694.884
691.08
690.348
693.951
689.476
700.953
692.593
689.93
694.701
691.621
701.765
712.027
711.354
703.303
705.744
697.958
690.433
703.688
702.807
693.227
684.532
685.004
684.592
693.718
701.269
708.116
708.361
732.685
799.777
842.464
829.063
851.98
930.994
1055.01
984.655
801.531
688.652
665.396
669.564
666.809
676.63
670.975
669.677
673.247
671.806
662.582
682.645
675.219
666.608
673.966
684.513
682.795
674.651
673.965
687.888
691.947
689.17
689.807
691.057
699.404
732.212
749.294
762.094
759.186
738.764
711.815
707.884
697.176
689.49
702.392
696.184
695.369
691.042
694.238
699.504
692.649
695.217
699.808
692.063
696.374
696.152
702.355
701.002
700.066
704.836
710.068
717.005
710.487
708.095
718.145
713.613
719.297
707.608
723.658
724.416
740.195
723.171
731.742
728.862
743.494
746.694
745.811
744.903
746.813
745.765
746.879
739.057
751.29
753.312
752.043
743.405
747.709
752.432
751.139
756.261
766.356
764.998
753.162
757.268
766.261
764.391
760.636
764.024
759.811
785.128
854.271
966.38
991.508
926.181
870.046
834.548
794.818
777.799
802.525
890.435
951.026
955.287
890.296
803.373
758.342
739.085
726.875
733.791
727.963
732.353
732.61
733.492
741.619
743.454
749.647
739.722
747.393
738.518
737.988
748.741
746.5
737.024
749.829
756.562
757.738
764.031
759.556
755.766
767.057
767.394
780.975
778.801
780.563
778.53
778.953
776.692
788.1
792.86
791.866
791.884
797.64
802.285
807.696
798.279
808.986
817.564
818.857
816.335
814.3
810.379
814.748
827.683
830.562
828.017
828.679
832.736
833.725
839.243
848.391
847.537
872.915
888.562
897.282
908.486
930.008
939.489
953.483
958.498
986.095
1024.55
1061.34
1042.49
989.524
945.193
931.171
950.499
947.953
945.672
951.419
974.934
1019.33
1014.57
961.725
904.725
868.555
847.941
834.395
830.435
865.763
878.116
878.794
848.196
818.676
799.648
814.503
821.022
808.805
806.618
801.271
799.144
833.414
857.361
868.598
866.051
854.527
862.659
875.433
886.297
921.572
951.835
974.032
1013.38
1105.92
1291.29
1442.94
1442.43
1245.85
1018.21
879.648
863.597
880.63
919.514
956.8
882.474
722.797
622.468
651.145
682.778
600.414
407.282
278.458
222.905
207.567
202.794
195.03
194.071
194.864
195.582
198.866
189.582
190.027
189.725
194.859
186.452
184.142
180.729
182.824
182.825
181.568
184.567
182.723
194.035
195.169
200.049
206.275
216.715
235.391
252.258
287.35
320.967
361.236
372.5
314.512
227.858
173.662
151.336
141.267
146.508
149.548
160.998
182.658
212.287
243.208
273.766
294.796
310.218
339.35
377.406
422.437
453.86
447.823
336.2
160.639
40.5926
11.0888
1
FeNiCo
FeNiCo
2021
6
1
15
45
11
0
16
Casa Info Follows
0
0
0
0
File = C:/Users/Mark/Downloads/EX506_S788_FeNiCo.sle
Group = Loop 2_UHV at 200C, #Treatments:, #Temp:200C , #Pressure:0.1mbar , #Atmosphere:O2, #Comments:
First of group = 0
Spectrum ID = 28
Analyzer lens = AngleResolvedMode22:1.5kV
Analyzer slit = 4:7x20c\C:mesh
Scan mode = FixedAnalyzerTransmission
Kinetic energy start = 926.61
PCA Coefs = 17565.9, 1591.62,
PCA Coefs = 17565.9, 1591.62, -114.645, -79.3215,
C:\Users\Mark\Downloads\EX506_S788_FeNiCo.vms
XPS
29
Al
1486.61
0
0
0
54.5
180
FAT
20
1
4.1408
0
0
0
0
0
O
1s
-1
kinetic energy
eV
926.61
0.1
2
counts
d
Transmission
d
pulse counting
0.1
2
0
0
0
0
0
1002
192.655
3742.68
1
1
574.778
1
574.941
1
578.232
1
564.002
1
561.832
1
562.792
1
564.181
1
570.866
1
575.791
1
584.578
1
581.616
1
575.641
1
579.012
1
569.43
1
570.093
1
585.198
1
576.401
1
578.213
1
588.093
1
580.949
1
585.824
1
589.744
1
589.051
1
578.728
1
583.365
1
592.786
1
593.426
1
596.825
1
589.04
1
587.963
1
596.23
1
594.302
1
602.85
1
593.49
1
601.517
1
605.197
1
610.187
1
610.046
1
610.337
1
595.187
1
612.199
1
612.672
1
610.06
1
603.925
1
618.085
1
629.936
1
618.778
1
618.221
1
603.613
1
615.716
1
611.165
1
618.033
1
616.291
1
622.697
1
620.36
1
610.593
1
617.578
1
637.04
1
621.023
1
621.128
1
613.935
1
623.172
1
624.529
1
614.525
1
620.808
1
613.238
1
621.997
1
620.77
1
629.76
1
618.44
1
617.986
1
616.776
1
607.687
1
608.121
1
616.332
1
604.757
1
604.612
1
607.08
1
609.4
1
626.278
1
619.609
1
608.294
1
602.067
1
596.854
1
596.118
1
604.495
1
595.58
1
589.518
1
592.379
1
603.084
1
597.21
1
593.354
1
595.99
1
582.876
1
589.471
1
595.287
1
592.835
1
583.235
1
573.865
1
597.146
1
593.777
1
570.481
1
580.895
1
572.724
1
580.515
1
569.163
1
571.952
1
567.565
1
565.5
1
563.319
1
560.712
1
551.82
1
553.572
1
553.5
1
555.997
1
552.224
1
543.805
1
543.278
1
547.461
1
545.519
1
529.855
1
538.8
1
525.02
1
528.997
1
534.473
1
534.535
1
541.313
1
532.292
1
533.682
1
534.323
1
523.636
1
532.233
1
525.971
1
519.534
1
518.266
1
525.172
1
529.022
1
522.93
1
517.755
1
513.756
1
512.744
1
514.631
1
511.831
1
503.854
1
504.527
1
520.722
1
516.434
1
500.965
1
504.242
1
504.976
1
506.144
1
504.304
1
502.787
1
494.111
1
504.114
1
504.239
1
503.3
1
496.531
1
494.752
1
501.709
1
495.839
1
494.888
1
493.148
1
491.739
1
487.515
1
476.459
1
488.431
1
493.388
1
481.603
1
476.226
1
473.987
1
474.277
1
475.811
1
475.285
1
475.666
1
479.134
1
478.769
1
457.529
1
454.033
1
470.892
1
466.877
1
458.592
1
455.682
1
465.273
1
463.614
1
450.207
1
444.351
1
448.571
1
441.77
1
438.918
1
445.888
1
438.435
1
441.488
1
436.242
1
435.572
1
430.33
1
430.401
1
433.067
1
431.323
1
434.729
1
435.574
1
426.685
1
424.393
1
426.15
1
418.357
1
428.008
1
427.641
1
422.44
1
425.675
1
423.67
1
424.91
1
430.308
1
419.241
1
422.246
1
419.182
1
411.553
1
414.957
1
419.503
1
419.78
1
424.898
1
415.031
1
416.343
1
422.132
1
417.778
1
424.628
1
431.35
1
423.956
1
419.506
1
415.664
1
412.643
1
423.866
1
430.378
1
419.498
1
415.372
1
418.926
1
417.471
1
407.206
1
410.385
1
413.274
1
409.473
1
416.304
1
415.975
1
411.738
1
405.782
1
416.037
1
415.466
1
424.43
1
419.145
1
416.394
1
416.204
1
418.192
1
414.712
1
424.059
1
433.844
1
438.264
1
438.196
1
441.518
1
454.53
1
468.745
1
482.027
1
483.037
1
496.124
1
521.917
1
548.465
1
581.883
1
610.53
1
651.81
1
701.518
1
769.246
1
841.402
1
913.325
1
1018.39
1
1114.15
1
1227.96
1
1337.94
1
1436.27
1
1556.36
1
1681.12
1
1771.97
1
1874.5
1
1963.08
1
2065.29
1
2172.06
1
2255.24
1
2362.7
1
2435.22
1
2531.77
1
2618.21
1
2736.78
1
2883.79
1
3033.47
1
3207.2
1
3370.64
1
3489.52
1
3607.04
1
3721.44
1
3699.63
1
3591.62
1
3433.11
1
3194.79
1
2861.4
1
2515.96
1
2123.17
1
1760.04
1
1436.46
1
1157.91
1
936.438
1
750.144
1
610.111
1
498.36
1
429.013
1
375.525
1
337.644
1
317.788
1
307.962
1
278.661
1
274.758
1
271.947
1
265.836
1
264.969
1
261.696
1
252.015
1
262.578
1
256.243
1
246.256
1
248.302
1
239.554
1
243.035
1
244.002
1
240.494
1
239.832
1
237.625
1
233.497
1
233.975
1
228.675
1
239.196
1
239.685
1
230.715
1
228.017
1
228.217
1
228.704
1
226.173
1
229.604
1
229.953
1
230.238
1
222.989
1
222.983
1
227.841
1
226.553
1
221.787
1
221.196
1
221.528
1
226.57
1
224.817
1
218.83
1
220.24
1
221.228
1
222.721
1
227.393
1
222.982
1
220.409
1
219.563
1
219.157
1
219.687
1
219.891
1
220.265
1
226.574
1
222.675
1
220.062
1
220.342
1
216.3
1
216.654
1
214.408
1
210.218
1
218.477
1
224.382
1
221.432
1
213.789
1
219.155
1
218.654
1
216.051
1
218.687
1
219.621
1
221.49
1
215.249
1
213.639
1
214.042
1
213.563
1
219.418
1
227.582
1
216.584
1
218.747
1
214.435
1
216.643
1
218.32
1
222.304
1
217.844
1
210.402
1
213.567
1
217.673
1
214.471
1
217.103
1
216.34
1
216.099
1
217.763
1
221.014
1
216.298
1
219.239
1
214.5
1
214.61
1
212.562
1
215.574
1
217.836
1
218.461
1
217.441
1
213.011
1
216.44
1
221.624
1
220.762
1
221.656
1
213.949
1
213.625
1
216.381
1
217.612
1
217.118
1
220.502
1
220.651
1
214.64
1
219.471
1
213.481
1
217.942
1
220.807
1
212.485
1
217.314
1
213.911
1
213.696
1
222.338
1
217.93
1
217.102
1
213.02
1
216.334
1
218.314
1
216.764
1
215.798
1
223.35
1
220.224
1
217.015
1
218.883
1
221.411
1
215.711
1
212.8
1
213.831
1
212.914
1
226.947
1
219.583
1
221.29
1
218.975
1
209.452
1
213.654
1
217.958
1
217.798
1
215.434
1
219.977
1
222.858
1
221.074
1
216.284
1
216.306
1
224.24
1
218.137
1
221.015
1
214.631
1
217.474
1
217.652
1
223.611
1
216.86
1
211.251
1
217.198
1
214.675
1
217.814
1
223.128
1
222.397
1
218.224
1
219.007
1
218.92
1
221.464
1
222.017
1
212.115
1
219.02
1
217.745
1
213.942
1
212.458
1
211.691
1
215.833
1
215.379
1
212.665
1
221.182
1
216.267
1
219.594
1
218.241
1
218.86
1
219.431
1
FeNiCo
FeNiCo
2021
6
1
15
45
41
0
16
Casa Info Follows
0
0
0
0
File = C:/Users/Mark/Downloads/EX506_S788_FeNiCo.sle
Group = Loop 2_UHV at 200C, #Treatments:, #Temp:200C , #Pressure:0.1mbar , #Atmosphere:O2, #Comments:
First of group = 0
Spectrum ID = 29
Analyzer lens = AngleResolvedMode22:1.5kV
Analyzer slit = 4:7x20c\C:mesh
Scan mode = FixedAnalyzerTransmission
Kinetic energy start = 1188.61
PCA Coefs = 2160.48, 81.9104,
PCA Coefs = 2160.48, 81.9104,
C:\Users\Mark\Downloads\EX506_S788_FeNiCo.vms
XPS
29
Al
1486.61
0
0
0
54.5
180
FAT
20
1
4.1408
0
0
0
0
0
C
1s
-1
kinetic energy
eV
1188.61
0.1
2
counts
d
Transmission
d
pulse counting
0.1
1
0
0
0
0
0
402
107.176
255.053
1
1
133.787
1
140.933
1
138.758
1
136.993
1
137.793
1
134.939
1
136.541
1
135.594
1
133.489
1
132.528
1
132.623
1
138.703
1
139.043
1
137.621
1
136.058
1
133.071
1
134.441
1
131.246
1
130.231
1
129.907
1
133.95
1
138.356
1
138.563
1
133.218
1
135.976
1
137.261
1
136.448
1
135.338
1
133.73
1
136.889
1
136.847
1
138.333
1
133.9
1
133.163
1
134.569
1
133.659
1
135.603
1
137.527
1
137.424
1
136.91
1
138.172
1
135.75
1
134.967
1
134.326
1
136.656
1
130.185
1
138.121
1
135.193
1
136.077
1
140.252
1
137.891
1
136.52
1
138.233
1
135.618
1
134.36
1
138.143
1
137.387
1
139.213
1
137.598
1
138.336
1
138.766
1
139.925
1
140.912
1
137.796
1
138.599
1
138.577
1
135.731
1
140.379
1
138.577
1
137.57
1
140.75
1
142.826
1
147.756
1
149.025
1
152.145
1
153.891
1
157.501
1
164.15
1
163.918
1
169.791
1
167.728
1
172.371
1
167.936
1
168.124
1
172.553
1
164.553
1
165.094
1
166.907
1
165.111
1
164.449
1
166.826
1
168.165
1
163.343
1
161.099
1
157.88
1
160.029
1
161.853
1
151.538
1
152.301
1
154.878
1
152.548
1
151.359
1
149.503
1
154.405
1
149.469
1
154.224
1
161.656
1
164.012
1
164.627
1
164.837
1
170.67
1
170.46
1
172.006
1
173.509
1
178.739
1
182.882
1
178.688
1
181.574
1
188.084
1
190.672
1
197.823
1
195.224
1
204.401
1
207.784
1
219.241
1
224.989
1
231.322
1
234.848
1
245.386
1
245.355
1
252.796
1
245.793
1
248.024
1
243.992
1
231.353
1
218.514
1
209.544
1
195.315
1
179.294
1
166.7
1
159.36
1
152.021
1
145.785
1
145.023
1
139.594
1
134.54
1
131.245
1
130.678
1
130.698
1
130.884
1
137.711
1
132.3
1
128.873
1
130.297
1
125.069
1
127.741
1
128.64
1
131.585
1
130.365
1
131.351
1
125.065
1
128.575
1
127.521
1
131.645
1
129.08
1
129.454
1
129.077
1
132.329
1
130.951
1
132.99
1
131.384
1
128.619
1
130.791
1
129.916
1
129.989
1
128.203
1
134.824
1
129.75
1
127.452
1
128.587
1
135.539
1
130.744
1
130.298
1
130.118
1
128.159
1
125.886
1
130.956
1
131.461
1
128.309
1
127.101
1
126.839
1
127.266
1
129.183
1
128.881
1
128.372
1
129.895
1
126.56
1
130.202
1
129.256
1
128.814
1
127.292
1
FeNiCo
FeNiCo
2021
6
1
15
46
16
0
16
Casa Info Follows
0
0
0
0
File = C:/Users/Mark/Downloads/EX506_S788_FeNiCo.sle
Group = Loop 2_UHV at 200C, #Treatments:, #Temp:200C , #Pressure:0.1mbar , #Atmosphere:O2, #Comments:
First of group = 0
Spectrum ID = 30
Analyzer lens = AngleResolvedMode22:1.5kV
Analyzer slit = 4:7x20c\C:mesh
Scan mode = FixedAnalyzerTransmission
Kinetic energy start = 1286.61
PCA Coefs = 2467.55, 63.0565,
PCA Coefs = 2467.55, 63.0565,
C:\Users\Mark\Downloads\EX506_S788_FeNiCo.vms
XPS
29
Al
1486.61
0
0
0
54.5
180
FAT
20
1
4.1408
0
0
0
0
0
Br
3p
-1
kinetic energy
eV
1286.61
0.1
2
counts
d
Transmission
d
pulse counting
0.1
1
0
0
0
0
0
502
115.638
228.167
1
1
145.113
1
144.374
1
142.965
1
140.109
1
140.836
1
139.951
1
144.543
1
146.109
1
144.128
1
144.121
1
141.024
1
142.647
1
140.342
1
141.301
1
141.421
1
139.608
1
139.401
1
144.633
1
143.054
1
135.93
1
141.498
1
143.192
1
144.375
1
140.666
1
144.092
1
140.403
1
141.549
1
143.407
1
142.543
1
142.589
1
142.594
1
142.847
1
139.637
1
142.154
1
136.024
1
141.211
1
146.872
1
140.503
1
141.484
1
134.898
1
138.973
1
139.594
1
142.982
1
140.923
1
139.127
1
137.953
1
143.2
1
142.744
1
142.246
1
139.045
1
140.274
1
145.721
1
144.734
1
143.1
1
144.33
1
147.298
1
143.484
1
144.693
1
142.243
1
145.505
1
145.51
1
143.7
1
146.835
1
145.751
1
147.857
1
150.011
1
149.647
1
155.992
1
163.689
1
165.137
1
166.549
1
171.362
1
184.14
1
185.288
1
186.488
1
197.907
1
204.364
1
207.898
1
214.005
1
218.07
1
220.536
1
222.288
1
216.282
1
216.526
1
209.058
1
199.758
1
198.777
1
188.627
1
183.13
1
175.165
1
167.287
1
163.591
1
166.905
1
168.909
1
165.936
1
160.858
1
160.281
1
165.328
1
162.699
1
167.783
1
167.226
1
167.225
1
166.32
1
168.138
1
168.672
1
170.44
1
167.304
1
170.169
1
167.167
1
166.789
1
164.254
1
161.921
1
163.664
1
155.445
1
156.351
1
156.391
1
154.185
1
155.413
1
157.766
1
153.045
1
150.025
1
145.31
1
148.056
1
142.559
1
145.584
1
142.432
1
141.556
1
145.212
1
145.664
1
139.327
1
143.312
1
145.083
1
144.366
1
145.29
1
143.907
1
149.559
1
147.84
1
145.983
1
141.567
1
144.437
1
144.656
1
145.039
1
146.778
1
146.027
1
148.526
1
148.776
1
148.541
1
150.103
1
148.257
1
149.779
1
151.372
1
154.38
1
155.186
1
154.693
1
153.186
1
154.628
1
157.329
1
162.064
1
166.462
1
166.833
1
169.919
1
171.324
1
175.856
1
180.154
1
185.268
1
184.785
1
184.718
1
188.368
1
196.915
1
198.968
1
203.993
1
204.481
1
200.903
1
198.255
1
196.859
1
195.228
1
196.968
1
200.354
1
186.709
1
178.916
1
176.737
1
172.642
1
167.025
1
163.662
1
164.302
1
161.588
1
160.783
1
156.171
1
152.147
1
149.477
1
152.152
1
148.237
1
143.143
1
147.807
1
148.559
1
145.757
1
147.119
1
142.394
1
144.466
1
138.594
1
140.822
1
135.428
1
140.07
1
136.93
1
137.586
1
137.023
1
139.617
1
142.902
1
135.372
1
136.466
1
136.617
1
132.019
1
136.461
1
143.929
1
139.332
1
135.501
1
134.768
1
136.812
1
137.182
1
135.984
1
138.547
1
142.584
1
139.541
1
138.05
1
141.248
1
139.182
1
140.057
1
140.301
1
136.667
1
140.708
1
135.535
1
136.469
1
134.353
1
135.233
1
135.226
1
139.195
1
133.666
1
137.748
1
141.583
1
140.365
1
137.419
1
136.204
1
135.198
1
137.966
1
135.962
1
135.306
1
137.616
1
140.29
1
140.465
1
134.188
1
139.615
1
FeNiCo
FeNiCo
2021
6
1
15
48
0
0
16
Casa Info Follows
0
0
0
0
File = C:/Users/Mark/Downloads/EX506_S788_FeNiCo.sle
Group = Loop 2_UHV at 200C, #Treatments:, #Temp:200C , #Pressure:0.1mbar , #Atmosphere:O2, #Comments:
First of group = 0
Spectrum ID = 31
Analyzer lens = AngleResolvedMode22:1.5kV
Analyzer slit = 4:7x20c\C:mesh
Scan mode = FixedAnalyzerTransmission
Kinetic energy start = 801.61
PCA Coefs = 9637.78, 94.2215,
PCA Coefs = 9637.78, 94.2215,
C:\Users\Mark\Downloads\EX506_S788_FeNiCo.vms
XPS
29
Al
1486.61
0
0
0
54.5
180
FAT
20
1
4.1408
0
0
0
0
0
NiLLM

-1
kinetic energy
eV
801.61
0.1
2
counts
d
Transmission
d
pulse counting
0.1
0
0
0
225.443
1
331.703
340.865
337.281
335.177
340.98
336.864
337.325
332.578
333.959
325.578
337.407
343.071
340.871
342.466
336.064
331.986
333.305
329.879
332.878
334.72
337.309
335.335
333.514
333.749
336.159
334.951
330.066
333.386
332.071
331.198
334.617
340.938
344.309
336.068
333.189
334.926
338.936
334.035
336.561
336.639
337.345
340.622
335.208
340.522
340.489
331.945
338.34
342.391
339.045
342.681
341.505
339.009
336.7
333.778
336.308
333.655
334.531
339.206
343.674
339.666
335.391
339.018
340.695
335.173
339.641
338.787
338.283
339.13
340.991
339.575
332.894
339.164
330.283
338.217
340.597
340.534
334.875
336.65
339.187
331.993
337.187
343.575
342.742
333.689
340.322
334.503
341.635
339.749
339.493
343.241
342.878
335.341
341.295
337.91
343.679
341.785
348.606
344.802
335.527
339.947
336.097
336.949
337.992
335.321
337.107
333.419
338.027
343.734
346.249
343.833
345.353
345.408
344.369
346.86
348.061
351.976
348.302
344.013
341.574
338.235
339.877
340.045
337.077
344.573
345.798
342.577
352.393
344.608
342.43
345.25
347.098
350.633
340.449
345.035
350.396
353.172
349.107
351.705
346.105
342.608
345.466
343.59
342.997
348.035
346.57
342.077
347.908
342.337
346.611
344.153
349.123
347.109
352.551
351.196
344.253
345.828
352.575
348.856
345.237
346.502
347.991
347.29
345.407
349.022
344.453
349.503
346.038
345.055
342.026
343.781
348.68
348.101
352.536
343.643
339.674
347.34
346.258
349.182
348.526
347.215
345.542
348.406
348.577
344.387
338.733
343.954
343.474
349.189
346.96
358.783
354.938
347.399
347.49
344.897
352.174
360.437
355.257
352.087
346.31
352.875
343.719
347.927
351.168
356.406
346.352
355.636
352.195
353.658
349.645
345.791
355.515
356.386
355.49
350.2
353.184
355.537
355.294
354.751
356.452
348.506
354.003
354.258
362.447
357.206
350.13
350.003
354.515
350.714
349.314
352.958
350.864
352.039
353.89
359.473
362.023
359.249
359.198
357.748
351.367
351.854
347.715
352.475
349.162
352.829
355.426
348.679
351.693
353.452
356.19
350.792
354.337
353.488
354.667
357.57
356.153
353.377
352.328
358.915
355.852
351.19
346.71
346.28
354.551
356.902
353.486
354.237
352.043
354.799
349.147
353.043
347.757
350.367
349.421
347.014
346.832
347.368
355.329
356.224
350.761
352.071
355.45
358.817
353.253
356.234
353.163
361.637
347.387
342.785
350.25
358.14
354.613
346.172
352.617
351.575
355.815
354.375
354.238
354.503
359.406
353.947
350.809
349.045
353.611
359.713
360.98
360.77
357.72
362.541
360.759
356.176
353.361
355.862
359.974
363.736
356.136
359.725
356.485
363.006
366.291
357.606
365.327
363.009
371.764
365.747
370.938
367.556
366.492
366.226
368.418
370.389
366.315
368.637
363.762
373.243
377.732
373.63
375.56
379.951
382.688
380.311
379.656
375.402
383.186
380.712
382.177
386.108
384.507
394.381
386.725
385.725
387.601
392.622
398.83
395.401
392.422
398.077
395.775
400.145
401.522
406.297
405.309
407.135
412.104
411.578
412.353
412.497
414.558
415.086
413.327
417.382
414.24
421.076
415.203
424.659
421.929
427.438
430.007
441.214
435.181
436.437
433.446
442.37
442.065
446.224
443.459
452.652
454.804
449.659
451.746
455.868
453.194
458.724
452.628
462.116
464.329
449.512
461.912
457.415
459.706
457.982
463.552
469.254
461.467
460.649
466.46
460.741
461.385
460.709
463.515
467.724
452.74
454.649
470.916
474.467
464.42
461.71
460.969
453.956
454.351
447.714
454.466
457.497
461.345
456.401
449.096
452.596
454.153
451.489
447.585
444.811
446.352
437.386
442.49
446.113
441.993
448.671
452.083
446.707
443.416
442.208
434.972
441.949
442.2
438.617
439.6
437.698
436.976
433.562
435.781
441.197
444.516
437.834
437.359
435.304
426.077
432.57
429.701
433.752
425.644
426.4
428.817
432.963
426.022
425.6
422.166
427.435
419.688
421.2
420.63
411.853
412.139
406.425
409.57
402.676
393.099
388.464
385.965
391.88
378.161
382.498
374.705
369.206
363.211
358.901
354.676
354.785
351.639
349.011
336.979
345.046
339.315
332.821
327.662
328.847
329.244
321.853
313.742
311.784
312.571
308.065
312.141
307.729
314.944
309.977
309.247
303.575
300.722
301.471
299.57
302.931
295.1
292.777
296.661
299.208
294.017
292.25
293.776
293.921
293.497
289.344
296.179
289.005
288.714
290.807
298.523
297.624
297.392
289.456
289.818
291.715
292.078
289.527
292.405
295.358
294.992
296.769
292.954
292.725
290.841
295.051
287.822
294.827
295.929
291.391
293.026
295.22
290.498
289.511
295.141
296.472
292.209
295.166
295.897
305.038
298.78
293.873
296.099
294.817
293.141
292.498
298.431
299.966
294.568
292.998
294.36
298.13
302.078
296.233
301.333
300.647
297.83
298.509
295.876
298.429
297.325
293.851
294.633
295.824
298.926
297.679
296.559
295.097
302.613
293.72
295.822
299.178
302.805
299.12
299.648
294.094
296.304
296.918
302.329
294.657
292.027
298.396
300.209
297.689
304.631
303.961
294.191
291.215
299.785
297.008
293.895
297.552
294.049
292.517
289.6
293.689
297.072
293.718
294.844
291.886
293.26
288.533
290.246
289.132
292.243
293.966
292.731
291.333
291.589
293.085
296.412
292.328
289.082
289.321
286.562
288.007
290.308
291.001
298.836
293.292
287.358
290.47
288.967
285.075
283.178
283.089
286.797
283.489
281.133
274.147
287.759
286.842
285.048
283.562
281.959
274.434
277.113
280.474
278.984
272.587
275.959
270.796
264.51
266.354
270.061
272.737
270.881
263.388
270.398
266.615
262.804
267.621
264.511
258.998
257.045
260.8
265.402
264.383
265.233
263.816
259.675
261.639
261.78
260.096
263.859
272.867
265.324
255.618
256.007
259.019
259.415
261.667
259.303
259.082
257.024
260.584
259.992
264.4
264.231
260.527
267.222
257.067
257.926
257.818
254.352
258.702
260.879
252.896
256.029
255.473
257.777
258.269
260.551
260.211
260.521
258.387
257.339
256.767
257.424
258.631
255.471
262.05
262.393
257.472
258.23
258.401
254.333
256.327
256.346
256.266
259.909
262.36
263.792
264.359
260.313
257.376
260.228
260.52
253.31
251.731
250.493
257.421
258.229
260.216
258.538
256.518
263.375
264.727
263.513
260.446
257.869
254.456
260.235
261.581
259.227
259.759
258.011
259.252
261.983
257.918
258.799
263.249
258.293
257.743
259.38
258.435
261.431
259.064
258.451
260.09
262.609
257.027
257.879
258.135
255.235
255.547
263.54
258.333
259.055
257.937
264.453
264.869
265.554
258.186
264.907
266.796
257.45
258.956
266.135
267.002
262.541
258.105
264.799
263.51
262.812
260.302
263.75
267.774
261.709
266.429
269.781
262.953
262.919
261.521
264.941
264.655
266.98
1
NiCo
NiCo
2021
5
28
7
56
1
0
15
Casa Info Follows
0
0
0
0
File = C:/Users/Mark/Downloads/EX502_S785_NiCo.sle
[...]
0.943821
1830.36
0.943635
1882.68
0.943446
1933.64
0.94326
1979.33
0.943074
2070.19
0.942885
2154.71
0.942699
2264.44
0.942513
2349.04
0.942327
2427.6
0.942141
2466.8
0.941955
2499.32
0.941769
2503.78
0.941583
2501.54
0.941397
2419.85
0.941211
2297.9
0.941025
2167.71
0.940839
2011.78
0.940653
1879.73
0.940467
1749.39
0.940284
1641.12
0.940098
1553.67
0.939912
1479.06
0.939729
1457.05
0.939543
1418.3
0.939357
1410.66
0.939174
1423.66
0.938988
1444.79
0.938805
1477.46
0.938619
1534.53
0.938436
1554.99
0.938253
1623.76
0.938067
1684.73
0.937884
1721.82
0.937701
1757.66
0.937518
1796.44
0.937335
1842.45
0.937149
1863.01
0.936966
1852.13
0.936783
1843.41
0.9366
1849.02
0.936417
1828.66
0.936234
1843.58
0.936051
1878.61
0.935868
1942.15
0.935688
2014.99
0.935505
2094.8
0.935322
2190.7
0.935139
2293.04
0.934959
2441.88
0.934776
2572.66
0.934593
2709.61
0.934413
2833.22
0.93423
2993.5
0.93405
3074.11
0.933867
3187.34
0.933687
3226.84
0.933504
3194.36
0.933324
3083.91
0.933141
2877.64
0.932961
2578.69
0.932781
2168.34
0.932601
1709.44
0.932418
1267.59
0.932238
887.396
0.932058
598.684
0.931878
417.264
0.931698
282.706
0.931518
195.95
0.931338
130.279
0.931158
85.535
0.930978
71.167
0.930798
62.047
0.930618
55.74
0.930438
39.111
0.930258
33.383
0.930081
25.846
0.929901
22.426
0.929721
20.952
0.929544
22.027
0.929364
18.013
0.929184
12.655
0.929007
15.271
0.928827
17.968
0.92865
11.955
0.92847
5.924
0.928293
9.997
0.928116
7.551
0.927936
5.77
0.927759
9.123
0.927582
4.497
0.927402
2.802
0.927225
3.242
0.927048
2.031
0.926871
6.023
0.926694
1.021
0.926517
1.446
0.92634
1.57
0.926163
6.655
0.925986
0.858
0.925809
3.649
0.925632
-1.989
0.925455
-0.345
0.925278
3.639
0.925101
-3.829
0.924924
-2.853
0.92475
-4.431
0.924573
-4.54
0.924396
-4.602
0.924222
1.587
0.924045
2.561
0.923871
-0.557
0.923694
-8.109
0.92352
-2.358
0.923343
0.853
0.923169
-3.694
0.922992
3.708
0.922818
5.502
0.922641
-1.453
0.922467
-1.042
0.922293
-2.342
0.922119
2.203
0.921942
0.424
0.921768
4.718
0.921594
-1.121
0.92142
1.802
0.921246
1.65
0.921072
-2.924
0.920898
-1.57
0.920724
1.364
0.92055
8.132
0.920376
-0.876
0.920202
4.523
0.920028
6.398
0.919857
-3.519
0.919683
-0.357
0.919509
-3.19
0.919335
2.304
0.919164
1.368
0.91899
0
0.918876
%&<>Ni
Ni
2021
4
29
13
47
1
0
18
Casa Info Follows
0
0
0
0
File = E:/OwnCloud/XPS lab/EX492_S776_Ni Oxidation.sle
Group = RT in vacuum, #Treatments:30min sputter, #Temp:RT , #Pressure:vacuum , #Atmosphere:{:}, #Comments:
First of group = 0
Spectrum ID = 4
Analyzer lens = AngleResolvedMode22:1.5kV
Analyzer slit = 4:7x20c\C:mesh
Scan mode = FixedAnalyzerTransmission
Kinetic energy start = 596.61
PCA Coefs = 190810, -40055.7, -202.957, -142.327, 70.9683,
C:\Users\Mark\Downloads\EX492_S776_Ni Oxidation.vms
c:\users\mark\downloads\ex492_ni references.vms
Energy offsets:  1:0 2:0
c:\users\mark\downloads\ex491-495 fe, ni, co oxide references.vms
XPS
1e+037
Al
1486.61
0
0
0
54.5
180
FAT
20
1
4.1408
0
0
0
0
0
Lineshapes

-1
kinetic energy
eV
596.61
0.1
2
counts
d
Transmission
d
pulse counting
1
1
0
0
0
0
2
ESCAPE DEPTH TYPE
d
0
MFP Exponent
d
0
1
0
0.3
5437.15
0.3
5464.98
0.3
5479.09
0.3
5473.37
0.3
5477.81
0.3
5485.13
0.3
5567.89
0.3
5542.89
0.3
5574.62
0.3
5546.93
0.3
5617.99
0.3
5623.95
0.3
5637
0.3
5684.81
0.3
5664.74
0.3
5723.59
0.3
5677.81
0.3
5732.78
0.3
5732.73
0.3
5753.38
0.3
5782.31
0.3
5752.12
0.3
5756.92
0.3
5853.57
0.3
5836.16
0.3
5892.51
0.3
5865.11
0.3
5870.07
0.3
5847.47
0.3
5792.9
0.3
5855.33
0.3
5788.93
0.3
5812.86
0.3
5840.98
0.3
5883.83
0.3
5899.23
0.3
5917.13
0.3
5913.71
0.3
6031.74
0.3
6094.27
0.3
6162.73
0.3
6235.24
0.3
6333.46
0.3
6388.41
0.3
6519.5
0.3
6640.59
0.3
6731.28
0.3
6899.96
0.3
7099.5
0.3
7116.74
0.3
7244.53
0.3
7349.21
0.3
7262.5
0.3
7235.32
0.3
7167.89
0.3
7163.43
0.3
7130.51
0.3
7163.35
0.3
7206.83
0.3
7469.36
0.3
7778.07
0.3
8128.67
0.3
8689.47
0.3
9479.17
0.3
10543.4
0.3
11616.9
0.3
12097.2
0.3
11327.2
0.3
9785.77
0.3
8058.17
0.3
6912.78
0.3
6205.55
0.3
5726.92
0.3
5502.74
0.3
5299.65
0.3
5164.74
0.3
4977.37
0.3
4969.77
0.3
4870.41
0.3
4859.92
0.3
4882.81
0.3
4823.84
0.3
4830.23
0.3
4823.13
0.3
4796.11
0.3
4807.12
0.3
4761.45
0.3
4738.6
0.3
4750.12
0.3
4785.4
0.3
4765.63
0.3
4819.91
0.3
4890.25
0.3
4934.29
0.3
5028.76
0.3
5182.32
0.3
5291.92
0.3
5466.96
0.3
5693.57
0.3
5904.97
0.3
6178.86
0.3
6386.32
0.3
6616.29
0.3
6865.7
0.3
6943.15
0.3
6842.23
0.3
6669.42
0.3
6430.73
0.3
6308.36
0.3
6252.25
0.3
6191.76
0.3
6226.78
0.3
6194.05
0.3
6317.73
0.3
6393.04
0.3
6461.85
0.3
6855.37
0.3
7236.85
0.3
7945.27
0.3
8956.57
0.3
10750.9
0.3
13863.7
0.3
18923.1
0.3
24340.1
0.3
23775.1
0.3
15894
0.3
8433.17
0.3
5059.38
0.3
3661.44
0.3
2990.83
0.3
2682.55
0.3
2430.37
0.3
2267.96
0.3
2162.9
0.3
2051.52
0.3
2022.68
0.3
1992.42
0.3
1942.6
0.3
1921.14
0.3
1916.78
0.3
1833.99
0.3
1875.76
0.3
1866.07
0.3
1858.16
0.3
1831.06
0.3
1861.42
0.3
1826.67
0.3
1835.5
0.3
1797.64
0.3
1828.18
0.3
1820.74
0.3
1806.87
0.3
1805.75
0.3
1811.2
0.3
1850.77
0.3
1810.78
0.3
1825.3
0.3
1801.87
0.3
1809.91
0.3
1849.59
0.3
1864.05
0.3
1833.37
0.3
1841.26
0.3
1798.24
0.3
1844.91
0.3
1869.19
0.3
1848.23
0.3
1817.3
0.3
1853.12
0.3
1898.17
0.3
1838.34
0.3
1848.63
0.3
1883.86
0.3
1893.31
0.3
1854.9
0.3
1910.83
0.3
1938.88
0.3
1924.37
0.3
1948.98
0.3
1948.02
0.3
1922.37
0.3
1873.08
0.3
1945.87
0.3
1919.19
0.3
1956.25
0.3
1997.43
0.3
1941.24
0.3
1907.32
0.3
1979.93
0.3
1960.95
0.3
1933.64
0.3
1963.75
0.3
2003.65
0.3
2020.05
0.3
2035.97
0.3
2006.1
0.3
2023.91
0.3
2029.8
0.3
2039.21
0.3
2041.43
0.3
2088.09
0.3
2138.54
0.3
2065.62
0.3
2087.82
0.3
2121.21
0.3
2106.13
0.3
2099.74
0.3
2104.49
0.3
2144.19
0.3
2173.73
0.3
2149.8
0.3
2189.31
0.3
2143.98
0.3
2182.33
0.3
2165.99
0.3
2198.08
0.3
2246.47
0.3
2240.91
0.3
2244.18
0.3
2284.5
0.3
2199.94
0.3
2234.31
0.3
2214.46
0.3
2227.66
0.3
2214.98
0.3
2212.99
0.3
2186.02
0.3
2159.16
0.3
2189.83
0.3
2160.63
0.3
2133.35
0.3
2180.81
0.3
2146.3
0.3
2126.93
0.3
2135.88
0.3
2078.5
0.3
2136.79
0.3
2135.74
0.3
2110.98
0.3
2077.89
0.3
2146.63
0.3
2139.5
0.3
2159.52
0.3
2129.17
0.3
2191.43
0.3
2179.14
0.3
2161.55
0.3
2169.63
0.3
2175.34
0.3
2262.88
0.3
2261.69
0.3
2250.69
0.3
2335.57
0.3
2264.72
0.3
2289.67
0.3
2361.06
0.3
2393.62
0.3
2378.67
0.3
2430.16
0.3
2473.88
0.3
2400.79
0.3
2417.13
0.3
2436.73
0.3
2405.25
0.3
2438.07
0.3
2375.83
0.3
2341.01
0.3
2323.93
0.3
2243.97
0.3
2241.07
0.3
2256.58
0.3
2230.85
0.3
2289.63
0.3
2217.26
0.3
2257.86
0.3
2247.61
0.3
2262.24
0.3
2272.93
0.3
2218.8
0.3
2205.28
0.3
2251.97
0.3
2255.98
0.3
2188.79
0.3
2237.53
0.3
2207.12
0.3
2248.28
0.3
2161.1
0.3
2222.68
0.3
2232.52
0.3
2230.59
0.3
2214.12
0.3
2220.57
0.3
2266.16
0.3
2245.07
0.3
2249.83
0.3
2274.99
0.3
2254.06
0.3
2277.99
0.3
2312.28
0.3
2297.77
0.3
2292.5
0.3
2365.04
0.3
2335.74
0.3
2350.69
0.3
2369.17
0.3
2337
0.3
2338.78
0.3
2395.95
0.3
2341.35
0.3
2366.61
0.3
2352.17
0.3
2443.95
0.3
2449.91
0.3
2438.78
0.3
2443.83
0.3
2393
0.3
2449.71
0.3
2450.27
0.3
2425.63
0.3
2451.19
0.3
2520.04
0.3
2512.2
0.3
2481.38
0.3
2449.02
0.3
2458.97
0.3
2545.24
0.3
2479.12
0.3
2574.24
0.3
2499.27
0.3
2538.99
0.3
2583.31
0.3
2576.56
0.3
2589.25
0.3
2611.61
0.3
2571.51
0.3
2664.6
0.3
2668.22
0.3
2662.55
0.3
2666.77
0.3
2697.23
0.3
2667.28
0.3
2768.9
0.3
2762.58
0.3
2751.31
0.3
2759.21
0.3
2730.97
0.3
2731.35
0.3
2748.62
0.3
2813.2
0.3
2827.17
0.3
2870.19
0.3
2833
0.3
2921.38
0.3
2891.53
0.3
2890.63
0.3
2893.75
0.3
2946.33
0.3
2980.02
0.3
2924.34
0.3
2987.69
0.3
3005.59
0.3
3056.74
0.3
3102.88
0.3
3134.4
0.3
3146.99
0.3
3189.35
0.3
3200.78
0.3
3212.06
0.3
3298.69
0.3
3357.92
0.3
3359.38
0.3
3374.91
0.3
3406.99
0.3
3420.12
0.3
3400.96
0.3
3395.4
0.3
3311.68
0.3
3316.24
0.3
3203.34
0.3
3257.97
0.3
3134.8
0.3
3081.73
0.3
2990.19
0.3
2977.16
0.3
2936.66
0.3
2934.46
0.3
2881.73
0.3
2916.67
0.3
2919.98
0.3
2924.84
0.3
2988.74
0.3
3028.08
0.3
3046.49
0.3
3089.3
0.3
3057.92
0.3
3133.6
0.3
3116.42
0.3
3122.64
0.3
3036.13
0.3
3009.55
0.3
2917.4
0.3
2811.83
0.3
2722.43
0.3
2617.73
0.3
2517.46
0.3
2372.35
0.3
2279.85
0.3
2136.31
0.3
2085.13
0.3
2006.3
0.3
1947.36
0.3
1874.46
0.3
1847.67
0.3
1780.87
0.3
1742.97
0.3
1716.37
0.3
1733.18
0.3
1623.33
0.3
1646.03
0.3
1643.53
0.3
1600.64
0.3
1609.91
0.3
1581.15
0.3
1582.73
0.3
1576.02
0.3
1590.83
0.3
1590.34
0.3
1570.48
0.3
1566.56
0.3
1584.48
0.3
1549.47
0.3
1514.58
0.3
1567.79
0.3
1549.36
0.3
1504.18
0.3
1494.23
0.3
1507.47
0.3
1450.44
0.3
1454.15
0.3
1480.43
0.3
1478.96
0.3
1459.35
0.3
1468.16
0.3
1453.07
0.3
1453.29
0.3
1455.62
0.3
1456.61
0.3
1462.45
0.3
1446.46
0.3
1455.77
0.3
1455.57
0.3
1452.83
0.3
1450.11
0.3
1459.76
0.3
1466.71
0.3
1502.68
0.3
1497.1
0.3
1480.39
0.3
1519.84
0.3
1523.93
0.3
1533.51
0.3
1543.23
0.3
1555.78
0.3
1573.62
0.3
1551.88
0.3
1588.99
0.3
1544.73
0.3
1500.6
0.3
1481.63
0.3
1436.65
0.3
1408.23
0.3
1369.45
0.3
1352.23
0.3
1358.28
0.3
1348.49
0.3
1324.3
0.3
1321.95
0.3
1341.75
0.3
1341.18
0.3
1289.71
0.3
1312.62
0.3
1330.89
0.3
1342.06
0.3
1273.74
0.3
1320.29
0.3
1307.64
0.3
1319.92
0.3
1320.5
0.3
1310.14
0.3
1256.93
0.3
1326.93
0.3
1306.69
0.3
1322.07
0.3
1339.64
0.3
1309.62
0.3
1358.55
0.3
1342.16
0.3
1359.57
0.3
1335.44
0.3
1373.07
0.3
1383.52
0.3
1376.69
0.3
1386.16
0.3
1355.26
0.3
1399.88
0.3
1405.54
0.3
1404.75
0.3
1432.49
0.3
1392.28
0.3
1415.74
0.3
1432.38
0.3
1456.47
0.3
1456.99
0.3
1431.61
0.3
1474.34
0.3
1477.27
0.3
1461.22
0.3
1490.32
0.3
1495.52
0.3
1557.22
0.3
1513.22
0.3
1544.29
0.3
1556.4
0.3
1537.75
0.3
1550.4
0.3
1546.99
0.3
1548.31
0.3
1554.56
0.3
1575.07
0.3
1569.03
0.3
1565.6
0.3
1555.67
0.3
1609.05
0.3
1619.63
0.3
1633.84
0.3
1658.87
0.3
1614.15
0.3
1649.67
0.3
1695.13
0.3
1696.44
0.3
1714.05
0.3
1697.06
0.3
1745.77
0.3
1729.98
0.3
1766.68
0.3
1765.73
0.3
1766.05
0.3
1780.94
0.3
1780.83
0.3
1776.08
0.3
1824.52
0.3
1832.95
0.3
1825.1
0.3
1837.53
0.3
1866.4
0.3
1866.46
0.3
1859.14
0.3
1864.15
0.3
1869.76
0.3
1894.72
0.3
1938.83
0.3
1917.21
0.3
1954.04
0.3
1991.31
0.3
1970.36
0.3
2067.8
0.3
2057.49
0.3
2137.6
0.3
2127.64
0.3
2175.84
0.3
2181.14
0.3
2224.33
0.3
2223.07
0.3
2266.21
0.3
2277.61
0.3
2273.28
0.3
2346.8
0.3
2343.39
0.3
2349.27
0.3
2385.03
0.3
2420.44
0.3
2458.88
0.3
2513.96
0.3
2605.82
0.3
2688.96
0.3
2773.7
0.3
2879.87
0.3
3047.01
0.3
3174.37
0.3
3401.08
0.3
3540.35
0.3
3737.48
0.3
3846.96
0.3
3840.51
0.3
3757.58
0.3
3616.35
0.3
3332.1
0.3
3112.54
0.3
2854.74
0.3
2671.44
0.3
2529.46
0.3
2386.32
0.3
2335.38
0.3
2208.29
0.3
2183.06
0.3
2140.53
0.3
2149.7
0.3
2143.03
0.3
2178.87
0.3
2220.88
0.3
2270.73
0.3
2278.38
0.3
2400.37
0.3
2463.91
0.3
2479.4
0.3
2478.29
0.3
2493.46
0.3
2430.65
0.3
2318.24
0.3
2192.45
0.3
2087.93
0.3
1945.1
0.3
1801.64
0.3
1702.52
0.3
1662.24
0.3
1546.51
0.3
1458.56
0.3
1380.78
0.3
1266.25
0.3
1195.02
0.3
1152.77
0.3
1064.39
0.3
942.98
0.3
822.66
0.3
745.36
0.3
685.92
0.3
622.87
0.3
589.5
0.3
538.12
0.3
518.57
0.3
470.94
0.3
492.91
0.3
455.95
0.3
486.92
0.3
457.43
0.3
468.73
0.3
503.08
0.3
484.66
0.3
497.33
0.3
469.13
0.3
427.52
0.3
452.8
0.3
407.37
0.3
399.12
0.3
347.08
0.3
309.36
0.3
289.37
0.3
231.27
0.3
224.33
0.3
196.3
0.3
172.3
0.3
196.35
0.3
155.91
0.3
158.1
0.3
143.84
0.3
161.25
0.3
139.91
0.3
138.88
0.3
124.91
0.3
132.78
0.3
144.45
0.3
105.35
0.3
120.68
0.3
115.07
0.3
87.43
0.3
86.84
0.3
62
0.3
64.9
0.3
43.7
0.3
37.58
0.3
22.81
0.3
23.42
0.3
38.07
0.3
0
0.3
%&<>NiO
NiO
2021
4
29
23
29
30
0
18
Casa Info Follows
0
0
0
0
File = E:/OwnCloud/XPS lab/EX492_S776_Ni Oxidation.sle
Group = RT in vacuum, #Treatments: , #Temp:RT , #Pressure:vacuum , #Atmosphere:, #Comments:
First of group = 0
Spectrum ID = 20
Analyzer lens = AngleResolvedMode22:1.5kV
Analyzer slit = 4:7x20c\C:mesh
Scan mode = FixedAnalyzerTransmission
Kinetic energy start = 596.61
PCA Coefs = 135146, 22871.4, -962.346, 884.156, -199.619,
C:\Users\Mark\Downloads\EX492_S776_Ni Oxidation.vms
c:\users\mark\downloads\ex492_ni references.vms
Energy offsets:  1:0 2:0
c:\users\mark\downloads\ex491-495 fe, ni, co oxide references.vms
XPS
1e+037
Al
1486.61
0
0
0
54.5
180
FAT
20
1
4.1408
0
0
0
0
0
Lineshapes

-1
kinetic energy
eV
596.61
0.1
2
counts
d
Transmission
d
pulse counting
1
1
0
0
0
0
2
ESCAPE DEPTH TYPE
d
0
MFP Exponent
d
0
1
0
0.3
3368.37
0.3
3330.94
0.3
3375.44
0.3
3350.09
0.3
3364.48
0.3
3294.04
0.3
3333.95
0.3
3330.41
0.3
3318.41
0.3
3317.38
0.3
3353.14
0.3
3358.05
0.3
3314.78
0.3
3330.32
0.3
3368.48
0.3
3430.69
0.3
3476.1
0.3
3544.44
0.3
3607.17
0.3
3713
0.3
3798.02
0.3
3945.75
0.3
4019.58
0.3
4113.89
0.3
4204.42
0.3
4357.79
0.3
4523.63
0.3
4747.76
0.3
4943.12
0.3
4994.46
0.3
5060.13
0.3
5088.64
0.3
5165.96
0.3
5214.15
0.3
5205.3
0.3
5185.66
0.3
5160.6
0.3
5083.67
0.3
5012.65
0.3
4932.64
0.3
4845.17
0.3
4728.82
0.3
4660.78
0.3
4530.22
0.3
4483.56
0.3
4479.11
0.3
4419.01
0.3
4406.7
0.3
4439.8
0.3
4520.45
0.3
4588.97
0.3
4775.62
0.3
4885.85
0.3
5075.79
0.3
5230.82
0.3
5361.69
0.3
5450.31
0.3
5524.04
0.3
5512.75
0.3
5543.1
0.3
5502.88
0.3
5547.48
0.3
5411.78
0.3
5035.57
0.3
4349.37
0.3
3610.91
0.3
3108.14
0.3
2877.52
0.3
2734.37
0.3
2722
0.3
2792.54
0.3
2869.65
0.3
3009.51
0.3
3115.22
0.3
3181.01
0.3
3255.79
0.3
3356.3
0.3
3489.79
0.3
3586.37
0.3
3580.08
0.3
3514.73
0.3
3567.73
0.3
3674.76
0.3
3821.96
0.3
4074.92
0.3
4200.04
0.3
4355.04
0.3
4506.05
0.3
4668.74
0.3
4802.61
0.3
5007.52
0.3
5269.2
0.3
5617.05
0.3
5855.07
0.3
6062.66
0.3
6294.5
0.3
6234.77
0.3
6115.7
0.3
5916.54
0.3
5648.69
0.3
5308.86
0.3
4940.07
0.3
4688.51
0.3
4414.9
0.3
4321.29
0.3
4279.59
0.3
4396.97
0.3
4560.55
0.3
4907.13
0.3
5430.89
0.3
6003.03
0.3
6567.31
0.3
7065.65
0.3
7376.14
0.3
7314.5
0.3
7131.02
0.3
7159.26
0.3
7553.27
0.3
8385.81
0.3
9632.41
0.3
9905.81
0.3
7855.94
0.3
4786.12
0.3
3029.59
0.3
2237.4
0.3
1915.83
0.3
1698.07
0.3
1592.79
0.3
1547.15
0.3
1455.67
0.3
1449.84
0.3
1441.53
0.3
1405.78
0.3
1428.71
0.3
1355.91
0.3
1371.72
0.3
1354.18
0.3
1367.57
0.3
1347.33
0.3
1330.69
0.3
1366.8
0.3
1326.89
0.3
1317.29
0.3
1333.17
0.3
1332.78
0.3
1319.81
0.3
1318.21
0.3
1306.06
0.3
1310.54
0.3
1337.16
0.3
1332.71
0.3
1316.36
0.3
1335.46
0.3
1329.56
0.3
1308.72
0.3
1304.39
0.3
1327.27
0.3
1317.62
0.3
1324.88
0.3
1298.76
0.3
1317.75
0.3
1324.4
0.3
1321.37
0.3
1343.3
0.3
1342.2
0.3
1355.97
0.3
1350.54
0.3
1349.81
0.3
1363.2
0.3
1371.62
0.3
1351.72
0.3
1351.95
0.3
1354.37
0.3
1381.86
0.3
1390.45
0.3
1373.41
0.3
1390.22
0.3
1372.28
0.3
1387.63
0.3
1414.37
0.3
1390.42
0.3
1408.99
0.3
1410.41
0.3
1424.48
0.3
1428.42
0.3
1431.68
0.3
1448.17
0.3
1452.08
0.3
1454.34
0.3
1455.89
0.3
1473.47
0.3
1448.56
0.3
1471.52
0.3
1469
0.3
1489.63
0.3
1486.83
0.3
1455.37
0.3
1498.02
0.3
1479.31
0.3
1496.74
0.3
1485.23
0.3
1485.97
0.3
1496.56
0.3
1514.3
0.3
1502.46
0.3
1516.64
0.3
1514.38
0.3
1514.73
0.3
1546.12
0.3
1551.63
0.3
1541.87
0.3
1561.02
0.3
1568.2
0.3
1592.75
0.3
1582.18
0.3
1581.79
0.3
1558.87
0.3
1556.24
0.3
1572.16
0.3
1567.05
0.3
1558.72
0.3
1549.73
0.3
1525.09
0.3
1538.4
0.3
1525.55
0.3
1512.71
0.3
1533.3
0.3
1529.88
0.3
1521.63
0.3
1547.6
0.3
1516.47
0.3
1546.8
0.3
1527.35
0.3
1522.84
0.3
1515.88
0.3
1535.62
0.3
1542.15
0.3
1552.21
0.3
1500.88
0.3
1545.31
0.3
1558.69
0.3
1543.38
0.3
1545.89
0.3
1569.22
0.3
1582.99
0.3
1601.21
0.3
1619.99
0.3
1606.67
0.3
1637.04
0.3
1624.14
0.3
1644.02
0.3
1655.14
0.3
1665.57
0.3
1666.08
0.3
1669.63
0.3
1667.44
0.3
1686.89
0.3
1678.52
0.3
1663.68
0.3
1643.65
0.3
1647.44
0.3
1646.79
0.3
1641.43
0.3
1627
0.3
1630.79
0.3
1620.44
0.3
1566.88
0.3
1592.58
0.3
1594.43
0.3
1588.96
0.3
1557.73
0.3
1568.1
0.3
1574.56
0.3
1553.58
0.3
1548.64
0.3
1554.98
0.3
1562.37
0.3
1540.47
0.3
1515.98
0.3
1542.71
0.3
1543.02
0.3
1562.22
0.3
1555.9
0.3
1557.41
0.3
1528.17
0.3
1533.27
0.3
1534.61
0.3
1552.5
0.3
1563.66
0.3
1579.89
0.3
1560.12
0.3
1569.05
0.3
1564.53
0.3
1564.91
0.3
1535.58
0.3
1547.79
0.3
1570.77
0.3
1575.58
0.3
1593.66
0.3
1599.63
0.3
1589.82
0.3
1591.48
0.3
1584.18
0.3
1617.65
0.3
1636.21
0.3
1592.76
0.3
1618.88
0.3
1590.22
0.3
1604.1
0.3
1639.05
0.3
1640.37
0.3
1621.67
0.3
1647.15
0.3
1610.3
0.3
1662.68
0.3
1646.49
0.3
1652.48
0.3
1642.52
0.3
1667.85
0.3
1663.06
0.3
1675.24
0.3
1675.07
0.3
1671.11
0.3
1661.34
0.3
1684.24
0.3
1704.7
0.3
1691.29
0.3
1691.4
0.3
1719.92
0.3
1712.77
0.3
1747.47
0.3
1738.13
0.3
1743.73
0.3
1722.57
0.3
1738.2
0.3
1745.29
0.3
1760.59
0.3
1767.41
0.3
1778.19
0.3
1803.88
0.3
1797.17
0.3
1793.06
0.3
1790.59
0.3
1817.78
0.3
1824.62
0.3
1829.11
0.3
1856.45
0.3
1850.03
0.3
1869.93
0.3
1906.54
0.3
1916.54
0.3
1929.25
0.3
1967.5
0.3
1985.8
0.3
2003.11
0.3
2031.09
0.3
2026.23
0.3
2042.72
0.3
2049.32
0.3
2099.33
0.3
2077.05
0.3
2102.23
0.3
2107.99
0.3
2146.13
0.3
2134.8
0.3
2177.22
0.3
2167.77
0.3
2184.79
0.3
2203.81
0.3
2179.67
0.3
2183.66
0.3
2214.23
0.3
2203.27
0.3
2173.34
0.3
2157.77
0.3
2182.8
0.3
2153.23
0.3
2164.42
0.3
2137.15
0.3
2148.22
0.3
2140.18
0.3
2167.42
0.3
2142.03
0.3
2160.06
0.3
2159.95
0.3
2147.45
0.3
2136.71
0.3
2120.48
0.3
2087.31
0.3
2090.81
0.3
2081.49
0.3
2064.27
0.3
2047.7
0.3
2010.68
0.3
1987.29
0.3
1935.39
0.3
1866.22
0.3
1849.52
0.3
1833.36
0.3
1748.89
0.3
1704.54
0.3
1647.85
0.3
1615.27
0.3
1562.05
0.3
1524.95
0.3
1498.15
0.3
1452.38
0.3
1407.6
0.3
1379.84
0.3
1340.14
0.3
1315.92
0.3
1286.87
0.3
1268.64
0.3
1229.93
0.3
1232.35
0.3
1210.39
0.3
1191.72
0.3
1181.1
0.3
1185.14
0.3
1167.02
0.3
1166.96
0.3
1149.04
0.3
1144.85
0.3
1126.98
0.3
1140.1
0.3
1134.79
0.3
1122.74
0.3
1129.67
0.3
1093.45
0.3
1106.75
0.3
1096.03
0.3
1093.77
0.3
1109.09
0.3
1104
0.3
1110.1
0.3
1083.65
0.3
1084.52
0.3
1082.28
0.3
1081.18
0.3
1101.86
0.3
1096.96
0.3
1085.77
0.3
1091.98
0.3
1085.5
0.3
1096.03
0.3
1089.64
0.3
1074.07
0.3
1076.61
0.3
1056.71
0.3
1070.22
0.3
1075.22
0.3
1064.36
0.3
1041.78
0.3
1051.11
0.3
1025.03
0.3
1021.65
0.3
1026.61
0.3
1024.26
0.3
1011
0.3
995.84
0.3
985.45
0.3
981.34
0.3
951.15
0.3
963.9
0.3
958.14
0.3
942.51
0.3
922.87
0.3
944.87
0.3
946.55
0.3
927.31
0.3
931.97
0.3
917.89
0.3
904.48
0.3
906.61
0.3
918.93
0.3
916.14
0.3
900.85
0.3
901.71
0.3
877.33
0.3
874.1
0.3
872.75
0.3
849.06
0.3
876.37
0.3
859.07
0.3
872.56
0.3
861.78
0.3
867.25
0.3
856.55
0.3
854.85
0.3
853.21
0.3
851.74
0.3
870.94
0.3
839.96
0.3
875.5
0.3
862.73
0.3
873.91
0.3
855.54
0.3
881.62
0.3
887.03
0.3
864.26
0.3
875.08
0.3
900.78
0.3
878.84
0.3
912.77
0.3
909.24
0.3
888.81
0.3
909.76
0.3
914.4
0.3
901.45
0.3
922.1
0.3
930.71
0.3
921
0.3
933.87
0.3
938.6
0.3
935.62
0.3
933.49
0.3
932.88
0.3
952.48
0.3
950.21
0.3
950.37
0.3
973.52
0.3
969.2
0.3
964.68
0.3
968.88
0.3
972.92
0.3
974.92
0.3
984.53
0.3
991.37
0.3
984.32
0.3
990.62
0.3
981.88
0.3
997.79
0.3
993.54
0.3
991.46
0.3
1011.7
0.3
1017.1
0.3
1016.98
0.3
1006.79
0.3
1016.62
0.3
1014.61
0.3
1028.73
0.3
1032.81
0.3
1031.81
0.3
1048.84
0.3
1046.33
0.3
1058.09
0.3
1083.72
0.3
1096.98
0.3
1088.89
0.3
1140.46
0.3
1142.75
0.3
1173.91
0.3
1183.92
0.3
1216.78
0.3
1235.14
0.3
1239.98
0.3
1272.23
0.3
1291.48
0.3
1276.62
0.3
1303.34
0.3
1309.24
0.3
1313.73
0.3
1332.91
0.3
1307.19
0.3
1310.99
0.3
1318.36
0.3
1340.49
0.3
1316.49
0.3
1313.2
0.3
1329.07
0.3
1359.49
0.3
1344.77
0.3
1352.47
0.3
1386.91
0.3
1399.46
0.3
1410.29
0.3
1452.96
0.3
1464.44
0.3
1489.69
0.3
1546.25
0.3
1585.84
0.3
1616.83
0.3
1612.9
0.3
1659.23
0.3
1688.98
0.3
1741.44
0.3
1758.21
0.3
1829.74
0.3
1865.88
0.3
1884.78
0.3
1967.22
0.3
2021.7
0.3
2048.75
0.3
2070.99
0.3
2064.61
0.3
2054.24
0.3
2028.47
0.3
1957.13
0.3
1904.57
0.3
1861
0.3
1804.04
0.3
1748.07
0.3
1700.2
0.3
1689.85
0.3
1628.79
0.3
1609.98
0.3
1597.15
0.3
1561.21
0.3
1537.76
0.3
1520.74
0.3
1515.54
0.3
1486.8
0.3
1452.66
0.3
1446.65
0.3
1427.56
0.3
1406.75
0.3
1402.16
0.3
1364.16
0.3
1368.86
0.3
1347.36
0.3
1318.39
0.3
1258.85
0.3
1234.89
0.3
1201.51
0.3
1139.75
0.3
1058.56
0.3
1003.85
0.3
909.28
0.3
838.17
0.3
755.61
0.3
687.33
0.3
620.28
0.3
585.23
0.3
534.05
0.3
502.94
0.3
460.4
0.3
443.57
0.3
427.16
0.3
413.8
0.3
397.99
0.3
393.64
0.3
383.1
0.3
371.56
0.3
379.8
0.3
375.36
0.3
371.2
0.3
373.5
0.3
364.05
0.3
354.27
0.3
336.73
0.3
336.08
0.3
341.48
0.3
293.14
0.3
304.43
0.3
279.08
0.3
286.91
0.3
261.16
0.3
249.79
0.3
232.63
0.3
222.58
0.3
207.67
0.3
186.69
0.3
189.9
0.3
168.86
0.3
169.38
0.3
163.77
0.3
161.76
0.3
143.23
0.3
128.9
0.3
122.97
0.3
139.97
0.3
124.77
0.3
127.56
0.3
118.63
0.3
118.52
0.3
83.91
0.3
68.66
0.3
82.89
0.3
82.34
0.3
56.61
0.3
32.15
0.3
43.64
0.3
19.27
0.3
0
0.3
end of experiment