File: src/xpsdeeplearning/data/references/Ni_references.vms
VAMAS Surface Chemical Analysis Standard Data Transfer Format 1988 May 4
Not Specified
Not Specified
Not Specified
Not Specified
6
Casa Info Follows CasaXPS Version 2.3.25PR1.0
0
Created by SpecsLab Prodigy, Version 4.73.2-r95032
SourceAnalyserAngle: Not Specified
CasaRowLabel:Ni
CasaRowLabel:NiO
NORM
REGULAR
0
1
Exp Variable
d
0
0
0
0
4
Survey
Ni
2021
4
29
13
43
28
0
17
Casa Info Follows
0
0
0
0
File = E:/OwnCloud/XPS lab/EX492_S776_Ni Oxidation.sle
Group = RT in vacuum, #Treatments:30min sputter, #Temp:RT , #Pressure:vacuum , #Atmosphere:{:}, #Comments:
First of group = 1
Spectrum ID = 3
Analyzer lens = LargeArea:1.5kV
Analyzer slit = 4:7x20c\C:mesh
Scan mode = FixedAnalyzerTransmission
Kinetic energy start = 286.61
PCA Coefs = 183133, -17152.6, -29.7063, -194.128,
C:\Users\Mark\Downloads\EX492_S776_Ni Oxidation.vms
c:\users\mark\downloads\ex492_ni references.vms
C:\Users\pielsticker\Lukas\MPI-CEC\Projects\deepxps\xpsdeeplearning\data\references\NiCoFe\EX491-495 Fe, Ni, Co oxide references.vms
XPS
3
Al
1486.61
0
0
0
54.5
180
FAT
100
1
4.1408
0
0
0
0
0
Survey

-1
kinetic energy
eV
286.61
1
2
counts
d
Transmission
d
pulse counting
0.1
1
0
0
0
0
2
ESCAPE DEPTH TYPE
d
1
MFP Exponent
d
0
297.34
1
4699.45
4711.84
4756.39
4739.41
4769.21
4767.2
4785.55
4796.73
4786.26
4821.66
4842.97
4857.94
4854.65
4866.86
4882.58
4884.61
4869.18
4902.97
4901.28
4952.19
5004.7
4978.68
4982.68
4980.08
4977.32
5023.29
4997.95
5031.01
5042.9
5081.65
5109.06
5103.86
5115.32
5156.99
5124.36
5154.89
5148.94
5149.3
5198.96
5196.32
5216.57
5247.88
5221.61
5254.21
5248.04
5274.07
5322.32
5312.85
5278
5300.56
5334.7
5323.64
5409.71
5431.31
5414.39
5439.14
5435.12
5464.02
5470.5
5488.32
5525.82
5545.28
5521.21
5557.72
5566.52
5578.92
5599.6
5633.68
5658.16
5658.92
5651.48
5718.1
5726.94
5722.06
5741.87
5762.12
5801.96
5815.79
5821.6
5822.84
5823.41
5834.23
5836.77
5854.92
5928.24
5921.31
5901.12
5931.68
5965.17
6018.48
6064.23
6023.05
6028.98
6046.58
6101.58
6138.56
6135.7
6130.28
6178.23
6223.22
6199.45
6219.48
6254.64
6272.31
6289.39
6238.54
6260.46
6341.71
6339.96
6355.07
6405.35
6426
6397.67
6444.8
6444.46
6447.52
6513.58
6510
6536.56
6545.2
6567.79
6622.92
6611.54
6624.43
6643.01
6653.56
6708.02
6727.22
6741.95
6742.7
6786.56
6829.28
6789.78
6851.28
6865.48
6886.71
6897.19
6952.96
6924.04
6953.54
6980.7
7024.95
7071.7
7060.7
7078.36
7118.11
7185.19
7209.65
7215.52
7197.97
7272.44
7290.63
7322.52
7362.36
7391.49
7362.89
7434.5
7446.08
7470.84
7491.39
7494.94
7503.1
7556.59
7638.88
7662.07
7641.17
7722.36
7754.09
7745.15
7751.1
7817.42
7884.72
7820.54
7861.23
7900.33
7909.8
7930.16
7962.4
8067.45
8066.95
8105.27
8196.69
8202.25
8244.6
8326.53
8457.48
8542.71
8660.07
8791.36
8933.09
9046.58
9092.66
9107.66
8917.83
8694.36
8389.67
8163.53
7999.89
7918.97
7775.96
7729.55
7685.82
7680.14
7678.65
7693.85
7704.14
7736.14
7672.02
7641.5
7704.02
7690.98
7680.76
7695.31
7740.99
7751.73
7761.53
7765.91
7804.17
7886.03
7836.41
7843.42
7927.06
7942.33
7972.94
7962.01
8004.42
8048.49
8033.31
8098.12
8121.48
8103.29
8058.79
8130.48
8132.96
8156.99
8147.22
8164.18
8141.35
8176.13
8226.16
8243.58
8220.16
8268.96
8289.66
8324.96
8366.3
8368.15
8402.6
8436.1
8513.66
8536.6
8519.14
8608.14
8548.37
8548.03
8620.14
8647.66
8659.61
8703.54
8785.05
8726.03
8727.8
8841.89
8878.5
8899.59
8866.93
8963.42
8992.54
8963.4
9048.3
9093.3
9111.13
9117.82
9188.15
9270.06
9286.82
9321.73
9300.59
9414
9392.04
9465.6
9538.19
9542.95
9583.2
9651.22
9688.13
9751.39
9826.62
9870.36
9941.61
10000.9
10041.7
10088.3
10152.3
10160.5
10256.8
10394.7
10434.4
10435.3
10585.2
10617.2
10628.9
10678.8
10787.1
10826
10883.7
10990.4
11032.5
11178.5
11172
11268
11328.8
11406.1
11547.3
11706.7
11736.7
11792.7
11888
11936.7
11882.2
11939.3
12167.3
12536.2
12932.5
13427.8
13829.6
13942.2
14230.1
15442.1
17259.1
17109.5
14410.9
11970.8
11007.8
10674.4
10581.9
10493.6
10586
10936.8
11619.5
12454.4
13051.2
13035.8
12847.4
13359.6
15822.1
21929.6
23869.7
16812.1
9266.23
7076.43
6574.16
6347.21
6242.77
6191.24
6221.19
6174.81
6195.86
6205.47
6244.69
6244.83
6247.59
6284.73
6316.98
6342.5
6388.69
6393.23
6411.39
6481.25
6480.69
6597.82
6586.56
6641.66
6695.8
6741.59
6783.44
6802.82
6740.38
6716.98
6694.85
6634.72
6663.98
6705.36
6755.67
6836.21
6902.57
6981.59
7024.09
7088.38
7061
6968.79
6842.09
6851.43
6829.72
6826.4
6820.64
6829.27
6901.11
6888.03
6892.81
6908.8
7009.44
7082.5
7129.84
7141.9
7205.54
7224.17
7231.17
7264.68
7338.72
7425.59
7498.5
7562.79
7600.22
7694.11
7792.23
7882.01
7936.88
8084.24
8251.27
8412.8
8541.23
8517.72
8434.19
8186.36
8028.98
7945.49
8000.44
8087.94
7985.78
7655.72
7221.23
6745.12
6384.51
6151.19
6011.26
5956.66
5931.68
5870.67
5810.94
5831.48
5752.92
5729.11
5697.08
5648.46
5717.46
5749.17
5788.31
5823.3
5786.96
5739.51
5659.24
5590.5
5487.37
5540.43
5534.76
5532.33
5503.35
5534.89
5589.86
5618.63
5641.51
5658.02
5722.75
5770.26
5804.97
5881.85
5926.9
5970.77
5973.52
6069.01
6085.76
6139.93
6182.79
6280.81
6335.81
6383.65
6454.32
6541.79
6690.6
6808.85
6992.58
7086.94
7220.61
7438.24
7847.18
8394.28
8939.95
8796.97
8052.33
7368.39
6979.77
6887.87
7015.03
7154.97
6955.71
6503.98
6034.47
5586.15
5150.42
4759.57
4456.16
4334.66
4294.17
4258.35
4205.11
4082.99
3947.82
3863.28
3804.58
3790.76
3758.46
3735.47
3651.62
3587.39
3584.03
3548.34
3531.14
3525.37
3560.86
3560.43
3597.06
3625.72
3668.04
3709.91
3758.39
3810.72
3824.18
3859.11
3881.89
3940.21
3961.65
3997.84
4031.7
4074.79
4096.77
4116.13
4141.52
4154.53
4171.04
4202.28
4236.25
4274.11
4345.37
4410.84
4511.83
4561.39
4646.48
4751.19
4893.82
5110.16
5428.86
5655.05
5793.85
6024.9
6419.41
7019.79
8010.19
9496.72
10394.5
9760.16
8266.54
6901.12
5874.6
4835.88
3618.47
2698.1
2287.41
2142.15
2090.25
2014.91
1939.47
1902.18
1907.29
1977.15
2056.68
2128.13
2046.28
1853.97
1662.72
1510.28
1346.59
1166.1
1024.01
933.557
892.728
869.089
870.537
853.423
847.078
843.092
845.637
850.404
837.323
826.453
829.73
833.135
826.842
832.116
853.165
849.736
860.984
854.911
837.403
841.038
847.095
845.643
837.818
826.455
828.329
822.983
822.294
821.227
813.99
815.085
826.461
822.778
814.049
818.541
833.558
820.108
823.218
817.383
812.711
820.861
846.202
822.745
827.286
831.688
831.817
841.229
855.854
841.369
838.962
846.136
856.319
849.174
844.622
845.864
846.034
841.264
849.834
859.227
841.45
839.966
850.55
847.247
864.768
860.876
861.104
855.974
856.608
851.328
852.559
858.513
867.55
867.979
872.483
874.626
886.469
869.956
875.121
863.664
886.696
883.987
911.408
951.851
1018.57
1101.75
1115.74
1054.39
942.988
872.44
857.346
837.802
838.161
846.093
849.586
854.658
857.729
862.396
860.115
837.596
862.135
866.828
861.721
871.381
879.934
872.484
880.171
870.231
874.447
864.048
872.842
864.603
879.018
882.366
883.61
889.35
887.649
889.721
886.978
883.065
895.011
893.947
898.993
900.295
905.899
913.145
922.936
925.138
916.439
929.682
916.215
925.987
934.021
912.706
907.342
916.217
901.216
900.327
915.086
912.407
905.294
900.855
908.461
910.578
903.403
895.854
901.908
905.267
895.077
900.875
913.564
920.197
916.272
914.822
914.288
918.524
913.639
914.347
906.819
933.767
912.342
916.32
925.738
926.991
938.112
930.568
929.232
952.463
930.37
932.59
947.831
943.113
937.956
945.417
947.771
936.094
946.999
934.677
955.125
952.645
947.699
941.865
958.54
943.428
954.106
968.1
956.36
957.89
957.652
961.495
968.069
979.446
971.532
972.107
975.559
977.825
980.982
986.314
991.321
998.812
985.099
978.006
965.944
969.859
964.531
978.608
988.281
987.44
997.28
1003.04
999.28
996.739
1001.33
992.747
996.433
1014.16
1009.91
1024.15
1025.41
1038.52
1035.41
1020.84
1015.64
1013.47
1028.27
1019.76
1024.16
1033.73
1021.53
1033.52
1043.12
1022.78
1031.77
1049.33
1038.21
1048.45
1040.06
1056.18
1051.05
1058.48
1041.72
1049.97
1042.17
1049.21
1052.64
1050.27
1054.49
1079.04
1064.43
1075.61
1056.98
1067.36
1074.74
1062.27
1082.17
1074.55
1081.14
1071.44
1068.3
1094.86
1104.31
1103.85
1103.92
1075.37
1102.39
1108.38
1112.43
1108.15
1103.52
1121.75
1131.82
1121.03
1122.25
1118.41
1131.02
1136.99
1136.33
1124.8
1111.25
1129.05
1140.54
1148.63
1136.86
1124.23
1124.46
1123.62
1134.16
1138.41
1144.55
1139.47
1142.64
1150.07
1156.13
1171.12
1184.09
1210.64
1237.32
1284.53
1281.15
1233.45
1200.3
1173.72
1172.13
1166.39
1156.29
1172.33
1190.2
1174.74
1177.08
1172.72
1180.11
1176.12
1200.51
1184.25
1188.37
1181.31
1181.6
1176.87
1183.74
1177.72
1191.77
1191.71
1198.57
1203.51
1214.95
1226.46
1216.32
1207.22
1232.01
1255.21
1278.39
1333.58
1433.96
1454.69
1321.39
1221.82
1211.79
1188.89
1188.38
1198.47
1199.37
1192.46
1181.59
1191.03
1205.51
1213.43
1223.19
1236.16
1221.12
1231.42
1236.42
1225.58
1234.91
1221.16
1222.35
1212.08
1218.73
1220.09
1221.02
1221.72
1211.14
1215.51
1227.64
1242.7
1235.48
1218.52
1222.41
1236.11
1238.51
1252.8
1269.2
1294.22
1372.9
1448.82
1529.67
1561.17
1402.1
1260.06
1226.09
1227.85
1233.31
1239.31
1235.91
1246.05
1218.7
1231.08
1261.53
1242.85
1250.9
1259.42
1272.23
1254.08
1262.78
1276.37
1261.64
1269.83
1265.8
1255.8
1290.66
1258.85
1255.74
1276.49
1299
1300.41
1298.16
1321.22
1307.95
1288.19
1292.89
1279.74
1310.75
1312.66
1320.04
1320.74
1332.92
1332.76
1347.73
1327.52
1351.21
1345.46
1334.12
1337.12
1357.22
1361.66
1362.73
1356.29
1360.61
1379.3
1374.9
1380.93
1404.35
1383.85
1388.39
1408.55
1397.12
1384.36
1403.51
1418.36
1414.79
1414.87
1425.03
1412.61
1422.66
1418.69
1436.59
1423.24
1432.14
1447.24
1460.34
1467.04
1467.61
1469.29
1462.97
1477.45
1509.87
1498
1499.08
1504.75
1521.29
1512.61
1553.31
1551.21
1546.63
1549.41
1542.57
1567.95
1585.74
1592.51
1584.31
1621.85
1625.09
1617.88
1645.45
1663.09
1662.57
1673.1
1693.44
1692.92
1702.97
1710.2
1723.97
1727.71
1723.05
1717.39
1711.65
1720.13
1741.13
1754.41
1775.92
1764.35
1788.79
1824.09
1822.27
1823.69
1857.1
1886.05
1919.09
1986.8
2088.5
2137.77
2174.3
2242.76
2315.89
2492.88
2767.74
3129.22
3192.2
2736.07
2230.25
1891.95
1729.42
1656.96
1641.91
1649.43
1643.11
1637.71
1650.58
1687.08
1682.98
1707.66
1726.16
1710.18
1722.2
1751.73
1778.1
1770.56
1765.83
1776.78
1779.09
1736.14
1727.2
1742.69
1740.99
1757.27
1777.22
1854.14
1902.54
2000.09
2071.3
2030.02
1907.91
1912.44
1974.27
2089.34
2250.82
2432.21
2676.45
3177.26
4060.19
4899.79
5191.53
4155.76
2412.44
1273.93
806.856
611.307
505.526
444.691
406.359
367.408
364.856
353.755
335.852
328.046
326.134
332.494
327.797
330.19
329.943
320.262
322.317
326.62
323.635
325.032
329.258
334.709
325.916
342.336
351.983
365.185
357.567
360.252
374.167
374.155
376.868
388.747
380.992
380.338
377.905
377.479
374.456
377.737
379.588
398.68
407.172
393.758
381.913
376.548
368.051
360.905
369.06
373.06
387.565
388.327
404.704
428.773
454.826
499.374
566.312
617.513
682.051
740.101
800.407
971.997
1327.61
1637.15
1368.55
636.463
1
Ni2p
Ni
2021
4
29
13
47
1
0
17
Casa Info Follows
0
0
0
0
File = E:/OwnCloud/XPS lab/EX492_S776_Ni Oxidation.sle
Group = RT in vacuum, #Treatments:30min sputter, #Temp:RT , #Pressure:vacuum , #Atmosphere:{:}, #Comments:
First of group = 0
Spectrum ID = 4
Analyzer lens = AngleResolvedMode22:1.5kV
Analyzer slit = 4:7x20c\C:mesh
Scan mode = FixedAnalyzerTransmission
Kinetic energy start = 596.61
PCA Coefs = 190810, -40055.7, -202.957, -142.327, 70.9683,
C:\Users\Mark\Downloads\EX492_S776_Ni Oxidation.vms
c:\users\mark\downloads\ex492_ni references.vms
C:\Users\pielsticker\Lukas\MPI-CEC\Projects\deepxps\xpsdeeplearning\data\references\NiCoFe\EX491-495 Fe, Ni, Co oxide references.vms
XPS
4
Al
1486.61
0
0
0
54.5
180
FAT
20
1
4.1408
0
0
0
0
0
Ni
2p
-1
kinetic energy
eV
596.61
0.1
2
counts
d
Transmission
d
pulse counting
0.1
3
0
0
0
0
2
ESCAPE DEPTH TYPE
d
1
MFP Exponent
d
0
1002
4049.78
27322.3
1
1
7694.49
1
7709.97
1
7774.09
1
7767.08
1
7793.16
1
7805.07
1
7794.91
1
7780.07
1
7726.26
1
7809.02
1
7820.68
1
7809.69
1
7803.3
1
7825.53
1
7862.65
1
7807.74
1
7816.49
1
7836.62
1
7815.06
1
7800.96
1
7861.02
1
7897.82
1
7863.47
1
7890.83
1
7872.82
1
7879.83
1
7924.06
1
7904.55
1
7951.42
1
7942.64
1
7876.86
1
7902.57
1
7913.54
1
7947.92
1
7882.93
1
7940.03
1
7953.88
1
7959.18
1
7962.96
1
7966.93
1
7918.34
1
7987.57
1
8014.74
1
8041.56
1
8033.48
1
7994.67
1
7967.4
1
7982.5
1
8053.52
1
8055.77
1
8009.96
1
8007.74
1
8017.1
1
8072.37
1
8062.71
1
8078.81
1
8056.22
1
8062.66
1
8069
1
8085.57
1
8083.31
1
8089.68
1
8107.8
1
8112.24
1
8123.94
1
8089.07
1
8082.05
1
8108.13
1
8116.91
1
8086.85
1
8130.15
1
8175.5
1
8183.5
1
8179.95
1
8162.14
1
8166.09
1
8211.19
1
8228.81
1
8222.44
1
8222.1
1
8239.74
1
8195.04
1
8201.44
1
8140.65
1
8200
1
8160.42
1
8166.75
1
8177.4
1
8182.68
1
8142.5
1
8122.83
1
8156.52
1
8155.76
1
8185.26
1
8147.92
1
8131.86
1
8118.86
1
8095.23
1
8125.77
1
8142.79
1
8132.58
1
8201.08
1
8170.91
1
8203.25
1
8148.61
1
8213.76
1
8194.45
1
8172.03
1
8229.16
1
8233.19
1
8231.02
1
8247.06
1
8315.53
1
8294.29
1
8243.64
1
8295.08
1
8362.68
1
8361.67
1
8391.15
1
8404.75
1
8424.2
1
8418.62
1
8462.51
1
8492.66
1
8514.99
1
8534.59
1
8565.17
1
8638.67
1
8607.93
1
8663.39
1
8687.29
1
8717.93
1
8718.34
1
8848.84
1
8794.06
1
8849.43
1
8956.96
1
8973.83
1
8970.52
1
9013.27
1
9095.81
1
9061.21
1
9120.03
1
9141.98
1
9229.89
1
9250.21
1
9361.42
1
9429.43
1
9430.17
1
9418.92
1
9446.67
1
9524.08
1
9556.45
1
9574.46
1
9559.65
1
9647.85
1
9679.14
1
9597.89
1
9561.74
1
9592.43
1
9590.3
1
9536.1
1
9565.25
1
9530.35
1
9463.56
1
9497.82
1
9510.55
1
9471.51
1
9493.36
1
9498.63
1
9447.48
1
9460.44
1
9452.55
1
9495.66
1
9493.28
1
9499.08
1
9564.26
1
9536.76
1
9644.48
1
9709.81
1
9799.29
1
9906.24
1
10007.9
1
10108
1
10184.4
1
10307.3
1
10458.6
1
10663.4
1
10812.9
1
11019.4
1
11306.5
1
11573.2
1
11809.1
1
12231.4
1
12604.5
1
12873.3
1
13248.7
1
13595.7
1
13946.8
1
14187.3
1
14364.4
1
14427.1
1
14295.5
1
13981.6
1
13657.1
1
13151.6
1
12636.4
1
12115.7
1
11510
1
10949.2
1
10388.1
1
9977.92
1
9590.44
1
9242.71
1
8973.91
1
8724.96
1
8535.48
1
8359.85
1
8243.03
1
8056.85
1
7956.54
1
7880.86
1
7832.67
1
7725.57
1
7681.87
1
7629.58
1
7562.65
1
7484.62
1
7494.67
1
7440.28
1
7359.28
1
7307.3
1
7301.19
1
7265.38
1
7299.7
1
7234.61
1
7220.37
1
7200.34
1
7274.55
1
7227.68
1
7189.85
1
7186.69
1
7214.85
1
7212.74
1
7150.56
1
7180.89
1
7153.77
1
7147.19
1
7172.19
1
7160.16
1
7174.67
1
7151.19
1
7153.06
1
7175.32
1
7164.31
1
7126.04
1
7101.48
1
7107.77
1
7137.05
1
7097
1
7084.59
1
7091.38
1
7103.17
1
7085.27
1
7068.53
1
7051.69
1
7117.12
1
7080.05
1
7102.67
1
7063.9
1
7115.33
1
7120.77
1
7117.41
1
7095.56
1
7126.87
1
7197.04
1
7149.84
1
7200.63
1
7219.65
1
7220.18
1
7259.62
1
7290.63
1
7264.22
1
7307.94
1
7296.23
1
7358.69
1
7431.44
1
7467.53
1
7512.25
1
7536.07
1
7559.35
1
7621.85
1
7713.06
1
7762.17
1
7796.89
1
7881.68
1
7985.02
1
8023.5
1
8087.94
1
8182.57
1
8234.9
1
8284.36
1
8426.42
1
8508.79
1
8587.12
1
8655.56
1
8716.25
1
8856.62
1
8897.45
1
8946.22
1
9010.38
1
9091.22
1
9195.63
1
9259.72
1
9297.86
1
9273.08
1
9267.54
1
9273.67
1
9172.16
1
9142.43
1
9050.77
1
8999.35
1
8926.02
1
8819.58
1
8760.66
1
8694.04
1
8655.5
1
8638.29
1
8619.23
1
8595.05
1
8582.18
1
8553.45
1
8528.59
1
8521.69
1
8498.66
1
8479.56
1
8556.71
1
8582.05
1
8512.43
1
8523.98
1
8553.39
1
8565.28
1
8647.66
1
8662.3
1
8656.01
1
8722.97
1
8756.4
1
8785.59
1
8791.78
1
8926.6
1
9007.82
1
9185.3
1
9310.65
1
9425.41
1
9566.78
1
9779.53
1
10039
1
10275.2
1
10564.1
1
10908.3
1
11286.5
1
11781.5
1
12386.2
1
13080.8
1
13911.4
1
14894.6
1
16193.6
1
17614.8
1
19349.4
1
21253
1
23244.7
1
25132
1
26670
1
27449.8
1
27309.6
1
26105
1
24020.3
1
21275.8
1
18223.9
1
15300.1
1
12762
1
10763.1
1
9274.81
1
8177.48
1
7389.31
1
6774.59
1
6305.5
1
5991.37
1
5694.54
1
5479.07
1
5320.76
1
5211.68
1
5097.4
1
5012.48
1
4910.29
1
4822.75
1
4760.3
1
4715.5
1
4668.12
1
4597.89
1
4555.5
1
4535.78
1
4492.83
1
4421.45
1
4407.44
1
4381.45
1
4396.78
1
4374.99
1
4352.61
1
4329.43
1
4338.79
1
4322.35
1
4286.62
1
4309.25
1
4272.53
1
4243.82
1
4253.81
1
4251.07
1
4245.72
1
4215.23
1
4246.71
1
4238.07
1
4227.06
1
4163.92
1
4200.79
1
4202.27
1
4205.69
1
4223.21
1
4201.59
1
4196
1
4202.24
1
4194.46
1
4188.09
1
4187.69
1
4172.62
1
4160.99
1
4146.58
1
4119.79
1
4191.35
1
4162.66
1
4139.87
1
4156.6
1
4143.4
1
4153.15
1
4165.43
1
4149.67
1
4142.3
1
4127.57
1
4126.69
1
4146.55
1
4158.11
1
4143.14
1
4125.33
1
4150.67
1
4140.71
1
4142.69
1
4136.8
1
4125.1
1
4137.28
1
4135.68
1
4171.39
1
4165.16
1
4141.13
1
4138.53
1
4149.84
1
4180.7
1
4182.47
1
4155.57
1
4140.71
1
4128.32
1
4134.3
1
4155.23
1
4140.17
1
4164.02
1
4131.8
1
4150.11
1
4124.71
1
4139.84
1
4136.4
1
4161.91
1
4179.52
1
4153.11
1
4202.13
1
4193.98
1
4193.96
1
4153.98
1
4163.3
1
4121.79
1
4160.11
1
4171.19
1
4172.88
1
4180.07
1
4128.17
1
4167.1
1
4187.27
1
4174.84
1
4186.69
1
4181.21
1
4199.12
1
4182.87
1
4171.84
1
Survey
NiO
2021
4
29
23
25
58
0
17
Casa Info Follows
0
0
0
0
File = E:/OwnCloud/XPS lab/EX492_S776_Ni Oxidation.sle
Group = RT in vacuum, #Treatments: , #Temp:RT , #Pressure:vacuum , #Atmosphere:, #Comments:
First of group = 1
Spectrum ID = 19
Analyzer lens = LargeArea:1.5kV
Analyzer slit = 4:7x20c\C:mesh
Scan mode = FixedAnalyzerTransmission
Kinetic energy start = 286.61
PCA Coefs = 144137, 9370.22, -1718.27, 1048.98,
C:\Users\Mark\Downloads\EX492_S776_Ni Oxidation.vms
c:\users\mark\downloads\ex492_ni references.vms
C:\Users\pielsticker\Lukas\MPI-CEC\Projects\deepxps\xpsdeeplearning\data\references\NiCoFe\EX491-495 Fe, Ni, Co oxide references.vms
XPS
15
Al
1486.61
0
0
0
54.5
180
FAT
100
1
4.1408
0
0
0
0
0
Survey

-1
kinetic energy
eV
286.61
1
2
counts
d
Transmission
d
pulse counting
0.1
1
0
0
0
0
2
ESCAPE DEPTH TYPE
d
1
MFP Exponent
d
0
106.665
1
4025.6
4055.22
4076.4
4059.62
4116.38
4116.66
4064.5
4086.43
4101.6
4150.96
4141.52
4139.77
4162.58
4167.49
4179.91
4225.19
4228.4
4211.03
4228.14
4231.34
4232.72
4246.14
4239.06
4244.83
4273.05
4306.67
4311.25
4346.39
4341.38
4328.93
4386.42
4368.1
4407.19
4432.95
4449.97
4439.32
4428.45
4475.74
4457.44
4461.42
4477.68
4512.19
4492.57
4525.66
4530.14
4545.18
4572.85
4599.57
4587.22
4611.88
4621.6
4656.6
4652.53
4676.53
4665.46
4641.49
4712.2
4719.34
4714.77
4708.45
4731.03
4771.33
4783.68
4792.02
4800.19
4844.52
4830.49
4837.28
4850.78
4877.21
4877.77
4887.84
4902.04
4915.27
4952.8
4961.25
4979.02
4978.54
5011.64
5026.69
5039.6
5060.02
5030.43
5076.76
5074.1
5113.22
5057.08
5092.89
5107.2
5148
5165.81
5191.11
5178.69
5171.77
5198.82
5187.54
5225.36
5264.62
5267.33
5263.6
5304.41
5286.74
5322.55
5301.32
5331.05
5339.72
5338.65
5382.49
5380.09
5407.78
5441.5
5441.92
5485.44
5498.22
5484.36
5534.21
5559.16
5542.67
5523.04
5570.32
5607.53
5609.85
5594.44
5635.8
5639.13
5642.97
5698.63
5670.59
5733.37
5756
5778.98
5753.29
5797.79
5825.71
5820.41
5868.61
5858.58
5860.25
5885.03
5880.61
5936.19
5957.96
5933.98
5956.01
5977.75
6015.63
6001.19
6027.23
6049.42
6061.81
6062.34
6081.62
6104.14
6120.9
6140.46
6226.39
6198.46
6212.86
6199.04
6248.45
6311.27
6252.08
6325.49
6301.87
6357.45
6370.69
6399.6
6412.1
6409.48
6399.17
6399.23
6417.74
6423.32
6450.85
6514.76
6553.45
6608.36
6660.75
6746.68
6821.5
6935.73
7037.75
7146.72
7216.15
7271.93
7329.85
7366.06
7345.07
7411.64
7461.69
7455.56
7306.57
7190.91
6991.78
6874.3
6760.87
6672.65
6632.42
6582.63
6574.6
6570.83
6606.92
6656.87
6692.44
6794.2
6799.98
6785.21
6742.42
6648.37
6599.95
6589.64
6628.71
6595.04
6580.67
6589.11
6602.1
6609.14
6613.59
6620.01
6698.65
6772.71
6914.94
7117.14
7357.96
7526.69
7593.86
7518.58
7315.14
7153.78
7020.58
6951.64
6883
6777.45
6703.5
6726.89
6652.7
6567.32
6591.95
6550.05
6551.7
6543
6553.66
6515.46
6549
6555.47
6589.39
6587.09
6594.38
6642.47
6657.52
6657.33
6717.33
6727.04
6723.44
6723.35
6750.7
6753.86
6819.33
6834.13
6832.69
6836.19
6854.24
6860.26
6891.23
6857.28
6907.59
6930.49
6959.15
7037.76
7046.24
7024.56
7093.96
7071.33
7139.72
7115.35
7134.47
7152.77
7221.91
7238.23
7272.13
7257.35
7261.94
7261.72
7302.22
7339.47
7392.24
7443.77
7483.3
7557.25
7533.08
7562.73
7605.99
7614.84
7626.37
7660.89
7670.91
7714.22
7740.78
7733.7
7786.52
7842.64
7836.19
7903.49
7967.74
7903.14
7918.74
7897.39
7858.62
7812.52
7854.63
7767.29
7723.19
7721.43
7750.17
7826.16
8076.75
8481.66
8979.38
9573.83
10005.2
10207.1
10115.4
9839.59
9526.79
9417.19
9719.12
10269.9
10545.7
10324.1
9206.29
7837.73
7305.49
7547.03
7918.72
8228.34
8714.58
9545.89
10468.1
11155.7
11219.2
10503.5
9812.68
10196.3
11612.7
12902.9
13690.9
12343.1
8759
5958.05
5222.54
5079.54
4968.66
4911.23
4915.86
4888.37
4864.19
4891.18
4890.67
4921.65
4935.27
4942.34
4951.65
4967.61
5003.84
5030.08
5033.05
5078.96
5101.76
5137.23
5165.08
5159.1
5168.86
5203.64
5251.43
5303.12
5276.48
5252.98
5239.21
5223.72
5237.85
5215.32
5234.26
5262.47
5323.16
5363.77
5415.56
5421.43
5465.69
5407.61
5391.39
5366.37
5293.76
5252.48
5231.09
5232.06
5270.36
5246.12
5289.75
5298.79
5284.5
5326.29
5371.88
5372.72
5400.94
5382.8
5384.76
5471.48
5497.21
5504.67
5525.49
5600.56
5633.39
5665.37
5741.08
5803.91
5855.56
5942.51
6023.27
6100.15
6192.55
6235.06
6283.26
6190.52
6178.36
6222.4
6160.41
6175.26
6057.09
5904.7
5759.07
5541.4
5352.69
5145.41
4995.24
4847.7
4774.7
4789.51
4765.2
4720.56
4690.61
4654.97
4678
4677.21
4639.19
4606.22
4587.47
4562.35
4514.5
4522.39
4460.94
4438.55
4401.3
4391.78
4375.04
4335.79
4338.32
4328.15
4334.42
4346.04
4363.07
4374.17
4357.89
4367.48
4404.78
4411.78
4471.38
4493.37
4477.63
4498.5
4567.04
4568.76
4574.26
4578.42
4634.78
4724.17
4819.87
4896.01
4974.33
4995.44
5012.76
5043.5
5069.1
5186.65
5326.17
5469.71
5667.04
5856.6
6073.55
6094.19
5913.3
5702.12
5500.18
5398.43
5265.78
5186.7
5116.47
4977.4
4670.55
4339.78
4036.3
3863.72
3727.85
3631.17
3606.81
3564.6
3532.08
3478.37
3417.32
3374.85
3316.29
3256.14
3224.94
3159.62
3140.63
3101.43
3082.48
3036.02
2996.84
3000.63
2976.31
3029.75
3018.91
3015.13
3034.92
3033.42
3063.97
3037.33
3078.79
3081.01
3079.34
3114.18
3124.57
3177.53
3198.81
3209.86
3244.94
3272.73
3280.51
3281.23
3290.84
3299.63
3302.19
3314
3311.16
3266.95
3244.73
3286.64
3393.95
3511.72
3656.02
3824.99
4068.02
4413.12
4740.84
5091.05
5362.62
5526.96
5584.3
5508.01
5446.11
5418.15
5376.68
5310.29
4986.91
4199
3396.89
2735
2320.49
2103.76
2057.67
2060.52
2074.2
2101.57
2131.08
2120.69
2113.22
2114.93
2112.21
2083.08
2040.47
1920.88
1755.92
1568.38
1429.52
1342.95
1288.64
1286.34
1280.25
1262.69
1260.31
1269.52
1264.35
1273.16
1283.2
1288.16
1289.74
1289.58
1312.49
1301.76
1314.23
1312.48
1303.1
1323.15
1315.41
1301.36
1284.99
1273.76
1293.94
1280.2
1297.18
1304.93
1299.08
1316.75
1316.88
1318.9
1309.67
1302.02
1308.75
1339.52
1344.72
1344.82
1370.9
1378.01
1365.8
1380.13
1400.35
1414.66
1398.15
1408.31
1405.45
1409.67
1412.83
1401.55
1393.11
1390.27
1386.94
1380.41
1371.55
1389.29
1378.9
1409.85
1415.64
1407.85
1452.31
1528.79
1611.36
1664.68
1672.05
1662.66
1590.69
1532.5
1460.07
1383.09
1344.18
1309.58
1277.99
1238.45
1208.18
1164.01
1129.89
1122.99
1121.67
1140.17
1151.8
1183.21
1208.42
1380.78
1956.98
2913.88
5322.25
7324.81
5226.63
1954.43
940.425
816.164
769.064
736.149
720.011
701.738
697.545
701.608
690.702
705.456
697.18
694.829
696.982
704.108
712
703.255
697.268
696.925
709.297
698.52
715.722
720.206
716.118
707.139
717.705
711.35
718.167
730.517
721.728
724.488
719.301
726.153
733.755
722.522
732.365
715.112
727.826
739.328
728
736.22
745.243
728.554
731.632
721.406
730.498
731.608
721.588
725.628
728.005
720.147
716.423
716.687
713.903
725.373
734.745
734.113
710.127
721.402
718.429
719.51
721.132
737.813
744.331
743.334
729.244
713.1
726.588
739.692
750.751
743.825
746.918
741.197
739.457
750.578
752.115
749.849
749.382
733.73
743.288
737.595
745.352
743.333
761.396
758.023
756.455
761.295
764.493
759.365
771.654
764.946
767.999
762.122
762.924
754.64
758.315
765.549
778.438
783.729
770.226
761.526
776.309
766.248
769.095
754.867
767.356
784.184
773.375
773.132
774.916
781.444
781.069
775.802
777.115
797.646
784.817
794.41
787.571
777.719
787.926
783.271
782.715
796.973
786.374
795.997
811.175
813.764
812.448
814.551
821.97
796.406
783.831
797.167
807.338
807.089
810.011
808.723
818.338
817.054
809.987
805.25
814.416
815.932
805.614
804.71
816.236
832.541
819.279
825.772
816.891
834.013
825.913
821.82
841.664
832.787
828.09
827.77
827.037
834.002
843.945
841.942
855.12
833.547
843.862
837.676
849.768
854.17
841.002
854.087
847.188
851.61
856.987
862.841
838.116
844.542
850.48
858.303
860.993
868.454
865.319
868.033
866.687
868.955
856.685
870.584
857.714
870.206
866.414
861.032
881.763
883.296
882.138
880.352
895.288
898.316
898.509
890.4
895.565
903.997
884.368
885.731
904.22
887.722
895.54
908.124
906.799
914.203
926.679
916.173
909.866
927.99
901.978
920.768
930.311
918.204
924.014
920.659
897.054
913.861
930.868
907.821
930.919
934.626
927.104
926.88
925.493
929.369
924.559
930.611
934.36
930.286
930.487
935.106
946.058
938.313
940.168
943.382
951.895
992.445
1019.67
1047.79
1089.95
1167.8
1136.58
1023.4
958.776
955.592
931.931
950.466
954.055
963.687
947.114
957.686
954.116
947.817
973.328
963.506
970.971
973.52
986.337
968.219
958.897
962.837
945.974
948.943
955.224
962.326
957.54
963.175
967.575
958.598
955.56
989.779
980.461
981.292
979.398
975.858
989.377
987.058
986.16
981.207
992.699
1006.08
1018.89
1017.61
1012.58
1013.65
1000.95
998.119
1001.86
1010.2
1000.68
987.901
1020.67
1015.63
1015.38
1032.51
1006.04
1012.23
1010.75
1025.55
1031.5
1013.03
1010.17
1015.87
1034.2
1031.17
1046.8
1022.41
1009.55
1032.76
1042.49
1035.22
1040.15
1046.22
1046.93
1053.82
1058.52
1035.96
1042.97
1075.18
1061.79
1057.87
1058.95
1050.92
1062.84
1061.9
1081.95
1102.83
1081.02
1102.97
1081.5
1090.27
1070.06
1063.03
1077.54
1087.56
1098.47
1090.54
1094.66
1087.9
1105.68
1099.17
1102.82
1098.87
1113.69
1120.64
1119.77
1111.16
1128.65
1124.02
1117.38
1125.24
1115.88
1103.24
1127.41
1134.96
1141.09
1167.62
1163.62
1155.58
1165.11
1148.69
1139.72
1158.65
1161.57
1170.8
1168.72
1174.58
1164.49
1179.63
1201.78
1202.6
1208.38
1194.76
1199.77
1213.39
1203.8
1211.23
1221.66
1223.97
1254.05
1263.45
1271
1284.6
1257.7
1274.82
1271.65
1290.99
1273.88
1278.87
1268.07
1261.29
1251.33
1247.48
1252.28
1233.69
1228.34
1205.66
1208.7
1216.94
1237.53
1272.78
1288.24
1357.41
1433.76
1485.04
1567.13
1626.97
1720.68
1765.32
1790.18
1834.49
1933.84
2036.39
2139.18
2115.92
1883.42
1546.72
1309.04
1200.99
1160.16
1145.19
1153.02
1136.32
1142.1
1116.72
1103.12
1106.85
1100.83
1103.88
1124.49
1126.1
1113.08
1143.98
1157.87
1165.11
1206.91
1277.55
1302.46
1307.37
1259.49
1172.56
1133.06
1146.34
1180.55
1255.5
1312.11
1341.44
1373.93
1408.47
1483
1590.4
1747.35
1914.32
2017.25
2096.42
2222.83
2528.25
3042.19
3391.35
3000.78
1889.98
954.421
579.678
445.673
378.375
354.962
327.769
301.981
293.522
287.522
285.518
279.335
278.646
284.288
278.819
284.827
274.183
279.482
284.299
290.818
292.004
293.747
285.498
299.033
296.779
286.788
280.83
275.047
268.241
261.528
261.741
269.176
278.56
267.367
276.127
282.496
301.322
298.05
304.167
315.94
333.644
347.716
381.91
455.808
493.779
446.211
342.186
250.005
203.821
189.457
188.821
209.897
240.697
294.353
377.599
480.549
555.99
578.498
560.868
564.034
589.111
675.989
843.075
1035.45
905.206
453.062
106.868
1
Ni2p
NiO
2021
4
29
23
29
30
0
17
Casa Info Follows
0
0
0
0
File = E:/OwnCloud/XPS lab/EX492_S776_Ni Oxidation.sle
Group = RT in vacuum, #Treatments: , #Temp:RT , #Pressure:vacuum , #Atmosphere:, #Comments:
First of group = 0
Spectrum ID = 20
Analyzer lens = AngleResolvedMode22:1.5kV
Analyzer slit = 4:7x20c\C:mesh
Scan mode = FixedAnalyzerTransmission
Kinetic energy start = 596.61
PCA Coefs = 135146, 22871.4, -962.346, 884.156, -199.619,
C:\Users\Mark\Downloads\EX492_S776_Ni Oxidation.vms
c:\users\mark\downloads\ex492_ni references.vms
C:\Users\pielsticker\Lukas\MPI-CEC\Projects\deepxps\xpsdeeplearning\data\references\NiCoFe\EX491-495 Fe, Ni, Co oxide references.vms
XPS
14
Al
1486.61
0
0
0
54.5
180
FAT
20
1
4.1408
0
0
0
0
0
Ni
2p
-1
kinetic energy
eV
596.61
0.1
2
counts
d
Transmission
d
pulse counting
0.1
3
0
0
0
0
2
ESCAPE DEPTH TYPE
d
1
MFP Exponent
d
0
1002
3223.86
12109.2
1
1
5414.88
1
5405.62
1
5374.87
1
5370.56
1
5355.25
1
5348.96
1
5333.13
1
5347.02
1
5388.81
1
5377.63
1
5380.12
1
5308.46
1
5352.28
1
5333.11
1
5341.6
1
5366.67
1
5315.82
1
5321.27
1
5296.23
1
5310.11
1
5343.29
1
5336.14
1
5308.48
1
5300.28
1
5332.6
1
5345.76
1
5345.57
1
5320.6
1
5305.24
1
5308.07
1
5319.57
1
5316.68
1
5377.35
1
5355.33
1
5354.05
1
5327.17
1
5360.24
1
5354.78
1
5322.74
1
5316.97
1
5351.37
1
5388.86
1
5332.51
1
5330.32
1
5341.09
1
5370.67
1
5450.75
1
5453.63
1
5432.88
1
5469.56
1
5484.82
1
5478.29
1
5539.09
1
5531.07
1
5546.63
1
5595.22
1
5593.53
1
5609.36
1
5688.64
1
5669.05
1
5715.19
1
5755.02
1
5804.86
1
5800.21
1
5869.68
1
5923.83
1
5947.94
1
5984.71
1
5989.83
1
6021.77
1
6083.71
1
6066.97
1
6116.08
1
6107.11
1
6196.66
1
6206.61
1
6245.59
1
6264.98
1
6359.98
1
6412.38
1
6486.75
1
6525.82
1
6602.39
1
6660.56
1
6749.95
1
6775.82
1
6869.34
1
6945.31
1
7004.53
1
6992.89
1
6996.65
1
7000.77
1
7060.25
1
7062.32
1
7112.42
1
7104.6
1
7090.83
1
7103.44
1
7143.81
1
7168.15
1
7160.08
1
7159.99
1
7216.34
1
7189.66
1
7216.64
1
7207.49
1
7211.35
1
7189.56
1
7187.85
1
7170.74
1
7192.74
1
7162.79
1
7125.21
1
7084.41
1
7085.86
1
7072.12
1
7043.44
1
7014.84
1
7022.15
1
6923.8
1
6934.83
1
6922.58
1
6847.17
1
6847.36
1
6807.09
1
6750.18
1
6731.01
1
6712.7
1
6655.4
1
6662.97
1
6649.34
1
6572.41
1
6532.41
1
6548.26
1
6543.03
1
6485.75
1
6503.62
1
6478.8
1
6481.3
1
6451.05
1
6438.54
1
6421.2
1
6413.33
1
6433.37
1
6408.89
1
6428.84
1
6429.25
1
6441.99
1
6487.83
1
6522.23
1
6522.64
1
6530.09
1
6561.45
1
6591.16
1
6683.59
1
6739.36
1
6777.81
1
6841.87
1
6864.02
1
6888.04
1
7016.48
1
7037.08
1
7077.98
1
7164.51
1
7199.9
1
7233.01
1
7272.53
1
7314.5
1
7363.88
1
7408.56
1
7433.48
1
7452.5
1
7479.31
1
7498.47
1
7526.23
1
7522
1
7509.14
1
7514.94
1
7558.77
1
7567.51
1
7545.29
1
7514.02
1
7458.91
1
7505.07
1
7504.02
1
7545.99
1
7549.67
1
7495.49
1
7467.74
1
7413.97
1
7368.88
1
7237.47
1
7037.76
1
6849.03
1
6649.27
1
6351.56
1
6078.15
1
5820.72
1
5613.1
1
5423.9
1
5269.05
1
5110.33
1
5004.7
1
4930.43
1
4879.71
1
4797.94
1
4785.82
1
4736.56
1
4717.82
1
4741.18
1
4724.19
1
4728.32
1
4756.73
1
4794.73
1
4784.77
1
4841.57
1
4871.84
1
4922.31
1
4965.95
1
5011.7
1
5046.86
1
5072.93
1
5117.41
1
5117.17
1
5162.28
1
5183.2
1
5256.83
1
5284.78
1
5257.98
1
5295.62
1
5354.55
1
5358.49
1
5399.74
1
5438.89
1
5491.98
1
5514.2
1
5559.69
1
5588.56
1
5586.78
1
5563.7
1
5582.27
1
5552.81
1
5542.23
1
5516.92
1
5543.51
1
5565.52
1
5569.92
1
5608.85
1
5682.84
1
5676.95
1
5740.99
1
5746.65
1
5824.15
1
5935.46
1
5964.53
1
6077.11
1
6102.77
1
6163.01
1
6202.23
1
6308.51
1
6342.35
1
6357.23
1
6407.73
1
6455.29
1
6508.24
1
6531.16
1
6569.17
1
6670.93
1
6712.75
1
6749.68
1
6804.8
1
6870.22
1
6913.2
1
7009.71
1
7128.07
1
7202.46
1
7271.39
1
7376.21
1
7480.22
1
7619.24
1
7624.01
1
7758.52
1
7857.26
1
7925.13
1
8014.32
1
8064.85
1
8172.34
1
8270.76
1
8296.69
1
8297.53
1
8292.39
1
8236.96
1
8254.89
1
8177.83
1
8117.89
1
8064.36
1
7964.17
1
7918.73
1
7756.55
1
7654.17
1
7650.88
1
7523.45
1
7425.16
1
7311.05
1
7218.78
1
7069.26
1
6942.26
1
6870.42
1
6761.38
1
6690.7
1
6567.77
1
6479.25
1
6417.09
1
6404.18
1
6311.91
1
6323.48
1
6286.94
1
6332.76
1
6281.78
1
6262.05
1
6353.27
1
6399.16
1
6430.13
1
6488.69
1
6562.74
1
6718.8
1
6835.04
1
6909.32
1
7083.59
1
7219.26
1
7433.08
1
7656.56
1
7817.59
1
8005.22
1
8186.25
1
8396.19
1
8569.5
1
8764.13
1
8963.79
1
9067.84
1
9185.75
1
9344.87
1
9378.33
1
9373.15
1
9402.9
1
9316.69
1
9214.51
1
9165.07
1
9133.21
1
9101.02
1
9106.64
1
9161.45
1
9201.65
1
9367.23
1
9555.46
1
9779.3
1
10026.7
1
10388
1
10821.8
1
11195.3
1
11634.6
1
11924.4
1
12085.8
1
11908
1
11483.2
1
10774
1
9858.13
1
8784.28
1
7741.67
1
6788.31
1
6038.31
1
5443.7
1
5031.78
1
4706.17
1
4422.91
1
4239.59
1
4067.76
1
3973.73
1
3918.02
1
3823.29
1
3743.67
1
3700.26
1
3646.11
1
3624
1
3594.98
1
3583.18
1
3574.2
1
3549.34
1
3506.26
1
3476.88
1
3457.86
1
3466.86
1
3464.39
1
3452.03
1
3426.78
1
3451.6
1
3443.72
1
3410.76
1
3418.11
1
3407.97
1
3404.37
1
3443.6
1
3430.9
1
3409.56
1
3405.78
1
3358.1
1
3387.29
1
3361.71
1
3373.91
1
3369.59
1
3343.36
1
3356.37
1
3353.38
1
3371.93
1
3369.76
1
3352.66
1
3365.3
1
3349.52
1
3315
1
3320.93
1
3332.88
1
3344.66
1
3343.83
1
3368.99
1
3322.01
1
3327.87
1
3329.08
1
3333.07
1
3314.84
1
3319.48
1
3348.68
1
3342.65
1
3335.36
1
3335.73
1
3325.45
1
3334.97
1
3337.72
1
3322.92
1
3322
1
3339.08
1
3333.72
1
3320.4
1
3329.95
1
3318.59
1
3308.25
1
3337.63
1
3312.4
1
3312.73
1
3346.89
1
3353.7
1
3339.35
1
3321.95
1
3322.12
1
3334.9
1
3333.22
1
3308.42
1
3318.55
1
3320.12
1
3322.55
1
3337.65
1
3301.81
1
3328.31
1
3331.75
1
3327.8
1
3333.99
1
3310.91
1
3298.38
1
3327.25
1
3306.58
1
3329.73
1
3317.17
1
3329.46
1
3366.01
1
3327.92
1
3319.81
1
3330.82
1
3311.83
1
3327.07
1
3324.16
1
3306.88
1
3300.95
1
3288.7
1
3304.94
1
3319.94
1
3348.09
1
3348.03
1
3326.59
1
3334.39
1
3337.95
1
3323.56
1
3348.58
1
3339.43
1
3345.49
1
3341.26
1
3346.39
1
3344.39
1
3314.26
1
3373.9
1
3358.16
1
3334.45
1
3362.27
1
end of experiment