File: src/xpsdeeplearning/data/references/Ti_references_irregular.vms
VAMAS Surface Chemical Analysis Standard Data Transfer Format 1988 May 4
Not Specified
Not Specified
Not Specified
Not Specified
8
Casa Info Follows CasaXPS Version 2.3.25PR1.0
0
Created by SpecsLab Prodigy, Version 4.55.1-r82379
SourceAnalyserAngle: 56.500000 d
CasaRowLabel:Ti metal
CasaRowLabel:TiO
CasaRowLabel:Ti2O3
CasaRowLabel:TiO2
NORM
IRREGULAR
3
1
Exp Variable
d
0
0
0
0
12
Ti2p
Ti metal
0
0
0
0
0
0
0
12
Casa Info Follows
0
0
0
0

PCA Coefs = 54487.5, 23477.3, -4356.52, 108.165,
PCA Coefs = 54487.5, 23477.3, -4356.52, 108.165, -1011.67,
c:\users\mark\owncloud\muelheim group\projects\tio2\analyzed data\experiment 2019-03-28_ti sheet_cec-1303 - vector analysis.vms
C:\Users\pielsticker\Downloads\Ti\EX209_CEC303 Ti slow oxidation - vectro fit - irregular.vms
C:\Users\pielsticker\Downloads\Ti\references_irregular.vms
C:\Users\pielsticker\Lukas\MPI-CEC\Projects\deepxps\xpsdeeplearning\data\references\Ti_references_irregular.vms
XPS
1e+037
Al
1486.61
1e+037
1e+037
1e+037
1e+037
1e+037
FAT
1e+037
1e+037
1e+037
1e+037
1e+037
1e+037
1e+037
1e+037
Ti
2p
-1
3
Kinetic Energy
eV
Intensity
d
transmission
d
pulse counting
1
1
1e+037
1e+037
1e+037
1e+037
3
MFP Exponent
d
0
ESCAPE DEPTH TYPE
d
1
PROPAGATION_CONVERGED
d
1
0
0
0
986.61
1
1379.61
986.81
1
1357.98
987.01
1
1338.23
987.21
1
1369.8
987.41
1
1326.81
987.61
1
1297.46
987.81
1
1417.54
988.01
1
1338.43
988.21
1
1331.1
988.41
1
1352.87
988.61
1
1322.33
988.81
1
1337.25
989.01
1
1331.42
989.21
1
1367.73
989.41
1
1331.19
989.61
1
1354.37
989.81
1
1414.58
990.01
1
1329.94
990.21
1
1299.66
990.41
1
1336.35
990.61
1
1329.05
990.81
1
1275.77
991.01
1
1391.23
991.21
1
1408.94
991.41
1
1311.37
991.61
1
1357.91
991.81
1
1318.21
992.01
1
1390.02
992.21
1
1376.27
992.41
1
1384.67
992.61
1
1345.15
992.81
1
1365.75
993.01
1
1363.56
993.21
1
1339.81
993.41
1
1325.31
993.61
1
1382.03
993.81
1
1311.58
994.01
1
1378.17
994.21
1
1438.27
994.41
1
1371.09
994.61
1
1391.69
994.81
1
1386.57
995.01
1
1321.43
995.21
1
1438.72
995.41
1
1401.62
995.61
1
1412.13
995.81
1
1360.03
996.01
1
1377.03
996.21
1
1442.57
996.41
1
1292.64
996.61
1
1394.63
996.81
1
1497.62
997.01
1
1444.74
997.21
1
1449.53
997.41
1
1436.63
997.61
1
1452.47
997.81
1
1365.02
998.01
1
1477.99
998.21
1
1349.93
998.41
1
1442.93
998.61
1
1425.03
998.81
1
1417.89
999.01
1
1357.04
999.21
1
1451.86
999.41
1
1447.06
999.61
1
1420.74
999.81
1
1469.79
1000.01
1
1469.51
1000.21
1
1474.49
1000.41
1
1499.16
1000.61
1
1501.69
1000.81
1
1424.29
1001.01
1
1439.25
1001.21
1
1449.63
1001.41
1
1516.59
1001.61
1
1446.03
1001.81
1
1482.6
1002.01
1
1464.51
1002.21
1
1599.73
1002.41
1
1464.08
1002.61
1
1491.64
1002.81
1
1493.78
1003.01
1
1562.09
1003.21
1
1533.6
1003.41
1
1515.64
1003.61
1
1584.04
1003.81
1
1498.88
1004.01
1
1576.33
1004.21
1
1589.92
1004.41
1
1571.07
1004.61
1
1641.64
1004.81
1
1545.26
1005.01
1
1642.09
1005.21
1
1587.97
1005.41
1
1622.77
1005.61
1
1685.78
1005.81
1
1667.52
1006.01
1
1692.51
1006.21
1
1741.68
1006.41
1
1597.06
1006.61
1
1670.17
1006.81
1
1620.58
1007.01
1
1653.77
1007.21
1
1772.5
1007.41
1
1777.14
1007.61
1
1707.44
1007.81
1
1823.56
1008.01
1
1798.18
1008.21
1
1712.2
1008.41
1
1786.61
1008.61
1
1800.84
1008.81
1
1794.35
1009.01
1
1746.38
1009.21
1
1744.82
1009.41
1
1879.87
1009.61
1
1876.88
1009.81
1
1811.09
1010.01
1
1720.69
1010.21
1
1845.77
1010.41
1
1887.68
1010.61
1
1897.2
1010.81
1
1882.49
1011.01
1
1869.6
1011.21
1
1872.84
1011.41
1
1754.08
1011.61
1
1836.8
1011.81
1
1916.85
1012.01
1
1946.96
1012.21
1
1901.22
1012.41
1
1873.84
1012.61
1
1919.9
1012.81
1
1933.45
1013.01
1
1825.82
1013.21
1
1934.56
1013.41
1
1848.74
1013.61
1
2018.38
1013.81
1
1920.36
1014.01
1
1984.06
1014.21
1
1948.81
1014.41
1
1951.41
1014.61
1
1969.69
1014.81
1
1991.82
1015.01
1
1909.56
1015.21
1
1955.57
1015.41
1
1852.58
1015.61
1
1933.49
1015.66
1
1965.15
1015.71
1
1971.51
1015.81
1
1768.22
1015.86
1
1933.58
1015.91
1
1956.42
1016.01
1
1869.75
1016.06
1
1938.97
1016.11
1
1999.16
1016.21
1
1929.9
1016.26
1
1848.81
1016.31
1
1938.1
1016.41
1
1808.37
1016.46
1
1823.87
1016.51
1
1940.62
1016.61
1
1812.92
1016.66
1
1895.27
1016.76
1
1942.68
1016.86
1
1882.81
1016.96
1
1901.64
1017.06
1
1889.43
1017.16
1
1926.96
1017.26
1
1844.52
1017.36
1
1863.37
1017.46
1
1887.82
1017.56
1
1912.49
1017.66
1
1966.08
1017.76
1
1876.22
1017.86
1
1906.06
1017.96
1
1950.47
1018.06
1
1766.07
1018.16
1
1838.78
1018.26
1
1809.91
1018.36
1
1828.37
1018.46
1
1836.04
1018.56
1
1865.96
1018.66
1
1796.13
1018.76
1
1805.1
1018.86
1
1837.8
1018.96
1
1816.02
1019.06
1
1846.53
1019.16
1
1816.55
1019.26
1
1751.26
1019.36
1
1833.22
1019.46
1
1794.61
1019.56
1
1772.53
1019.66
1
1816.7
1019.76
1
1753.41
1019.86
1
1781.79
1019.96
1
1744.31
1020.06
1
1709.92
1020.16
1
1729.59
1020.26
1
1661.76
1020.36
1
1691.15
1020.46
1
1641.03
1020.56
1
1685.23
1020.66
1
1743.33
1020.76
1
1641.08
1020.86
1
1642.85
1020.96
1
1642.46
1021.06
1
1655.18
1021.16
1
1677.89
1021.26
1
1575.95
1021.36
1
1637.82
1021.46
1
1624.47
1021.56
1
1617.64
1021.66
1
1601.39
1021.76
1
1634.78
1021.86
1
1529.38
1021.96
1
1631.87
1022.06
1
1609.53
1022.16
1
1618.58
1022.26
1
1611.16
1022.36
1
1555.75
1022.46
1
1596.04
1022.56
1
1625.18
1022.66
1
1559.8
1022.76
1
1603
1022.86
1
1614.94
1022.96
1
1646.62
1023.06
1
1574.2
1023.16
1
1616.84
1023.26
1
1681.81
1023.36
1
1643.74
1023.46
1
1685.63
1023.56
1
1709.65
1023.66
1
1678.15
1023.76
1
1734.06
1023.86
1
1749.23
1023.96
1
1678.21
1024.06
1
1667.25
1024.16
1
1737.96
1024.26
1
1784.91
1024.36
1
1847.48
1024.46
1
1841.84
1024.56
1
1880.13
1024.66
1
1958.79
1024.76
1
1929.9
1024.86
1
2011.96
1024.96
1
1956.88
1025.06
1
1984.67
1025.16
1
2056.17
1025.26
1
2070.19
1025.36
1
2115.4
1025.46
1
2320.48
1025.56
1
2379.47
1025.66
1
2474.45
1025.76
1
2593.62
1025.86
1
2727.02
1025.96
1
2860.44
1026.06
1
3137.41
1026.16
1
3305.52
1026.26
1
3530.05
1026.36
1
3658.58
1026.46
1
3966.76
1026.56
1
4079.39
1026.66
1
4028.53
1026.76
1
3963.71
1026.86
1
3698.38
1026.96
1
3422.72
1027.06
1
3153.17
1027.16
1
2829.88
1027.26
1
2474.68
1027.36
1
2254.55
1027.46
1
2031.41
1027.56
1
1832.39
1027.66
1
1626.62
1027.76
1
1630.39
1027.86
1
1470.7
1027.96
1
1361.87
1028.06
1
1325.99
1028.16
1
1338
1028.26
1
1321.05
1028.36
1
1233.07
1028.46
1
1236.26
1028.56
1
1202.57
1028.66
1
1188.95
1028.76
1
1213.76
1028.86
1
1218.24
1028.96
1
1264.76
1029.06
1
1216.39
1029.16
1
1290.32
1029.26
1
1207.88
1029.36
1
1256.9
1029.46
1
1235.28
1029.56
1
1330.8
1029.66
1
1324.2
1029.76
1
1308.33
1029.86
1
1324.21
1029.96
1
1352.92
1030.06
1
1373.89
1030.16
1
1426.87
1030.26
1
1499.48
1030.36
1
1526.2
1030.46
1
1530.68
1030.56
1
1578.27
1030.66
1
1658.45
1030.76
1
1707.29
1030.86
1
1789.62
1030.96
1
1794.29
1031.06
1
1842.23
1031.16
1
1996.49
1031.26
1
2098.6
1031.36
1
2191.78
1031.46
1
2365.36
1031.56
1
2539.57
1031.66
1
2578.6
1031.76
1
2917.59
1031.86
1
3160.55
1031.96
1
3381.58
1032.06
1
3778.39
1032.16
1
4160
1032.26
1
4784.78
1032.36
1
5563.98
1032.46
1
6216.12
1032.56
1
6849.11
1032.66
1
7348.28
1032.76
1
7540.43
1032.86
1
7300.02
1032.96
1
6650.6
1033.06
1
5814.3
1033.16
1
4719.32
1033.26
1
3539.61
1033.36
1
2604.1
1033.46
1
1789.26
1033.56
1
1208.84
1033.66
1
840.511
1033.76
1
639.592
1033.86
1
442.715
1033.96
1
325.708
1034.06
1
273.502
1034.16
1
224.698
1034.26
1
189.398
1034.36
1
145.057
1034.46
1
171.61
1034.56
1
126.164
1034.66
1
98.7856
1034.76
1
102.57
1034.86
1
102.569
1034.96
1
86.0091
1035.06
1
65.2265
1035.16
1
81.7472
1035.26
1
72.9072
1035.36
1
54.6963
1035.46
1
51.4427
1035.56
1
27.7958
1035.66
1
47.0201
1035.76
1
31.6776
1035.86
1
39.7689
1035.96
1
46.7088
1036.06
1
21.9353
1036.16
1
24.5338
1036.26
1
32.2861
1036.36
1
16.5913
1036.46
1
33.4338
1036.56
1
-0.320683
1036.66
1
1.25567
1036.76
1
17.9205
1036.86
1
25.6579
1036.96
1
4.06964
1037.06
1
-0.175084
1037.16
1
-11.2699
1037.26
1
-6.23708
1037.36
1
-0.235253
1037.46
1
10.0545
1037.56
1
-5.57347
1037.66
1
-10.6555
1037.76
1
1.42326
1037.86
1
-15.8064
1037.96
1
-3.04375
1038.06
1
19.9889
1038.16
1
-3.13742
1038.26
1
-9.16297
1038.36
1
-16.0218
1038.46
1
-21.0405
1038.56
1
4.97534
1038.66
1
-15.0884
1038.76
1
16.2773
1038.86
1
-0.530202
1038.96
1
-7.12591
1039.06
1
-11.6532
1039.16
1
7.07497
1039.26
1
-12.9418
1039.36
1
-22.8096
1039.46
1
-17.3984
1039.56
1
-8.62249
1039.66
1
-3.7872
1039.76
1
-12.3709
1039.86
1
-13.1936
1039.96
1
-37.2227
1040.06
1
3.24155
1040.16
1
0
1040.26
1
0
1040.36
1
0
1040.46
1
0
1040.56
1
0
1
Ti2p
TiO
0
0
0
0
0
0
0
14
Casa Info Follows
0
0
0
0

PCA Coefs = 41396.7, -3191.99, 1103.12, 387.504,
PCA Coefs = 41396.7, -3191.99, 1103.12, 387.504, -363.953,
PCA Coefs = 41439, -2585.94, 1104.79, -371.422, -359.987, 128.966,
c:\users\mark\owncloud\muelheim group\projects\tio2\analyzed data\experiment 2019-03-28_ti sheet_cec-1303 - vector analysis.vms
c:\users\mark\owncloud\muelheim group\projects\tio2\analyzed data\experiment 2019-03-28_ti sheet_cec-1303 - vector analysis.vms
C:\Users\pielsticker\Downloads\Ti\EX209_CEC303 Ti slow oxidation - vectro fit - irregular.vms
C:\Users\pielsticker\Downloads\Ti\references_irregular.vms
C:\Users\pielsticker\Lukas\MPI-CEC\Projects\deepxps\xpsdeeplearning\data\references\Ti_references_irregular.vms
XPS
1e+037
Al
1486.61
1e+037
1e+037
1e+037
1e+037
1e+037
FAT
1e+037
1e+037
1e+037
1e+037
1e+037
1e+037
1e+037
1e+037
Ti
2p
-1
3
Kinetic Energy
eV
Intensity
d
transmission
d
pulse counting
1
1
1e+037
1e+037
1e+037
1e+037
3
MFP Exponent
d
0
ESCAPE DEPTH TYPE
d
1
PROPAGATION_CONVERGED
d
1
0
0
0
986.61
1
0
986.81
1
0
987.01
1
0
987.21
1
0
987.41
1
418.506
987.61
1
440.148
987.81
1
430.838
988.01
1
424.025
988.21
1
418.792
988.41
1
454.731
988.61
1
440.084
988.81
1
432.304
989.01
1
446.848
989.21
1
427.43
989.41
1
424.875
989.61
1
420.255
989.81
1
437.574
990.01
1
437.73
990.21
1
412.513
990.41
1
431.311
990.61
1
433.572
990.81
1
409.864
991.01
1
426.173
991.21
1
414.74
991.41
1
426.44
991.61
1
419.722
991.81
1
436.796
992.01
1
430.264
992.21
1
408.522
992.41
1
445.551
992.61
1
442.301
992.81
1
427.755
993.01
1
456.361
993.21
1
450.223
993.41
1
436.61
993.61
1
448.84
993.81
1
447.565
994.01
1
431.631
994.21
1
439.397
994.41
1
436.637
994.61
1
439.383
994.81
1
437.081
995.01
1
441.987
995.21
1
435.758
995.41
1
440.249
995.61
1
470.201
995.81
1
465.133
996.01
1
452.422
996.21
1
465.086
996.41
1
459.164
996.61
1
449.258
996.81
1
458.529
997.01
1
477.211
997.21
1
460.033
997.41
1
445.237
997.61
1
462.703
997.81
1
451.872
998.01
1
469.161
998.21
1
475.462
998.41
1
456.623
998.61
1
480.575
998.81
1
476.11
999.01
1
488.889
999.21
1
473.36
999.41
1
489.987
999.61
1
499.989
999.81
1
503.847
1000.01
1
472.305
1000.21
1
470.454
1000.41
1
470.1
1000.61
1
488.566
1000.81
1
487.255
1001.01
1
485.732
1001.21
1
498.971
1001.41
1
495.287
1001.61
1
515.751
1001.81
1
521.562
1002.01
1
520.4
1002.21
1
510.643
1002.41
1
516.99
1002.61
1
511.597
1002.81
1
518.202
1003.01
1
525.184
1003.21
1
517.622
1003.41
1
508.334
1003.61
1
520.695
1003.81
1
529.331
1004.01
1
532.939
1004.21
1
527.727
1004.41
1
533.308
1004.61
1
544.611
1004.81
1
532.448
1005.01
1
563.09
1005.21
1
542.99
1005.41
1
545.665
1005.61
1
526.3
1005.81
1
572.365
1006.01
1
549.727
1006.21
1
548.66
1006.41
1
563.665
1006.61
1
577.334
1006.81
1
553.853
1007.01
1
584.367
1007.21
1
565.461
1007.41
1
562.378
1007.61
1
558.304
1007.81
1
548.855
1008.01
1
587.028
1008.21
1
582.535
1008.41
1
570.811
1008.61
1
573.391
1008.81
1
560.161
1009.01
1
597.167
1009.21
1
585.585
1009.41
1
580.41
1009.61
1
584.575
1009.81
1
563.558
1010.01
1
592.348
1010.21
1
591.048
1010.41
1
562.049
1010.61
1
613.504
1010.81
1
590.102
1011.01
1
597.336
1011.21
1
580.7
1011.41
1
612.752
1011.61
1
591.136
1011.81
1
581.801
1012.01
1
607.547
1012.21
1
616.005
1012.41
1
606.481
1012.61
1
611.253
1012.81
1
623.68
1013.01
1
618.895
1013.21
1
597.049
1013.41
1
595.137
1013.61
1
596.239
1013.81
1
584.361
1014.01
1
618.527
1014.21
1
606.433
1014.41
1
600.324
1014.61
1
577.321
1014.81
1
594.519
1015.01
1
603.592
1015.21
1
592.667
1015.41
1
598.124
1015.61
1
613.572
1015.66
1
596.493
1015.71
1
589.147
1015.81
1
588.693
1015.86
1
581.863
1015.91
1
590.761
1016.01
1
606.759
1016.06
1
596.144
1016.11
1
592.706
1016.21
1
598.696
1016.26
1
606.286
1016.31
1
599.476
1016.41
1
595.682
1016.46
1
597.099
1016.51
1
598.501
1016.61
1
605.691
1016.66
1
593.859
1016.76
1
596.403
1016.86
1
594.915
1016.96
1
587.636
1017.06
1
606.761
1017.16
1
607.689
1017.26
1
604.424
1017.36
1
596.921
1017.46
1
596.989
1017.56
1
630.31
1017.66
1
607.099
1017.76
1
587.203
1017.86
1
605.75
1017.96
1
625.619
1018.06
1
605.926
1018.16
1
625.144
1018.26
1
627.313
1018.36
1
632.086
1018.46
1
633.444
1018.56
1
644.948
1018.66
1
636.764
1018.76
1
641.379
1018.86
1
637.855
1018.96
1
636.099
1019.06
1
652.623
1019.16
1
641.447
1019.26
1
632.682
1019.36
1
663.565
1019.46
1
635.212
1019.56
1
660.336
1019.66
1
633.939
1019.76
1
654.36
1019.86
1
664.706
1019.96
1
659.696
1020.06
1
657.005
1020.16
1
639.889
1020.26
1
647.107
1020.36
1
650.887
1020.46
1
650.078
1020.56
1
647.973
1020.66
1
642.48
1020.76
1
641.294
1020.86
1
621.76
1020.96
1
633.689
1021.06
1
641.391
1021.16
1
642.629
1021.26
1
625.183
1021.36
1
597.361
1021.46
1
611.948
1021.56
1
603.574
1021.66
1
611.698
1021.76
1
606.544
1021.86
1
598.509
1021.96
1
611.599
1022.06
1
613.523
1022.16
1
590.066
1022.26
1
606.824
1022.36
1
613.648
1022.46
1
630.209
1022.56
1
631.426
1022.66
1
616.234
1022.76
1
617.276
1022.86
1
612.854
1022.96
1
619.12
1023.06
1
616.27
1023.16
1
630.329
1023.26
1
642.111
1023.36
1
661.154
1023.46
1
649.041
1023.56
1
653.472
1023.66
1
672.917
1023.76
1
699.632
1023.86
1
722.662
1023.96
1
707.336
1024.06
1
724.502
1024.16
1
738.511
1024.26
1
762.687
1024.36
1
786.671
1024.46
1
843.475
1024.56
1
861.424
1024.66
1
917.206
1024.76
1
972.005
1024.86
1
1028.03
1024.96
1
1085.06
1025.06
1
1127.84
1025.16
1
1180.85
1025.26
1
1205.46
1025.36
1
1242.28
1025.46
1
1289.05
1025.56
1
1306.35
1025.66
1
1311.04
1025.76
1
1283.7
1025.86
1
1318.77
1025.96
1
1291.32
1026.06
1
1281.26
1026.16
1
1239.21
1026.26
1
1203.76
1026.36
1
1158.37
1026.46
1
1078.51
1026.56
1
1020.15
1026.66
1
928.974
1026.76
1
889.388
1026.86
1
824.393
1026.96
1
792
1027.06
1
714.097
1027.16
1
695.528
1027.26
1
685.561
1027.36
1
668.26
1027.46
1
631.47
1027.56
1
637.027
1027.66
1
640.778
1027.76
1
634.57
1027.86
1
618.156
1027.96
1
599.723
1028.06
1
629.057
1028.16
1
620.889
1028.26
1
629.837
1028.36
1
622.267
1028.46
1
620.128
1028.56
1
631.855
1028.66
1
614.635
1028.76
1
598.893
1028.86
1
628.933
1028.96
1
613.245
1029.06
1
626.144
1029.16
1
628.511
1029.26
1
627.299
1029.36
1
627.466
1029.46
1
638.279
1029.56
1
656.9
1029.66
1
664.871
1029.76
1
682.119
1029.86
1
691.803
1029.96
1
711.438
1030.06
1
722.547
1030.16
1
779.71
1030.26
1
818.387
1030.36
1
841.578
1030.46
1
869.894
1030.56
1
953.821
1030.66
1
1014.67
1030.76
1
1098.15
1030.86
1
1180.55
1030.96
1
1290.65
1031.06
1
1413.9
1031.16
1
1522.83
1031.26
1
1683.65
1031.36
1
1805.37
1031.46
1
1882.09
1031.56
1
1937.36
1031.66
1
1902.05
1031.76
1
1820.49
1031.86
1
1733.01
1031.96
1
1674.2
1032.06
1
1594.21
1032.16
1
1532.43
1032.26
1
1412.55
1032.36
1
1276.98
1032.46
1
1103.07
1032.56
1
898.867
1032.66
1
693.039
1032.76
1
524.306
1032.86
1
360.997
1032.96
1
265.384
1033.06
1
184.599
1033.16
1
146.727
1033.26
1
115.72
1033.36
1
84.3599
1033.46
1
73.258
1033.56
1
65.1807
1033.66
1
49.6746
1033.76
1
49.7747
1033.86
1
36.4411
1033.96
1
32.4556
1034.06
1
31.6081
1034.16
1
33.807
1034.26
1
29.7257
1034.36
1
21.9194
1034.46
1
30.7035
1034.56
1
21.3205
1034.66
1
23.786
1034.76
1
17.8064
1034.86
1
18.0522
1034.96
1
20.7355
1035.06
1
13.6358
1035.16
1
12.7428
1035.26
1
9.25257
1035.36
1
17.8825
1035.46
1
21.1059
1035.56
1
16.1824
1035.66
1
17.0204
1035.76
1
9.60597
1035.86
1
11.145
1035.96
1
12.7076
1036.06
1
16.3768
1036.16
1
9.75438
1036.26
1
6.69721
1036.36
1
7.37087
1036.46
1
5.21011
1036.56
1
8.72831
1036.66
1
3.6229
1036.76
1
3.17743
1036.86
1
1.47699
1036.96
1
9.76206
1037.06
1
5.90447
1037.16
1
5.99246
1037.26
1
3.90965
1037.36
1
5.08157
1037.46
1
6.53262
1037.56
1
6.63376
1037.66
1
4.39155
1037.76
1
0.0817091
1037.86
1
-0.488158
1037.96
1
3.97329
1038.06
1
1.92559
1038.16
1
5.79007
1038.26
1
2.19749
1038.36
1
-0.0809204
1038.46
1
4.7773
1038.56
1
8.75129
1038.66
1
3.21884
1038.76
1
-1.35327
1038.86
1
-1.81348
1038.96
1
1.8464
1039.06
1
3.18172
1039.16
1
1.00807
1039.26
1
0
1039.36
1
0
1039.46
1
0
1039.56
1
0
1039.66
1
0
1039.76
1
0
1039.86
1
0
1039.96
1
0
1040.06
1
0
1040.16
1
0
1040.26
1
0
1040.36
1
0
1040.46
1
0
1040.56
1
0
1
Ti2p
Ti2O3
0
0
0
0
0
0
0
13
Casa Info Follows
0
0
0
0

PCA Coefs = 179186, -26548.4, -22890.8, 3691.07, -1602.46, -1706.5,
C:\Users\Mark\ownCloud\Muelheim Group\Projects\TiO2\analyzed data\EX209_CEC303 Ti slow oxidation - curated - irregular.vms
c:\users\mark\owncloud\muelheim group\projects\tio2\analyzed data\experiment 2019-03-28_ti sheet_cec-1303 - vector analysis.vms
C:\Users\pielsticker\Downloads\Ti\EX209_CEC303 Ti slow oxidation - vectro fit - irregular.vms
CasaXP2
C:\Users\pielsticker\Downloads\Ti\references_irregular.vms
C:\Users\pielsticker\Lukas\MPI-CEC\Projects\deepxps\xpsdeeplearning\data\references\Ti_references_irregular.vms
XPS
1e+037
Al
1486.61
1e+037
1e+037
1e+037
1e+037
1e+037
FAT
1e+037
1e+037
1e+037
1e+037
1e+037
1e+037
1e+037
1e+037
Ti
2p
-1
3
Kinetic Energy
eV
Intensity
d
transmission
d
pulse counting
1
1
1e+037
1e+037
1e+037
1e+037
3
MFP Exponent
d
0
ESCAPE DEPTH TYPE
d
1
PROPAGATION_CONVERGED
d
1
0
0
0
986.61
1
0
986.81
1
0
987.01
1
2534.66
987.21
1
2540.32
987.41
1
2546.02
987.61
1
2551.71
987.81
1
2557.43
988.01
1
2563.15
988.21
1
2568.89
988.41
1
2574.65
988.61
1
2580.42
988.81
1
2586.21
989.01
1
2592.01
989.21
1
2597.83
989.41
1
2603.65
989.61
1
2609.5
989.81
1
2615.4
990.01
1
2621.8
990.21
1
2628.21
990.41
1
2634.65
990.61
1
2641.09
990.81
1
2647.56
991.01
1
2654.05
991.21
1
2660.55
991.41
1
2667.08
991.61
1
2673.62
991.81
1
2680.19
992.01
1
2686.76
992.21
1
2693.38
992.41
1
2699.99
992.61
1
2706.66
992.81
1
2713.33
993.01
1
2720.03
993.21
1
2726.96
993.41
1
2734.4
993.61
1
2741.86
993.81
1
2749.35
994.01
1
2756.86
994.21
1
2764.39
994.41
1
2771.96
994.61
1
2779.53
994.81
1
2787.17
995.01
1
2794.8
995.21
1
2802.49
995.41
1
2810.19
995.61
1
2817.92
995.81
1
2825.68
996.01
1
2833.46
996.21
1
2841.28
996.41
1
2849.12
996.61
1
2857.46
996.81
1
2866.23
997.01
1
2875.06
997.21
1
2883.9
997.41
1
2892.79
997.61
1
2901.69
997.81
1
2910.65
998.01
1
2919.62
998.21
1
2926.65
998.41
1
2935.73
998.61
1
2944.89
998.81
1
2954.15
999.01
1
2963.5
999.21
1
2972.97
999.41
1
2982.5
999.61
1
2992.17
999.81
1
3001.89
1000.01
1
3011.74
1000.21
1
3021.66
1000.41
1
3031.69
1000.61
1
3041.8
1000.81
1
3052.02
1001.01
1
3062.33
1001.21
1
3072.75
1001.41
1
3083.29
1001.61
1
3093.9
1001.81
1
3104.64
1002.01
1
3115.44
1002.21
1
3126.36
1002.41
1
3137.36
1002.61
1
3148.46
1002.81
1
3159.64
1003.01
1
3170.93
1003.21
1
3182.29
1003.41
1
3193.8
1003.61
1
3205.4
1003.81
1
3217.08
1004.01
1
3228.85
1004.21
1
3240.69
1004.41
1
3252.63
1004.61
1
3264.63
1004.81
1
3276.72
1005.01
1
3288.87
1005.21
1
3301.09
1005.41
1
3313.4
1005.61
1
3325.85
1005.81
1
3338.35
1006.01
1
3350.92
1006.21
1
3363.53
1006.41
1
3376.19
1006.61
1
3388.72
1006.81
1
3401.48
1007.01
1
3414.25
1007.21
1
3427.09
1007.41
1
3439.92
1007.61
1
3452.82
1007.81
1
3465.69
1008.01
1
3478.59
1008.21
1
3491.48
1008.41
1
3504.34
1008.61
1
3517.21
1008.81
1
3529.97
1009.01
1
3542.78
1009.21
1
3555.35
1009.41
1
3568.02
1009.61
1
3580.33
1009.81
1
3592.71
1010.01
1
3604.71
1010.21
1
3616.66
1010.41
1
3628.23
1010.61
1
3639.57
1010.81
1
3650.59
1011.01
1
3661.07
1011.21
1
3671.39
1011.41
1
3680.74
1011.61
1
3690.17
1011.81
1
3698.04
1012.01
1
3706.07
1012.21
1
3712.37
1012.41
1
3718.54
1012.61
1
3723.06
1012.81
1
3726.92
1013.01
1
3729.37
1013.21
1
3730.44
1013.41
1
3730.56
1013.61
1
3728.37
1013.81
1
3725.88
1014.01
1
3719.97
1014.21
1
3714.45
1014.41
1
3704.68
1014.61
1
3695.2
1014.81
1
3682.1
1015.01
1
3668.45
1015.21
1
3652.12
1015.41
1
3634.37
1015.61
1
3625.84
1015.66
1
3615.11
1015.71
1
3609.62
1015.81
1
3604.19
1015.86
1
3593.58
1015.91
1
3588.38
1016.01
1
3583.28
1016.06
1
3571.92
1016.11
1
3565.64
1016.21
1
3559.45
1016.26
1
3547.41
1016.31
1
3541.56
1016.41
1
3535.81
1016.46
1
3524.34
1016.51
1
3517.6
1016.61
1
3511.01
1016.66
1
3498.24
1016.76
1
3486.1
1016.86
1
3474.63
1016.96
1
3461.97
1017.06
1
3449.55
1017.16
1
3438.03
1017.26
1
3427.55
1017.36
1
3417.27
1017.46
1
3406.89
1017.56
1
3397.8
1017.66
1
3390.14
1017.76
1
3383.95
1017.86
1
3377.82
1017.96
1
3373.58
1018.06
1
3371.39
1018.16
1
3371.43
1018.26
1
3373
1018.36
1
3376.8
1018.46
1
3383.45
1018.56
1
3393.25
1018.66
1
3406.04
1018.76
1
3421.76
1018.86
1
3441.2
1018.96
1
3464.61
1019.06
1
3492.19
1019.16
1
3523.9
1019.26
1
3560.42
1019.36
1
3601.75
1019.46
1
3648.01
1019.56
1
3699.4
1019.66
1
3755.98
1019.76
1
3817.74
1019.86
1
3884.92
1019.96
1
3957.41
1020.06
1
4035.38
1020.16
1
4118.22
1020.26
1
4206.02
1020.36
1
4298.2
1020.46
1
4395.27
1020.56
1
4496.01
1020.66
1
4599.65
1020.76
1
4704.83
1020.86
1
4813.16
1020.96
1
4923.03
1021.06
1
5032.97
1021.16
1
5142.11
1021.26
1
5249.77
1021.36
1
5356.04
1021.46
1
5458.61
1021.56
1
5556.41
1021.66
1
5648.51
1021.76
1
5735.41
1021.86
1
5814.66
1021.96
1
5885.27
1022.06
1
5946.31
1022.16
1
5997.95
1022.26
1
6039.67
1022.36
1
6069.86
1022.46
1
6087.81
1022.56
1
6093.25
1022.66
1
6087.92
1022.76
1
6070.03
1022.86
1
6039.72
1022.96
1
5997.27
1023.06
1
5944.62
1023.16
1
5880.87
1023.26
1
5806.76
1023.36
1
5723.32
1023.46
1
5632.41
1023.56
1
5535.69
1023.66
1
5433.15
1023.76
1
5326.34
1023.86
1
5216.77
1023.96
1
5108.2
1024.06
1
5000.49
1024.16
1
4895.34
1024.26
1
4794.67
1024.36
1
4701.6
1024.46
1
4617.33
1024.56
1
4543.15
1024.66
1
4480.83
1024.76
1
4432.65
1024.86
1
4400.88
1024.96
1
4385.83
1025.06
1
4388.87
1025.16
1
4411.38
1025.26
1
4455.73
1025.36
1
4521.23
1025.46
1
4608.35
1025.56
1
4717.33
1025.66
1
4849.05
1025.76
1
5003.01
1025.86
1
5178.01
1025.96
1
5372.92
1026.06
1
5586.72
1026.16
1
5818.49
1026.26
1
6065.31
1026.36
1
6324.81
1026.46
1
6594.51
1026.56
1
6872.49
1026.66
1
7154.68
1026.76
1
7437.73
1026.86
1
7718.05
1026.96
1
7992.59
1027.06
1
8257.69
1027.16
1
8509.3
1027.26
1
8743.8
1027.36
1
8957.88
1027.46
1
9148.9
1027.56
1
9313.1
1027.66
1
9447.8
1027.76
1
9550.78
1027.86
1
9620.76
1027.96
1
9655.72
1028.06
1
9654.5
1028.16
1
9616.61
1028.26
1
9542.38
1028.36
1
9432.38
1028.46
1
9287.19
1028.56
1
9108.21
1028.66
1
8897.33
1028.76
1
8657.33
1028.86
1
8390.24
1028.96
1
8098.89
1029.06
1
7786.37
1029.16
1
7456.33
1029.26
1
7111.88
1029.36
1
6756.28
1029.46
1
6392.88
1029.56
1
6025.16
1029.66
1
5656.43
1029.76
1
5289.4
1029.86
1
4926.87
1029.96
1
4571.38
1030.06
1
4225.62
1030.16
1
3891.17
1030.26
1
3569.74
1030.36
1
3262.73
1030.46
1
2971.48
1030.56
1
2696.69
1030.66
1
2438.78
1030.76
1
2198.03
1030.86
1
1974.59
1030.96
1
1768.44
1031.06
1
1579
1031.16
1
1405.79
1031.26
1
1248.16
1031.36
1
1105.65
1031.46
1
977.194
1031.56
1
861.898
1031.66
1
758.848
1031.76
1
667.253
1031.86
1
586.149
1031.96
1
514.529
1032.06
1
451.504
1032.16
1
396.268
1032.26
1
348.128
1032.36
1
306.171
1032.46
1
269.698
1032.56
1
238.056
1032.66
1
210.8
1032.76
1
187.268
1032.86
1
166.95
1032.96
1
149.413
1033.06
1
134.348
1033.16
1
121.412
1033.26
1
110.231
1033.36
1
100.545
1033.46
1
92.1457
1033.56
1
84.9317
1033.66
1
78.6216
1033.76
1
73.0719
1033.86
1
68.1585
1033.96
1
63.8651
1034.06
1
60.0402
1034.16
1
56.5842
1034.26
1
53.4391
1034.36
1
50.6038
1034.46
1
48.0632
1034.56
1
45.7351
1034.66
1
43.5894
1034.76
1
41.6001
1034.86
1
39.8132
1034.96
1
38.1257
1035.06
1
36.5206
1035.16
1
34.9841
1035.26
1
33.5583
1035.36
1
32.2049
1035.46
1
30.8959
1035.56
1
29.627
1035.66
1
28.6764
1035.76
1
27.5043
1035.86
1
26.3449
1035.96
1
25.1978
1036.06
1
24.0629
1036.16
1
23.098
1036.26
1
22.1745
1036.36
1
21.2618
1036.46
1
20.3594
1036.56
1
19.4983
1036.66
1
18.6655
1036.76
1
17.8418
1036.86
1
17.0271
1036.96
1
16.2326
1037.06
1
15.4784
1037.16
1
14.7727
1037.26
1
14.0829
1037.36
1
13.4005
1037.46
1
12.7601
1037.56
1
12.1301
1037.66
1
11.5072
1037.76
1
10.891
1037.86
1
10.2996
1037.96
1
9.72941
1038.06
1
9.16511
1038.16
1
8.62657
1038.26
1
8.10193
1038.36
1
7.60653
1038.46
1
7.11642
1038.56
1
6.63138
1038.66
1
6.15134
1038.76
1
5.69796
1038.86
1
5.25347
1038.96
1
4.98139
1039.06
1
4.54273
1039.16
1
4.12757
1039.26
1
0
1039.36
1
0
1039.46
1
0
1039.56
1
0
1039.66
1
0
1039.76
1
0
1039.86
1
0
1039.96
1
0
1040.06
1
0
1040.16
1
0
1040.26
1
0
1040.36
1
0
1040.46
1
0
1040.56
1
0
1
Ti2p
TiO2
0
0
0
0
0
0
0
13
Casa Info Follows
0
0
0
0

PCA Coefs = 41279.5, -30.0911,
CasaXP11_irregular-March172021151537
c:\users\mark\owncloud\muelheim group\projects\tio2\analyzed data\experiment 2019-03-28_ti sheet_cec-1303 - vector analysis.vms
C:\Users\pielsticker\Downloads\Ti\EX209_CEC303 Ti slow oxidation - vectro fit - irregular.vms
CasaXP2
C:\Users\pielsticker\Downloads\Ti\references_irregular.vms
C:\Users\pielsticker\Lukas\MPI-CEC\Projects\deepxps\xpsdeeplearning\data\references\Ti_references_irregular.vms
XPS
1e+037
Al
1486.61
1e+037
1e+037
1e+037
1e+037
1e+037
FAT
1e+037
1e+037
1e+037
1e+037
1e+037
1e+037
1e+037
1e+037
Ti
2p
-1
3
Kinetic Energy
eV
Intensity
d
transmission
d
pulse counting
1
1
1e+037
1e+037
1e+037
1e+037
3
MFP Exponent
d
0
ESCAPE DEPTH TYPE
d
1
PROPAGATION_CONVERGED
d
1
0
0
0
986.41
1
0
986.61
1
768.707
986.81
1
768.435
987.01
1
767.617
987.21
1
795.763
987.41
1
763.262
987.61
1
771.299
987.81
1
798.462
988.01
1
750.701
988.21
1
762.703
988.41
1
809.875
988.61
1
802.762
988.81
1
797.075
989.01
1
772.809
989.21
1
768.177
989.41
1
789.669
989.61
1
779.037
989.81
1
788.664
990.01
1
763.133
990.21
1
770.168
990.41
1
774.174
990.61
1
788.367
990.81
1
805.974
991.01
1
777.448
991.21
1
794.388
991.41
1
783.245
991.61
1
791.152
991.81
1
769.968
992.01
1
796.65
992.21
1
810.03
992.41
1
785.408
992.61
1
788.478
992.81
1
812.978
993.01
1
819.208
993.21
1
792.38
993.41
1
807.064
993.61
1
829.266
993.81
1
811.888
994.01
1
821.861
994.21
1
837.714
994.41
1
857.286
994.61
1
845.806
994.81
1
858.359
995.01
1
844.704
995.21
1
876.151
995.41
1
870.002
995.61
1
872.576
995.81
1
878.814
996.01
1
865.276
996.21
1
877.735
996.41
1
886.844
996.61
1
902.856
996.81
1
874.966
997.01
1
865.949
997.21
1
882.212
997.41
1
898.615
997.61
1
883.438
997.81
1
893.677
998.01
1
900.29
998.21
1
903.615
998.41
1
880.647
998.61
1
873.733
998.81
1
916.252
999.01
1
905.374
999.21
1
911.213
999.41
1
902.687
999.61
1
904.045
999.81
1
897.236
1000.01
1
926.681
1000.21
1
925.526
1000.41
1
896.397
1000.61
1
926.249
1000.81
1
911.683
1001.01
1
950.296
1001.21
1
958.371
1001.41
1
937.444
1001.61
1
914.447
1001.81
1
942.783
1002.01
1
920.58
1002.21
1
943.013
1002.41
1
963.942
1002.61
1
921.771
1002.81
1
951.811
1003.01
1
932.785
1003.21
1
948.212
1003.41
1
950.44
1003.61
1
937.391
1003.81
1
945.101
1004.01
1
934.292
1004.21
1
931.659
1004.41
1
926.828
1004.61
1
914.475
1004.81
1
933.151
1005.01
1
922.632
1005.21
1
942.994
1005.41
1
926.796
1005.61
1
940.143
1005.81
1
956.727
1006.01
1
940.591
1006.21
1
981.819
1006.41
1
1008.37
1006.61
1
1013.6
1006.81
1
1014.27
1007.01
1
1015.57
1007.21
1
1024.19
1007.41
1
1080.99
1007.61
1
1079.45
1007.81
1
1086.71
1008.01
1
1098.97
1008.21
1
1103.98
1008.41
1
1094.43
1008.61
1
1119.73
1008.81
1
1100.64
1009.01
1
1081.55
1009.21
1
1072.29
1009.41
1
1068.03
1009.61
1
1048.27
1009.81
1
1041.99
1010.01
1
1010.81
1010.21
1
981.444
1010.41
1
1016.22
1010.61
1
996.998
1010.81
1
990.319
1011.01
1
974.063
1011.21
1
981.065
1011.41
1
977.353
1011.61
1
997.831
1011.81
1
1023.17
1012.01
1
1057
1012.21
1
1056.94
1012.41
1
1098.57
1012.61
1
1088.82
1012.81
1
1110.64
1013.01
1
1154.69
1013.21
1
1178.23
1013.41
1
1235.84
1013.61
1
1236.37
1013.81
1
1227.79
1014.01
1
1278.21
1014.21
1
1268.86
1014.41
1
1257.63
1014.61
1
1240.09
1014.81
1
1218.87
1015.01
1
1171.19
1015.21
1
1122.54
1015.41
1
1067.41
1015.46
1
1067.29
1015.51
1
1042.15
1015.61
1
1039.02
1015.66
1
1052.82
1015.71
1
1013.77
1015.81
1
984.758
1015.86
1
978.853
1015.91
1
992.657
1016.01
1
997.976
1016.06
1
962.513
1016.11
1
978.607
1016.21
1
925.061
1016.26
1
950.873
1016.31
1
914.095
1016.41
1
924.448
1016.46
1
887.492
1016.56
1
879.719
1016.66
1
879.291
1016.76
1
856.757
1016.86
1
879.182
1016.96
1
840.365
1017.06
1
838.737
1017.16
1
813.429
1017.26
1
819.672
1017.36
1
810.392
1017.46
1
797.662
1017.56
1
778.964
1017.66
1
800.196
1017.76
1
749.445
1017.86
1
760.85
1017.96
1
761.03
1018.06
1
783.447
1018.16
1
764.45
1018.26
1
777.982
1018.36
1
777.032
1018.46
1
741.676
1018.56
1
762.665
1018.66
1
752.13
1018.76
1
774.162
1018.86
1
786.274
1018.96
1
783.227
1019.06
1
787.6
1019.16
1
830.725
1019.26
1
865.198
1019.36
1
845.633
1019.46
1
863.046
1019.56
1
913.775
1019.66
1
925.225
1019.76
1
971.033
1019.86
1
972.082
1019.96
1
1031.97
1020.06
1
1079.9
1020.16
1
1142.77
1020.26
1
1234.21
1020.36
1
1301.29
1020.46
1
1402.01
1020.56
1
1505.27
1020.66
1
1564.52
1020.76
1
1699.57
1020.86
1
1802.46
1020.96
1
1969.59
1021.06
1
2061.9
1021.16
1
2171.67
1021.26
1
2257.47
1021.36
1
2367.68
1021.46
1
2451.52
1021.56
1
2485.79
1021.66
1
2550.8
1021.76
1
2501.27
1021.86
1
2497.04
1021.96
1
2489.07
1022.06
1
2401.55
1022.16
1
2306.04
1022.26
1
2227.36
1022.36
1
2067.64
1022.46
1
1950.63
1022.56
1
1827.21
1022.66
1
1672.22
1022.76
1
1578.01
1022.86
1
1434.8
1022.96
1
1348.1
1023.06
1
1235.91
1023.16
1
1158.64
1023.26
1
1128.58
1023.36
1
1032.33
1023.46
1
996.215
1023.56
1
937.285
1023.66
1
904.001
1023.76
1
860.988
1023.86
1
830.683
1023.96
1
814.335
1024.06
1
784.465
1024.16
1
784.869
1024.26
1
778.737
1024.36
1
758.673
1024.46
1
751.087
1024.56
1
748.745
1024.66
1
748.907
1024.76
1
759.631
1024.86
1
746.531
1024.96
1
778.526
1025.06
1
759.716
1025.16
1
777.027
1025.26
1
786.215
1025.36
1
791.529
1025.46
1
813.631
1025.56
1
823.737
1025.66
1
847.126
1025.76
1
871.589
1025.86
1
931.456
1025.96
1
975.757
1026.06
1
1058.22
1026.16
1
1166.62
1026.26
1
1291.99
1026.36
1
1511.6
1026.46
1
1744.35
1026.56
1
2048.32
1026.66
1
2474.29
1026.76
1
3041.37
1026.86
1
3616.82
1026.96
1
4302.5
1027.06
1
4948.24
1027.16
1
5592.03
1027.26
1
6117.37
1027.36
1
6544.88
1027.46
1
6705.58
1027.56
1
6634.5
1027.66
1
6363.31
1027.76
1
5828.6
1027.86
1
5100.96
1027.96
1
4440.83
1028.06
1
3670.51
1028.16
1
2989.35
1028.26
1
2373.67
1028.36
1
1882.81
1028.46
1
1449.51
1028.56
1
1138.66
1028.66
1
880.955
1028.76
1
710.739
1028.86
1
593.143
1028.96
1
493.952
1029.06
1
430.007
1029.16
1
375.74
1029.26
1
307.498
1029.36
1
289.607
1029.46
1
261.454
1029.56
1
241.45
1029.66
1
195.994
1029.76
1
178.111
1029.86
1
171.642
1029.96
1
148.703
1030.06
1
122.799
1030.16
1
123.658
1030.26
1
113.168
1030.36
1
89.9611
1030.46
1
82.6402
1030.56
1
71.4293
1030.66
1
75.3822
1030.76
1
65.8195
1030.86
1
53.6695
1030.96
1
45.9551
1031.06
1
45.7672
1031.16
1
37.6953
1031.26
1
45.1279
1031.36
1
43.102
1031.46
1
41.8022
1031.56
1
34.3535
1031.66
1
41.0285
1031.76
1
24.1728
1031.86
1
24.8709
1031.96
1
30.3581
1032.06
1
26.7379
1032.16
1
27.4104
1032.26
1
35.0028
1032.36
1
18.7488
1032.46
1
31.8477
1032.56
1
28.1205
1032.66
1
22.1481
1032.76
1
23.383
1032.86
1
18.631
1032.96
1
12.2888
1033.06
1
16.5876
1033.16
1
13.8555
1033.26
1
7.00553
1033.36
1
9.75463
1033.46
1
10.5411
1033.56
1
9.85089
1033.66
1
15.0159
1033.76
1
16.9822
1033.86
1
10.2562
1033.96
1
14.6918
1034.06
1
18.4523
1034.16
1
20.0307
1034.26
1
12.6893
1034.36
1
4.38198
1034.46
1
13.7239
1034.56
1
12.7116
1034.66
1
12.2761
1034.76
1
4.75145
1034.86
1
11.4553
1034.96
1
19.1661
1035.06
1
14.8176
1035.16
1
12.2612
1035.26
1
13.668
1035.36
1
6.80692
1035.46
1
3.57823
1035.56
1
10.8517
1035.66
1
8.48454
1035.76
1
9.99754
1035.86
1
3.32511
1035.96
1
5.30515
1036.06
1
-0.15255
1036.16
1
4.10473
1036.26
1
1.58446
1036.36
1
12.2091
1036.46
1
14.8672
1036.56
1
4.71866
1036.66
1
9.98924
1036.76
1
6.98157
1036.86
1
8.02528
1036.96
1
-3.58963
1037.06
1
3.92434
1037.16
1
8.52046
1037.26
1
6.96935
1037.36
1
-6.73835
1037.46
1
4.97275
1037.56
1
-2.7992
1037.66
1
5.40891
1037.76
1
-3.69174
1037.86
1
2.41516
1037.96
1
3.25827
1038.06
1
-0.126762
1038.16
1
2.44671
1038.26
1
0.257914
1038.36
1
3.89457
1038.46
1
-5.8306
1038.56
1
4.5545
1038.66
1
0.264434
1038.76
1
1.67889
1038.86
1
3.29361
1038.96
1
7.03935
1039.06
1
3.16899
1039.16
1
7.20019
1039.26
1
-2.25084
1039.36
1
-2.53558
1039.46
1
-4.11686
1039.56
1
2.61504
1039.66
1
-3.20836
1039.76
1
4.38263
1039.86
1
6.05281
1039.96
1
3.3128
1040.06
1
1.48788
1040.16
1
2.66528
1040.26
1
2.751
1040.36
1
0
1
&TiO
TiO
0
0
0
0
0
0
0
13
Casa Info Follows
0
0
0
0

PCA Coefs = 41396.7, -3191.99, 1103.12, 387.504,
PCA Coefs = 41396.7, -3191.99, 1103.12, 387.504, -363.953,
PCA Coefs = 41439, -2585.94, 1104.79, -371.422, -359.987, 128.966,
c:\users\mark\owncloud\muelheim group\projects\tio2\analyzed data\experiment 2019-03-28_ti sheet_cec-1303 - vector analysis.vms
c:\users\mark\owncloud\muelheim group\projects\tio2\analyzed data\experiment 2019-03-28_ti sheet_cec-1303 - vector analysis.vms
C:\Users\pielsticker\Downloads\Ti\EX209_CEC303 Ti slow oxidation - vectro fit - irregular.vms
C:\Users\pielsticker\Lukas\MPI-CEC\Projects\deepxps\xpsdeeplearning\data\references\Ti_references_irregular.vms
XPS
1e+037
Al
1486.61
1e+037
1e+037
1e+037
1e+037
1e+037
FAT
1e+037
1e+037
1e+037
1e+037
1e+037
1e+037
1e+037
1e+037
Ti
2p LS
-1
3
Kinetic Energy
eV
Intensity
d
transmission
d
pulse counting
1
1
1e+037
1e+037
1e+037
1e+037
3
MFP Exponent
d
0
ESCAPE DEPTH TYPE
d
1
PROPAGATION_CONVERGED
d
1
0
0
0
986.61
1
0
986.81
1
0
987.01
1
0
987.21
1
0
987.41
1
418.506
987.61
1
440.148
987.81
1
430.838
988.01
1
424.025
988.21
1
418.792
988.41
1
454.731
988.61
1
440.084
988.81
1
432.304
989.01
1
446.848
989.21
1
427.43
989.41
1
424.875
989.61
1
420.255
989.81
1
437.574
990.01
1
437.73
990.21
1
412.513
990.41
1
431.311
990.61
1
433.572
990.81
1
409.864
991.01
1
426.173
991.21
1
414.74
991.41
1
426.44
991.61
1
419.722
991.81
1
436.796
992.01
1
430.264
992.21
1
408.522
992.41
1
445.551
992.61
1
442.301
992.81
1
427.755
993.01
1
456.361
993.21
1
450.223
993.41
1
436.61
993.61
1
448.84
993.81
1
447.565
994.01
1
431.631
994.21
1
439.397
994.41
1
436.637
994.61
1
439.383
994.81
1
437.081
995.01
1
441.987
995.21
1
435.758
995.41
1
440.249
995.61
1
470.201
995.81
1
465.133
996.01
1
452.422
996.21
1
465.086
996.41
1
459.164
996.61
1
449.258
996.81
1
458.529
997.01
1
477.211
997.21
1
460.033
997.41
1
445.237
997.61
1
462.703
997.81
1
451.872
998.01
1
469.161
998.21
1
475.462
998.41
1
456.623
998.61
1
480.575
998.81
1
476.11
999.01
1
488.889
999.21
1
473.36
999.41
1
489.987
999.61
1
499.989
999.81
1
503.847
1000.01
1
472.305
1000.21
1
470.454
1000.41
1
470.1
1000.61
1
488.566
1000.81
1
487.255
1001.01
1
485.732
1001.21
1
498.971
1001.41
1
495.287
1001.61
1
515.751
1001.81
1
521.562
1002.01
1
520.4
1002.21
1
510.643
1002.41
1
516.99
1002.61
1
511.597
1002.81
1
518.202
1003.01
1
525.184
1003.21
1
517.622
1003.41
1
508.334
1003.61
1
520.695
1003.81
1
529.331
1004.01
1
532.939
1004.21
1
527.727
1004.41
1
533.308
1004.61
1
544.611
1004.81
1
532.448
1005.01
1
563.09
1005.21
1
542.99
1005.41
1
545.665
1005.61
1
526.3
1005.81
1
572.365
1006.01
1
549.727
1006.21
1
548.66
1006.41
1
563.665
1006.61
1
577.334
1006.81
1
553.853
1007.01
1
584.367
1007.21
1
565.461
1007.41
1
562.378
1007.61
1
558.304
1007.81
1
548.855
1008.01
1
587.028
1008.21
1
582.535
1008.41
1
570.811
1008.61
1
573.391
1008.81
1
560.161
1009.01
1
597.167
1009.21
1
585.585
1009.41
1
580.41
1009.61
1
584.575
1009.81
1
563.558
1010.01
1
592.348
1010.21
1
591.048
1010.41
1
562.049
1010.61
1
613.504
1010.81
1
590.102
1011.01
1
597.336
1011.21
1
580.7
1011.41
1
612.752
1011.61
1
591.136
1011.81
1
581.801
1012.01
1
607.547
1012.21
1
616.005
1012.41
1
606.481
1012.61
1
611.253
1012.81
1
623.68
1013.01
1
618.895
1013.21
1
597.049
1013.41
1
595.137
1013.61
1
596.239
1013.81
1
584.361
1014.01
1
618.527
1014.21
1
606.433
1014.41
1
600.324
1014.61
1
577.321
1014.81
1
594.519
1015.01
1
603.592
1015.21
1
592.667
1015.41
1
598.124
1015.61
1
613.572
1015.66
1
596.493
1015.71
1
589.147
1015.81
1
588.693
1015.86
1
581.863
1015.91
1
590.761
1016.01
1
606.759
1016.06
1
596.144
1016.11
1
592.706
1016.21
1
598.696
1016.26
1
606.286
1016.31
1
599.476
1016.41
1
595.682
1016.46
1
597.099
1016.51
1
598.501
1016.61
1
605.691
1016.66
1
593.859
1016.76
1
596.403
1016.86
1
594.915
1016.96
1
587.636
1017.06
1
606.761
1017.16
1
607.689
1017.26
1
604.424
1017.36
1
596.921
1017.46
1
596.989
1017.56
1
630.31
1017.66
1
607.099
1017.76
1
587.203
1017.86
1
605.75
1017.96
1
625.619
1018.06
1
605.926
1018.16
1
625.144
1018.26
1
627.313
1018.36
1
632.086
1018.46
1
633.444
1018.56
1
644.948
1018.66
1
636.764
1018.76
1
641.379
1018.86
1
637.855
1018.96
1
636.099
1019.06
1
652.623
1019.16
1
641.447
1019.26
1
632.682
1019.36
1
663.565
1019.46
1
635.212
1019.56
1
660.336
1019.66
1
633.939
1019.76
1
654.36
1019.86
1
664.706
1019.96
1
659.696
1020.06
1
657.005
1020.16
1
639.889
1020.26
1
647.107
1020.36
1
650.887
1020.46
1
650.078
1020.56
1
647.973
1020.66
1
642.48
1020.76
1
641.294
1020.86
1
621.76
1020.96
1
633.689
1021.06
1
641.391
1021.16
1
642.629
1021.26
1
625.183
1021.36
1
597.361
1021.46
1
611.948
1021.56
1
603.574
1021.66
1
611.698
1021.76
1
606.544
1021.86
1
598.509
1021.96
1
611.599
1022.06
1
613.523
1022.16
1
590.066
1022.26
1
606.824
1022.36
1
613.648
1022.46
1
630.209
1022.56
1
631.426
1022.66
1
616.234
1022.76
1
617.276
1022.86
1
612.854
1022.96
1
619.12
1023.06
1
616.27
1023.16
1
630.329
1023.26
1
642.111
1023.36
1
661.154
1023.46
1
649.041
1023.56
1
653.472
1023.66
1
672.917
1023.76
1
699.632
1023.86
1
722.662
1023.96
1
707.336
1024.06
1
724.502
1024.16
1
738.511
1024.26
1
762.687
1024.36
1
786.671
1024.46
1
843.475
1024.56
1
861.424
1024.66
1
917.206
1024.76
1
972.005
1024.86
1
1028.03
1024.96
1
1085.06
1025.06
1
1127.84
1025.16
1
1180.85
1025.26
1
1205.46
1025.36
1
1242.28
1025.46
1
1289.05
1025.56
1
1306.35
1025.66
1
1311.04
1025.76
1
1283.7
1025.86
1
1318.77
1025.96
1
1291.32
1026.06
1
1281.26
1026.16
1
1239.21
1026.26
1
1203.76
1026.36
1
1158.37
1026.46
1
1078.51
1026.56
1
1020.15
1026.66
1
928.974
1026.76
1
889.388
1026.86
1
824.393
1026.96
1
792
1027.06
1
714.097
1027.16
1
695.528
1027.26
1
685.561
1027.36
1
668.26
1027.46
1
631.47
1027.56
1
637.027
1027.66
1
640.778
1027.76
1
634.57
1027.86
1
618.156
1027.96
1
599.723
1028.06
1
629.057
1028.16
1
620.889
1028.26
1
629.837
1028.36
1
622.267
1028.46
1
620.128
1028.56
1
631.855
1028.66
1
614.635
1028.76
1
598.893
1028.86
1
628.933
1028.96
1
613.245
1029.06
1
626.144
1029.16
1
628.511
1029.26
1
627.299
1029.36
1
627.466
1029.46
1
638.279
1029.56
1
656.9
1029.66
1
664.871
1029.76
1
682.119
1029.86
1
691.803
1029.96
1
711.438
1030.06
1
722.547
1030.16
1
779.71
1030.26
1
818.387
1030.36
1
841.578
1030.46
1
869.894
1030.56
1
953.821
1030.66
1
1014.67
1030.76
1
1098.15
1030.86
1
1180.55
1030.96
1
1290.65
1031.06
1
1413.9
1031.16
1
1522.83
1031.26
1
1683.65
1031.36
1
1805.37
1031.46
1
1882.09
1031.56
1
1937.36
1031.66
1
1902.05
1031.76
1
1820.49
1031.86
1
1733.01
1031.96
1
1674.2
1032.06
1
1594.21
1032.16
1
1532.43
1032.26
1
1412.55
1032.36
1
1276.98
1032.46
1
1103.07
1032.56
1
898.867
1032.66
1
693.039
1032.76
1
524.306
1032.86
1
360.997
1032.96
1
265.384
1033.06
1
184.599
1033.16
1
146.727
1033.26
1
115.72
1033.36
1
84.3599
1033.46
1
73.258
1033.56
1
65.1807
1033.66
1
49.6746
1033.76
1
49.7747
1033.86
1
36.4411
1033.96
1
32.4556
1034.06
1
31.6081
1034.16
1
33.807
1034.26
1
29.7257
1034.36
1
21.9194
1034.46
1
30.7035
1034.56
1
21.3205
1034.66
1
23.786
1034.76
1
17.8064
1034.86
1
18.0522
1034.96
1
20.7355
1035.06
1
13.6358
1035.16
1
12.7428
1035.26
1
9.25257
1035.36
1
17.8825
1035.46
1
21.1059
1035.56
1
16.1824
1035.66
1
17.0204
1035.76
1
9.60597
1035.86
1
11.145
1035.96
1
12.7076
1036.06
1
16.3768
1036.16
1
9.75438
1036.26
1
6.69721
1036.36
1
7.37087
1036.46
1
5.21011
1036.56
1
8.72831
1036.66
1
3.6229
1036.76
1
3.17743
1036.86
1
1.47699
1036.96
1
9.76206
1037.06
1
5.90447
1037.16
1
5.99246
1037.26
1
3.90965
1037.36
1
5.08157
1037.46
1
6.53262
1037.56
1
6.63376
1037.66
1
4.39155
1037.76
1
0.0817091
1037.86
1
-0.488158
1037.96
1
3.97329
1038.06
1
1.92559
1038.16
1
5.79007
1038.26
1
2.19749
1038.36
1
-0.0809204
1038.46
1
4.7773
1038.56
1
8.75129
1038.66
1
[...]
1020.86
1
621.76
1020.96
1
633.689
1021.06
1
641.391
1021.16
1
642.629
1021.26
1
625.183
1021.36
1
597.361
1021.46
1
611.948
1021.56
1
603.574
1021.66
1
611.698
1021.76
1
606.544
1021.86
1
598.509
1021.96
1
611.599
1022.06
1
613.523
1022.16
1
590.066
1022.26
1
606.824
1022.36
1
613.648
1022.46
1
630.209
1022.56
1
631.426
1022.66
1
616.234
1022.76
1
617.276
1022.86
1
612.854
1022.96
1
619.12
1023.06
1
616.27
1023.16
1
630.329
1023.26
1
642.111
1023.36
1
661.154
1023.46
1
649.041
1023.56
1
653.472
1023.66
1
672.917
1023.76
1
699.632
1023.86
1
722.662
1023.96
1
707.336
1024.06
1
724.502
1024.16
1
738.511
1024.26
1
762.687
1024.36
1
786.671
1024.46
1
843.475
1024.56
1
861.424
1024.66
1
917.206
1024.76
1
972.005
1024.86
1
1028.03
1024.96
1
1085.06
1025.06
1
1127.84
1025.16
1
1180.85
1025.26
1
1205.46
1025.36
1
1242.28
1025.46
1
1289.05
1025.56
1
1306.35
1025.66
1
1311.04
1025.76
1
1283.7
1025.86
1
1318.77
1025.96
1
1291.32
1026.06
1
1281.26
1026.16
1
1239.21
1026.26
1
1203.76
1026.36
1
1158.37
1026.46
1
1078.51
1026.56
1
1020.15
1026.66
1
928.974
1026.76
1
889.388
1026.86
1
824.393
1026.96
1
792
1027.06
1
714.097
1027.16
1
695.528
1027.26
1
685.561
1027.36
1
668.26
1027.46
1
631.47
1027.56
1
637.027
1027.66
1
640.778
1027.76
1
634.57
1027.86
1
618.156
1027.96
1
599.723
1028.06
1
629.057
1028.16
1
620.889
1028.26
1
629.837
1028.36
1
622.267
1028.46
1
620.128
1028.56
1
631.855
1028.66
1
614.635
1028.76
1
598.893
1028.86
1
628.933
1028.96
1
613.245
1029.06
1
626.144
1029.16
1
628.511
1029.26
1
627.299
1029.36
1
627.466
1029.46
1
638.279
1029.56
1
656.9
1029.66
1
664.871
1029.76
1
682.119
1029.86
1
691.803
1029.96
1
711.438
1030.06
1
722.547
1030.16
1
779.71
1030.26
1
818.387
1030.36
1
841.578
1030.46
1
869.894
1030.56
1
953.821
1030.66
1
1014.67
1030.76
1
1098.15
1030.86
1
1180.55
1030.96
1
1290.65
1031.06
1
1413.9
1031.16
1
1522.83
1031.26
1
1683.65
1031.36
1
1805.37
1031.46
1
1882.09
1031.56
1
1937.36
1031.66
1
1902.05
1031.76
1
1820.49
1031.86
1
1733.01
1031.96
1
1674.2
1032.06
1
1594.21
1032.16
1
1532.43
1032.26
1
1412.55
1032.36
1
1276.98
1032.46
1
1103.07
1032.56
1
898.867
1032.66
1
693.039
1032.76
1
524.306
1032.86
1
360.997
1032.96
1
265.384
1033.06
1
184.599
1033.16
1
146.727
1033.26
1
115.72
1033.36
1
84.3599
1033.46
1
73.258
1033.56
1
65.1807
1033.66
1
49.6746
1033.76
1
49.7747
1033.86
1
36.4411
1033.96
1
32.4556
1034.06
1
31.6081
1034.16
1
33.807
1034.26
1
29.7257
1034.36
1
21.9194
1034.46
1
30.7035
1034.56
1
21.3205
1034.66
1
23.786
1034.76
1
17.8064
1034.86
1
18.0522
1034.96
1
20.7355
1035.06
1
13.6358
1035.16
1
12.7428
1035.26
1
9.25257
1035.36
1
17.8825
1035.46
1
21.1059
1035.56
1
16.1824
1035.66
1
17.0204
1035.76
1
9.60597
1035.86
1
11.145
1035.96
1
12.7076
1036.06
1
16.3768
1036.16
1
9.75438
1036.26
1
6.69721
1036.36
1
7.37087
1036.46
1
5.21011
1036.56
1
8.72831
1036.66
1
3.6229
1036.76
1
3.17743
1036.86
1
1.47699
1036.96
1
9.76206
1037.06
1
5.90447
1037.16
1
5.99246
1037.26
1
3.90965
1037.36
1
5.08157
1037.46
1
6.53262
1037.56
1
6.63376
1037.66
1
4.39155
1037.76
1
0.0817091
1037.86
1
-0.488158
1037.96
1
3.97329
1038.06
1
1.92559
1038.16
1
5.79007
1038.26
1
2.19749
1038.36
1
-0.0809204
1038.46
1
4.7773
1038.56
1
8.75129
1038.66
1
3.21884
1038.76
1
-1.35327
1038.86
1
-1.81348
1038.96
1
1.8464
1039.06
1
3.18172
1039.16
1
1.00807
1039.26
1
0
1039.36
1
0
1039.46
1
0
1039.56
1
0
1039.66
1
0
1039.76
1
0
1039.86
1
0
1039.96
1
0
1040.06
1
0
1040.16
1
0
1040.26
1
0
1040.36
1
0
1040.46
1
0
1040.56
1
0
1
Ti2p
Ti2O3
0
0
0
0
0
0
0
15
Casa Info Follows
0
0
1
CASA region (*Ti 2p*) (*Min Limits*) 987.96 1039.26 7.7123335 2 0 0 0 -1643 0 0 (*Ti 2p*) 47.8784 0 7.81
1
CASA comp (*Ti2O3*) (*&TI2O3*) Area 0.99917178 1e-020 472189.94 -1 1 MFWHM 1 1 1 -1 1 Position 1012.9114 1012.6114 1013.2114 -1 1 RSF 7.71233 MASS 47.8784 INDEX 2 (*Ti2O3*) CONST (**) UNCORRECTEDRSF 7.81

PCA Coefs = 179186, -26548.4, -22890.8, 3691.07, -1602.46, -1706.5,
C:\Users\Mark\ownCloud\Muelheim Group\Projects\TiO2\analyzed data\EX209_CEC303 Ti slow oxidation - curated - irregular.vms
c:\users\mark\owncloud\muelheim group\projects\tio2\analyzed data\experiment 2019-03-28_ti sheet_cec-1303 - vector analysis.vms
C:\Users\pielsticker\Downloads\Ti\EX209_CEC303 Ti slow oxidation - vectro fit - irregular.vms
CasaXP2
C:\Users\pielsticker\Downloads\Ti\references_irregular.vms
C:\Users\pielsticker\Lukas\MPI-CEC\Projects\deepxps\xpsdeeplearning\data\references\Ti_references_irregular.vms
XPS
1e+037
Al
1486.61
1e+037
1e+037
1e+037
1e+037
1e+037
FAT
1e+037
1e+037
1e+037
1e+037
1e+037
1e+037
1e+037
1e+037
Ti
2p fit
-1
3
Kinetic Energy
eV
Intensity
d
transmission
d
pulse counting
1
1
1e+037
1e+037
1e+037
1e+037
3
MFP Exponent
d
0
ESCAPE DEPTH TYPE
d
1
PROPAGATION_CONVERGED
d
1
0
0
0
986.61
1
0
986.81
1
0
987.01
1
2534.66
987.21
1
2540.32
987.41
1
2546.02
987.61
1
2551.71
987.81
1
2557.43
988.01
1
2563.15
988.21
1
2568.89
988.41
1
2574.65
988.61
1
2580.42
988.81
1
2586.21
989.01
1
2592.01
989.21
1
2597.83
989.41
1
2603.65
989.61
1
2609.5
989.81
1
2615.4
990.01
1
2621.8
990.21
1
2628.21
990.41
1
2634.65
990.61
1
2641.09
990.81
1
2647.56
991.01
1
2654.05
991.21
1
2660.55
991.41
1
2667.08
991.61
1
2673.62
991.81
1
2680.19
992.01
1
2686.76
992.21
1
2693.38
992.41
1
2699.99
992.61
1
2706.66
992.81
1
2713.33
993.01
1
2720.03
993.21
1
2726.96
993.41
1
2734.4
993.61
1
2741.86
993.81
1
2749.35
994.01
1
2756.86
994.21
1
2764.39
994.41
1
2771.96
994.61
1
2779.53
994.81
1
2787.17
995.01
1
2794.8
995.21
1
2802.49
995.41
1
2810.19
995.61
1
2817.92
995.81
1
2825.68
996.01
1
2833.46
996.21
1
2841.28
996.41
1
2849.12
996.61
1
2857.46
996.81
1
2866.23
997.01
1
2875.06
997.21
1
2883.9
997.41
1
2892.79
997.61
1
2901.69
997.81
1
2910.65
998.01
1
2919.62
998.21
1
2926.65
998.41
1
2935.73
998.61
1
2944.89
998.81
1
2954.15
999.01
1
2963.5
999.21
1
2972.97
999.41
1
2982.5
999.61
1
2992.17
999.81
1
3001.89
1000.01
1
3011.74
1000.21
1
3021.66
1000.41
1
3031.69
1000.61
1
3041.8
1000.81
1
3052.02
1001.01
1
3062.33
1001.21
1
3072.75
1001.41
1
3083.29
1001.61
1
3093.9
1001.81
1
3104.64
1002.01
1
3115.44
1002.21
1
3126.36
1002.41
1
3137.36
1002.61
1
3148.46
1002.81
1
3159.64
1003.01
1
3170.93
1003.21
1
3182.29
1003.41
1
3193.8
1003.61
1
3205.4
1003.81
1
3217.08
1004.01
1
3228.85
1004.21
1
3240.69
1004.41
1
3252.63
1004.61
1
3264.63
1004.81
1
3276.72
1005.01
1
3288.87
1005.21
1
3301.09
1005.41
1
3313.4
1005.61
1
3325.85
1005.81
1
3338.35
1006.01
1
3350.92
1006.21
1
3363.53
1006.41
1
3376.19
1006.61
1
3388.72
1006.81
1
3401.48
1007.01
1
3414.25
1007.21
1
3427.09
1007.41
1
3439.92
1007.61
1
3452.82
1007.81
1
3465.69
1008.01
1
3478.59
1008.21
1
3491.48
1008.41
1
3504.34
1008.61
1
3517.21
1008.81
1
3529.97
1009.01
1
3542.78
1009.21
1
3555.35
1009.41
1
3568.02
1009.61
1
3580.33
1009.81
1
3592.71
1010.01
1
3604.71
1010.21
1
3616.66
1010.41
1
3628.23
1010.61
1
3639.57
1010.81
1
3650.59
1011.01
1
3661.07
1011.21
1
3671.39
1011.41
1
3680.74
1011.61
1
3690.17
1011.81
1
3698.04
1012.01
1
3706.07
1012.21
1
3712.37
1012.41
1
3718.54
1012.61
1
3723.06
1012.81
1
3726.92
1013.01
1
3729.37
1013.21
1
3730.44
1013.41
1
3730.56
1013.61
1
3728.37
1013.81
1
3725.88
1014.01
1
3719.97
1014.21
1
3714.45
1014.41
1
3704.68
1014.61
1
3695.2
1014.81
1
3682.1
1015.01
1
3668.45
1015.21
1
3652.12
1015.41
1
3634.37
1015.61
1
3625.84
1015.66
1
3615.11
1015.71
1
3609.62
1015.81
1
3604.19
1015.86
1
3593.58
1015.91
1
3588.38
1016.01
1
3583.28
1016.06
1
3571.92
1016.11
1
3565.64
1016.21
1
3559.45
1016.26
1
3547.41
1016.31
1
3541.56
1016.41
1
3535.81
1016.46
1
3524.34
1016.51
1
3517.6
1016.61
1
3511.01
1016.66
1
3498.24
1016.76
1
3486.1
1016.86
1
3474.63
1016.96
1
3461.97
1017.06
1
3449.55
1017.16
1
3438.03
1017.26
1
3427.55
1017.36
1
3417.27
1017.46
1
3406.89
1017.56
1
3397.8
1017.66
1
3390.14
1017.76
1
3383.95
1017.86
1
3377.82
1017.96
1
3373.58
1018.06
1
3371.39
1018.16
1
3371.43
1018.26
1
3373
1018.36
1
3376.8
1018.46
1
3383.45
1018.56
1
3393.25
1018.66
1
3406.04
1018.76
1
3421.76
1018.86
1
3441.2
1018.96
1
3464.61
1019.06
1
3492.19
1019.16
1
3523.9
1019.26
1
3560.42
1019.36
1
3601.75
1019.46
1
3648.01
1019.56
1
3699.4
1019.66
1
3755.98
1019.76
1
3817.74
1019.86
1
3884.92
1019.96
1
3957.41
1020.06
1
4035.38
1020.16
1
4118.22
1020.26
1
4206.02
1020.36
1
4298.2
1020.46
1
4395.27
1020.56
1
4496.01
1020.66
1
4599.65
1020.76
1
4704.83
1020.86
1
4813.16
1020.96
1
4923.03
1021.06
1
5032.97
1021.16
1
5142.11
1021.26
1
5249.77
1021.36
1
5356.04
1021.46
1
5458.61
1021.56
1
5556.41
1021.66
1
5648.51
1021.76
1
5735.41
1021.86
1
5814.66
1021.96
1
5885.27
1022.06
1
5946.31
1022.16
1
5997.95
1022.26
1
6039.67
1022.36
1
6069.86
1022.46
1
6087.81
1022.56
1
6093.25
1022.66
1
6087.92
1022.76
1
6070.03
1022.86
1
6039.72
1022.96
1
5997.27
1023.06
1
5944.62
1023.16
1
5880.87
1023.26
1
5806.76
1023.36
1
5723.32
1023.46
1
5632.41
1023.56
1
5535.69
1023.66
1
5433.15
1023.76
1
5326.34
1023.86
1
5216.77
1023.96
1
5108.2
1024.06
1
5000.49
1024.16
1
4895.34
1024.26
1
4794.67
1024.36
1
4701.6
1024.46
1
4617.33
1024.56
1
4543.15
1024.66
1
4480.83
1024.76
1
4432.65
1024.86
1
4400.88
1024.96
1
4385.83
1025.06
1
4388.87
1025.16
1
4411.38
1025.26
1
4455.73
1025.36
1
4521.23
1025.46
1
4608.35
1025.56
1
4717.33
1025.66
1
4849.05
1025.76
1
5003.01
1025.86
1
5178.01
1025.96
1
5372.92
1026.06
1
5586.72
1026.16
1
5818.49
1026.26
1
6065.31
1026.36
1
6324.81
1026.46
1
6594.51
1026.56
1
6872.49
1026.66
1
7154.68
1026.76
1
7437.73
1026.86
1
7718.05
1026.96
1
7992.59
1027.06
1
8257.69
1027.16
1
8509.3
1027.26
1
8743.8
1027.36
1
8957.88
1027.46
1
9148.9
1027.56
1
9313.1
1027.66
1
9447.8
1027.76
1
9550.78
1027.86
1
9620.76
1027.96
1
9655.72
1028.06
1
9654.5
1028.16
1
9616.61
1028.26
1
9542.38
1028.36
1
9432.38
1028.46
1
9287.19
1028.56
1
9108.21
1028.66
1
8897.33
1028.76
1
8657.33
1028.86
1
8390.24
1028.96
1
8098.89
1029.06
1
7786.37
1029.16
1
7456.33
1029.26
1
7111.88
1029.36
1
6756.28
1029.46
1
6392.88
1029.56
1
6025.16
1029.66
1
5656.43
1029.76
1
5289.4
1029.86
1
4926.87
1029.96
1
4571.38
1030.06
1
4225.62
1030.16
1
3891.17
1030.26
1
3569.74
1030.36
1
3262.73
1030.46
1
2971.48
1030.56
1
2696.69
1030.66
1
2438.78
1030.76
1
2198.03
1030.86
1
1974.59
1030.96
1
1768.44
1031.06
1
1579
1031.16
1
1405.79
1031.26
1
1248.16
1031.36
1
1105.65
1031.46
1
977.194
1031.56
1
861.898
1031.66
1
758.848
1031.76
1
667.253
1031.86
1
586.149
1031.96
1
514.529
1032.06
1
451.504
1032.16
1
396.268
1032.26
1
348.128
1032.36
1
306.171
1032.46
1
269.698
1032.56
1
238.056
1032.66
1
210.8
1032.76
1
187.268
1032.86
1
166.95
1032.96
1
149.413
1033.06
1
134.348
1033.16
1
121.412
1033.26
1
110.231
1033.36
1
100.545
1033.46
1
92.1457
1033.56
1
84.9317
1033.66
1
78.6216
1033.76
1
73.0719
1033.86
1
68.1585
1033.96
1
63.8651
1034.06
1
60.0402
1034.16
1
56.5842
1034.26
1
53.4391
1034.36
1
50.6038
1034.46
1
48.0632
1034.56
1
45.7351
1034.66
1
43.5894
1034.76
1
41.6001
1034.86
1
39.8132
1034.96
1
38.1257
1035.06
1
36.5206
1035.16
1
34.9841
1035.26
1
33.5583
1035.36
1
32.2049
1035.46
1
30.8959
1035.56
1
29.627
1035.66
1
28.6764
1035.76
1
27.5043
1035.86
1
26.3449
1035.96
1
25.1978
1036.06
1
24.0629
1036.16
1
23.098
1036.26
1
22.1745
1036.36
1
21.2618
1036.46
1
20.3594
1036.56
1
19.4983
1036.66
1
18.6655
1036.76
1
17.8418
1036.86
1
17.0271
1036.96
1
16.2326
1037.06
1
15.4784
1037.16
1
14.7727
1037.26
1
14.0829
1037.36
1
13.4005
1037.46
1
12.7601
1037.56
1
12.1301
1037.66
1
11.5072
1037.76
1
10.891
1037.86
1
10.2996
1037.96
1
9.72941
1038.06
1
9.16511
1038.16
1
8.62657
1038.26
1
8.10193
1038.36
1
7.60653
1038.46
1
7.11642
1038.56
1
6.63138
1038.66
1
6.15134
1038.76
1
5.69796
1038.86
1
5.25347
1038.96
1
4.98139
1039.06
1
4.54273
1039.16
1
4.12757
1039.26
1
0
1039.36
1
0
1039.46
1
0
1039.56
1
0
1039.66
1
0
1039.76
1
0
1039.86
1
0
1039.96
1
0
1040.06
1
0
1040.16
1
0
1040.26
1
0
1040.36
1
0
1040.46
1
0
1040.56
1
0
1
Ti2p
TiO2
0
0
0
0
0
0
0
15
Casa Info Follows
0
0
1
CASA region (*Ti 2p*) (*Min Limits*) 987.96 1039.26 7.7123335 2 0 0 0 -1643 0 0 (*Ti 2p*) 47.8784 0 7.81
1
CASA comp (*TiO2*) (*&TIO2*) Area 1.0006404 1e-020 472189.94 -1 1 MFWHM 1 1 1 -1 1 Position 1012.0574 1011.7574 1012.3574 -1 1 RSF 7.71233 MASS 47.8784 INDEX 3 (*TiO2*) CONST (**) UNCORRECTEDRSF 7.81

PCA Coefs = 41279.5, -30.0911,
CasaXP11_irregular-March172021151537
c:\users\mark\owncloud\muelheim group\projects\tio2\analyzed data\experiment 2019-03-28_ti sheet_cec-1303 - vector analysis.vms
C:\Users\pielsticker\Downloads\Ti\EX209_CEC303 Ti slow oxidation - vectro fit - irregular.vms
CasaXP2
C:\Users\pielsticker\Downloads\Ti\references_irregular.vms
C:\Users\pielsticker\Lukas\MPI-CEC\Projects\deepxps\xpsdeeplearning\data\references\Ti_references_irregular.vms
XPS
1e+037
Al
1486.61
1e+037
1e+037
1e+037
1e+037
1e+037
FAT
1e+037
1e+037
1e+037
1e+037
1e+037
1e+037
1e+037
1e+037
Ti
2p fit
-1
3
Kinetic Energy
eV
Intensity
d
transmission
d
pulse counting
1
1
1e+037
1e+037
1e+037
1e+037
3
MFP Exponent
d
0
ESCAPE DEPTH TYPE
d
1
PROPAGATION_CONVERGED
d
1
0
0
0
986.41
1
0
986.61
1
768.707
986.81
1
768.435
987.01
1
767.617
987.21
1
795.763
987.41
1
763.262
987.61
1
771.299
987.81
1
798.462
988.01
1
750.701
988.21
1
762.703
988.41
1
809.875
988.61
1
802.762
988.81
1
797.075
989.01
1
772.809
989.21
1
768.177
989.41
1
789.669
989.61
1
779.037
989.81
1
788.664
990.01
1
763.133
990.21
1
770.168
990.41
1
774.174
990.61
1
788.367
990.81
1
805.974
991.01
1
777.448
991.21
1
794.388
991.41
1
783.245
991.61
1
791.152
991.81
1
769.968
992.01
1
796.65
992.21
1
810.03
992.41
1
785.408
992.61
1
788.478
992.81
1
812.978
993.01
1
819.208
993.21
1
792.38
993.41
1
807.064
993.61
1
829.266
993.81
1
811.888
994.01
1
821.861
994.21
1
837.714
994.41
1
857.286
994.61
1
845.806
994.81
1
858.359
995.01
1
844.704
995.21
1
876.151
995.41
1
870.002
995.61
1
872.576
995.81
1
878.814
996.01
1
865.276
996.21
1
877.735
996.41
1
886.844
996.61
1
902.856
996.81
1
874.966
997.01
1
865.949
997.21
1
882.212
997.41
1
898.615
997.61
1
883.438
997.81
1
893.677
998.01
1
900.29
998.21
1
903.615
998.41
1
880.647
998.61
1
873.733
998.81
1
916.252
999.01
1
905.374
999.21
1
911.213
999.41
1
902.687
999.61
1
904.045
999.81
1
897.236
1000.01
1
926.681
1000.21
1
925.526
1000.41
1
896.397
1000.61
1
926.249
1000.81
1
911.683
1001.01
1
950.296
1001.21
1
958.371
1001.41
1
937.444
1001.61
1
914.447
1001.81
1
942.783
1002.01
1
920.58
1002.21
1
943.013
1002.41
1
963.942
1002.61
1
921.771
1002.81
1
951.811
1003.01
1
932.785
1003.21
1
948.212
1003.41
1
950.44
1003.61
1
937.391
1003.81
1
945.101
1004.01
1
934.292
1004.21
1
931.659
1004.41
1
926.828
1004.61
1
914.475
1004.81
1
933.151
1005.01
1
922.632
1005.21
1
942.994
1005.41
1
926.796
1005.61
1
940.143
1005.81
1
956.727
1006.01
1
940.591
1006.21
1
981.819
1006.41
1
1008.37
1006.61
1
1013.6
1006.81
1
1014.27
1007.01
1
1015.57
1007.21
1
1024.19
1007.41
1
1080.99
1007.61
1
1079.45
1007.81
1
1086.71
1008.01
1
1098.97
1008.21
1
1103.98
1008.41
1
1094.43
1008.61
1
1119.73
1008.81
1
1100.64
1009.01
1
1081.55
1009.21
1
1072.29
1009.41
1
1068.03
1009.61
1
1048.27
1009.81
1
1041.99
1010.01
1
1010.81
1010.21
1
981.444
1010.41
1
1016.22
1010.61
1
996.998
1010.81
1
990.319
1011.01
1
974.063
1011.21
1
981.065
1011.41
1
977.353
1011.61
1
997.831
1011.81
1
1023.17
1012.01
1
1057
1012.21
1
1056.94
1012.41
1
1098.57
1012.61
1
1088.82
1012.81
1
1110.64
1013.01
1
1154.69
1013.21
1
1178.23
1013.41
1
1235.84
1013.61
1
1236.37
1013.81
1
1227.79
1014.01
1
1278.21
1014.21
1
1268.86
1014.41
1
1257.63
1014.61
1
1240.09
1014.81
1
1218.87
1015.01
1
1171.19
1015.21
1
1122.54
1015.41
1
1067.41
1015.46
1
1067.29
1015.51
1
1042.15
1015.61
1
1039.02
1015.66
1
1052.82
1015.71
1
1013.77
1015.81
1
984.758
1015.86
1
978.853
1015.91
1
992.657
1016.01
1
997.976
1016.06
1
962.513
1016.11
1
978.607
1016.21
1
925.061
1016.26
1
950.873
1016.31
1
914.095
1016.41
1
924.448
1016.46
1
887.492
1016.56
1
879.719
1016.66
1
879.291
1016.76
1
856.757
1016.86
1
879.182
1016.96
1
840.365
1017.06
1
838.737
1017.16
1
813.429
1017.26
1
819.672
1017.36
1
810.392
1017.46
1
797.662
1017.56
1
778.964
1017.66
1
800.196
1017.76
1
749.445
1017.86
1
760.85
1017.96
1
761.03
1018.06
1
783.447
1018.16
1
764.45
1018.26
1
777.982
1018.36
1
777.032
1018.46
1
741.676
1018.56
1
762.665
1018.66
1
752.13
1018.76
1
774.162
1018.86
1
786.274
1018.96
1
783.227
1019.06
1
787.6
1019.16
1
830.725
1019.26
1
865.198
1019.36
1
845.633
1019.46
1
863.046
1019.56
1
913.775
1019.66
1
925.225
1019.76
1
971.033
1019.86
1
972.082
1019.96
1
1031.97
1020.06
1
1079.9
1020.16
1
1142.77
1020.26
1
1234.21
1020.36
1
1301.29
1020.46
1
1402.01
1020.56
1
1505.27
1020.66
1
1564.52
1020.76
1
1699.57
1020.86
1
1802.46
1020.96
1
1969.59
1021.06
1
2061.9
1021.16
1
2171.67
1021.26
1
2257.47
1021.36
1
2367.68
1021.46
1
2451.52
1021.56
1
2485.79
1021.66
1
2550.8
1021.76
1
2501.27
1021.86
1
2497.04
1021.96
1
2489.07
1022.06
1
2401.55
1022.16
1
2306.04
1022.26
1
2227.36
1022.36
1
2067.64
1022.46
1
1950.63
1022.56
1
1827.21
1022.66
1
1672.22
1022.76
1
1578.01
1022.86
1
1434.8
1022.96
1
1348.1
1023.06
1
1235.91
1023.16
1
1158.64
1023.26
1
1128.58
1023.36
1
1032.33
1023.46
1
996.215
1023.56
1
937.285
1023.66
1
904.001
1023.76
1
860.988
1023.86
1
830.683
1023.96
1
814.335
1024.06
1
784.465
1024.16
1
784.869
1024.26
1
778.737
1024.36
1
758.673
1024.46
1
751.087
1024.56
1
748.745
1024.66
1
748.907
1024.76
1
759.631
1024.86
1
746.531
1024.96
1
778.526
1025.06
1
759.716
1025.16
1
777.027
1025.26
1
786.215
1025.36
1
791.529
1025.46
1
813.631
1025.56
1
823.737
1025.66
1
847.126
1025.76
1
871.589
1025.86
1
931.456
1025.96
1
975.757
1026.06
1
1058.22
1026.16
1
1166.62
1026.26
1
1291.99
1026.36
1
1511.6
1026.46
1
1744.35
1026.56
1
2048.32
1026.66
1
2474.29
1026.76
1
3041.37
1026.86
1
3616.82
1026.96
1
4302.5
1027.06
1
4948.24
1027.16
1
5592.03
1027.26
1
6117.37
1027.36
1
6544.88
1027.46
1
6705.58
1027.56
1
6634.5
1027.66
1
6363.31
1027.76
1
5828.6
1027.86
1
5100.96
1027.96
1
4440.83
1028.06
1
3670.51
1028.16
1
2989.35
1028.26
1
2373.67
1028.36
1
1882.81
1028.46
1
1449.51
1028.56
1
1138.66
1028.66
1
880.955
1028.76
1
710.739
1028.86
1
593.143
1028.96
1
493.952
1029.06
1
430.007
1029.16
1
375.74
1029.26
1
307.498
1029.36
1
289.607
1029.46
1
261.454
1029.56
1
241.45
1029.66
1
195.994
1029.76
1
178.111
1029.86
1
171.642
1029.96
1
148.703
1030.06
1
122.799
1030.16
1
123.658
1030.26
1
113.168
1030.36
1
89.9611
1030.46
1
82.6402
1030.56
1
71.4293
1030.66
1
75.3822
1030.76
1
65.8195
1030.86
1
53.6695
1030.96
1
45.9551
1031.06
1
45.7672
1031.16
1
37.6953
1031.26
1
45.1279
1031.36
1
43.102
1031.46
1
41.8022
1031.56
1
34.3535
1031.66
1
41.0285
1031.76
1
24.1728
1031.86
1
24.8709
1031.96
1
30.3581
1032.06
1
26.7379
1032.16
1
27.4104
1032.26
1
35.0028
1032.36
1
18.7488
1032.46
1
31.8477
1032.56
1
28.1205
1032.66
1
22.1481
1032.76
1
23.383
1032.86
1
18.631
1032.96
1
12.2888
1033.06
1
16.5876
1033.16
1
13.8555
1033.26
1
7.00553
1033.36
1
9.75463
1033.46
1
10.5411
1033.56
1
9.85089
1033.66
1
15.0159
1033.76
1
16.9822
1033.86
1
10.2562
1033.96
1
14.6918
1034.06
1
18.4523
1034.16
1
20.0307
1034.26
1
12.6893
1034.36
1
4.38198
1034.46
1
13.7239
1034.56
1
12.7116
1034.66
1
12.2761
1034.76
1
4.75145
1034.86
1
11.4553
1034.96
1
19.1661
1035.06
1
14.8176
1035.16
1
12.2612
1035.26
1
13.668
1035.36
1
6.80692
1035.46
1
3.57823
1035.56
1
10.8517
1035.66
1
8.48454
1035.76
1
9.99754
1035.86
1
3.32511
1035.96
1
5.30515
1036.06
1
-0.15255
1036.16
1
4.10473
1036.26
1
1.58446
1036.36
1
12.2091
1036.46
1
14.8672
1036.56
1
4.71866
1036.66
1
9.98924
1036.76
1
6.98157
1036.86
1
8.02528
1036.96
1
-3.58963
1037.06
1
3.92434
1037.16
1
8.52046
1037.26
1
6.96935
1037.36
1
-6.73835
1037.46
1
4.97275
1037.56
1
-2.7992
1037.66
1
5.40891
1037.76
1
-3.69174
1037.86
1
2.41516
1037.96
1
3.25827
1038.06
1
-0.126762
1038.16
1
2.44671
1038.26
1
0.257914
1038.36
1
3.89457
1038.46
1
-5.8306
1038.56
1
4.5545
1038.66
1
0.264434
1038.76
1
1.67889
1038.86
1
3.29361
1038.96
1
7.03935
1039.06
1
3.16899
1039.16
1
7.20019
1039.26
1
-2.25084
1039.36
1
-2.53558
1039.46
1
-4.11686
1039.56
1
2.61504
1039.66
1
-3.20836
1039.76
1
4.38263
1039.86
1
6.05281
1039.96
1
3.3128
1040.06
1
1.48788
1040.16
1
2.66528
1040.26
1
2.751
1040.36
1
0
1
end of experiment