File: xpsdeeplearning/data/references/NiCoFe/EX491-495 Fe, Ni, Co oxide references.vms
VAMAS Surface Chemical Analysis Standard Data Transfer Format 1988 May 4
Not Specified
Not Specified
Not Specified
Not Specified
13
Casa Info Follows CasaXPS Version 2.3.24PR1.0
0
Created by SpecsLab Prodigy, Version 4.73.2-r95032
SourceAnalyserAngle: Not Specified
CasaRowLabel:Co
CasaRowLabel:Co3O4
CasaRowLabel:CoO
CasaRowLabel:Fe
CasaRowLabel:Fe2O3
CasaRowLabel:Fe3O4
CasaRowLabel:FeO
CasaRowLabel:Ni
CasaRowLabel:NiO
NORM
REGULAR
9
1
Exp Variable
d
0
0
0
0
62
Survey
Co
2021
4
27
18
28
6
0
15
Casa Info Follows
0
0
0
0
File = E:/OwnCloud/XPS lab/EX491_S745_Co.sle
Group = RT in vacuum, #Treatments:4h sputter, #Temp:RT , #Pressure:vacuum , #Atmosphere:{:}, #Comments:
First of group = 1
Spectrum ID = 13
Analyzer lens = LargeArea:1.5kV
Analyzer slit = 4:7x20c\C:mesh
Scan mode = FixedAnalyzerTransmission
Kinetic energy start = 286.61
PCA Coefs = 148206, -15288.9, -1023.74, -577.522, -1664.67, 621.197,
C:\Users\Mark\Downloads\EX491_S745_Co (1).vms
XPS
1
Al
1486.61
0
0
0
54.5
180
FAT
100
1
4.1408
0
0
0
0
0
Survey

-1
kinetic energy
eV
286.61
1
2
counts
d
Transmission
d
pulse counting
0.1
0
0
0
191.047
1
3654.4
3665.99
3654.94
3667.85
3674.77
3692.47
3693.12
3691.98
3710.61
3689.09
3701.53
3719.47
3734.31
3754.87
3758.52
3787.56
3801.82
3780.63
3756.14
3790.89
3824.62
3826.37
3811.29
3827.25
3869.91
3838.93
3863.57
3893.23
3891
3892.39
3949.49
3913.14
3899.41
3912.73
3958.12
3934.23
3952.55
3994.67
3990.13
3956.77
4009.88
4034.72
4009.5
4035.09
4053.12
4067.85
4077.08
4079.16
4068.44
4104.51
4126.88
4128.85
4138.58
4145.27
4186.37
4169.97
4184.22
4184.05
4221.04
4247.74
4283.6
4249.97
4226.58
4251.9
4263.35
4260.5
4318.77
4339.31
4299.72
4309.18
4368.27
4350.77
4364.33
4382.72
4369.89
4408.6
4414.66
4418.66
4402
4440.6
4460.18
4453.55
4484.29
4498.56
4520.6
4528.95
4533.06
4541.35
4544.99
4623.02
4585.29
4601.13
4614.4
4618.05
4629.18
4647.02
4665.98
4646.13
4657.82
4651.47
4748.25
4747.59
4752.53
4746.22
4768.54
4776.47
4830.06
4819.58
4811.26
4825.86
4837.24
4849.53
4879.66
4872.56
4866.39
4887.26
4940.21
4962.44
4940.39
4934.41
4984.2
5019.41
5038.51
5017.83
5013.04
5048.1
5075.72
5112.66
5105.57
5104.38
5109.49
5117.98
5161.86
5187.33
5161.07
5183.74
5193.93
5225.17
5203.14
5229.14
5188.21
5265.5
5255.74
5268.24
5299.46
5337.56
5332.52
5341.09
5344.08
5350.16
5362.57
5369.84
5425.57
5441.55
5450.48
5431.88
5411.7
5461.81
5528.73
5524.64
5496.87
5534.56
5557.05
5546.73
5620.65
5644.82
5658.29
5653.06
5673.48
5715.03
5655.18
5713.16
5744.48
5740.64
5772.6
5769.36
5814.22
5818.28
5817.12
5813.16
5857.57
5830.3
5878.11
5936.11
5914.07
5909.82
5919.48
5976.88
5992.47
6022.47
6039.78
6076.66
6066.87
6003.4
6060.8
6131.99
6155.57
6110.32
6156.22
6176.85
6219.14
6191.25
6251.71
6295.59
6269.98
6286.33
6347.73
6330.13
6405.18
6352.99
6335.43
6398.33
6415
6427.51
6498.98
6545.03
6546.39
6536.73
6565.61
6590.95
6600.58
6640.27
6687.82
6724.71
6777.83
6760.64
6787.22
6829.61
6833.51
6831.2
6812.74
6863.58
6880.36
6912.99
6933.69
6939.4
6962.57
7056.12
7039.22
7063.53
7079.52
7119.52
7115.26
7143.17
7168.91
7198.29
7269.22
7305.13
7281.24
7326.94
7322.62
7388.59
7382.19
7423.56
7442.31
7485.81
7483.42
7511.99
7535.28
7574.7
7607.23
7685.24
7740.52
7736.32
7737.05
7819.2
7879.74
7939.12
8075.72
8098.69
8255.27
8334.44
8382.9
8463.93
8534.18
8583.92
8426.03
8251.34
7990.96
7798.42
7637.86
7558.13
7533.1
7433.38
7385.87
7383.68
7410.21
7371.04
7339.35
7331.6
7337.19
7360.71
7392.48
7446.33
7412.12
7415.78
7473.16
7457.31
7529.4
7513.83
7515.35
7517.1
7603.23
7666.64
7659.34
7674.83
7771.12
7766.63
7767.06
7756.93
7841.18
7908.5
7962.72
8018.89
8044.34
8123.36
8168.43
8180.24
8168.47
8185.84
8198.58
8204.22
8174.16
8192.15
8193.17
8251.11
8323.37
8394.67
8393.76
8507.81
8666.78
8734.52
8731.95
8621.45
8519.29
8411.59
8419.69
8493.03
8534.69
8529.09
8568.18
8623.2
8628.73
8725.79
8727.89
8792.53
8861.61
8922.46
8924.61
9032.5
9129.32
9135.67
9297.43
9311.49
9392.21
9434.44
9627.73
9718.86
9846.65
9991.17
10123.5
10230.1
10255.1
10171.3
10059.4
9901.94
9880.64
9983.55
10116.9
10156
10000.2
9554.12
9141.52
8923.74
8755.1
8683.35
8623.74
8630.12
8613.28
8643.1
8679.97
8763.56
8786.77
8846.32
8853.49
8957.49
9056.24
8969.24
8953.15
9033.04
9092.51
9091.8
9152.22
9216.96
9281.63
9407.43
9452.07
9575.65
9704.29
9803.51
9911.12
10169.2
10482.1
10919.7
11693.5
12849.2
13641.8
12528.7
10346.8
9090.62
8818.29
8784.51
8935.99
9133.74
9385.16
9713.6
10171.4
10654.1
11277.6
12535.4
15804
18922.9
15652.8
9424.02
6553.38
5823.89
5421.47
5228.54
5164.03
4948.19
4667.88
4258.27
3639.85
3126.78
2758.81
2631.65
2557.65
2495.85
2465.68
2415.58
2347.93
2268.23
2274.96
2255.22
2201.01
2142.05
2115.27
2082.85
2045.08
2070.76
2072.96
2070.66
2077.75
2130.73
2195.05
2194.88
2198.19
2222.96
2244.69
2249.03
2277.39
2274.1
2292.76
2311.61
2351.65
2343.22
2340.75
2353.2
2354.48
2377.18
2403.29
2438.15
2481.42
2529.75
2555.55
2613.81
2668.59
2784.65
2911.93
3030.58
3185.38
3433.21
3666.69
4009.35
4497.51
5049.15
5549.36
5639.76
5139.31
4305.06
3314.05
2363.25
1717.26
1428.28
1250.03
1170.38
1158.2
1129.12
1150.64
1182.77
1251.62
1243.96
1248.51
1175.99
1039.46
895.466
776.892
674.097
599.503
559.526
559.709
543.265
525.381
526.795
529.561
514.999
524.398
523.228
520.226
526.769
531.189
517.748
518.934
522.566
525.986
527.829
529.323
521.915
531.696
531.854
534.535
526.934
528.279
525.611
536.872
524.444
519.763
534.741
527.188
519.419
509.445
526.343
512.579
519.502
519.268
521.76
509.058
516.546
525.254
530.123
525.095
516.658
515.852
520.02
526.205
514.695
510.113
522.959
522.737
547.952
526.979
525.8
529.923
535.436
527.744
528.522
534.445
535.098
519.506
537.83
538.531
531.997
527.29
534.998
526.449
536.207
538.438
527.897
527.8
538.712
521.992
535.534
542.301
539.651
546.046
537.05
543.364
544.438
536.828
546.901
556.887
552.049
554.582
544.956
541.448
555.893
560.692
544.389
564.085
559.591
545.531
544.851
560.774
558.498
553.549
564.677
561.035
558.784
563.617
550.625
553.569
570.839
563.729
554.741
555.693
573.792
574.714
584.544
583.153
574.487
584.663
579.575
576.161
597.003
591.355
602.906
600.908
578.017
590.904
590.607
590.75
600.689
604.633
598.115
601.17
596.667
581.036
582.281
581.839
588.233
588.302
586.405
583.06
583.202
581.66
592.625
596.424
594.78
603.309
613.432
588.878
582.931
582.047
596.477
599.582
593.069
594.303
603.577
604.596
615.752
613.867
604.958
577.908
590.642
617.002
625.081
629.309
624.753
687.39
764.409
823.778
781.017
658.113
597.386
607.059
600.901
602.69
607.267
606.058
605.275
604.697
611.554
599.964
600.479
619.373
608.123
612.631
601.097
609.166
610.721
617.094
621.198
612.679
608.786
611.565
608.203
635.71
627.456
630.96
630.72
625.901
625.954
617.409
615.607
636.944
634.651
628.29
638.796
626.753
627.586
631.926
636.935
638.682
641.412
646.972
651.21
644.45
646.895
630.04
637.583
650.07
649.371
649.092
643.296
634.177
653.573
653.148
655.546
655.814
648.847
642.804
652.965
654.433
653.236
662.015
661.954
654.934
641.009
654.043
667.249
671.899
667.588
672.73
669.342
667.92
669.419
665.71
677.07
667.106
678.08
677.225
672.888
668.317
677.243
678.551
670.413
682.689
677.78
681.269
678.269
689.035
700.191
673.616
682.212
680.382
674.603
677.712
681.448
701.351
713.102
703.459
700.742
686.297
679.327
699.405
711.18
682.164
695.408
692.977
687.711
697.041
699.834
703.398
707.349
710.113
718.977
721.231
720.079
720.642
715.141
728.802
723.742
720.64
711.975
711.205
716.186
725.918
733.65
735.522
732.262
735.598
728.572
725.544
729.048
741.72
715.725
733.232
724.529
741.782
741.833
748.006
768.225
751.074
762.502
751.522
738.186
745.351
759.367
750.633
752.114
758.148
760.644
760.902
770.962
769.632
769.384
767.929
762.603
776.326
743.859
763.622
780.537
781.912
766.159
775.02
784.049
788.156
785.525
796.613
780.414
783.694
791.31
784.474
789.094
781.665
798.314
803.008
790.004
787.804
787.986
801.68
811.517
797.595
805.974
810.289
807.188
818.332
812.171
816.416
805.888
802.23
817.115
812.114
811.564
813
818.258
816.461
817.532
813.945
812.649
824.725
824.106
831.763
831.449
830.669
842.872
847.194
866.361
882.475
904.799
922.64
878.911
856.427
861.373
845.287
824.582
825.172
824.634
843.993
832.006
831.51
834.223
848.275
856.773
852.931
863.996
865.091
862.105
857.829
852.442
864.23
849.599
856.562
872.344
879.102
885.161
853.722
875.385
861.237
866.757
869.626
884.536
859.976
866.993
874.822
963.764
1032.88
991.664
898.037
864.341
870.108
861.583
878.525
869.859
881.456
885.535
889.412
886.699
886.88
888.049
889.313
890.33
890.27
914.03
922.894
912.046
910.383
894.695
913.486
898.075
882.752
883.466
885.851
900.318
891.575
894.832
912.485
907.547
904.56
895.005
900.868
904.286
917.162
927.406
941.322
1013.9
1071.16
1119.14
1082.06
987.937
918.319
929.571
905.477
902.206
910.555
902.177
907.359
901.009
904.756
895.054
903.211
907.425
907.134
916.726
916.737
913.938
919.261
936.583
938.896
935.386
936.268
930.597
914.564
924.59
936.089
937.546
951.78
947.368
944.335
963.082
946.816
952.605
963.758
967.221
938.294
944.354
955.79
961.173
956.358
978.055
974.031
976.772
963.877
976.796
998.927
977.069
991.682
980.21
980.423
991.802
997.911
984.253
996.9
1004.33
1015.15
1010.58
1022.68
1011.51
1024.9
1025.24
1010.84
1035.75
1030.49
1022.59
1033.42
1056.78
1040.08
1049.12
1046.64
1056.19
1053.21
1047.76
1052.57
1075.23
1061.4
1063.36
1069.23
1077.19
1060.11
1053.62
1086.08
1098.45
1098.92
1094.76
1094.37
1099.72
1094.73
1098.06
1119.85
1125.56
1135.11
1117.53
1131.02
1152.46
1172.05
1154.37
1150.35
1171.62
1174.21
1177.46
1194.92
1215.87
1212.93
1225.07
1218.86
1241.72
1255.37
1234.65
1267.01
1287.02
1284.76
1303.76
1292.39
1285.9
1293.76
1309.7
1298.48
1289.66
1288.29
1300.94
1305.67
1299.18
1309.89
1339.16
1340.66
1371.39
1375.6
1394.76
1428.43
1467.56
1501.17
1556.66
1617.27
1667.65
1695.71
1762.81
1860.21
2074.53
2268.58
2197.83
1878.15
1549.5
1357.22
1298.04
1258.67
1220.05
1226.65
1233.48
1233.38
1261.56
1254.66
1279.84
1315.58
1287.97
1300.01
1297.29
1320.19
1318.54
1307.86
1301.44
1330.95
1334.2
1360.62
1359.66
1356.04
1355.84
1367.29
1392.41
1442.78
1470.89
1478.99
1470.09
1484.29
1505.84
1563.03
1679.45
1832.93
2091.38
2560.03
3226.88
3574.58
2750.12
1421.84
640.694
410.622
320.521
283.143
251.162
227.784
226.579
213.643
210.612
205.197
206.174
204.779
207.137
200.941
194.32
200.16
206.064
203.343
203.556
214.322
221.484
211.391
223.51
231.1
234.309
232.16
233.194
235.864
234.022
239.678
234.113
238.403
240.424
241.299
242.084
247.903
233.847
224.838
227.064
228.147
228.125
229.101
231.825
246.698
256.166
266.459
288.563
319.164
340.295
375.724
411.318
451.736
534.37
639.108
752.805
866.673
702.726
316.703
1
Ni2p
Co
2021
4
27
18
31
38
0
15
Casa Info Follows
0
0
0
0
File = E:/OwnCloud/XPS lab/EX491_S745_Co.sle
Group = RT in vacuum, #Treatments:4h sputter, #Temp:RT , #Pressure:vacuum , #Atmosphere:{:}, #Comments:
First of group = 0
Spectrum ID = 14
Analyzer lens = AngleResolvedMode22:1.5kV
Analyzer slit = 4:7x20c\C:mesh
Scan mode = FixedAnalyzerTransmission
Kinetic energy start = 596.61
PCA Coefs = 88161, 874.253, -205.672, -14.2742,
C:\Users\Mark\Downloads\EX491_S745_Co (1).vms
XPS
1
Al
1486.61
0
0
0
54.5
180
FAT
20
1
4.1408
0
0
0
0
0
Ni
2p
-1
kinetic energy
eV
596.61
0.1
2
counts
d
Transmission
d
pulse counting
0.1
2
0
0
0
0
0
1002
3532.66
4584.98
1
1
3591.67
1
3600.06
1
3581.49
1
3591.26
1
3609.91
1
3610.17
1
3610.35
1
3612.63
1
3614.44
1
3604.67
1
3611.32
1
3597.89
1
3598.85
1
3616.09
1
3640.9
1
3624.21
1
3621.53
1
3627.24
1
3641.89
1
3629.7
1
3643.83
1
3649.19
1
3632.85
1
3648.26
1
3643.08
1
3667.99
1
3639.67
1
3652.65
1
3651.15
1
3635.15
1
3647.88
1
3648.05
1
3653.19
1
3674.57
1
3668.9
1
3650.92
1
3660.11
1
3672.34
1
3668.09
1
3674.92
1
3689.95
1
3697.37
1
3682.07
1
3662.95
1
3683.84
1
3677.98
1
3686.51
1
3711.64
1
3677.2
1
3689.08
1
3713.46
1
3716.98
1
3699.48
1
3708.66
1
3707.39
1
3719.94
1
3702.69
1
3723.52
1
3716.9
1
3724.09
1
3709.59
1
3711.49
1
3711.27
1
3705.32
1
3720.94
1
3706.1
1
3711.76
1
3715.16
1
3733.86
1
3728.86
1
3711.87
1
3730.56
1
3748.06
1
3744.92
1
3727.28
1
3728.72
1
3740.34
1
3747.14
1
3750.08
1
3744.05
1
3757.22
1
3769.21
1
3748.98
1
3743.55
1
3753.29
1
3749.42
1
3768.35
1
3773.39
1
3765.52
1
3768.68
1
3757.24
1
3769.99
1
3756.23
1
3756.18
1
3770.29
1
3772.88
1
3756.29
1
3767.91
1
3788.51
1
3775.55
1
3766.31
1
3788.39
1
3790.63
1
3762.55
1
3753.97
1
3755.59
1
3757.57
1
3774.85
1
3772.37
1
3764.58
1
3740.08
1
3755.64
1
3759.2
1
3764.57
1
3776.27
1
3766.95
1
3760.05
1
3762.74
1
3743.57
1
3746.26
1
3751.04
1
3761.8
1
3752.32
1
3746.81
1
3744.03
1
3747.23
1
3734.23
1
3753.9
1
3740.3
1
3739.92
1
3756.23
1
3749.33
1
3729.85
1
3721.6
1
3752.12
1
3753.66
1
3735.93
1
3730.67
1
3745.35
1
3733.9
1
3737.8
1
3740.4
1
3739.51
1
3744.54
1
3743.67
1
3721.95
1
3731.78
1
3757.54
1
3751
1
3737.57
1
3733.21
1
3739.13
1
3768.82
1
3790.61
1
3779.88
1
3779.73
1
3761.95
1
3780.52
1
3781.3
1
3785.53
1
3759.5
1
3762.89
1
3760.07
1
3771.81
1
3780.99
1
3781.58
1
3796.45
1
3803.92
1
3802.25
1
3791.26
1
3777.66
1
3786.86
1
3782.22
1
3771.29
1
3786.66
1
3800.01
1
3819.53
1
3809.05
1
3814.07
1
3807.86
1
3818.43
1
3821.73
1
3813.77
1
3831.76
1
3839.37
1
3838.1
1
3849.79
1
3847.01
1
3853.2
1
3850.7
1
3865.12
1
3871.52
1
3896.98
1
3867.09
1
3882.41
1
3894.76
1
3895.31
1
3895.32
1
3893.11
1
3913.94
1
3911.31
1
3889.65
1
3889.07
1
3922.37
1
3916
1
3907.8
1
3930.9
1
3941.18
1
3931.65
1
3948.53
1
3956.88
1
3964.03
1
3978.5
1
3963.67
1
3967.5
1
3952.06
1
3970.91
1
3978.55
1
3962.27
1
3984.2
1
3989.83
1
3985.61
1
3984.08
1
3981.44
1
3950.97
1
3950.26
1
3961.71
1
3956.31
1
3961.17
1
3949.51
1
3941.25
1
3912.02
1
3917.43
1
3912.86
1
3904.99
1
3899.61
1
3891.68
1
3893.96
1
3898.41
1
3898.9
1
3888.17
1
3876.63
1
3853.49
1
3882.16
1
3878.64
1
3898.08
1
3878.06
1
3871.02
1
3886.81
1
3872.37
1
3856.05
1
3854.38
1
3846.34
1
3836.39
1
3848.75
1
3851.9
1
3840.05
1
3835.36
1
3840.36
1
3847.9
1
3849.22
1
3843.05
1
3863.24
1
3864.2
1
3857.01
1
3858.9
1
3856.81
1
3843.03
1
3847.92
1
3847.02
1
3849.6
1
3846.71
1
3864.16
1
3873.42
1
3874.29
1
3856.52
1
3850.25
1
3846.92
1
3863.09
1
3850.84
1
3847.45
1
3862.01
1
3859.19
1
3867.23
1
3857.7
1
3859.03
1
3885.88
1
3869.27
1
3873.03
1
3917.7
1
3897.44
1
3882.9
1
3879.14
1
3876.64
1
3882.62
1
3867.67
1
3878.81
1
3892.17
1
3879.2
1
3901.24
1
3899.51
1
3898.95
1
3897.29
1
3900.47
1
3906.19
1
3884.56
1
3891.13
1
3882.01
1
3889.66
1
3902.34
1
3887.44
1
3894.03
1
3892.5
1
3915.28
1
3911.26
1
3895.86
1
3915.54
1
3921.96
1
3923.47
1
3926.52
1
3923.08
1
3917.3
1
3915.72
1
3930.53
1
3951.53
1
3936.25
1
3919.9
1
3941.47
1
3951.23
1
3940.15
1
3932.54
1
3921.06
1
3933.38
1
3959.04
1
3958.31
1
3976.14
1
3975.92
1
3951.2
1
3973.03
1
3977.99
1
3972.82
1
3973.49
1
3965.87
1
3974.58
1
3968.49
1
3972.42
1
3993.24
1
3980.78
1
3965.15
1
3988.51
1
3980.33
1
3989.09
1
3992.84
1
4000.78
1
4018.57
1
3988.49
1
4003.33
1
4003.09
1
4000.25
1
3988.11
1
4017.17
1
4018.3
1
4003.38
1
4010.02
1
4006.39
1
4045.92
1
4013.34
1
4024.17
1
4027.78
1
4034.06
1
4016.54
1
4040.31
1
4040.52
1
4044.88
1
4021.73
1
4029.35
1
4031.59
1
4055.78
1
4033.98
1
4054.52
1
4066.63
1
4060.04
1
4062.45
1
4054.67
1
4044.59
1
4083.85
1
4080.75
1
4076.92
1
4090.91
1
4097.89
1
4100.39
1
4100.31
1
4097.68
1
4099.33
1
4097
1
4094.4
1
4113.26
1
4100.25
1
4118.86
1
4111.39
1
4111.31
1
4115.33
1
4112.54
1
4128.25
1
4146.76
1
4137.05
1
4150.16
1
4132.85
1
4151.86
1
4166.23
1
4169.92
1
4144.12
1
4158.14
1
4165.14
1
4168.11
1
4190.15
1
4198.23
1
4185.94
1
4193.98
1
4200.5
1
4188.23
1
4181.64
1
4188.38
1
4170.91
1
4196.12
1
4212.02
1
4213.3
1
4215.69
1
4218.14
1
4219.89
1
4235.66
1
4251.2
1
4237.03
1
4234.68
1
4232.84
1
4260.43
1
4269.18
1
4253.95
1
4256.56
1
4245.3
1
4269.67
1
4261.98
1
4271.43
1
4257.59
1
4258.57
1
4278.34
1
4263.77
1
4260.32
1
4274.42
1
4255.02
1
4288.99
1
4303.08
1
4311.99
1
4288.29
1
4289.29
1
4301.31
1
4304.46
1
4302.86
1
4316.13
1
4311.37
1
4307.77
1
4307.47
1
4343.24
1
4326.22
1
4324.05
1
4315.31
1
4328.91
1
4342.06
1
4359.06
1
4354.54
1
4356.59
1
4371.92
1
4379.19
1
4383.15
1
4380.37
1
4372.68
1
4414.63
1
4414.62
1
4396.89
1
4398.05
1
4392.66
1
4424.28
1
4423.75
1
4435.59
1
4431.74
1
4454.52
1
4444.72
1
4464.17
1
4462.55
1
4470.45
1
4470.12
1
4485.13
1
4497.8
1
4507.26
1
4527.15
1
4513.82
1
4507.28
1
4505.05
1
4524.27
1
4522.34
1
4526.55
1
Co2p
Co
2021
4
27
18
36
14
0
15
Casa Info Follows
0
0
0
0
File = E:/OwnCloud/XPS lab/EX491_S745_Co.sle
Group = RT in vacuum, #Treatments:4h sputter, #Temp:RT , #Pressure:vacuum , #Atmosphere:{:}, #Comments:
First of group = 0
Spectrum ID = 15
Analyzer lens = AngleResolvedMode22:1.5kV
Analyzer slit = 4:7x20c\C:mesh
Scan mode = FixedAnalyzerTransmission
Kinetic energy start = 646.61
PCA Coefs = 117821, -21153.7, -1403.13, 970.754, 1743.34,
C:\Users\Mark\Downloads\EX491_S745_Co (1).vms
XPS
1
Al
1486.61
0
0
0
54.5
180
FAT
20
1
4.1408
0
0
0
0
0
Co
2p
-1
kinetic energy
eV
646.61
0.1
2
counts
d
Transmission
d
pulse counting
0.1
2
0
0
0
0
0
1402
2120.19
13889.6
1
1
4565.58
1
4573.78
1
4592.52
1
4594.61
1
4589.69
1
4625.72
1
4632.34
1
4631.83
1
4617.53
1
4622.36
1
4628.75
1
4610.33
1
4632.59
1
4652.39
1
4642.18
1
4638.13
1
4638.33
1
4636.05
1
4663.47
1
4659.32
1
4661.18
1
4667.98
1
4662.28
1
4655.87
1
4634.72
1
4634.58
1
4621.88
1
4640.71
1
4643.94
1
4641.59
1
4631.49
1
4605.81
1
4636.11
1
4633.43
1
4611.44
1
4623.11
1
4605.16
1
4584.81
1
4595.82
1
4589.15
1
4578.12
1
4587.29
1
4580.29
1
4540.5
1
4526.17
1
4526.69
1
4532.22
1
4489.65
1
4503.42
1
4509.74
1
4497.77
1
4503.13
1
4497.29
1
4512.85
1
4485.34
1
4494.74
1
4483.6
1
4474.39
1
4469.59
1
4451.37
1
4425.91
1
4467.92
1
4467.25
1
4444.25
1
4463.18
1
4484.65
1
4500.96
1
4465.22
1
4441.89
1
4448.85
1
4476.73
1
4486.37
1
4491.61
1
4511.35
1
4526.53
1
4512.47
1
4515.82
1
4521.5
1
4519.35
1
4519.94
1
4541.25
1
4560.45
1
4612.8
1
4626.28
1
4638.57
1
4605.67
1
4629.09
1
4643.45
1
4655.13
1
4652.27
1
4667.74
1
4654.73
1
4691.46
1
4699.84
1
4681.69
1
4657.73
1
4685.2
1
4652.53
1
4660.02
1
4649.62
1
4616.76
1
4623.6
1
4618.29
1
4610.17
1
4578.82
1
4569.14
1
4515.38
1
4510.69
1
4484.02
1
4465.77
1
4433.52
1
4385.32
1
4354.16
1
4367.07
1
4324.94
1
4286.76
1
4258.85
1
4232.18
1
4189.11
1
4181.66
1
4174.6
1
4162.63
1
4147.71
1
4100.91
1
4083.54
1
4068.67
1
4055.87
1
4063.55
1
4036.66
1
4038.03
1
4002.93
1
4013.89
1
3994.06
1
3977.06
1
3986.67
1
3986.11
1
3961.77
1
3941.76
1
3968.53
1
3960.37
1
3954.85
1
3917.05
1
3915.17
1
3928.73
1
3917.22
1
3947.12
1
3931.18
1
3917.23
1
3902.98
1
3872
1
3911.59
1
3914.28
1
3908.09
1
3940.57
1
3932.52
1
3892.21
1
3920.19
1
3939.9
1
3910.85
1
3890.28
1
3878
1
3907.75
1
3899.35
1
3867.71
1
3884.25
1
3891.64
1
3893.9
1
3913.15
1
3901.38
1
3914.45
1
3882.95
1
3893.55
1
3911.72
1
3884.93
1
3902.85
1
3912.22
1
3885.39
1
3878.58
1
3909.17
1
3928.02
1
3910.91
1
3916.38
1
3923.95
1
3932.93
1
3886.43
1
3887.47
1
3892.57
1
3925.69
1
3912.36
1
3891.64
1
3900.66
1
3902.32
1
3930.83
1
3916.06
1
3909.01
1
3932.12
1
3931.42
1
3899.78
1
3895.55
1
3898.03
1
3918.04
1
3911.14
1
3898.61
1
3916.07
1
3938.36
1
3929.22
1
3925.19
1
3918.33
1
3940.54
1
3972.24
1
3966.15
1
3932.3
1
3921.75
1
3952.09
1
3946.19
1
3953.93
1
3964.75
1
3978.08
1
3943.78
1
3975.15
1
3966.39
1
3953.27
1
3981.42
1
3951.86
1
3978.86
1
3985.28
1
3985.37
1
3973.32
1
3986.93
1
3951.53
1
3955.54
1
3980.08
1
3993.82
1
4006.91
1
4013.88
1
4012.95
1
4004.59
1
3996.62
1
4014.7
1
4018.43
1
4011.66
1
4024.78
1
4008.87
1
4027.81
1
4022.19
1
4028.99
1
4039.46
1
4033.2
1
4063.18
1
4049.45
1
4039.69
1
4061.92
1
4065.55
1
4095.46
1
4069.28
1
4068.61
1
4057.23
1
4059.45
1
4085.93
1
4083.34
1
4055.85
1
4065.13
1
4051.45
1
4058.02
1
4064.88
1
4068.04
1
4055.55
1
4055.36
1
4047.27
1
4053.44
1
4045.58
1
4048.7
1
4022.46
1
4064.16
1
4058.76
1
4031.75
1
4029.82
1
4037.41
1
4010.65
1
4031.14
1
4028.63
1
4022.63
1
4041.42
1
4022.72
1
4043.11
1
4027.42
1
4054.13
1
4028.87
1
4024.91
1
4033.74
1
4041.64
1
4020.82
1
4054.24
1
4054.77
1
4040.36
1
4027.76
1
4036.72
1
4051.28
1
4027.17
1
4038.59
1
4053.37
1
4051.15
1
4053.17
1
4061.02
1
4055.42
1
4048.65
1
4074.19
1
4067.43
1
4091.31
1
4098.42
1
4093.23
1
4056.82
1
4064.68
1
4075.78
1
4089.18
1
4080.15
1
4100.41
1
4073.47
1
4069.8
1
4098.24
1
4089.62
1
4080.22
1
4071.68
1
4090.51
1
4115.9
1
4121.8
1
4112.85
1
4104.45
1
4149.54
1
4124.48
1
4138.13
1
4148.64
1
4170.52
1
4164.72
1
4188.67
1
4180.95
1
4165.31
1
4181.17
1
4187.54
1
4178.91
1
4180.78
1
4170.71
1
4227.2
1
4204.86
1
4202.67
1
4193.58
1
4197.05
1
4206.8
1
4199.6
1
4190.95
1
4209.2
1
4203.65
1
4226.81
1
4216.54
1
4217.43
1
4223.24
1
4229.41
1
4207.41
1
4240.63
1
4227.9
1
4233.24
1
4233.87
1
4252.25
1
4245.27
1
4257.93
1
4271.98
1
4245.85
1
4271.46
1
4273.98
1
4270.29
1
4272.6
1
4269.69
1
4281.04
1
4281.05
1
4311.61
1
4310.13
1
4282.84
1
4300.29
1
4320.27
1
4322.87
1
4341.28
1
4316.74
1
4316.45
1
4353.22
1
4329.21
1
4297.05
1
4319.06
1
4356.98
1
4376.28
1
4332.61
1
4350.19
1
4331.19
1
4359.29
1
4372.86
1
4362.28
1
4350.3
1
4377.97
1
4384.89
1
4408.84
1
4374.81
1
4374.07
1
4391.63
1
4399.03
1
4430.32
1
4450.77
1
4432.11
1
4436.09
1
4435.21
1
4448.8
1
4467.75
1
4474.36
1
4483.76
1
4497.12
1
4507.46
1
4527.36
1
4554.93
1
4544.55
1
4537.73
1
4556.31
1
4579.77
1
4577.42
1
4561.8
1
4623.04
1
4629.61
1
4633.98
1
4655.1
1
4667.86
1
4705.97
1
4730.06
1
4735.01
1
4752.94
1
4762.72
1
4792.45
1
4828.71
1
4828.7
1
4886.79
1
4913.73
1
4912.83
1
4935.49
1
4970.35
1
5023.92
1
5003.6
1
5051.46
1
5095.98
1
5137.54
1
5176.99
1
5229.74
1
5275.57
1
5304.85
1
5395.1
1
5429.72
1
5489.65
1
5540.86
1
5613.38
1
5699.42
1
5753.3
1
5831.5
1
5898.96
1
5980.26
1
6059.09
1
6178.68
1
6314.94
1
6411.18
1
6580.71
1
6699.06
1
6811.43
1
6936.81
1
7019.51
1
7041.27
1
7002.25
1
6864.2
1
6666.02
1
6434.5
1
6160.47
1
5878.15
1
5568.63
1
5279.12
1
5042.33
1
4837.55
1
4678.37
1
4510.26
1
4388.43
1
4303.01
1
4220.3
1
4147.16
1
4148.13
1
4054.21
1
4026.64
1
4015.76
1
4003.33
1
3955.86
1
3933.92
1
3904.73
1
3885.48
1
3875.89
1
3872.25
1
3829.81
1
3833.4
1
3830.76
1
3818.97
1
3824.02
1
3833.07
1
3813.13
1
3829
1
3808.58
1
3816.19
1
3820.59
1
3836.14
1
3851.1
1
3846.77
1
3837.17
1
3852.67
1
3853.64
1
3858.56
1
3896.86
1
3906.7
1
3901.95
1
3898.55
1
3884.65
1
3907.55
1
3933.9
1
3938.84
1
3931.22
1
3945.38
1
3945.76
1
3973.09
1
3988.31
1
3951.12
1
3970.79
1
3978
1
4011.65
1
4007.99
1
4008.87
1
4017.56
1
4024.89
1
4042.1
1
4070.59
1
4075.64
1
4066.28
1
4088.84
1
4091.6
1
4120.27
1
4107.12
1
4119.94
1
4126.51
1
4146.41
1
4135.17
1
4189.59
1
4216.82
1
4203.09
1
4203.86
1
4211.39
1
4242.9
1
4239.47
1
4277.85
1
4321.15
1
4327.86
1
4336.87
1
4344.37
1
4350.66
1
4360.84
1
4415.33
1
4399.67
1
4435.12
1
4454.85
1
4492.73
1
4494.65
1
4496.45
1
4550.34
1
4589.65
1
4615.25
1
4643.2
1
4683.1
1
4683.46
1
4720.65
1
4736.58
1
4789.94
1
4824.6
1
4822.89
1
4823.44
1
4875.44
1
4914.05
1
4888.3
1
4912.45
1
4905.75
1
4944.81
1
4961.19
1
4943.26
1
4970.8
1
5034.78
1
5025.78
1
5072.26
1
5151.96
1
5199.74
1
5242.44
1
5270.47
1
5403.71
1
5465.66
1
5529.36
1
5661.11
1
5744.31
1
5868.5
1
5997.12
1
6158.41
1
6342.74
1
6468.35
1
6720.09
1
6931.28
1
7225.09
1
7534.2
1
7946.21
1
8467.86
1
9085.86
1
9874.31
1
10799.3
1
11826.9
1
12812.9
1
13570.3
1
13923.1
1
13602.9
1
12656.8
1
11198.9
1
9520.84
1
7833.75
1
6439.82
1
5397.08
1
4667.5
1
4182.13
1
3815.72
1
3572.46
1
3406.33
1
3281.26
1
3175.14
1
3117.13
1
3049.81
1
2975.06
1
2948.42
1
2919.17
1
2884.24
1
2855.6
1
2843.81
1
2808.89
1
2803.59
1
2775.38
1
2766.78
1
2740.08
1
2693.98
1
2668.73
1
2657.65
1
2618.4
1
2593.98
1
2578.61
1
2536.15
1
2501.95
1
2483.01
1
2464.76
1
2433.08
1
2389.5
1
2370.49
1
2349.62
1
2376.13
1
2339.65
1
2307.94
1
2300.04
1
2282.35
1
2290.45
1
2300.01
1
2269.94
1
2253.01
1
2262.6
1
2265.68
1
2273.46
1
2271.7
1
2273.8
1
2264.05
1
2274.8
1
2272.8
1
2267.31
1
2259.87
1
2260.94
1
2283.3
1
2301.67
1
2283.84
1
2283.05
1
2300.14
1
2298.28
1
2283.51
1
2277.61
1
2288.35
1
2286.29
1
2286.73
1
2266.66
1
2255.9
1
2258.2
1
2230.89
1
2209.46
1
2186.02
1
2179.3
1
2177.35
1
2160.91
1
2138.65
1
Fe2p
Co
2021
4
27
18
40
49
0
15
Casa Info Follows
0
0
0
0
File = E:/OwnCloud/XPS lab/EX491_S745_Co.sle
Group = RT in vacuum, #Treatments:4h sputter, #Temp:RT , #Pressure:vacuum , #Atmosphere:{:}, #Comments:
First of group = 0
Spectrum ID = 16
Analyzer lens = AngleResolvedMode22:1.5kV
Analyzer slit = 4:7x20c\C:mesh
Scan mode = FixedAnalyzerTransmission
Kinetic energy start = 716.61
PCA Coefs = 32468.6, -4575.75, -244.522, -299.101, -116.521,
C:\Users\Mark\Downloads\EX491_S745_Co (1).vms
XPS
1
Al
1486.61
0
0
0
54.5
180
FAT
20
1
4.1408
0
0
0
0
0
Fe
2p
-1
kinetic energy
eV
716.61
0.1
2
counts
d
Transmission
d
pulse counting
0.1
2
0
0
0
0
0
1402
456.429
2662.14
1
1
2140.53
1
2131.21
1
2109.54
1
2096
1
2065.13
1
2053.15
1
2021.2
1
2017.9
1
2009.73
1
2002.16
1
1981.63
1
1956.09
1
1933.75
1
1928.91
1
1910.74
1
1905.49
1
1869.03
1
1837.99
1
1820.09
1
1806.02
1
1768.19
1
1726.17
1
1719.76
1
1682.45
1
1651.12
1
1615.9
1
1571.98
1
1529.59
1
1463.78
1
1426.97
1
1422.98
1
1379.69
1
1336.62
1
1324.51
1
1310.13
1
1288.63
1
1275.87
1
1260.23
1
1250.77
1
1250.04
1
1218.06
1
1206.2
1
1194.8
1
1197.15
1
1187.36
1
1189.48
1
1188.26
1
1172.11
1
1165.7
1
1172.87
1
1144.17
1
1147.09
1
1142.97
1
1144.71
1
1152.02
1
1141.8
1
1130.13
1
1134.49
1
1112.53
1
1102.93
1
1119.01
1
1114.99
1
1127.56
1
1116.24
1
1114.68
1
1115.82
1
1126.54
1
1105.33
1
1112.07
1
1123.2
1
1115.62
1
1102.12
1
1099.57
1
1098.32
1
1099.03
1
1111.54
1
1101.76
1
1087.1
1
1105.14
1
1099.8
1
1092.48
1
1106.65
1
1100.67
1
1089.12
1
1084.06
1
1090.69
1
1073.32
1
1077.38
1
1066.33
1
1062.08
1
1062.54
1
1070.22
1
1080.35
1
1062.94
1
1041.95
1
1044.98
1
1039.84
1
1058.39
1
1034.44
1
1041.55
1
1035.14
1
1029.66
1
1033.41
1
1026.4
1
1029.16
1
1023.73
1
1024.47
1
1016.57
1
1009.26
1
1022.87
1
1029.28
1
1011.82
1
1015.67
1
1011.27
1
1009.61
1
1014.57
1
1014.92
1
1012.28
1
1002
1
1016.98
1
1014.8
1
1007.84
1
1002.26
1
1004.54
1
1018.41
1
1002.44
1
994.94
1
999.388
1
1017.16
1
999.341
1
1001.83
1
1005.56
1
1004.65
1
1000.93
1
991.912
1
979.865
1
985.128
1
992.411
1
982.657
1
979.025
1
977.279
1
970.328
1
963.504
1
963.691
1
972.368
1
978.404
1
967.248
1
959.555
1
974.27
1
970.972
1
956.026
1
948.589
1
959.419
1
955.681
1
961.695
1
966.944
1
955.549
1
956.384
1
945.082
1
946.793
1
938.427
1
954.227
1
941.446
1
945.397
1
938.483
1
927.654
1
919.285
1
925.872
1
919.757
1
928.298
1
934.552
1
934.637
1
929.24
1
931.049
1
934.51
1
912.673
1
932.236
1
930.432
1
921.434
1
913.014
1
917.637
1
914.497
1
930.409
1
914.45
1
921.121
1
916.844
1
913.034
1
918.97
1
910.936
1
923.565
1
908.762
1
910.664
1
918.98
1
922.909
1
925.014
1
927.011
1
913.975
1
907.785
1
915.953
1
923.341
1
909.059
1
909.584
1
910.44
1
912.214
1
919.64
1
934.855
1
925.394
1
915.058
1
919.619
1
921.508
1
923.018
1
927.242
1
917.056
1
916.812
1
924.435
1
925.261
1
928.2
1
932.729
1
941.634
1
940.97
1
933.522
1
923.866
1
932.265
1
931.072
1
939.554
1
930.523
1
930.699
1
937.96
1
943.823
1
944.617
1
941.64
1
937.598
1
943.283
1
945.979
1
943.162
1
954.204
1
943.863
1
954.782
1
955.293
1
948.699
1
945.933
1
951.834
1
945.544
1
939.918
1
948.565
1
950.391
1
965.006
1
953.385
1
952.308
1
961.048
1
954.759
1
960.627
1
970.886
1
958.535
1
961.16
1
957.771
1
970.402
1
964.418
1
960.138
1
988.215
1
975.569
1
960.269
1
967.542
1
967.158
1
960.022
1
981.135
1
981.227
1
962.688
1
971.552
1
990.269
1
993.502
1
986.246
1
979.084
1
974.118
1
993.933
1
1000.8
1
983.012
1
994.972
1
974.657
1
978.773
1
991.763
1
981.033
1
977.451
1
991.752
1
994.873
1
1002.33
1
990.923
1
997.405
1
998.32
1
1006.77
1
1009.52
1
1013.8
1
1003.03
1
1004.72
1
1010.4
1
1001.37
1
997.397
1
1007.62
1
1011.12
1
1011.27
1
1003.32
1
1008.97
1
1015.94
1
1013.07
1
1023.94
1
1012.23
1
1010.51
1
1016.75
1
1023.8
1
1023.49
1
1019.16
1
1027.58
1
1017.52
1
1014.72
1
1016.94
1
1008.64
1
1025.66
1
1026.76
1
1027.12
1
1015.99
1
1008.06
1
1019.08
1
1015.39
1
1018.99
1
1035.81
1
1038.86
1
1040.78
1
1023.45
1
1023.63
1
1028.81
1
1017.57
1
1038.12
1
1036.83
1
1041.31
1
1042.21
1
1026.59
1
1022.7
1
1041.58
1
1030.98
1
1020.88
1
1040.14
1
1048.28
1
1030.99
1
1033.39
1
1040.33
1
1042.98
1
1054.05
1
1040.76
1
1048.49
1
1022.74
1
1025.84
1
1039.23
1
1035.64
1
1040.81
1
1036.95
1
1035.24
1
1034.43
1
1039.27
1
1030.27
1
1031.04
1
1033.66
1
1032.48
1
1041.62
1
1037.05
1
1051.81
1
1049.03
1
1045.34
1
1050.93
1
1052.63
1
1025.83
1
1044.79
1
1041.21
1
1042.44
1
1038.83
1
1045.03
1
1041.51
1
1051.38
1
1048.92
1
1052.96
1
1051.2
1
1038.53
1
1040.8
1
1054.18
1
1039.92
1
1045.32
1
1055.25
1
1040.9
1
1044.98
1
1042.32
1
1045.96
1
1033.7
1
1050.84
1
1048.04
1
1045.33
1
1035.02
1
1058.01
1
1060.71
1
1056.67
1
1047.53
1
1052.05
1
1052.2
1
1057.68
1
1049.71
1
1048.92
1
1056.05
1
1039.29
1
1063.28
1
1062.93
1
1054.84
1
1060.05
1
1045.18
1
1056.2
1
1080.66
1
1061.19
1
1060.65
1
1066.86
1
1051.38
1
1064.39
1
1069.32
1
1072.14
1
1075.49
1
1070.07
1
1080
1
1076.51
1
1086.13
1
1077.88
1
1084.61
1
1070.92
1
1074.32
1
1080.67
1
1077.08
1
1081.57
1
1088.27
1
1090.86
1
1095.86
1
1086.43
1
1091.09
1
1079.32
1
1082.11
1
1093.73
1
1103.53
1
1098.23
1
1109.11
1
1103.71
1
1102.22
1
1105.16
1
1109.19
1
1104.21
1
1106.34
1
1105.8
1
1094.67
1
1109.73
1
1123.61
1
1114.88
1
1105.07
1
1107.03
1
1129.18
1
1137.34
1
1131.76
1
1132.34
1
1139.04
1
1138.43
1
1131.73
1
1133.14
1
1152.37
1
1141.58
1
1157.26
1
1148.6
1
1159.46
1
1180.33
1
1180.05
1
1178.86
1
1181.53
1
1190.77
1
1187.16
1
1196.91
1
1201.42
1
1206.11
1
1215.63
1
1209.97
1
1217.04
1
1229.06
1
1230.71
1
1244.64
1
1252.19
1
1266.94
1
1272.12
1
1260.09
1
1259.46
1
1281.63
1
1291.4
1
1293.37
1
1303.3
1
1295.71
1
1320.9
1
1309.9
1
1316.78
1
1323.91
1
1348.66
1
1353.61
1
1359.37
1
1369.58
1
1378.61
1
1371.39
1
1381.32
1
1389.05
1
1399.62
1
1406.27
1
1406.72
1
1399.17
1
1426.73
1
1424.8
1
1448.17
1
1456
1
1465.22
1
1457.77
1
1462.34
1
1487.76
1
1500.13
1
1510.32
1
1509.88
1
1528.65
1
1553.7
1
1550.71
1
1550.56
1
1572.71
1
1587.86
1
1597.52
1
1624.9
1
1608.86
1
1622.64
1
1660.36
1
1671.42
1
1694.73
1
1738.22
1
1728.39
1
1741.78
1
1761.19
1
1782.25
1
1797.59
1
1826.48
1
1865.22
1
1882.16
1
1898.18
1
1918.66
1
1941.49
1
1975.39
1
2007.45
1
2028.5
1
2049.87
1
2066.86
1
2108.56
1
2159.33
1
2149.79
1
2206.4
1
2234.44
1
2253.55
1
2298.42
1
2341.53
1
2368.34
1
2387.15
1
2436.61
1
2462.48
1
2471.49
1
2500.52
1
2523.84
1
2557.32
1
2585.42
1
2559.09
1
2577.79
1
2605.04
1
2603.91
1
2600
1
2618.01
1
2599.89
1
2561.97
1
2549.71
1
2542.1
1
2508.34
1
2506.75
1
2480.92
1
2447.59
1
2397.78
1
2378.3
1
2348.97
1
2306.69
1
2252.97
1
2223.31
1
2181.96
1
2139.57
1
2102.35
1
2069.4
1
2036.98
1
1982.55
1
1950.56
1
1900.52
1
1854.31
1
1814.31
1
1781.17
1
1758.77
1
1722.21
1
1656.26
1
1604.01
1
1553.56
1
1515.2
1
1463.79
1
1396.7
1
1347.78
1
1284.06
1
1228.76
1
1178.25
1
1112.57
1
1055.94
1
999.328
1
946.701
1
898.101
1
852.352
1
817.286
1
790.446
1
762.028
1
729.467
1
710.709
1
691.222
1
662.927
1
657.163
1
659.52
1
633.558
1
620.657
1
608.151
1
615.575
1
600.193
1
583.58
1
578.848
1
573.072
1
568.931
1
547.742
1
545.557
1
551.515
1
541.729
1
529.967
1
526.843
1
519.711
1
515.581
1
515.406
1
507.036
1
506.607
1
501.278
1
501.052
1
500.958
1
487.25
1
494.196
1
494.728
1
490.08
1
492.067
1
497.708
1
486.664
1
476.664
1
492.234
1
478.305
1
481.379
1
481.793
1
477.812
1
482.264
1
481.966
1
472.184
1
474.246
1
471.404
1
478.376
1
477.404
1
483.154
1
492.513
1
479.769
1
486.975
1
478.334
1
480.94
1
469.67
1
473.645
1
480.502
1
480.367
1
467.232
1
478.512
1
485.738
1
488.947
1
486.938
1
479.459
1
487.088
1
477.312
1
473.748
1
473.759
1
484.465
1
493.059
1
496.375
1
491.781
1
498.19
1
504.439
1
494.887
1
504.26
1
493.987
1
504.661
1
499.737
1
517.897
1
O1s
Co
2021
4
27
18
43
3
0
15
Casa Info Follows
0
0
0
0
File = E:/OwnCloud/XPS lab/EX491_S745_Co.sle
Group = RT in vacuum, #Treatments:4h sputter, #Temp:RT , #Pressure:vacuum , #Atmosphere:{:}, #Comments:
First of group = 0
Spectrum ID = 17
Analyzer lens = AngleResolvedMode22:1.5kV
Analyzer slit = 4:7x20c\C:mesh
Scan mode = FixedAnalyzerTransmission
Kinetic energy start = 926.61
PCA Coefs = 3893.53, 1858.99, -3657.86, -17.8739, 208.516, -19.2583, 6.26844,
C:\Users\Mark\Downloads\EX491_S745_Co (1).vms
XPS
1
Al
1486.61
0
0
0
54.5
180
FAT
20
1
4.1408
0
0
0
0
0
O
1s
-1
kinetic energy
eV
926.61
0.1
2
counts
d
Transmission
d
pulse counting
0.1
2
0
0
0
0
0
1002
208.107
375.515
1
1
249.835
1
248.774
1
250.052
1
248.861
1
246.135
1
246.397
1
244.911
1
245.919
1
246.072
1
243.053
1
248.117
1
249.367
1
242.761
1
248.729
1
248.82
1
244.94
1
242.52
1
239.378
1
244.853
1
249.178
1
242.68
1
242.083
1
246.078
1
241.731
1
243.484
1
243.262
1
245.645
1
245.781
1
246.831
1
243.301
1
242.959
1
239.097
1
244.563
1
243.862
1
247.239
1
247.384
1
245.103
1
245.56
1
245.829
1
246.514
1
249.707
1
242.64
1
238.411
1
246.881
1
247.34
1
246.291
1
248.114
1
245.704
1
248.724
1
252.39
1
250.569
1
243.416
1
241.87
1
245.972
1
244.638
1
248.297
1
245.517
1
247.445
1
247.905
1
248.318
1
248.67
1
252.101
1
248.424
1
250.557
1
246.01
1
248.95
1
247.573
1
246.839
1
246.032
1
250.958
1
251.305
1
254.589
1
249.114
1
253.757
1
250.753
1
244.888
1
244.231
1
250.146
1
240.211
1
248.42
1
246.5
1
244.59
1
249.537
1
256.371
1
251.225
1
249.588
1
254.165
1
251.076
1
250.552
1
249.823
1
245.463
1
245.047
1
245.51
1
247.346
1
250.924
1
247.514
1
248.667
1
249.348
1
252.979
1
249.296
1
245.278
1
248.823
1
247.644
1
249.238
1
247.622
1
249.794
1
248.699
1
247.007
1
249.837
1
242.937
1
249.085
1
250.306
1
251.724
1
250.69
1
249.494
1
250.01
1
250.229
1
246.641
1
245.103
1
250.331
1
250.946
1
250.403
1
250.876
1
248.319
1
245.939
1
252.308
1
249.613
1
247.351
1
245.24
1
246.318
1
247.913
1
244.072
1
249.124
1
251.424
1
244.707
1
240.872
1
245.223
1
250.696
1
245.634
1
252.755
1
247.227
1
248.946
1
250.396
1
250.086
1
248.173
1
248.437
1
253.357
1
246.688
1
249.224
1
254.833
1
252.089
1
251.577
1
253.772
1
251.194
1
248.673
1
250.045
1
246.495
1
244.946
1
249.729
1
250.535
1
251.075
1
255.239
1
250.158
1
251.454
1
248.859
1
248.589
1
251.524
1
247.166
1
243.981
1
248.084
1
246.396
1
248.705
1
247.234
1
249.567
1
250.671
1
250.065
1
251.043
1
249.845
1
247.157
1
243.886
1
252.093
1
251.152
1
245.877
1
252.16
1
247.902
1
247.402
1
250.764
1
251.337
1
245.798
1
246.18
1
248.952
1
252.206
1
250.841
1
251.903
1
244.64
1
253.634
1
248.401
1
248.398
1
250.413
1
247.192
1
249.473
1
250.738
1
248.907
1
254.785
1
251.848
1
245.812
1
251.362
1
251.806
1
249.268
1
248.548
1
249.167
1
255.803
1
253.159
1
247.923
1
248.98
1
254.241
1
250.475
1
245.422
1
246.303
1
246.845
1
249.49
1
258.354
1
252.091
1
247.249
1
248.355
1
249.815
1
250.743
1
246.274
1
249.439
1
247.958
1
244.221
1
248.154
1
248.745
1
252.994
1
250.938
1
248.76
1
249.124
1
247.908
1
248.039
1
248.553
1
256.004
1
250.9
1
254.738
1
249.443
1
247.138
1
251.775
1
252.193
1
253.789
1
246.243
1
251.472
1
248.553
1
254.187
1
250.154
1
251.778
1
248.937
1
252.924
1
252.704
1
249.474
1
256.947
1
257.676
1
255.725
1
253.5
1
256.552
1
254.515
1
254.467
1
256.564
1
257.577
1
259.567
1
262.929
1
256.942
1
263.125
1
261.777
1
267.64
1
269.76
1
272.988
1
275.101
1
281.216
1
282.603
1
282.327
1
291.697
1
288.381
1
294.125
1
302.064
1
305.329
1
296.764
1
303.692
1
308.113
1
300.982
1
304.83
1
310.129
1
314.928
1
313.727
1
316.98
1
321.934
1
322.831
1
323.855
1
335.238
1
343.497
1
350.942
1
356.707
1
358.338
1
357.863
1
355.617
1
350.633
1
337.718
1
315.769
1
307.128
1
291.222
1
280.324
1
268.211
1
257.41
1
253.041
1
255.305
1
247.233
1
242.942
1
242.682
1
243.535
1
245.77
1
243.271
1
236.591
1
241.803
1
243.018
1
241.961
1
244.739
1
238.96
1
244.058
1
244.031
1
244.047
1
245.941
1
248.533
1
247.711
1
243.019
1
242.294
1
243.78
1
240.328
1
243.026
1
241.994
1
243.482
1
245.924
1
244.508
1
243.672
1
243.503
1
242.351
1
246.233
1
244.303
1
242.043
1
240.786
1
239.249
1
244.636
1
244.928
1
242.055
1
240.046
1
241.117
1
243.901
1
243.222
1
248.535
1
251.155
1
247.582
1
244.203
1
244.651
1
242.669
1
244.12
1
242.867
1
239.501
1
246.353
1
241.68
1
248.405
1
243.171
1
243.277
1
246.019
1
247.194
1
245.683
1
245.848
1
243.801
1
245.98
1
244.238
1
248.143
1
243.572
1
240.673
1
241.441
1
246.28
1
247.422
1
243.751
1
242.698
1
247.999
1
243.183
1
244.002
1
247.815
1
248.169
1
241.331
1
242.29
1
245.062
1
247.215
1
249.056
1
249.411
1
243.351
1
247.357
1
242.561
1
242.475
1
241.185
1
244.573
1
245.824
1
244.105
1
241.852
1
244.811
1
253.521
1
248.085
1
241.776
1
240.743
1
245.099
1
245.588
1
247.469
1
243.068
1
243.65
1
246.706
1
247.424
1
245.666
1
247.153
1
245.972
1
243.209
1
247.317
1
246.742
1
247.389
1
241.361
1
242.821
1
245.997
1
249.289
1
246.975
1
245.353
1
242.289
1
248.064
1
245.074
1
242.548
1
247.25
1
243.493
1
240.772
1
246.033
1
246.198
1
246.665
1
246.19
1
246.811
1
246.21
1
237.647
1
243.111
1
250.706
1
247.527
1
243.081
1
248.561
1
244.799
1
245.79
1
244.725
1
245.539
1
247.585
1
248.312
1
247.142
1
248.469
1
244.202
1
243.367
1
243.47
1
245.321
1
244.9
1
245.745
1
245.597
1
248.51
1
247.13
1
248.155
1
249.444
1
249.266
1
246.577
1
247.073
1
245.739
1
249.272
1
250.871
1
248.562
1
243.525
1
243.551
1
244.413
1
243.339
1
245.97
1
244.089
1
246.523
1
243.961
1
245.169
1
248.998
1
245.762
1
246.237
1
250.984
1
247.96
1
244.164
1
244.792
1
245.776
1
250.354
1
249.962
1
250.028
1
249.052
1
248.671
1
252.994
1
246.871
1
254.003
1
252.092
1
248.417
1
C1s
Co
2021
4
27
18
43
33
0
17
Casa Info Follows
0
0
0
0
File = E:/OwnCloud/XPS lab/EX491_S745_Co.sle
Group = RT in vacuum, #Treatments:4h sputter, #Temp:RT , #Pressure:vacuum , #Atmosphere:{:}, #Comments:
First of group = 0
Spectrum ID = 18
Analyzer lens = AngleResolvedMode22:1.5kV
Analyzer slit = 4:7x20c\C:mesh
Scan mode = FixedAnalyzerTransmission
Kinetic energy start = 1188.61
PCA Coefs = 2387.61, -184.706, -1.20518, -98.5401,
PCA Coefs = 2387.61, -184.706, -1.20518, -98.5401, -66.673,
PCA Coefs = 2387.61, -184.706, -1.20518, -98.5401, -66.673, -39.5323, 28.5491,
C:\Users\Mark\Downloads\EX491_S745_Co (1).vms
XPS
1
Al
1486.61
0
0
0
54.5
180
FAT
20
1
4.1408
0
0
0
0
0
C
1s
-1
kinetic energy
eV
1188.61
0.1
2
counts
d
Transmission
d
pulse counting
0.1
1
0
0
0
0
0
402
140.049
248.234
1
1
165.284
1
162.567
1
153.074
1
153.546
1
157.041
1
169.517
1
167.269
1
162.935
1
156.858
1
159.018
1
162.328
1
161.599
1
166.932
1
173.655
1
161.975
1
164.52
1
175.062
1
165.185
1
159.157
1
152.066
1
150.321
1
160.856
1
154.828
1
158.066
1
168.495
1
163.928
1
156.596
1
167.42
1
171.095
1
165.109
1
156.08
1
163.435
1
168.579
1
161.114
1
173.225
1
167.393
1
167.763
1
166.683
1
167.014
1
170.786
1
163.188
1
161.22
1
164.799
1
161.951
1
172.633
1
171.037
1
162.042
1
162.32
1
165.299
1
163.013
1
175.643
1
162.019
1
155.356
1
159.267
1
161.388
1
162.474
1
163.944
1
172.617
1
171.889
1
168.192
1
162.723
1
159.704
1
171.004
1
166.888
1
172.491
1
169.785
1
166.526
1
160.894
1
169.232
1
166.565
1
166.585
1
168.446
1
164.008
1
161.477
1
172.368
1
166.82
1
162.507
1
170.575
1
159.428
1
166.682
1
164.889
1
175.124
1
169.094
1
166.019
1
160.988
1
170.818
1
169.487
1
149.223
1
154.026
1
151.317
1
168.082
1
170.143
1
168.328
1
167.665
1
149.745
1
149.9
1
143.517
1
154.361
1
148.97
1
153.867
1
159.162
1
151.605
1
146.228
1
154.148
1
162.833
1
170.877
1
148.397
1
155.174
1
167.092
1
157.773
1
163.655
1
164.643
1
180.82
1
174.786
1
161.181
1
168.699
1
176.863
1
177.33
1
180.224
1
183.167
1
170.042
1
172.473
1
178.58
1
165.701
1
170.884
1
176.125
1
185.217
1
173.014
1
175.579
1
165.907
1
158.067
1
164.151
1
175.213
1
183.616
1
184.285
1
165.142
1
173.061
1
186.493
1
181.947
1
184.513
1
195.197
1
201.68
1
203.583
1
192.023
1
201.905
1
206.122
1
224.867
1
226.791
1
229.982
1
241.177
1
242.799
1
234.481
1
225.419
1
209.393
1
192.456
1
186.28
1
173.856
1
172.546
1
177.853
1
164.932
1
154.897
1
157.156
1
165.185
1
166.675
1
161.06
1
166.715
1
156.825
1
163.336
1
160.749
1
157.348
1
157.918
1
157.3
1
153.687
1
149.189
1
150.554
1
165.942
1
165.125
1
174.366
1
170.951
1
166.055
1
155.862
1
156.73
1
157.677
1
155.887
1
149.152
1
164.144
1
162.582
1
160.717
1
166.022
1
163.574
1
156.139
1
163.894
1
165.814
1
163.864
1
160.875
1
162.691
1
161.85
1
160.617
1
149.46
1
165.182
1
162.733
1
Survey
Co3O4
2021
4
28
13
55
24
0
15
Casa Info Follows
0
0
0
0
File = E:/OwnCloud/XPS lab/EX491_S745_Co.sle
[...]
1
769.444
1
761.848
1
772.37
1
767.335
1
768.533
1
764.888
1
776.454
1
773.865
1
780.615
1
791.676
1
802.948
1
795.646
1
801.106
1
802.12
1
807.936
1
803.407
1
811.313
1
809.954
1
818.227
1
824.275
1
837.663
1
836.585
1
842.43
1
851.003
1
858.708
1
862.559
1
866.139
1
875.709
1
873.606
1
884.298
1
893.739
1
895.686
1
897.199
1
899.042
1
904.502
1
912.667
1
924.417
1
929.257
1
928.936
1
932.404
1
942.223
1
953.077
1
964.201
1
980.104
1
982.565
1
997.525
1
992.569
1
1009.88
1
1017.91
1
1027.1
1
1044.96
1
1050.07
1
1056.07
1
1059.47
1
1073.69
1
1080.71
1
1094.1
1
1100.7
1
1113.44
1
1122.03
1
1124.37
1
1142.43
1
1147.97
1
1149.49
1
1145.44
1
1149.54
1
1157.54
1
1169.1
1
1169.15
1
1171.93
1
1182.04
1
1191.98
1
1197.17
1
1195.5
1
1193.02
1
1195.3
1
1196.14
1
1188.58
1
1194.39
1
1205.3
1
1199.7
1
1202.69
1
1208.54
1
1216.64
1
1211.42
1
1200.37
1
1213.4
1
1215.43
1
1221.25
1
1223.1
1
1222.25
1
1212.04
1
1200.33
1
1201.13
1
1207.97
1
1212.02
1
1197.83
1
1194.05
1
1188.1
1
1188.69
1
1194.01
1
1182.24
1
1170.01
1
1167.01
1
1170.47
1
1167.52
1
1158.42
1
1158.66
1
1152.74
1
1145.59
1
1158.25
1
1162.93
1
1151.14
1
1153.16
1
1153.19
1
1150.17
1
1158.84
1
1156.29
1
1170.61
1
1157.28
1
1170.29
1
1172.9
1
1156.8
1
1162.69
1
1160.13
1
1157.4
1
1154.78
1
1164.66
1
1151.26
1
1155.59
1
1154.67
1
1156.73
1
1143.97
1
1160.42
1
1150.71
1
1165.39
1
1172.01
1
1157.81
1
1156.86
1
1159.17
1
1151.34
1
1167.43
1
1169.43
1
1158.36
1
1150.56
1
1152.17
1
1132.88
1
1122.32
1
1111.02
1
1104.86
1
1093.76
1
1076.1
1
1061.77
1
1030.83
1
1005.64
1
992.736
1
966.494
1
940.816
1
919.134
1
892.094
1
879.834
1
848.497
1
819.667
1
800.698
1
784.372
1
766.587
1
746.294
1
728.584
1
714.512
1
699.948
1
686.109
1
662.811
1
650.277
1
642.313
1
621.364
1
614.564
1
599.168
1
571.859
1
562.752
1
550.028
1
546.198
1
529.782
1
523.127
1
514.546
1
500.03
1
488.865
1
481.895
1
481.161
1
467.408
1
463.536
1
461.416
1
457.831
1
455.834
1
449.344
1
449.95
1
443.219
1
437.336
1
437.064
1
433.884
1
438.076
1
437.517
1
438.087
1
439.178
1
432.666
1
434.862
1
430.445
1
429.97
1
429.793
1
437.173
1
437.107
1
428.185
1
430.313
1
434.815
1
436.334
1
433.523
1
431.835
1
435.79
1
435.53
1
436.975
1
439.075
1
440.946
1
437.557
1
440.389
1
443.487
1
444.061
1
442.709
1
440.875
1
442.839
1
442.715
1
443.278
1
444.378
1
449.021
1
449.44
1
446.115
1
446.842
1
456.022
1
452.326
1
451.378
1
447.783
1
451.249
1
457.29
1
450.62
1
452.586
1
456.871
1
449.826
1
452.055
1
455.367
1
451.818
1
453.236
1
458.287
1
449.802
1
457.516
1
456.427
1
461.507
1
458.145
1
460.073
1
463.445
1
459.168
1
458.601
1
457.681
1
458.656
1
453.233
1
449.708
1
462.143
1
465.683
1
458.588
1
454.635
1
461.993
1
455.06
1
460.651
1
457.961
1
460.011
1
456.18
1
449.401
1
454.191
1
444.556
1
453.945
1
457.627
1
453.95
1
454.094
1
457.556
1
452.089
1
449.581
1
455.244
1
450.408
1
448.307
1
454.199
1
455.532
1
450.504
1
452.18
1
445.354
1
448.632
1
447.442
1
448.518
1
455.081
1
453.346
1
451.711
1
451.903
1
444.277
1
443.258
1
444.121
1
448.634
1
444.981
1
446.003
1
444.36
1
446.171
1
449.986
1
440.957
1
436.787
1
440.744
1
444.272
1
440.612
1
435.007
1
434.896
1
428.588
1
427.358
1
431.866
1
432.124
1
428.729
1
418.839
1
413.835
1
408.675
1
402.918
1
399.024
1
396.778
1
388.756
1
379.176
1
383.444
1
376.047
1
375.627
1
371.468
1
361.089
1
356.167
1
351.731
1
348.201
1
347.897
1
341.456
1
338.854
1
333.866
1
328.252
1
325.461
1
317.68
1
319.742
1
315.769
1
310.264
1
312.012
1
306.05
1
303.304
1
293.685
1
295.177
1
294.232
1
291.836
1
295.116
1
289.408
1
283.991
1
278.382
1
285.555
1
281.825
1
276.511
1
282.607
1
278.877
1
274.967
1
275.92
1
274.838
1
276.623
1
275.392
1
271.813
1
271.05
1
269.795
1
269.58
1
268.669
1
271.322
1
273.655
1
272.189
1
273.341
1
276.431
1
275.456
1
268.722
1
272.55
1
273.979
1
275.138
1
269.3
1
274.846
1
268.409
1
273.094
1
271.91
1
267.2
1
268.531
1
270.208
1
272.225
1
273.658
1
269.259
1
271.528
1
273.237
1
269.928
1
266.382
1
269.563
1
274.244
1
271.972
1
267.305
1
269.39
1
267.59
1
267.484
1
270.202
1
270.043
1
271.352
1
268.314
1
268.952
1
269.084
1
273.211
1
273.252
1
271.975
1
278.583
1
267.562
1
273.027
1
O1s
NiO
2021
4
29
23
43
26
0
16
Casa Info Follows
0
0
0
0
File = E:/OwnCloud/XPS lab/EX492_S776_Ni Oxidation.sle
Group = RT in vacuum, #Treatments: , #Temp:RT , #Pressure:vacuum , #Atmosphere:, #Comments:
First of group = 0
Spectrum ID = 24
Analyzer lens = AngleResolvedMode22:1.5kV
Analyzer slit = 4:7x20c\C:mesh
Scan mode = FixedAnalyzerTransmission
Kinetic energy start = 926.61
PCA Coefs = 21726.9, -665.417, -1051.38, 161.867,
C:\Users\Mark\Downloads\EX492_S776_Ni Oxidation.vms
c:\users\mark\downloads\ex492_ni references.vms
XPS
14
Al
1486.61
0
0
0
54.5
180
FAT
20
1
4.1408
0
0
0
0
0
O
1s
-1
kinetic energy
eV
926.61
0.1
2
counts
d
Transmission
d
pulse counting
0.1
2
0
0
0
0
2
ESCAPE DEPTH TYPE
d
1
MFP Exponent
d
0
1002
235.059
6563.1
1
1
584.084
1
589.669
1
579
1
587.849
1
578.353
1
575.11
1
585.049
1
572.826
1
586.289
1
591.271
1
588.35
1
588.735
1
589.892
1
582.3
1
576.757
1
582.704
1
578.798
1
585.862
1
593.069
1
595.704
1
587.523
1
592.616
1
588.389
1
598.305
1
594.263
1
597.318
1
595.117
1
600.038
1
592.718
1
594.5
1
584.603
1
597.949
1
609.988
1
605.574
1
599.054
1
612.122
1
608.12
1
608.376
1
613.232
1
616.594
1
625.557
1
631.418
1
626.341
1
613.522
1
615.975
1
626.172
1
634.181
1
640.734
1
643.453
1
662.408
1
661.944
1
659.936
1
668.734
1
673.125
1
684.583
1
683.383
1
694.321
1
695.08
1
691.919
1
692.797
1
708.199
1
697.012
1
703.093
1
704.316
1
705.319
1
704.37
1
713.232
1
718.227
1
724.017
1
719.691
1
717.975
1
714.053
1
718.165
1
716.09
1
709.99
1
711.658
1
703.479
1
709.181
1
702.061
1
695.549
1
690.486
1
697.847
1
696.02
1
683.804
1
688.098
1
677.588
1
683.283
1
683.185
1
684.687
1
668.557
1
666.165
1
662.565
1
682.533
1
673.205
1
669.825
1
658.556
1
658.419
1
655.382
1
654.705
1
654.823
1
658.169
1
639.572
1
643.119
1
642.796
1
643.315
1
628.009
1
628.184
1
629.719
1
644.982
1
637.218
1
625.937
1
619.094
1
623.17
1
611.049
1
611.99
1
604.613
1
604.501
1
604.266
1
591.434
1
586.441
1
595.121
1
591.315
1
584.91
1
575.396
1
568.733
1
567.865
1
574.814
1
573.435
1
571.576
1
573.515
1
558.607
1
561.756
1
562.765
1
556.04
1
566.831
1
562.326
1
553.64
1
551.541
1
548.053
1
546.214
1
558.655
1
554.67
1
543.174
1
549.28
1
556.198
1
559.524
1
545.1
1
550.858
1
556.797
1
551.191
1
559.928
1
557.122
1
554.588
1
550.843
1
547.326
1
538.977
1
550.323
1
545.87
1
539.893
1
537.994
1
532.561
1
518.52
1
519.542
1
525.017
1
514.982
1
507.198
1
508.758
1
515.511
1
515.773
1
501.383
1
504.833
1
495.895
1
506.75
1
502.11
1
503.727
1
496.666
1
489.755
1
501.605
1
492.423
1
484.765
1
479.575
1
485.375
1
479.071
1
480.928
1
470.95
1
471.222
1
470.391
1
461.235
1
467.397
1
462.04
1
463.244
1
462.597
1
470.66
1
466.057
1
470.639
1
467.784
1
468.322
1
462.183
1
463.414
1
462.732
1
460.712
1
458.055
1
462.845
1
463.718
1
456.099
1
459.04
1
458.544
1
456.449
1
455.746
1
455.133
1
451.143
1
454.733
1
462.641
1
447.194
1
442.127
1
448.673
1
443.101
1
454.409
1
445.586
1
441.607
1
445.229
1
458.965
1
458.242
1
461.999
1
459.551
1
458.69
1
457.599
1
456.542
1
461.647
1
458.815
1
461.337
1
465.161
1
461.633
1
461.017
1
460.633
1
464.699
1
460.947
1
459.672
1
466.704
1
471.338
1
467.724
1
462.736
1
465.546
1
468.782
1
458.252
1
473.462
1
463.861
1
458.193
1
475.467
1
473.244
1
473.578
1
478.619
1
482.11
1
474.579
1
478.018
1
478.054
1
478.729
1
489.001
1
481.414
1
485.795
1
484.378
1
495.157
1
499.593
1
495.229
1
502.459
1
493.259
1
505.1
1
503.177
1
517.269
1
529.218
1
539.12
1
559.483
1
573.821
1
585.686
1
605.145
1
644.309
1
691.774
1
741.183
1
811.555
1
868.258
1
957.098
1
1042.86
1
1127.78
1
1207.5
1
1272.9
1
1306.84
1
1319.53
1
1320.54
1
1289.22
1
1223.47
1
1179.96
1
1134.83
1
1095.31
1
1064.73
1
1080.32
1
1135.26
1
1254.61
1
1484.75
1
1854.7
1
2307.5
1
2942.62
1
3667.42
1
4484.6
1
5284.12
1
5992.99
1
6431.09
1
6542.4
1
6348.52
1
5826.08
1
5038.29
1
4140.16
1
3242.46
1
2438.89
1
1812.84
1
1342.22
1
1018.67
1
794.462
1
646.639
1
543.565
1
484.662
1
449.102
1
417.331
1
401.787
1
381.429
1
380.824
1
367.062
1
351.488
1
343.173
1
345.389
1
344.742
1
345.657
1
332.043
1
332.007
1
328.833
1
319.024
1
317.713
1
309.551
1
310.505
1
315.076
1
311.612
1
316.133
1
311
1
304.418
1
307.683
1
313.395
1
310.164
1
307.264
1
305.414
1
296.39
1
292.381
1
299.54
1
302.552
1
295.24
1
290.753
1
294.393
1
296.68
1
298.762
1
298.961
1
304.871
1
295.156
1
292.919
1
292.839
1
299.007
1
295.714
1
295.389
1
302.565
1
292.622
1
296.396
1
295.218
1
297.565
1
289.507
1
292.718
1
289.649
1
288.499
1
298.379
1
292.94
1
296.949
1
303.39
1
298.299
1
294.632
1
287.538
1
289.086
1
293.616
1
287.834
1
284.906
1
284.25
1
290.976
1
286.712
1
290.311
1
293.651
1
288.226
1
297.679
1
299.777
1
288.896
1
287.138
1
293.788
1
295.159
1
291.618
1
295.665
1
290.895
1
291.79
1
296.1
1
290.733
1
283.855
1
284.323
1
277.114
1
283.913
1
285.28
1
286.334
1
284.622
1
291.024
1
285.052
1
291.572
1
290.888
1
293.122
1
289.04
1
291.216
1
290.003
1
302.452
1
288.362
1
288.997
1
284.447
1
290.244
1
294.943
1
285.848
1
293.743
1
289.389
1
287.356
1
281.541
1
291.938
1
295.089
1
295.676
1
292.304
1
282.901
1
282.685
1
287.995
1
288.606
1
287.352
1
285.013
1
287.302
1
282.948
1
281.762
1
291.409
1
298.426
1
292.096
1
289.001
1
288.421
1
291.716
1
298.237
1
287.443
1
286.423
1
291.491
1
288.198
1
286.891
1
288.678
1
288.358
1
294.561
1
288.62
1
284.764
1
287.694
1
291.129
1
293.367
1
293.957
1
292.253
1
296.276
1
292.664
1
288.781
1
289.61
1
287.466
1
286.125
1
293.867
1
296.272
1
285.141
1
284.727
1
283.272
1
282.274
1
290.283
1
289.629
1
288.777
1
297.322
1
291.114
1
280.937
1
287.289
1
290.826
1
288.049
1
288.885
1
288.808
1
294.926
1
292.775
1
291.379
1
289.706
1
288.234
1
289.039
1
288.759
1
292.442
1
291.737
1
282.252
1
289.867
1
295.49
1
294.671
1
293.478
1
Survey
NiO
2021
4
29
23
25
58
0
16
Casa Info Follows
0
0
0
0
File = E:/OwnCloud/XPS lab/EX492_S776_Ni Oxidation.sle
Group = RT in vacuum, #Treatments: , #Temp:RT , #Pressure:vacuum , #Atmosphere:, #Comments:
First of group = 1
Spectrum ID = 19
Analyzer lens = LargeArea:1.5kV
Analyzer slit = 4:7x20c\C:mesh
Scan mode = FixedAnalyzerTransmission
Kinetic energy start = 286.61
PCA Coefs = 144137, 9370.22, -1718.27, 1048.98,
C:\Users\Mark\Downloads\EX492_S776_Ni Oxidation.vms
c:\users\mark\downloads\ex492_ni references.vms
XPS
15
Al
1486.61
0
0
0
54.5
180
FAT
100
1
4.1408
0
0
0
0
0
Survey

-1
kinetic energy
eV
286.61
1
2
counts
d
Transmission
d
pulse counting
0.1
1
0
0
0
0
2
ESCAPE DEPTH TYPE
d
1
MFP Exponent
d
0
106.665
1
4025.6
4055.22
4076.4
4059.62
4116.38
4116.66
4064.5
4086.43
4101.6
4150.96
4141.52
4139.77
4162.58
4167.49
4179.91
4225.19
4228.4
4211.03
4228.14
4231.34
4232.72
4246.14
4239.06
4244.83
4273.05
4306.67
4311.25
4346.39
4341.38
4328.93
4386.42
4368.1
4407.19
4432.95
4449.97
4439.32
4428.45
4475.74
4457.44
4461.42
4477.68
4512.19
4492.57
4525.66
4530.14
4545.18
4572.85
4599.57
4587.22
4611.88
4621.6
4656.6
4652.53
4676.53
4665.46
4641.49
4712.2
4719.34
4714.77
4708.45
4731.03
4771.33
4783.68
4792.02
4800.19
4844.52
4830.49
4837.28
4850.78
4877.21
4877.77
4887.84
4902.04
4915.27
4952.8
4961.25
4979.02
4978.54
5011.64
5026.69
5039.6
5060.02
5030.43
5076.76
5074.1
5113.22
5057.08
5092.89
5107.2
5148
5165.81
5191.11
5178.69
5171.77
5198.82
5187.54
5225.36
5264.62
5267.33
5263.6
5304.41
5286.74
5322.55
5301.32
5331.05
5339.72
5338.65
5382.49
5380.09
5407.78
5441.5
5441.92
5485.44
5498.22
5484.36
5534.21
5559.16
5542.67
5523.04
5570.32
5607.53
5609.85
5594.44
5635.8
5639.13
5642.97
5698.63
5670.59
5733.37
5756
5778.98
5753.29
5797.79
5825.71
5820.41
5868.61
5858.58
5860.25
5885.03
5880.61
5936.19
5957.96
5933.98
5956.01
5977.75
6015.63
6001.19
6027.23
6049.42
6061.81
6062.34
6081.62
6104.14
6120.9
6140.46
6226.39
6198.46
6212.86
6199.04
6248.45
6311.27
6252.08
6325.49
6301.87
6357.45
6370.69
6399.6
6412.1
6409.48
6399.17
6399.23
6417.74
6423.32
6450.85
6514.76
6553.45
6608.36
6660.75
6746.68
6821.5
6935.73
7037.75
7146.72
7216.15
7271.93
7329.85
7366.06
7345.07
7411.64
7461.69
7455.56
7306.57
7190.91
6991.78
6874.3
6760.87
6672.65
6632.42
6582.63
6574.6
6570.83
6606.92
6656.87
6692.44
6794.2
6799.98
6785.21
6742.42
6648.37
6599.95
6589.64
6628.71
6595.04
6580.67
6589.11
6602.1
6609.14
6613.59
6620.01
6698.65
6772.71
6914.94
7117.14
7357.96
7526.69
7593.86
7518.58
7315.14
7153.78
7020.58
6951.64
6883
6777.45
6703.5
6726.89
6652.7
6567.32
6591.95
6550.05
6551.7
6543
6553.66
6515.46
6549
6555.47
6589.39
6587.09
6594.38
6642.47
6657.52
6657.33
6717.33
6727.04
6723.44
6723.35
6750.7
6753.86
6819.33
6834.13
6832.69
6836.19
6854.24
6860.26
6891.23
6857.28
6907.59
6930.49
6959.15
7037.76
7046.24
7024.56
7093.96
7071.33
7139.72
7115.35
7134.47
7152.77
7221.91
7238.23
7272.13
7257.35
7261.94
7261.72
7302.22
7339.47
7392.24
7443.77
7483.3
7557.25
7533.08
7562.73
7605.99
7614.84
7626.37
7660.89
7670.91
7714.22
7740.78
7733.7
7786.52
7842.64
7836.19
7903.49
7967.74
7903.14
7918.74
7897.39
7858.62
7812.52
7854.63
7767.29
7723.19
7721.43
7750.17
7826.16
8076.75
8481.66
8979.38
9573.83
10005.2
10207.1
10115.4
9839.59
9526.79
9417.19
9719.12
10269.9
10545.7
10324.1
9206.29
7837.73
7305.49
7547.03
7918.72
8228.34
8714.58
9545.89
10468.1
11155.7
11219.2
10503.5
9812.68
10196.3
11612.7
12902.9
13690.9
12343.1
8759
5958.05
5222.54
5079.54
4968.66
4911.23
4915.86
4888.37
4864.19
4891.18
4890.67
4921.65
4935.27
4942.34
4951.65
4967.61
5003.84
5030.08
5033.05
5078.96
5101.76
5137.23
5165.08
5159.1
5168.86
5203.64
5251.43
5303.12
5276.48
5252.98
5239.21
5223.72
5237.85
5215.32
5234.26
5262.47
5323.16
5363.77
5415.56
5421.43
5465.69
5407.61
5391.39
5366.37
5293.76
5252.48
5231.09
5232.06
5270.36
5246.12
5289.75
5298.79
5284.5
5326.29
5371.88
5372.72
5400.94
5382.8
5384.76
5471.48
5497.21
5504.67
5525.49
5600.56
5633.39
5665.37
5741.08
5803.91
5855.56
5942.51
6023.27
6100.15
6192.55
6235.06
6283.26
6190.52
6178.36
6222.4
6160.41
6175.26
6057.09
5904.7
5759.07
5541.4
5352.69
5145.41
4995.24
4847.7
4774.7
4789.51
4765.2
4720.56
4690.61
4654.97
4678
4677.21
4639.19
4606.22
4587.47
4562.35
4514.5
4522.39
4460.94
4438.55
4401.3
4391.78
4375.04
4335.79
4338.32
4328.15
4334.42
4346.04
4363.07
4374.17
4357.89
4367.48
4404.78
4411.78
4471.38
4493.37
4477.63
4498.5
4567.04
4568.76
4574.26
4578.42
4634.78
4724.17
4819.87
4896.01
4974.33
4995.44
5012.76
5043.5
5069.1
5186.65
5326.17
5469.71
5667.04
5856.6
6073.55
6094.19
5913.3
5702.12
5500.18
5398.43
5265.78
5186.7
5116.47
4977.4
4670.55
4339.78
4036.3
3863.72
3727.85
3631.17
3606.81
3564.6
3532.08
3478.37
3417.32
3374.85
3316.29
3256.14
3224.94
3159.62
3140.63
3101.43
3082.48
3036.02
2996.84
3000.63
2976.31
3029.75
3018.91
3015.13
3034.92
3033.42
3063.97
3037.33
3078.79
3081.01
3079.34
3114.18
3124.57
3177.53
3198.81
3209.86
3244.94
3272.73
3280.51
3281.23
3290.84
3299.63
3302.19
3314
3311.16
3266.95
3244.73
3286.64
3393.95
3511.72
3656.02
3824.99
4068.02
4413.12
4740.84
5091.05
5362.62
5526.96
5584.3
5508.01
5446.11
5418.15
5376.68
5310.29
4986.91
4199
3396.89
2735
2320.49
2103.76
2057.67
2060.52
2074.2
2101.57
2131.08
2120.69
2113.22
2114.93
2112.21
2083.08
2040.47
1920.88
1755.92
1568.38
1429.52
1342.95
1288.64
1286.34
1280.25
1262.69
1260.31
1269.52
1264.35
1273.16
1283.2
1288.16
1289.74
1289.58
1312.49
1301.76
1314.23
1312.48
1303.1
1323.15
1315.41
1301.36
1284.99
1273.76
1293.94
1280.2
1297.18
1304.93
1299.08
1316.75
1316.88
1318.9
1309.67
1302.02
1308.75
1339.52
1344.72
1344.82
1370.9
1378.01
1365.8
1380.13
1400.35
1414.66
1398.15
1408.31
1405.45
1409.67
1412.83
1401.55
1393.11
1390.27
1386.94
1380.41
1371.55
1389.29
1378.9
1409.85
1415.64
1407.85
1452.31
1528.79
1611.36
1664.68
1672.05
1662.66
1590.69
1532.5
1460.07
1383.09
1344.18
1309.58
1277.99
1238.45
1208.18
1164.01
1129.89
1122.99
1121.67
1140.17
1151.8
1183.21
1208.42
1380.78
1956.98
2913.88
5322.25
7324.81
5226.63
1954.43
940.425
816.164
769.064
736.149
720.011
701.738
697.545
701.608
690.702
705.456
697.18
694.829
696.982
704.108
712
703.255
697.268
696.925
709.297
698.52
715.722
720.206
716.118
707.139
717.705
711.35
718.167
730.517
721.728
724.488
719.301
726.153
733.755
722.522
732.365
715.112
727.826
739.328
728
736.22
745.243
728.554
731.632
721.406
730.498
731.608
721.588
725.628
728.005
720.147
716.423
716.687
713.903
725.373
734.745
734.113
710.127
721.402
718.429
719.51
721.132
737.813
744.331
743.334
729.244
713.1
726.588
739.692
750.751
743.825
746.918
741.197
739.457
750.578
752.115
749.849
749.382
733.73
743.288
737.595
745.352
743.333
761.396
758.023
756.455
761.295
764.493
759.365
771.654
764.946
767.999
762.122
762.924
754.64
758.315
765.549
778.438
783.729
770.226
761.526
776.309
766.248
769.095
754.867
767.356
784.184
773.375
773.132
774.916
781.444
781.069
775.802
777.115
797.646
784.817
794.41
787.571
777.719
787.926
783.271
782.715
796.973
786.374
795.997
811.175
813.764
812.448
814.551
821.97
796.406
783.831
797.167
807.338
807.089
810.011
808.723
818.338
817.054
809.987
805.25
814.416
815.932
805.614
804.71
816.236
832.541
819.279
825.772
816.891
834.013
825.913
821.82
841.664
832.787
828.09
827.77
827.037
834.002
843.945
841.942
855.12
833.547
843.862
837.676
849.768
854.17
841.002
854.087
847.188
851.61
856.987
862.841
838.116
844.542
850.48
858.303
860.993
868.454
865.319
868.033
866.687
868.955
856.685
870.584
857.714
870.206
866.414
861.032
881.763
883.296
882.138
880.352
895.288
898.316
898.509
890.4
895.565
903.997
884.368
885.731
904.22
887.722
895.54
908.124
906.799
914.203
926.679
916.173
909.866
927.99
901.978
920.768
930.311
918.204
924.014
920.659
897.054
913.861
930.868
907.821
930.919
934.626
927.104
926.88
925.493
929.369
924.559
930.611
934.36
930.286
930.487
935.106
946.058
938.313
940.168
943.382
951.895
992.445
1019.67
1047.79
1089.95
1167.8
1136.58
1023.4
958.776
955.592
931.931
950.466
954.055
963.687
947.114
957.686
954.116
947.817
973.328
963.506
970.971
973.52
986.337
968.219
958.897
962.837
945.974
948.943
955.224
962.326
957.54
963.175
967.575
958.598
955.56
989.779
980.461
981.292
979.398
975.858
989.377
987.058
986.16
981.207
992.699
1006.08
1018.89
1017.61
1012.58
1013.65
1000.95
998.119
1001.86
1010.2
1000.68
987.901
1020.67
1015.63
1015.38
1032.51
1006.04
1012.23
1010.75
1025.55
1031.5
1013.03
1010.17
1015.87
1034.2
1031.17
1046.8
1022.41
1009.55
1032.76
1042.49
1035.22
1040.15
1046.22
1046.93
1053.82
1058.52
1035.96
1042.97
1075.18
1061.79
1057.87
1058.95
1050.92
1062.84
1061.9
1081.95
1102.83
1081.02
1102.97
1081.5
1090.27
1070.06
1063.03
1077.54
1087.56
1098.47
1090.54
1094.66
1087.9
1105.68
1099.17
1102.82
1098.87
1113.69
1120.64
1119.77
1111.16
1128.65
1124.02
1117.38
1125.24
1115.88
1103.24
1127.41
1134.96
1141.09
1167.62
1163.62
1155.58
1165.11
1148.69
1139.72
1158.65
1161.57
1170.8
1168.72
1174.58
1164.49
1179.63
1201.78
1202.6
1208.38
1194.76
1199.77
1213.39
1203.8
1211.23
1221.66
1223.97
1254.05
1263.45
1271
1284.6
1257.7
1274.82
1271.65
1290.99
1273.88
1278.87
1268.07
1261.29
1251.33
1247.48
1252.28
1233.69
1228.34
1205.66
1208.7
1216.94
1237.53
1272.78
1288.24
1357.41
1433.76
1485.04
1567.13
1626.97
1720.68
1765.32
1790.18
1834.49
1933.84
2036.39
2139.18
2115.92
1883.42
1546.72
1309.04
1200.99
1160.16
1145.19
1153.02
1136.32
1142.1
1116.72
1103.12
1106.85
1100.83
1103.88
1124.49
1126.1
1113.08
1143.98
1157.87
1165.11
1206.91
1277.55
1302.46
1307.37
1259.49
1172.56
1133.06
1146.34
1180.55
1255.5
1312.11
1341.44
1373.93
1408.47
1483
1590.4
1747.35
1914.32
2017.25
2096.42
2222.83
2528.25
3042.19
3391.35
3000.78
1889.98
954.421
579.678
445.673
378.375
354.962
327.769
301.981
293.522
287.522
285.518
279.335
278.646
284.288
278.819
284.827
274.183
279.482
284.299
290.818
292.004
293.747
285.498
299.033
296.779
286.788
280.83
275.047
268.241
261.528
261.741
269.176
278.56
267.367
276.127
282.496
301.322
298.05
304.167
315.94
333.644
347.716
381.91
455.808
493.779
446.211
342.186
250.005
203.821
189.457
188.821
209.897
240.697
294.353
377.599
480.549
555.99
578.498
560.868
564.034
589.111
675.989
843.075
1035.45
905.206
453.062
106.868
1
end of experiment