File: xpsdeeplearning/data/references/NiCoFe/EX491-495 FeCo summed.vms
VAMAS Surface Chemical Analysis Standard Data Transfer Format 1988 May 4
Not Specified
Not Specified
Not Specified
Not Specified
11
Casa Info Follows CasaXPS Version 2.3.24PR1.0
0
Created by SpecsLab Prodigy, Version 4.73.2-r95032
SourceAnalyserAngle: Not Specified
CasaRowLabel:Co metal
CasaRowLabel:Co3O4
CasaRowLabel:CoO
CasaRowLabel:Fe metal
CasaRowLabel:Fe2O3
CasaRowLabel:Fe3O4
CasaRowLabel:FeO
NORM
REGULAR
3
1
Exp Variable
d
0
0
0
0
21
Co2p
Co metal
2021
4
27
18
36
14
0
16
Casa Info Follows
0
0
0
0
File = E:/OwnCloud/XPS lab/EX491_S745_Co.sle
Group = RT in vacuum, #Treatments:4h sputter, #Temp:RT , #Pressure:vacuum , #Atmosphere:{:}, #Comments:
First of group = 0
Spectrum ID = 15
Analyzer lens = AngleResolvedMode22:1.5kV
Analyzer slit = 4:7x20c\C:mesh
Scan mode = FixedAnalyzerTransmission
Kinetic energy start = 646.61
PCA Coefs = 117821, -21153.7, -1403.13, 970.754, 1743.34,
C:\Users\Mark\Downloads\EX491_S745_Co (1).vms
c:\users\pielsticker\lukas\mpi-cec\projects\deepxps\xpsdeeplearning\data\references\nicofe\ex491-495 fe, ni, co oxide references.vms
XPS
1
Al
1486.61
0
0
0
54.5
180
FAT
20
1
4.1408
0
0
0
0
0
Co
2p
-1
kinetic energy
eV
646.61
0.1
2
counts
d
Transmission
d
pulse counting
0.1
2
0
0
0
0
2
ESCAPE DEPTH TYPE
d
1
MFP Exponent
d
0
1402
2120.19
13889.6
1
1
4565.58
1
4573.78
1
4592.52
1
4594.61
1
4589.69
1
4625.72
1
4632.34
1
4631.83
1
4617.53
1
4622.36
1
4628.75
1
4610.33
1
4632.59
1
4652.39
1
4642.18
1
4638.13
1
4638.33
1
4636.05
1
4663.47
1
4659.32
1
4661.18
1
4667.98
1
4662.28
1
4655.87
1
4634.72
1
4634.58
1
4621.88
1
4640.71
1
4643.94
1
4641.59
1
4631.49
1
4605.81
1
4636.11
1
4633.43
1
4611.44
1
4623.11
1
4605.16
1
4584.81
1
4595.82
1
4589.15
1
4578.12
1
4587.29
1
4580.29
1
4540.5
1
4526.17
1
4526.69
1
4532.22
1
4489.65
1
4503.42
1
4509.74
1
4497.77
1
4503.13
1
4497.29
1
4512.85
1
4485.34
1
4494.74
1
4483.6
1
4474.39
1
4469.59
1
4451.37
1
4425.91
1
4467.92
1
4467.25
1
4444.25
1
4463.18
1
4484.65
1
4500.96
1
4465.22
1
4441.89
1
4448.85
1
4476.73
1
4486.37
1
4491.61
1
4511.35
1
4526.53
1
4512.47
1
4515.82
1
4521.5
1
4519.35
1
4519.94
1
4541.25
1
4560.45
1
4612.8
1
4626.28
1
4638.57
1
4605.67
1
4629.09
1
4643.45
1
4655.13
1
4652.27
1
4667.74
1
4654.73
1
4691.46
1
4699.84
1
4681.69
1
4657.73
1
4685.2
1
4652.53
1
4660.02
1
4649.62
1
4616.76
1
4623.6
1
4618.29
1
4610.17
1
4578.82
1
4569.14
1
4515.38
1
4510.69
1
4484.02
1
4465.77
1
4433.52
1
4385.32
1
4354.16
1
4367.07
1
4324.94
1
4286.76
1
4258.85
1
4232.18
1
4189.11
1
4181.66
1
4174.6
1
4162.63
1
4147.71
1
4100.91
1
4083.54
1
4068.67
1
4055.87
1
4063.55
1
4036.66
1
4038.03
1
4002.93
1
4013.89
1
3994.06
1
3977.06
1
3986.67
1
3986.11
1
3961.77
1
3941.76
1
3968.53
1
3960.37
1
3954.85
1
3917.05
1
3915.17
1
3928.73
1
3917.22
1
3947.12
1
3931.18
1
3917.23
1
3902.98
1
3872
1
3911.59
1
3914.28
1
3908.09
1
3940.57
1
3932.52
1
3892.21
1
3920.19
1
3939.9
1
3910.85
1
3890.28
1
3878
1
3907.75
1
3899.35
1
3867.71
1
3884.25
1
3891.64
1
3893.9
1
3913.15
1
3901.38
1
3914.45
1
3882.95
1
3893.55
1
3911.72
1
3884.93
1
3902.85
1
3912.22
1
3885.39
1
3878.58
1
3909.17
1
3928.02
1
3910.91
1
3916.38
1
3923.95
1
3932.93
1
3886.43
1
3887.47
1
3892.57
1
3925.69
1
3912.36
1
3891.64
1
3900.66
1
3902.32
1
3930.83
1
3916.06
1
3909.01
1
3932.12
1
3931.42
1
3899.78
1
3895.55
1
3898.03
1
3918.04
1
3911.14
1
3898.61
1
3916.07
1
3938.36
1
3929.22
1
3925.19
1
3918.33
1
3940.54
1
3972.24
1
3966.15
1
3932.3
1
3921.75
1
3952.09
1
3946.19
1
3953.93
1
3964.75
1
3978.08
1
3943.78
1
3975.15
1
3966.39
1
3953.27
1
3981.42
1
3951.86
1
3978.86
1
3985.28
1
3985.37
1
3973.32
1
3986.93
1
3951.53
1
3955.54
1
3980.08
1
3993.82
1
4006.91
1
4013.88
1
4012.95
1
4004.59
1
3996.62
1
4014.7
1
4018.43
1
4011.66
1
4024.78
1
4008.87
1
4027.81
1
4022.19
1
4028.99
1
4039.46
1
4033.2
1
4063.18
1
4049.45
1
4039.69
1
4061.92
1
4065.55
1
4095.46
1
4069.28
1
4068.61
1
4057.23
1
4059.45
1
4085.93
1
4083.34
1
4055.85
1
4065.13
1
4051.45
1
4058.02
1
4064.88
1
4068.04
1
4055.55
1
4055.36
1
4047.27
1
4053.44
1
4045.58
1
4048.7
1
4022.46
1
4064.16
1
4058.76
1
4031.75
1
4029.82
1
4037.41
1
4010.65
1
4031.14
1
4028.63
1
4022.63
1
4041.42
1
4022.72
1
4043.11
1
4027.42
1
4054.13
1
4028.87
1
4024.91
1
4033.74
1
4041.64
1
4020.82
1
4054.24
1
4054.77
1
4040.36
1
4027.76
1
4036.72
1
4051.28
1
4027.17
1
4038.59
1
4053.37
1
4051.15
1
4053.17
1
4061.02
1
4055.42
1
4048.65
1
4074.19
1
4067.43
1
4091.31
1
4098.42
1
4093.23
1
4056.82
1
4064.68
1
4075.78
1
4089.18
1
4080.15
1
4100.41
1
4073.47
1
4069.8
1
4098.24
1
4089.62
1
4080.22
1
4071.68
1
4090.51
1
4115.9
1
4121.8
1
4112.85
1
4104.45
1
4149.54
1
4124.48
1
4138.13
1
4148.64
1
4170.52
1
4164.72
1
4188.67
1
4180.95
1
4165.31
1
4181.17
1
4187.54
1
4178.91
1
4180.78
1
4170.71
1
4227.2
1
4204.86
1
4202.67
1
4193.58
1
4197.05
1
4206.8
1
4199.6
1
4190.95
1
4209.2
1
4203.65
1
4226.81
1
4216.54
1
4217.43
1
4223.24
1
4229.41
1
4207.41
1
4240.63
1
4227.9
1
4233.24
1
4233.87
1
4252.25
1
4245.27
1
4257.93
1
4271.98
1
4245.85
1
4271.46
1
4273.98
1
4270.29
1
4272.6
1
4269.69
1
4281.04
1
4281.05
1
4311.61
1
4310.13
1
4282.84
1
4300.29
1
4320.27
1
4322.87
1
4341.28
1
4316.74
1
4316.45
1
4353.22
1
4329.21
1
4297.05
1
4319.06
1
4356.98
1
4376.28
1
4332.61
1
4350.19
1
4331.19
1
4359.29
1
4372.86
1
4362.28
1
4350.3
1
4377.97
1
4384.89
1
4408.84
1
4374.81
1
4374.07
1
4391.63
1
4399.03
1
4430.32
1
4450.77
1
4432.11
1
4436.09
1
4435.21
1
4448.8
1
4467.75
1
4474.36
1
4483.76
1
4497.12
1
4507.46
1
4527.36
1
4554.93
1
4544.55
1
4537.73
1
4556.31
1
4579.77
1
4577.42
1
4561.8
1
4623.04
1
4629.61
1
4633.98
1
4655.1
1
4667.86
1
4705.97
1
4730.06
1
4735.01
1
4752.94
1
4762.72
1
4792.45
1
4828.71
1
4828.7
1
4886.79
1
4913.73
1
4912.83
1
4935.49
1
4970.35
1
5023.92
1
5003.6
1
5051.46
1
5095.98
1
5137.54
1
5176.99
1
5229.74
1
5275.57
1
5304.85
1
5395.1
1
5429.72
1
5489.65
1
5540.86
1
5613.38
1
5699.42
1
5753.3
1
5831.5
1
5898.96
1
5980.26
1
6059.09
1
6178.68
1
6314.94
1
6411.18
1
6580.71
1
6699.06
1
6811.43
1
6936.81
1
7019.51
1
7041.27
1
7002.25
1
6864.2
1
6666.02
1
6434.5
1
6160.47
1
5878.15
1
5568.63
1
5279.12
1
5042.33
1
4837.55
1
4678.37
1
4510.26
1
4388.43
1
4303.01
1
4220.3
1
4147.16
1
4148.13
1
4054.21
1
4026.64
1
4015.76
1
4003.33
1
3955.86
1
3933.92
1
3904.73
1
3885.48
1
3875.89
1
3872.25
1
3829.81
1
3833.4
1
3830.76
1
3818.97
1
3824.02
1
3833.07
1
3813.13
1
3829
1
3808.58
1
3816.19
1
3820.59
1
3836.14
1
3851.1
1
3846.77
1
3837.17
1
3852.67
1
3853.64
1
3858.56
1
3896.86
1
3906.7
1
3901.95
1
3898.55
1
3884.65
1
3907.55
1
3933.9
1
3938.84
1
3931.22
1
3945.38
1
3945.76
1
3973.09
1
3988.31
1
3951.12
1
3970.79
1
3978
1
4011.65
1
4007.99
1
4008.87
1
4017.56
1
4024.89
1
4042.1
1
4070.59
1
4075.64
1
4066.28
1
4088.84
1
4091.6
1
4120.27
1
4107.12
1
4119.94
1
4126.51
1
4146.41
1
4135.17
1
4189.59
1
4216.82
1
4203.09
1
4203.86
1
4211.39
1
4242.9
1
4239.47
1
4277.85
1
4321.15
1
4327.86
1
4336.87
1
4344.37
1
4350.66
1
4360.84
1
4415.33
1
4399.67
1
4435.12
1
4454.85
1
4492.73
1
4494.65
1
4496.45
1
4550.34
1
4589.65
1
4615.25
1
4643.2
1
4683.1
1
4683.46
1
4720.65
1
4736.58
1
4789.94
1
4824.6
1
4822.89
1
4823.44
1
4875.44
1
4914.05
1
4888.3
1
4912.45
1
4905.75
1
4944.81
1
4961.19
1
4943.26
1
4970.8
1
5034.78
1
5025.78
1
5072.26
1
5151.96
1
5199.74
1
5242.44
1
5270.47
1
5403.71
1
5465.66
1
5529.36
1
5661.11
1
5744.31
1
5868.5
1
5997.12
1
6158.41
1
6342.74
1
6468.35
1
6720.09
1
6931.28
1
7225.09
1
7534.2
1
7946.21
1
8467.86
1
9085.86
1
9874.31
1
10799.3
1
11826.9
1
12812.9
1
13570.3
1
13923.1
1
13602.9
1
12656.8
1
11198.9
1
9520.84
1
7833.75
1
6439.82
1
5397.08
1
4667.5
1
4182.13
1
3815.72
1
3572.46
1
3406.33
1
3281.26
1
3175.14
1
3117.13
1
3049.81
1
2975.06
1
2948.42
1
2919.17
1
2884.24
1
2855.6
1
2843.81
1
2808.89
1
2803.59
1
2775.38
1
2766.78
1
2740.08
1
2693.98
1
2668.73
1
2657.65
1
2618.4
1
2593.98
1
2578.61
1
2536.15
1
2501.95
1
2483.01
1
2464.76
1
2433.08
1
2389.5
1
2370.49
1
2349.62
1
2376.13
1
2339.65
1
2307.94
1
2300.04
1
2282.35
1
2290.45
1
2300.01
1
2269.94
1
2253.01
1
2262.6
1
2265.68
1
2273.46
1
2271.7
1
2273.8
1
2264.05
1
2274.8
1
2272.8
1
2267.31
1
2259.87
1
2260.94
1
2283.3
1
2301.67
1
2283.84
1
2283.05
1
2300.14
1
2298.28
1
2283.51
1
2277.61
1
2288.35
1
2286.29
1
2286.73
1
2266.66
1
2255.9
1
2258.2
1
2230.89
1
2209.46
1
2186.02
1
2179.3
1
2177.35
1
2160.91
1
2138.65
1
Fe2p
Co metal
2021
4
27
18
40
49
0
16
Casa Info Follows
0
0
0
0
File = E:/OwnCloud/XPS lab/EX491_S745_Co.sle
Group = RT in vacuum, #Treatments:4h sputter, #Temp:RT , #Pressure:vacuum , #Atmosphere:{:}, #Comments:
First of group = 0
Spectrum ID = 16
Analyzer lens = AngleResolvedMode22:1.5kV
Analyzer slit = 4:7x20c\C:mesh
Scan mode = FixedAnalyzerTransmission
Kinetic energy start = 716.61
PCA Coefs = 32468.6, -4575.75, -244.522, -299.101, -116.521,
C:\Users\Mark\Downloads\EX491_S745_Co (1).vms
c:\users\pielsticker\lukas\mpi-cec\projects\deepxps\xpsdeeplearning\data\references\nicofe\ex491-495 fe, ni, co oxide references.vms
XPS
1
Al
1486.61
0
0
0
54.5
180
FAT
20
1
4.1408
0
0
0
0
0
Fe
2p
-1
kinetic energy
eV
716.61
0.1
2
counts
d
Transmission
d
pulse counting
0.1
2
0
0
0
0
2
ESCAPE DEPTH TYPE
d
1
MFP Exponent
d
0
1402
456.429
2662.14
1
1
2140.53
1
2131.21
1
2109.54
1
2096
1
2065.13
1
2053.15
1
2021.2
1
2017.9
1
2009.73
1
2002.16
1
1981.63
1
1956.09
1
1933.75
1
1928.91
1
1910.74
1
1905.49
1
1869.03
1
1837.99
1
1820.09
1
1806.02
1
1768.19
1
1726.17
1
1719.76
1
1682.45
1
1651.12
1
1615.9
1
1571.98
1
1529.59
1
1463.78
1
1426.97
1
1422.98
1
1379.69
1
1336.62
1
1324.51
1
1310.13
1
1288.63
1
1275.87
1
1260.23
1
1250.77
1
1250.04
1
1218.06
1
1206.2
1
1194.8
1
1197.15
1
1187.36
1
1189.48
1
1188.26
1
1172.11
1
1165.7
1
1172.87
1
1144.17
1
1147.09
1
1142.97
1
1144.71
1
1152.02
1
1141.8
1
1130.13
1
1134.49
1
1112.53
1
1102.93
1
1119.01
1
1114.99
1
1127.56
1
1116.24
1
1114.68
1
1115.82
1
1126.54
1
1105.33
1
1112.07
1
1123.2
1
1115.62
1
1102.12
1
1099.57
1
1098.32
1
1099.03
1
1111.54
1
1101.76
1
1087.1
1
1105.14
1
1099.8
1
1092.48
1
1106.65
1
1100.67
1
1089.12
1
1084.06
1
1090.69
1
1073.32
1
1077.38
1
1066.33
1
1062.08
1
1062.54
1
1070.22
1
1080.35
1
1062.94
1
1041.95
1
1044.98
1
1039.84
1
1058.39
1
1034.44
1
1041.55
1
1035.14
1
1029.66
1
1033.41
1
1026.4
1
1029.16
1
1023.73
1
1024.47
1
1016.57
1
1009.26
1
1022.87
1
1029.28
1
1011.82
1
1015.67
1
1011.27
1
1009.61
1
1014.57
1
1014.92
1
1012.28
1
1002
1
1016.98
1
1014.8
1
1007.84
1
1002.26
1
1004.54
1
1018.41
1
1002.44
1
994.94
1
999.388
1
1017.16
1
999.341
1
1001.83
1
1005.56
1
1004.65
1
1000.93
1
991.912
1
979.865
1
985.128
1
992.411
1
982.657
1
979.025
1
977.279
1
970.328
1
963.504
1
963.691
1
972.368
1
978.404
1
967.248
1
959.555
1
974.27
1
970.972
1
956.026
1
948.589
1
959.419
1
955.681
1
961.695
1
966.944
1
955.549
1
956.384
1
945.082
1
946.793
1
938.427
1
954.227
1
941.446
1
945.397
1
938.483
1
927.654
1
919.285
1
925.872
1
919.757
1
928.298
1
934.552
1
934.637
1
929.24
1
931.049
1
934.51
1
912.673
1
932.236
1
930.432
1
921.434
1
913.014
1
917.637
1
914.497
1
930.409
1
914.45
1
921.121
1
916.844
1
913.034
1
918.97
1
910.936
1
923.565
1
908.762
1
910.664
1
918.98
1
922.909
1
925.014
1
927.011
1
913.975
1
907.785
1
915.953
1
923.341
1
909.059
1
909.584
1
910.44
1
912.214
1
919.64
1
934.855
1
925.394
1
915.058
1
919.619
1
921.508
1
923.018
1
927.242
1
917.056
1
916.812
1
924.435
1
925.261
1
928.2
1
932.729
1
941.634
1
940.97
1
933.522
1
923.866
1
932.265
1
931.072
1
939.554
1
930.523
1
930.699
1
937.96
1
943.823
1
944.617
1
941.64
1
937.598
1
943.283
1
945.979
1
943.162
1
954.204
1
943.863
1
954.782
1
955.293
1
948.699
1
945.933
1
951.834
1
945.544
1
939.918
1
948.565
1
950.391
1
965.006
1
953.385
1
952.308
1
961.048
1
954.759
1
960.627
1
970.886
1
958.535
1
961.16
1
957.771
1
970.402
1
964.418
1
960.138
1
988.215
1
975.569
1
960.269
1
967.542
1
967.158
1
960.022
1
981.135
1
981.227
1
962.688
1
971.552
1
990.269
1
993.502
1
986.246
1
979.084
1
974.118
1
993.933
1
1000.8
1
983.012
1
994.972
1
974.657
1
978.773
1
991.763
1
981.033
1
977.451
1
991.752
1
994.873
1
1002.33
1
990.923
1
997.405
1
998.32
1
1006.77
1
1009.52
1
1013.8
1
1003.03
1
1004.72
1
1010.4
1
1001.37
1
997.397
1
1007.62
1
1011.12
1
1011.27
1
1003.32
1
1008.97
1
1015.94
1
1013.07
1
1023.94
1
1012.23
1
1010.51
1
1016.75
1
1023.8
1
1023.49
1
1019.16
1
1027.58
1
1017.52
1
1014.72
1
1016.94
1
1008.64
1
1025.66
1
1026.76
1
1027.12
1
1015.99
1
1008.06
1
1019.08
1
1015.39
1
1018.99
1
1035.81
1
1038.86
1
1040.78
1
1023.45
1
1023.63
1
1028.81
1
1017.57
1
1038.12
1
1036.83
1
1041.31
1
1042.21
1
1026.59
1
1022.7
1
1041.58
1
1030.98
1
1020.88
1
1040.14
1
1048.28
1
1030.99
1
1033.39
1
1040.33
1
1042.98
1
1054.05
1
1040.76
1
1048.49
1
1022.74
1
1025.84
1
1039.23
1
1035.64
1
1040.81
1
1036.95
1
1035.24
1
1034.43
1
1039.27
1
1030.27
1
1031.04
1
1033.66
1
1032.48
1
1041.62
1
1037.05
1
1051.81
1
1049.03
1
1045.34
1
1050.93
1
1052.63
1
1025.83
1
1044.79
1
1041.21
1
1042.44
1
1038.83
1
1045.03
1
1041.51
1
1051.38
1
1048.92
1
1052.96
1
1051.2
1
1038.53
1
1040.8
1
1054.18
1
1039.92
1
1045.32
1
1055.25
1
1040.9
1
1044.98
1
1042.32
1
1045.96
1
1033.7
1
1050.84
1
1048.04
1
1045.33
1
1035.02
1
1058.01
1
1060.71
1
1056.67
1
1047.53
1
1052.05
1
1052.2
1
1057.68
1
1049.71
1
1048.92
1
1056.05
1
1039.29
1
1063.28
1
1062.93
1
1054.84
1
1060.05
1
1045.18
1
1056.2
1
1080.66
1
1061.19
1
1060.65
1
1066.86
1
1051.38
1
1064.39
1
1069.32
1
1072.14
1
1075.49
1
1070.07
1
1080
1
1076.51
1
1086.13
1
1077.88
1
1084.61
1
1070.92
1
1074.32
1
1080.67
1
1077.08
1
1081.57
1
1088.27
1
1090.86
1
1095.86
1
1086.43
1
1091.09
1
1079.32
1
1082.11
1
1093.73
1
1103.53
1
1098.23
1
1109.11
1
1103.71
1
1102.22
1
1105.16
1
1109.19
1
1104.21
1
1106.34
1
1105.8
1
1094.67
1
1109.73
1
1123.61
1
1114.88
1
1105.07
1
1107.03
1
1129.18
1
1137.34
1
1131.76
1
1132.34
1
1139.04
1
1138.43
1
1131.73
1
1133.14
1
1152.37
1
1141.58
1
1157.26
1
1148.6
1
1159.46
1
1180.33
1
1180.05
1
1178.86
1
1181.53
1
1190.77
1
1187.16
1
1196.91
1
1201.42
1
1206.11
1
1215.63
1
1209.97
1
1217.04
1
1229.06
1
1230.71
1
1244.64
1
1252.19
1
1266.94
1
1272.12
1
1260.09
1
1259.46
1
1281.63
1
1291.4
1
1293.37
1
1303.3
1
1295.71
1
1320.9
1
1309.9
1
1316.78
1
1323.91
1
1348.66
1
1353.61
1
1359.37
1
1369.58
1
1378.61
1
1371.39
1
1381.32
1
1389.05
1
1399.62
1
1406.27
1
1406.72
1
1399.17
1
1426.73
1
1424.8
1
1448.17
1
1456
1
1465.22
1
1457.77
1
1462.34
1
1487.76
1
1500.13
1
1510.32
1
1509.88
1
1528.65
1
1553.7
1
1550.71
1
1550.56
1
1572.71
1
1587.86
1
1597.52
1
1624.9
1
1608.86
1
1622.64
1
1660.36
1
1671.42
1
1694.73
1
1738.22
1
1728.39
1
1741.78
1
1761.19
1
1782.25
1
1797.59
1
1826.48
1
1865.22
1
1882.16
1
1898.18
1
1918.66
1
1941.49
1
1975.39
1
2007.45
1
2028.5
1
2049.87
1
2066.86
1
2108.56
1
2159.33
1
2149.79
1
2206.4
1
2234.44
1
2253.55
1
2298.42
1
2341.53
1
2368.34
1
2387.15
1
2436.61
1
2462.48
1
2471.49
1
2500.52
1
2523.84
1
2557.32
1
2585.42
1
2559.09
1
2577.79
1
2605.04
1
2603.91
1
2600
1
2618.01
1
2599.89
1
2561.97
1
2549.71
1
2542.1
1
2508.34
1
2506.75
1
2480.92
1
2447.59
1
2397.78
1
2378.3
1
2348.97
1
2306.69
1
2252.97
1
2223.31
1
2181.96
1
2139.57
1
2102.35
1
2069.4
1
2036.98
1
1982.55
1
1950.56
1
1900.52
1
1854.31
1
1814.31
1
1781.17
1
1758.77
1
1722.21
1
1656.26
1
1604.01
1
1553.56
1
1515.2
1
1463.79
1
1396.7
1
1347.78
1
1284.06
1
1228.76
1
1178.25
1
1112.57
1
1055.94
1
999.328
1
946.701
1
898.101
1
852.352
1
817.286
1
790.446
1
762.028
1
729.467
1
710.709
1
691.222
1
662.927
1
657.163
1
659.52
1
633.558
1
620.657
1
608.151
1
615.575
1
600.193
1
583.58
1
578.848
1
573.072
1
568.931
1
547.742
1
545.557
1
551.515
1
541.729
1
529.967
1
526.843
1
519.711
1
515.581
1
515.406
1
507.036
1
506.607
1
501.278
1
501.052
1
500.958
1
487.25
1
494.196
1
494.728
1
490.08
1
492.067
1
497.708
1
486.664
1
476.664
1
492.234
1
478.305
1
481.379
1
481.793
1
477.812
1
482.264
1
481.966
1
472.184
1
474.246
1
471.404
1
478.376
1
477.404
1
483.154
1
492.513
1
479.769
1
486.975
1
478.334
1
480.94
1
469.67
1
473.645
1
480.502
1
480.367
1
467.232
1
478.512
1
485.738
1
488.947
1
486.938
1
479.459
1
487.088
1
477.312
1
473.748
1
473.759
1
484.465
1
493.059
1
496.375
1
491.781
1
498.19
1
504.439
1
494.887
1
504.26
1
493.987
1
504.661
1
499.737
1
517.897
1
Co2p
Co3O4
2021
4
28
14
3
32
0
16
Casa Info Follows
0
0
0
0
File = E:/OwnCloud/XPS lab/EX491_S745_Co.sle
Group = Loop 5_ RT in vacuum, #Treatments: , #Temp:RT , #Pressure:vacuum , #Atmosphere: , #Comments:
First of group = 0
Spectrum ID = 35
Analyzer lens = AngleResolvedMode22:1.5kV
Analyzer slit = 4:7x20c\C:mesh
Scan mode = FixedAnalyzerTransmission
Kinetic energy start = 646.61
PCA Coefs = 121097, 10503.5, 4030.21, -1208.61, 399.219,
C:\Users\Mark\Downloads\EX491_S745_Co (1).vms
c:\users\pielsticker\lukas\mpi-cec\projects\deepxps\xpsdeeplearning\data\references\nicofe\ex491-495 fe, ni, co oxide references.vms
XPS
2
Al
1486.61
0
0
0
54.5
180
FAT
20
1
4.1408
0
0
0
0
0
Co
2p
-1
kinetic energy
eV
646.61
0.1
2
counts
d
Transmission
d
pulse counting
0.1
3
0
0
0
0
2
ESCAPE DEPTH TYPE
d
1
MFP Exponent
d
0
1402
2338.41
9790.8
1
1
4874.31
1
4899.15
1
4906.93
1
4914.08
1
4923.15
1
4897.92
1
4907
1
4928.19
1
4927.38
1
4947.5
1
4931.35
1
4913.69
1
4931.09
1
4936.01
1
4933.23
1
4935.56
1
4923.07
1
4909.71
1
4931.01
1
4933.03
1
4921.09
1
4904.73
1
4928.58
1
4916.7
1
4914.77
1
4922.88
1
4918.25
1
4918
1
4905.29
1
4910.8
1
4893.82
1
4890.32
1
4916.98
1
4909.28
1
4897.06
1
4900.35
1
4881.96
1
4878.58
1
4874.58
1
4868.89
1
4859.94
1
4872.63
1
4875.84
1
4859.41
1
4856.38
1
4866.25
1
4863.03
1
4872.76
1
4874.43
1
4862.53
1
4863.39
1
4878.97
1
4871.59
1
4866.55
1
4879.81
1
4872.64
1
4862.51
1
4866
1
4887.22
1
4866.54
1
4875.13
1
4880.45
1
4884.2
1
4885.64
1
4911.21
1
4895.37
1
4893.96
1
4892.06
1
4879.67
1
4885.18
1
4898.59
1
4879.6
1
4895.94
1
4892.78
1
4904.13
1
4899.4
1
4912.61
1
4905.63
1
4906.53
1
4898.28
1
4889.43
1
4876.57
1
4886.18
1
4885.57
1
4869.18
1
4865.32
1
4859.71
1
4886.91
1
4850.27
1
4859.12
1
4853.83
1
4833.74
1
4810.63
1
4819.77
1
4783.83
1
4775.12
1
4779.85
1
4765.22
1
4741.95
1
4709.28
1
4709.57
1
4680.19
1
4677.36
1
4646.65
1
4635.91
1
4618.38
1
4601.06
1
4588.43
1
4579.29
1
4568.01
1
4547.84
1
4529.83
1
4504.66
1
4494.87
1
4472.73
1
4472.21
1
4447.87
1
4431.17
1
4411.71
1
4397.97
1
4401.1
1
4393.04
1
4366.72
1
4368.73
1
4355.94
1
4357.21
1
4346.01
1
4324.82
1
4337.11
1
4327.33
1
4327.34
1
4324.08
1
4307.18
1
4300.96
1
4305.88
1
4302.02
1
4280.74
1
4281.88
1
4261.55
1
4277.74
1
4287
1
4287.11
1
4283.06
1
4270.49
1
4264.07
1
4274.99
1
4280.63
1
4279.19
1
4259.87
1
4263.41
1
4270.62
1
4264.62
1
4288.64
1
4272.78
1
4268.18
1
4255.22
1
4255.89
1
4264.57
1
4261.38
1
4264.49
1
4269
1
4272.93
1
4266.43
1
4262.87
1
4264.77
1
4266.04
1
4259.46
1
4252.46
1
4266.86
1
4269.63
1
4249.45
1
4274.79
1
4257.9
1
4270.52
1
4262.44
1
4253.34
1
4252.18
1
4255.8
1
4256.1
1
4268.83
1
4266.45
1
4262.11
1
4249.59
1
4245.01
1
4251.15
1
4250.65
1
4230.82
1
4241.03
1
4230.47
1
4242.17
1
4235.59
1
4234.01
1
4232.32
1
4226.46
1
4237.5
1
4233.36
1
4221.24
1
4215.75
1
4226.08
1
4221.33
1
4218.31
1
4194.32
1
4193.69
1
4222.88
1
4206.47
1
4210.82
1
4209.14
1
4190.1
1
4202.72
1
4213.22
1
4197.28
1
4202.51
1
4198.43
1
4198.24
1
4174.86
1
4205.3
1
4188.78
1
4213.26
1
4195.94
1
4175.4
1
4180.73
1
4194.95
1
4200.21
1
4179.21
1
4171.22
1
4182.66
1
4174.57
1
4179.69
1
4182.3
1
4176.19
1
4170.34
1
4160.72
1
4161.9
1
4155.85
1
4148.16
1
4143.33
1
4163.24
1
4160.28
1
4150.58
1
4130.58
1
4148.63
1
4138.35
1
4119.16
1
4132.09
1
4130.89
1
4122.1
1
4112.57
1
4126.78
1
4128.76
1
4122.8
1
4106.94
1
4122.81
1
4108.75
1
4080.16
1
4082.61
1
4092.82
1
4101.54
1
4095.26
1
4092.09
1
4089.29
1
4103.81
1
4101.88
1
4066.33
1
4077.52
1
4082.57
1
4079.97
1
4072.21
1
4061.75
1
4059.76
1
4084.85
1
4087.77
1
4069.49
1
4050.3
1
4044.91
1
4028.05
1
4035.71
1
4031.63
1
4035.52
1
4038.22
1
4054.74
1
4050.15
1
4038.64
1
4032.06
1
4049.43
1
4066.04
1
4048.56
1
4048.15
1
4046.02
1
4057.15
1
4043.91
1
4039.32
1
4025.58
1
4031.26
1
4052.58
1
4049.91
1
4051.36
1
4041.61
1
4050.99
1
4051.17
1
4041.52
1
4045.76
1
4055.7
1
4057.68
1
4067.44
1
4067.58
1
4085.2
1
4058.9
1
4072.51
1
4065.12
1
4062.82
1
4070.23
1
4081.36
1
4086.62
1
4094.61
1
4098
1
4109.49
1
4110.18
1
4112.97
1
4125.26
1
4131.37
1
4129.82
1
4135.6
1
4139.11
1
4168.39
1
4173.6
1
4176.69
1
4180.51
1
4202.47
1
4224.5
1
4234.54
1
4250.62
1
4240.57
1
4274.75
1
4292.37
1
4313.79
1
4300.02
1
4307.72
1
4324.11
1
4339.06
1
4355.56
1
4368.93
1
4391.69
1
4394.09
1
4410.25
1
4411.09
1
4416.37
1
4435.45
1
4437.73
1
4444.36
1
4443.04
1
4463.29
1
4468.71
1
4483.88
1
4498.57
1
4493.55
1
4488.97
1
4485.23
1
4509.55
1
4496.9
1
4499.54
1
4493.29
1
4511.05
1
4485.14
1
4477.99
1
4492.92
1
4462
1
4463.13
1
4454.8
1
4457.56
1
4496.3
1
4465.78
1
4448.27
1
4445.75
1
4422.14
1
4417.93
1
4430.44
1
4411.52
1
4394.04
1
4388.04
1
4396.1
1
4368.86
1
4344.1
1
4328.66
1
4328.53
1
4323.9
1
4320.32
1
4310.36
1
4294.49
1
4279.33
1
4285.18
1
4264.6
1
4254.3
1
4260.26
1
4266.56
1
4250.34
1
4259.19
1
4222.73
1
4233.84
1
4243.42
1
4227.15
1
4240.16
1
4232.69
1
4249.78
1
4270.57
1
4257.24
1
4257.31
1
4297.98
1
4296.09
1
4317.76
1
4324.68
1
4348.62
1
4364.09
1
4398.79
1
4434.87
1
4461.77
1
4476.97
1
4534.53
1
4550.6
1
4593.12
1
4641.15
1
4692.36
1
4734.51
1
4798.94
1
4849.38
1
4906.09
1
4949.11
1
5024.6
1
5074.91
1
5142.5
1
5218.83
1
5298.92
1
5356.14
1
5417.11
1
5477.49
1
5552.38
1
5613.86
1
5683.78
1
5719.11
1
5783.45
1
5834.78
1
5873.96
1
5927.19
1
5957.87
1
6001.83
1
6036.13
1
6066.22
1
6085.84
1
6098.26
1
6118.13
1
6171.88
1
6208.49
1
6286.47
1
6359.09
1
6454.42
1
6498.75
1
6530.91
1
6502.89
1
6390.96
1
6199.28
1
5917.75
1
5629.04
1
5330.71
1
5033.71
1
4779.03
1
4579.33
1
4415.86
1
4294.43
1
4166.49
1
4084.86
1
4029.51
1
3972.13
1
3934.55
1
3909.31
1
3897.8
1
3883.61
1
3887.62
1
3890.26
1
3903.02
1
3903.27
1
3910.82
1
3924.78
1
3952.53
1
3977.47
1
4003.03
1
4020.01
1
4048.03
1
4077.04
1
4100.84
1
4135.59
1
4141.37
1
4165.67
1
4203.83
1
4231.55
1
4252.87
1
4269.62
1
4284.29
1
4287.87
1
4312.89
1
4353.23
1
4354.76
1
4357.38
1
4390.48
1
4385.98
1
4383.54
1
4376.09
1
4388.08
1
4419.72
1
4430.92
1
4422.59
1
4419.68
1
4428.82
1
4438.57
1
4417.75
1
4427.88
1
4410.86
1
4397.29
1
4386.68
1
4387.34
1
4367.17
1
4359.31
1
4362.92
1
4341.28
1
4346.8
1
4352.16
1
4335.05
1
4313.14
1
4326.59
1
4323.22
1
4311.38
1
4313.79
1
4354.23
1
4345.21
1
4331.29
1
4353.98
1
4346.32
1
4335.09
1
4328.45
1
4352.2
1
4351.18
1
4351.28
1
4355.18
1
4342.83
1
4388.3
1
4381.54
1
4367.99
1
4362.96
1
4370.83
1
4363.65
1
4374.72
1
4358.86
1
4347.83
1
4373.41
1
4381.21
1
4392.96
1
4396.55
1
4408.13
1
4423.04
1
4419.83
1
4432.86
1
4446.5
1
4480.98
1
4523.46
1
4547.07
1
4588.3
1
4643.98
1
4681.43
1
4715.67
1
4780.82
1
4852.2
1
4921.26
1
4981.57
1
5042.33
1
5149.32
1
5239.38
1
5342.77
1
5451.05
1
5561.95
1
5682.33
1
5800.56
1
5954.24
1
6116.08
1
6232.67
1
6389.51
1
6572.71
1
6732.83
1
6880.6
1
7041.13
1
7201.61
1
7363.26
1
7552.24
1
7710.33
1
7869.82
1
8061.76
1
8221.06
1
8351.72
1
8494.8
1
8586.38
1
8655.17
1
8748.39
1
8778.47
1
8930.03
1
9060.56
1
9202.25
1
9430.15
1
9637.46
1
9777.93
1
9762.67
1
9542.68
1
9061.49
1
8419.58
1
7660.66
1
6875.64
1
6185.17
1
5625.52
1
5170.82
1
4825.73
1
4535.96
1
4251.39
1
3997.96
1
3782.67
1
3580.5
1
3422.18
1
3282.22
1
3203.44
1
3143.96
1
3072.56
1
3022.36
1
3007.79
1
2966.76
1
2954.79
1
2926.19
1
2922.46
1
2891.52
1
2870.36
1
2858.07
1
2848.05
1
2820.37
1
2804.29
1
2792.29
1
2771.25
1
2766.01
1
2757.26
1
2739.59
1
2724.12
1
2715.66
1
2710.67
1
2696.93
1
2668.03
1
2662.11
1
2660.77
1
2653.28
1
2643.89
1
2623.28
1
2630.83
1
2616.75
1
2619.83
1
2606.83
1
2593.88
1
2594.84
1
2595.47
1
2580.89
1
2575.78
1
2574.82
1
2559.33
1
2557.45
1
2558.59
1
2544.08
1
2550.95
1
2538.87
1
2534.03
1
2519.94
1
2506.31
1
2514.19
1
2514.21
1
2501.68
1
2502.88
1
2495.23
1
2494.96
1
2496.17
1
2484.58
1
2489.46
1
2481.78
1
2503.19
1
2493.2
1
2469.32
1
2479.95
1
2479.42
1
2486.47
1
2474.39
1
2465.76
1
2472.4
1
2462.19
1
2458.47
1
2444.63
1
2432.51
1
2428
1
2430.73
1
2437.06
1
2427.84
1
2415.98
1
2401.99
1
Fe2p
Co3O4
2021
4
28
14
29
15
0
16
Casa Info Follows
0
0
0
0
File = E:/OwnCloud/XPS lab/EX491_S745_Co.sle
Group = Loop 5_ RT in vacuum, #Treatments: , #Temp:RT , #Pressure:vacuum , #Atmosphere: , #Comments:
First of group = 0
Spectrum ID = 39
Analyzer lens = AngleResolvedMode22:1.5kV
Analyzer slit = 4:7x20c\C:mesh
Scan mode = FixedAnalyzerTransmission
Kinetic energy start = 716.61
PCA Coefs = 195201, 8547.87, 2120.12, 1589.24, -1006.69,
C:\Users\Mark\Downloads\EX491_S745_Co (1).vms
c:\users\pielsticker\lukas\mpi-cec\projects\deepxps\xpsdeeplearning\data\references\nicofe\ex491-495 fe, ni, co oxide references.vms
XPS
14
Al
1486.61
0
0
0
54.5
180
FAT
20
1
4.1408
0
0
0
0
0
Fe
2p
-1
kinetic energy
eV
716.61
0.1
2
counts
d
Transmission
d
pulse counting
0.1
15
0
0
0
0
2
ESCAPE DEPTH TYPE
d
1
MFP Exponent
d
0
1402
4771.2
11702.7
1
1
11517
1
11607.8
1
11691.8
1
11477.8
1
11556.6
1
11423.9
1
11182.1
1
11297.7
1
11328.3
1
11018.9
1
11135.4
1
10901.1
1
10888.3
1
10495
1
10396.4
1
10336
1
10407.9
1
10224.5
1
10093.8
1
9807.24
1
9788.05
1
9573.98
1
9517.83
1
9405.87
1
9156.38
1
9049.54
1
9170.01
1
8982.27
1
8883.18
1
8893.51
1
8901.7
1
8716.82
1
8403.85
1
8316.5
1
8337.57
1
8462.42
1
8361.56
1
8257.25
1
8243.92
1
8246.47
1
8146.69
1
8148.8
1
8049.96
1
8010.07
1
7875.83
1
7951.08
1
7955.43
1
7998.57
1
7958.47
1
7825.74
1
7639.08
1
7728.59
1
7959.97
1
7938.2
1
7862.39
1
7727.18
1
7845.67
1
7787.5
1
7820.4
1
7719.14
1
7672.68
1
7704.58
1
7646.83
1
7560.85
1
7532.95
1
7594.37
1
7740.62
1
7724.25
1
7615.5
1
7562.14
1
7503.79
1
7579.33
1
7578.34
1
7445.13
1
7448.53
1
7505.97
1
7409.41
1
7517
1
7564.42
1
7426.85
1
7414.97
1
7284.11
1
7359.41
1
7425.58
1
7452.31
1
7451.33
1
7521.51
1
7448.62
1
7359.1
1
7272.14
1
7328.44
1
7323.99
1
7250.18
1
7233.87
1
7244.15
1
7289.23
1
7398.38
1
7141.33
1
7210.21
1
7306.84
1
7380.65
1
7373.94
1
7173.04
1
7061.45
1
7208.03
1
7111.35
1
7180.14
1
7154.81
1
7059.05
1
7128.07
1
7137.71
1
7253.42
1
7193.02
1
7141.07
1
7107.48
1
7105.94
1
7197.46
1
7143.21
1
7084.75
1
7132.93
1
7106.1
1
7207.44
1
7052.81
1
7058.6
1
7099.35
1
7095.11
1
7079.06
1
7050.74
1
6955.66
1
6921.88
1
6965.85
1
6970.54
1
7048.45
1
6867.09
1
6905.36
1
6858.32
1
6980.01
1
7047.17
1
6887.42
1
7007.46
1
6982.32
1
6682.37
1
6935.13
1
6834.75
1
6758.58
1
6753.9
1
6668.78
1
6732.27
1
6778.72
1
6693.99
1
6552.36
1
6642.12
1
6662.4
1
6611.62
1
6498.43
1
6624.81
1
6579.17
1
6578.39
1
6524.25
1
6499.41
1
6562.36
1
6591.42
1
6521.92
1
6388.15
1
6475.96
1
6473.69
1
6525.25
1
6377.74
1
6448.15
1
6400.14
1
6375.2
1
6425.27
1
6411.87
1
6423.22
1
6481.21
1
6375.7
1
6417.86
1
6334.3
1
6274.82
1
6304.17
1
6269.73
1
6284.94
1
6337.89
1
6334.6
1
6376.77
1
6364.6
1
6342.91
1
6398.38
1
6381.64
1
6302.49
1
6275.56
1
6383.84
1
6250.33
1
6128.75
1
6340.06
1
6375.13
1
6323.56
1
6324.11
1
6281.82
1
6253.31
1
6342.53
1
6311.42
1
6273.17
1
6313.24
1
6389.14
1
6389
1
6357.95
1
6295.81
1
6365.29
1
6297.07
1
6336.6
1
6247.99
1
6289.52
1
6285.14
1
6250.78
1
6318.82
1
6280.9
1
6339.78
1
6264.64
1
6357.63
1
6350.77
1
6258.9
1
6331
1
6299.68
1
6404.5
1
6323.71
1
6278.18
1
6372.1
1
6464.59
1
6321.37
1
6229.67
1
6172.21
1
6329.24
1
6361.87
1
6355.91
1
6290.83
1
6317.39
1
6346.12
1
6330.52
1
6232.7
1
6294.47
1
6340.4
1
6463.6
1
6499.22
1
6342.68
1
6205.2
1
6273.96
1
6358.05
1
6325.58
1
6378.32
1
6402.77
1
6365.64
1
6348.52
1
6328.9
1
6409.06
1
6527.48
1
6410.24
1
6393.4
1
6409.12
1
6327.71
1
6343.55
1
6289.37
1
6338.18
1
6464.05
1
6410.35
1
6375.32
1
6440.72
1
6371.9
1
6382.82
1
6330.89
1
6367.83
1
6418.72
1
6371.99
1
6426.84
1
6392.34
1
6424.66
1
6352.51
1
6429.93
1
6357.07
1
6362.93
1
6335.09
1
6272.69
1
6306.11
1
6456.35
1
6442.1
1
6464.12
1
6426.64
1
6293.28
1
6416.19
1
6350.22
1
6391.43
1
6405.8
1
6309.49
1
6372.39
1
6444.58
1
6375.38
1
6353.03
1
6278.05
1
6338.56
1
6362.32
1
6362.92
1
6356.77
1
6308.28
1
6368.06
1
6410.44
1
6314.61
1
6361.14
1
6418.74
1
6388.05
1
6327.93
1
6336.33
1
6401.14
1
6417.57
1
6382.86
1
6426.54
1
6498.35
1
6543.13
1
6558.73
1
6376.56
1
6452.97
1
6480.02
1
6553.4
1
6512.11
1
6383.64
1
6381.87
1
6422.75
1
6409.46
1
6405.29
1
6344.77
1
6391.62
1
6389.5
1
6345.9
1
6381.75
1
6297.44
1
6375.79
1
6425.96
1
6457.35
1
6377.56
1
6392.82
1
6417.71
1
6356.31
1
6294.57
1
6382.96
1
6346.03
1
6369.75
1
6445.03
1
6522.28
1
6452.37
1
6393.3
1
6420.02
1
6425.81
1
6234.69
1
6388.16
1
6458.01
1
6365.02
1
6313.05
1
6302.42
1
6327.25
1
6455.76
1
6351.34
1
6318.15
1
6260.2
1
6434.37
1
6439.08
1
6304.42
1
6374.22
1
6253.42
1
6303.47
1
6420.77
1
6359.08
1
6302.41
1
6389.53
1
6533.3
1
6463.97
1
6503.77
1
6389.07
1
6378.76
1
6340.15
1
6333.09
1
6387.68
1
6425.42
1
6371.92
1
6410.03
1
6493.31
1
6302.13
1
6291.08
1
6346.84
1
6478.45
1
6381.22
1
6324.32
1
6366.49
1
6250.67
1
6293.94
1
6335.93
1
6399.88
1
6361.37
1
6269.95
1
6363.84
1
6380.36
1
6387.99
1
6226.25
1
6267.07
1
6283.43
1
6404.28
1
6343.99
1
6425.49
1
6424.43
1
6328.3
1
6455.35
1
6336.62
1
6391.36
1
6446.95
1
6318.28
1
6305.34
1
6348.1
1
6321.22
1
6415.31
1
6412.95
1
6333.27
1
6425.96
1
6469.76
1
6410.01
1
6319.8
1
6424.05
1
6417.11
1
6454.42
1
6443.02
1
6439.75
1
6419.62
1
6431.18
1
6449.01
1
6560.75
1
6583.47
1
6549.01
1
6481.41
1
6541.42
1
6491.14
1
6499.46
1
6653.6
1
6648.28
1
6744.65
1
6584.98
1
6535.77
1
6702.63
1
6775.02
1
6804.05
1
6760.26
1
6792.53
1
6753.33
1
6673.91
1
6689.07
1
6748.1
1
6865.51
1
6835.05
1
6884.04
1
6921.15
1
7042.06
1
7005.61
1
6914.79
1
6919.16
1
7161.82
1
7126.89
1
7102.2
1
7110.09
1
7057.09
1
7187.69
1
7150.25
1
7246.5
1
7239.14
1
7405.89
1
7335.27
1
7403.1
1
7539.09
1
7455.15
1
7523.46
1
7522.32
1
7601.22
1
7672.38
1
7543.2
1
7588.54
1
7738.4
1
7879.06
1
7814.23
1
7799.06
1
7755.43
1
7859.59
1
7919.9
1
8003.25
1
8086.05
1
8259.41
1
8233.48
1
8231.31
1
8253.97
1
8174.58
1
8237.82
1
8393.11
1
8391.26
1
8559.23
1
8615.82
1
8690.65
1
8646.69
1
8658.03
1
8671.5
1
8802.05
1
8883.24
1
9047.59
1
9002.49
1
8952
1
9142.95
1
9067.56
1
9098.14
1
9120.75
1
9139.36
1
9296.7
1
9336.58
1
9372.24
1
9225.96
1
9421.04
1
9463.3
1
9446.07
1
9571.75
1
9492.41
1
9634.41
1
9714.57
1
9621.46
1
9650.62
1
9559.58
1
9792.47
1
9736.46
1
9838.65
1
9934.13
1
9986.9
1
10128.9
1
10016.4
1
10047.9
1
10120.6
1
10038.9
1
10086.6
1
10102.6
1
10217
1
10126.4
1
10100.4
1
10153
1
10136.5
1
10187.7
1
10128.1
1
10082
1
10236.5
1
10273
1
10215.6
1
10217.1
1
10194.1
1
10308
1
10358.7
1
10209.5
1
10268.6
1
10227.5
1
10334.7
1
10314
1
10190.9
1
10272
1
10287.7
1
10397.8
1
10468.6
1
10428.3
1
10377
1
10443.9
1
10487.6
1
10632.9
1
10636
1
10748.4
1
10884.1
1
10762
1
10761.5
1
10783
1
10771.7
1
10806.4
1
10883.7
1
10691.8
1
10679.2
1
10607.1
1
10348.6
1
10392
1
10288.2
1
10077.9
1
9955.16
1
9939.98
1
9781.69
1
9820.05
1
9783.11
1
9684.91
1
9488.75
1
9771.19
1
9507.29
1
9320.39
1
9269.46
1
9255.53
1
9156.03
1
9025.4
1
8843.48
1
8824.7
1
8764.08
1
8580.67
1
8457.87
1
8246.88
1
8227.52
1
8021.14
1
7809.91
1
7629.52
1
7442.19
1
7347.27
1
7328.84
1
7135.42
1
6881.63
1
6806.78
1
6778.86
1
6697.4
1
6613.22
1
6493.74
1
6292.46
1
6342.11
1
6250.96
1
6059.01
1
6194.62
1
6125.19
1
5998.67
1
5901.51
1
5751.77
1
5748.82
1
5679.57
1
5669.85
1
5543.77
1
5405.53
1
5452.37
1
5400.55
1
5397.32
1
5273.73
1
5360.64
1
5294.21
1
5194.72
1
5088.45
1
5131.93
1
5165.4
1
5136
1
5124.15
1
4932.36
1
4961.37
1
5029.3
1
5042.69
1
5011.89
1
4983.69
1
4903.33
1
5038.27
1
4986.49
1
4932.54
1
4771.49
1
4958.37
1
4882.56
1
4941.82
1
4930.07
1
4937.87
1
4916.66
1
4864.61
1
4880.33
1
4879.46
1
4905.18
1
4925.7
1
4918.76
1
4910.13
1
4801.17
1
4819.32
1
4836.67
1
4889.71
1
4907.53
1
4905.12
1
4848.64
1
4899.94
1
4821.68
1
4886.55
1
4994.19
1
4895.52
1
4978.82
1
4952.83
1
5026.23
1
4991.79
1
4902.96
1
5015.38
1
5014.52
1
4994.2
1
4933.84
1
4928.53
1
5019.86
1
5034.6
1
4922.76
1
4917.84
1
4988.36
1
5127.98
1
5068.32
1
4990.06
1
5025.85
1
4960.33
1
Co2p
CoO
2021
4
29
9
50
16
0
16
Casa Info Follows
0
0
0
0
File = E:/OwnCloud/XPS lab/EX491_S745_Co.sle
Group = Loop 11_ RT in vacuum, #Treatments: , #Temp:RT , #Pressure:vacuum , #Atmosphere: , #Comments:
First of group = 0
Spectrum ID = 61
Analyzer lens = AngleResolvedMode22:1.5kV
Analyzer slit = 4:7x20c\C:mesh
Scan mode = FixedAnalyzerTransmission
Kinetic energy start = 646.61
PCA Coefs = 146858, 18127.4, -14522.3, -1131.5, -938.021,
C:\Users\Mark\Downloads\EX491_S745_Co (1).vms
c:\users\pielsticker\lukas\mpi-cec\projects\deepxps\xpsdeeplearning\data\references\nicofe\ex491-495 fe, ni, co oxide references.vms
XPS
8
Al
1486.61
0
0
0
54.5
180
FAT
20
1
4.1408
0
0
0
0
0
Co
2p
-1
kinetic energy
eV
646.61
0.1
2
counts
d
Transmission
d
pulse counting
0.1
3
0
0
0
0
2
ESCAPE DEPTH TYPE
d
1
MFP Exponent
d
0
1402
2556.35
10658.9
1
1
5793.49
1
5769.83
1
5778.71
1
5793.63
1
5824.14
1
5800.77
1
5775.7
1
5779.5
1
5824.43
1
5771.05
1
5757.64
1
5800.48
1
5809.69
1
5781.79
1
5762.01
1
5820.93
1
5789.52
1
5789.72
1
5788.65
1
5747.62
1
5713.6
1
5735.09
1
5758.97
1
5782.19
1
5755.33
1
5754
1
5749.84
1
5760.21
1
5714.93
1
5730.73
1
5717.53
1
5733.84
1
5783.62
1
5764.39
1
5750.08
1
5706.17
1
5710.57
1
5775.05
1
5732.2
1
5732.33
1
5777.68
1
5752.96
1
5718.55
1
5719.85
1
5742.52
1
5758.4
1
5746.43
1
5736.17
1
5752.67
1
5776.23
1
5773.43
1
5773.14
1
5754.87
1
5717.55
1
5746.9
1
5749.14
1
5815.13
1
5783.64
1
5791.97
1
5801.8
1
5844.23
1
5776.14
1
5786.45
1
5787.41
1
5816.46
1
5779.54
1
5800.57
1
5833.82
1
5806.85
1
5810.39
1
5790.78
1
5766.05
1
5754.93
1
5803.2
1
5761.97
1
5762.91
1
5754.17
1
5784.2
1
5782.09
1
5750.94
1
5713.89
1
5714.6
1
5689.32
1
5687.11
1
5664.86
1
5622.49
1
5617.77
1
5622.64
1
5629.93
1
5591.64
1
5564.16
1
5495.03
1
5482.19
1
5499.92
1
5457.85
1
5396.59
1
5389.73
1
5393.43
1
5373.73
1
5359.55
1
5325.33
1
5311.19
1
5261.36
1
5226.56
1
5209.16
1
5250.1
1
5220.74
1
5187.71
1
5195.49
1
5147.97
1
5142.86
1
5137.96
1
5143.73
1
5071.07
1
5055.82
1
5061.95
1
5050.19
1
5084.71
1
5093.97
1
5024.79
1
5028.16
1
5022.74
1
4982
1
5011.43
1
4999.29
1
5000.47
1
4988.08
1
4978
1
4947.82
1
4990.69
1
4976.88
1
4985.71
1
4961.71
1
4955.57
1
4943.25
1
4928.93
1
4926.53
1
4905.66
1
4920.49
1
4930.85
1
4939.62
1
4921.31
1
4928.34
1
4902.63
1
4938.92
1
4917.99
1
4941.64
1
4939.42
1
4893.49
1
4892.88
1
4944.97
1
4896.84
1
4909.48
1
4881.53
1
4871.26
1
4919.57
1
4885.68
1
4846
1
4888.58
1
4911.27
1
4920.47
1
4925.96
1
4941.63
1
4917.94
1
4920.7
1
4906.33
1
4906.68
1
4931.43
1
4904.64
1
4922.6
1
4941.17
1
4914.76
1
4918.11
1
4946.79
1
4945.94
1
4897.61
1
4931.64
1
4952.05
1
4932
1
4918.49
1
4923.74
1
4933.57
1
4926.89
1
4898.44
1
4951.9
1
4938.59
1
4935
1
4967.75
1
4987.1
1
4979.03
1
4898.93
1
4958.6
1
4958.07
1
4954.99
1
4919.84
1
4935.87
1
4932
1
4956.8
1
4976.97
1
4943.39
1
4937.77
1
4967.86
1
4951.02
1
4962.1
1
4931.93
1
4946.7
1
4945.08
1
4941.64
1
4911.94
1
4886.15
1
4941.61
1
4917.3
1
4950.51
1
4915.77
1
4921.33
1
4939.12
1
4960.52
1
4934.6
1
4926.02
1
4893.77
1
4930.18
1
4896.72
1
4875.85
1
4914.02
1
4906.59
1
4914.23
1
4871.98
1
4861.96
1
4885.18
1
4896.42
1
4890.41
1
4859.55
1
4825.29
1
4845.6
1
4856.34
1
4841.85
1
4848.07
1
4842.62
1
4813.11
1
4793.02
1
4801.65
1
4775.01
1
4805.73
1
4779
1
4782.77
1
4734.47
1
4708.07
1
4729.81
1
4725.29
1
4705.84
1
4743
1
4715.95
1
4725.42
1
4701.5
1
4707.99
1
4698.6
1
4678.59
1
4621.68
1
4612.6
1
4634.59
1
4651.45
1
4615.01
1
4607.39
1
4609.12
1
4606.3
1
4621.14
1
4624.87
1
4592.67
1
4606.97
1
4570.15
1
4583.4
1
4594.43
1
4565.83
1
4563.91
1
4509.29
1
4551.23
1
4536.8
1
4521.57
1
4519.04
1
4528.22
1
4528.2
1
4514.42
1
4514.77
1
4525.51
1
4502.34
1
4496.64
1
4474.79
1
4480.22
1
4453.43
1
4444.93
1
4471.44
1
4469.89
1
4466.88
1
4465.54
1
4466.6
1
4458.35
1
4486.88
1
4488.34
1
4532.02
1
4475.85
1
4480.26
1
4494.58
1
4465.39
1
4464.14
1
4470.03
1
4487.05
1
4481.48
1
4488.48
1
4470
1
4460.89
1
4500.81
1
4553.73
1
4517.95
1
4529.47
1
4528.81
1
4573.75
1
4579.93
1
4608.2
1
4598.7
1
4640.74
1
4639.3
1
4634.6
1
4676.24
1
4739.9
1
4755.43
1
4710.06
1
4743.32
1
4774.89
1
4783.31
1
4758.91
1
4808.5
1
4837.09
1
4876.9
1
4866.84
1
4868.18
1
4913.6
1
4973.16
1
5006.32
1
5031.18
1
5094.28
1
5075.39
1
5124.06
1
5138.35
1
5157.11
1
5211.01
1
5253.13
1
5327.67
1
5353.55
1
5386.65
1
5418.48
1
5467.19
1
5527.44
1
5603.21
1
5638.88
1
5721.5
1
5788.28
1
5880.47
1
5949.27
1
6008.12
1
6089.39
1
6115.14
1
6213.68
1
6304.39
1
6342.57
1
6400.14
1
6535.83
1
6509.01
1
6550.05
1
6644.98
1
6655.68
1
6648.49
1
6623.17
1
6626.63
1
6589.09
1
6583.64
1
6552.61
1
6572.91
1
6441.04
1
6387.56
1
6362.13
1
6260.24
1
6213.49
1
6158.92
1
6114.09
1
6074.97
1
6000.26
1
5929.25
1
5851.27
1
5770.74
1
5760.73
1
5710.76
1
5667.82
1
5590.33
1
5554.29
1
5507.89
1
5494.05
1
5467.73
1
5443.64
1
5433.62
1
5405.48
1
5433.82
1
5417.93
1
5428.88
1
5445.45
1
5456.05
1
5488.54
1
5526.37
1
5547.86
1
5608.75
1
5667.34
1
5721.86
1
5774.46
1
5827.32
1
5902.81
1
6030.63
1
6105.55
1
6171.92
1
6227.55
1
6378.61
1
6460.31
1
6591.71
1
6670.09
1
6750.79
1
6777.2
1
6918.69
1
7056.07
1
7085.33
1
7121.49
1
7161.43
1
7222.61
1
7326.94
1
7344.73
1
7357.04
1
7385.39
1
7454.66
1
7461.28
1
7452.56
1
7464.74
1
7416.4
1
7403.89
1
7340.47
1
7331.99
1
7242.78
1
7131.03
1
7032.57
1
6991.16
1
6838.79
1
6660.16
1
6542.54
1
6354.83
1
6214.31
1
6054.99
1
5929.5
1
5718.51
1
5512.59
1
5345.22
1
5207.94
1
5051.97
1
4967.01
1
4882.2
1
4722.67
1
4660.17
1
4631.1
1
4591.16
1
4516.73
1
4494.35
1
4481.47
1
4454.85
1
4428.37
1
4416.59
1
4462.29
1
4432.81
1
4445.67
1
4462.12
1
4474.55
1
4516.75
1
4539.79
1
4517.93
1
4560.66
1
4585.08
1
4673.1
1
4696.88
1
4711.66
1
4727.76
1
4776.91
1
4765.07
1
4821.82
1
4874.11
1
4898.68
1
4907.77
1
4927.68
1
4969.74
1
4971.48
1
5018.38
1
5067.95
1
5056.2
1
5078.07
1
5098.25
1
5165.26
1
5182.56
1
5219.14
1
5245.78
1
5327.71
1
5341.41
1
5406.1
1
5434.44
1
5517.26
1
5602.97
1
5653.28
1
5735.73
1
5841.38
1
5884.38
1
5935.56
1
6026.6
1
6140.52
1
6243.54
1
6314.72
1
6337.17
1
6419.21
1
6501.65
1
6587.89
1
6626.41
1
6646.42
1
6740.91
1
6817.7
1
6846.04
1
6953.91
1
6953.9
1
7015.85
1
7047.98
1
7101.75
1
7165.33
1
7218.87
1
7266.27
1
7348
1
7371.05
1
7316.21
1
7382.63
1
7324.9
1
7293.03
1
7245.04
1
7177.46
1
7142.49
1
7045.02
1
7023.8
1
6895.23
1
6830.41
1
6739.48
1
6643.74
1
6632.25
1
6630.32
1
6591.83
1
6598.33
1
6575.15
1
6531.98
1
6613.92
1
6640.59
1
6651.93
1
6703.61
1
6743.4
1
6836.81
1
6923.2
1
6988.41
1
7081.4
1
7184.37
1
7309.88
1
7444.86
1
7566.28
1
7690.3
1
7807.2
1
7891.8
1
7959.14
1
8091.18
1
8233.31
1
8334.37
1
8417.31
1
8509.89
1
8613.45
1
8740.49
1
8852.38
1
8954.2
1
9055.61
1
9244.31
1
9333.22
1
9423.61
1
9568.04
1
9720.64
1
9835.06
1
9957.61
1
10032.5
1
10123.1
1
10254.2
1
10362.2
1
10486.6
1
10495.8
1
10500.9
1
10547.4
1
10490
1
10496.6
1
10331.7
1
10209.8
1
10073.6
1
9854.09
1
9648.25
1
9457.95
1
9177.54
1
8819.24
1
8416.77
1
8038.94
1
7675.15
1
7209.58
1
6694.9
1
6258.65
1
5863.55
1
5465.44
1
5114.25
1
4748.5
1
4484.21
1
4248.08
1
4071.84
1
3928.19
1
3848.2
1
3749.03
1
3687.68
1
3642.69
1
3563.91
1
3545.61
1
3541.72
1
3480.46
1
3484.22
1
3494.43
1
3428.99
1
3402.28
1
3393.13
1
3349.96
1
3340.49
1
3301.33
1
3313.93
1
3300.39
1
3295.76
1
3260.03
1
3221.01
1
3217.27
1
3215.73
1
3197.69
1
3178
1
3171.31
1
3186.18
1
3144.98
1
3147
1
3139.48
1
3094.96
1
3104.28
1
3102.71
1
3080.88
1
3092.66
1
3068.87
1
3061.28
1
3054.32
1
3047.58
1
3008.9
1
3022.82
1
3022.41
1
3026.81
1
3022.62
1
3013.82
1
2983.56
1
2994.07
1
3002.59
1
2952.01
1
2993.31
1
2985.52
1
2957.78
1
2975.44
1
2935.4
1
2942.52
1
2932.42
1
2944.54
1
2954.26
1
2946.27
1
2923.9
1
2912.64
1
2924.42
1
2942.57
1
2896.78
1
2881.23
1
2856.98
1
2848.07
1
2836.05
1
2813.23
1
2826.89
1
2817.17
1
2786.8
1
2732.04
1
2750.86
1
2744.78
1
2710.28
1
2679.96
1
2629.85
1
2620.59
1
2572.15
1
Fe2p
CoO
2021
4
29
9
54
50
0
16
Casa Info Follows
0
0
0
0
File = E:/OwnCloud/XPS lab/EX491_S745_Co.sle
Group = Loop 11_ RT in vacuum, #Treatments: , #Temp:RT , #Pressure:vacuum , #Atmosphere: , #Comments:
First of group = 0
Spectrum ID = 62
Analyzer lens = AngleResolvedMode22:1.5kV
Analyzer slit = 4:7x20c\C:mesh
Scan mode = FixedAnalyzerTransmission
Kinetic energy start = 716.61
PCA Coefs = 45246.8, 333.588, -2496.54, 534.268, 63.0123,
C:\Users\Mark\Downloads\EX491_S745_Co (1).vms
c:\users\pielsticker\lukas\mpi-cec\projects\deepxps\xpsdeeplearning\data\references\nicofe\ex491-495 fe, ni, co oxide references.vms
XPS
8
Al
1486.61
0
0
0
54.5
180
FAT
20
1
4.1408
0
0
0
0
0
Fe
2p
-1
kinetic energy
eV
716.61
0.1
2
counts
d
Transmission
d
[...]
3.28884
1886.2
3.2886
1902.68
3.28836
1896.77
3.28813
1909.27
3.28789
1897.42
3.28765
1919.56
3.28741
1921.63
3.28718
1913.53
3.28694
1933.51
3.2867
1919.03
3.28646
1925.5
3.28623
1937.36
3.28599
1941.03
3.28575
1944.84
3.28552
1952.03
3.28528
1960.57
3.28504
1959.99
3.28481
1954.24
3.28457
1972.11
3.28433
1953.57
3.2841
1967.22
3.28386
1977
3.28362
1988.47
3.28339
1981.88
3.28315
1973.77
3.28291
1983.37
3.28268
1989.28
3.28244
2010.46
3.2822
2000.59
3.28197
2008.58
3.28173
2010.52
3.28149
2003.9
3.28126
1999.03
3.28102
2005.43
3.28079
2018.61
3.28055
2012.43
3.28031
2009.12
3.28008
2015.87
3.27984
2026.93
3.27961
2017.4
3.27937
2018.48
3.27914
2039.21
3.2789
2029.28
3.27866
2038.92
3.27843
2049.73
3.27819
2026.38
3.27796
2038.75
3.27772
2021.77
3.27749
2040.71
3.27725
2048.79
3.27702
2037.03
3.27678
2042.25
3.27655
2057.46
3.27631
2063.38
3.27608
2063.89
3.27584
2058.23
3.27561
2057.52
3.27537
2072.32
3.27514
2076.2
3.2749
2073.86
3.27467
2080.56
3.27443
2088.36
3.2742
2091.64
3.27396
2106.58
3.27373
2103.87
3.27349
2097.91
3.27326
2099.38
3.27303
2107.46
3.27279
2101.73
3.27256
2119.25
3.27232
2118.31
3.27209
2107.73
3.27185
2107.59
3.27162
2106.31
3.27139
2103.51
3.27115
2104.69
3.27092
2108.65
3.27068
2100.49
3.27045
2103.11
3.27022
2111.1
3.26998
2107.42
3.26975
2094.29
3.26952
2090.82
3.26928
2074.57
3.26905
2071.41
3.26882
2073.42
3.26858
2055.95
3.26835
2044.14
3.26812
2034.34
3.26788
2024.34
3.26765
2033.28
3.26742
2025.82
3.26718
2007.54
3.26695
2000.8
3.26672
1988.12
3.26648
1980.47
3.26625
1960.36
3.26602
1950.73
3.26579
1942.01
3.26555
1924.6
3.26532
1910.71
3.26509
1896.28
3.26485
1880.92
3.26462
1874.48
3.26439
1870.26
3.26416
1853.93
3.26392
1841.2
3.26369
1817.27
3.26346
1809.12
3.26323
1797.6
3.263
1795.14
3.26276
1783.6
3.26253
1756.34
3.2623
1742.26
3.26207
1731.1
3.26184
1737.89
3.2616
1722.45
3.26137
1709.32
3.26114
1689.64
3.26091
1671.06
3.26068
1676.98
3.26044
1660.9
3.26021
1646.19
3.25998
1649.81
3.25975
1647.06
3.25952
1636.87
3.25929
1650.97
3.25906
1644.67
3.25882
1622.05
3.25859
1609.66
3.25836
1631
3.25813
1607.92
3.2579
1604.3
3.25767
1605.9
3.25744
1606.11
3.25721
1599.7
3.25698
1599.42
3.25674
1603.4
3.25651
1583.89
3.25628
1580.28
3.25605
1591.57
3.25582
1576.58
3.25559
1578.53
3.25536
1580.51
3.25513
1581.85
3.2549
1590.89
3.25467
1583.02
3.25444
1576.05
3.25421
1577.49
3.25398
1567.57
3.25375
1584.64
3.25352
1582.57
3.25329
1576.62
3.25306
1584.89
3.25283
1580.92
3.2526
1583.35
3.25237
1570.84
3.25214
1581.74
3.25191
1576.2
3.25168
1576.65
3.25145
1570.2
3.25122
1576.18
3.25099
1580.52
3.25076
1588.07
3.25053
1581.71
3.2503
1591.32
3.25007
1572.61
3.24984
1585.13
3.24961
1594.48
3.24938
1588.12
3.24915
1596.16
3.24892
1592.29
3.24869
1592.83
3.24847
1593.56
3.24824
1590.61
3.24801
1587.06
3.24778
1600.4
3.24755
1605.57
3.24732
1593.02
3.24709
1584.69
3.24686
1610.85
3.24663
1597.85
3.24641
1593.93
3.24618
1598.06
3.24595
1602.09
3.24572
1602.16
3.24549
1611.59
3.24526
1614.95
3.24503
1601.32
3.24481
1604.52
3.24458
1610.05
3.24435
1608.43
3.24412
1620.94
3.24389
1604.67
3.24367
1610.18
3.24344
1623.2
3.24321
1612.69
3.24298
1624.49
3.24275
1613.79
3.24253
1611.08
3.2423
1596.24
3.24207
1602.82
3.24184
1602.42
3.24161
1608.5
3.24139
1622.61
3.24116
1616.96
3.24093
1613.88
3.2407
1596.8
3.24048
Fe2p
FeO
2021
5
12
9
41
29
0
17
Casa Info Follows
0
0
0
0
File = C:/Users/Mark/Downloads/EX495_S779_Fe2O3.sle

Group = Loop 8_800C in UHV, #Treatments: , #Temp:RT, #Pressure:UHV, #Atmosphere:, #Comments:

First of group = 0

Spectrum ID = 55

Analyzer lens = AngleResolvedMode22:1.5kV

Analyzer slit = 4:7x20c\C:mesh

Scan mode = FixedAnalyzerTransmission

Kinetic energy start = 716.61

C:\Users\Mark\Downloads\EX495_S779_FeO 800C.vms
PCA Coefs = 49262.6, 808.529,
C:\Users\Mark\Downloads\EX495_S779_FeO.vms
c:\users\pielsticker\lukas\mpi-cec\projects\deepxps\xpsdeeplearning\data\references\nicofe\ex491-495 fe, ni, co oxide references.vms
XPS
8
Al
1486.61
0
0
0
54.5
180
FAT
20
1
4.1408
0
0
0
0
0
Fe
2p
-1
kinetic energy
eV
716.61
0.1
2
counts
d
Transmission
d
pulse counting
0.1
3
0
0
0
0
2
ESCAPE DEPTH TYPE
d
1
MFP Exponent
d
0
306.846
3.06292
1608.18
1610.36
1599.12
1604.4
1600.27
1597.06
1592.82
1590.18
1591.79
1595.95
1591.1
1585.13
1571.54
1576.92
1576.32
1567.79
1580.6
1572.14
1559.98
1561.15
1561.09
1543.42
1524.53
1543.59
1535.78
1541.56
1535.44
1541.68
1532.17
1522.16
1513.95
1514.41
1517.18
1511.72
1506.82
1500.46
1494.83
1501.19
1501.75
1500.72
1499.14
1481.33
1480.33
1487.26
1488.84
1486.49
1465.1
1474.46
1477.17
1475.75
1472.74
1477.26
1475.24
1471.91
1471.16
1471.31
1474.37
1468.67
1470.85
1464.35
1459.5
1469.73
1467.97
1473.46
1470.42
1476.67
1469.47
1458.21
1475.92
1468.52
1465.61
1462.21
1471.59
1470.41
1461.94
1455.18
1472.66
1464.85
1476.81
1471.82
1470.33
1469.96
1481.66
1457.19
1468.84
1469.01
1454.24
1465.99
1477.72
1484.76
1481.2
1492.74
1477.76
1477.86
1487
1489.4
1476.22
1462.52
1475.78
1489.84
1491.77
1483.97
1493.58
1483.27
1488.85
1495.47
1475.36
1490.04
1491.39
1487.72
1502.55
1497.34
1499.41
1510.94
1503.47
1512.16
1502.38
1505.89
1510.16
1509.29
1511.72
1513.35
1505.13
1511.62
1512.46
1513.96
1514.44
1516.29
1529.55
1522.32
1510.73
1514.2
1515.51
1518.11
1511.74
1524.45
1515.92
1517.07
1522.09
1514.63
1523.93
1524.85
1525.27
1532.54
1526.05
1534.05
1537.3
1530.09
1532.43
1542.25
1537.62
1536.92
1533.01
1536.64
1543.04
1544.92
1542.35
1537.59
1543.34
1543.78
1534.55
1538.04
1549.13
1553.06
1556.55
1543.73
1547.8
1549.35
1559.89
1562.25
1554.27
1555.63
1572.86
1553.85
1556.57
1551.48
1566.95
1565.32
1557.99
1553.57
1569.47
1572.46
1570.12
1569.5
1562.97
1564.39
1558.18
1565.41
1570.23
1576.54
1582.23
1581.18
1588.83
1584.95
1576.08
1588.45
1582.44
1581.79
1571.95
1584.37
1590.03
1593.08
1593.43
1594.52
1594.78
1597.54
1596.51
1596.98
1605.83
1604.51
1607.67
1599.6
1598.25
1604.83
1622.76
1618.16
1611.99
1597.55
1615.72
1627.52
1625.79
1613.84
1623.69
1626.55
1625.12
1620.64
1624.96
1619.74
1625.62
1638.15
1636.13
1641.8
1636.71
1631.24
1630.11
1625.98
1647.51
1643.35
1638.5
1647.29
1646.23
1658.93
1652.62
1646.75
1651.32
1653.79
1660.28
1659.67
1662.91
1668.14
1660.98
1668.14
1668.8
1662.77
1659.14
1680.51
1674.11
1669.16
1663.94
1664.88
1682.51
1674.54
1673.06
1662.26
1661.9
1673.16
1673.67
1670.39
1681.42
1665.12
1661.84
1664.02
1662.13
1649.66
1657.48
1659.05
1650.25
1655.48
1651.92
1652.93
1653.16
1648.29
1640.24
1638.44
1645.26
1634.98
1641.77
1639.44
1633.06
1638.16
1623.01
1637.35
1631.97
1627.68
1627.14
1611.96
1625.11
1625.34
1629.79
1607.63
1629.96
1626.61
1635.44
1641.26
1629.08
1632.38
1637.03
1637.07
1630.35
1636.42
1638.64
1624.23
1629.32
1621.72
1640.14
1638.81
1641.76
1639.29
1643.84
1646.41
1641.83
1638.57
1642.32
1653.34
1642.46
1632
1640.29
1644.43
1647.65
1650.94
1667.36
1665.79
1667.21
1676.78
1669.15
1662.76
1681.39
1674.55
1682.43
1688.54
1683.33
1693.45
1703.24
1704.61
1705.21
1708.74
1726.92
1711.55
1723.68
1735.02
1728.41
1747.05
1764.31
1749.39
1756.69
1765.33
1779.84
1789.39
1786.18
1787.57
1807.55
1810.19
1821.89
1821.53
1824.4
1833.59
1837.07
1852.37
1860.42
1877.03
1874.3
1890.69
1895.18
1912.07
1908.45
1933.75
1941.73
1948.68
1962.16
1971.02
1978.55
1994.03
2002.67
2018.19
2009.62
2023.08
2044.89
2061.64
2075.04
2084.14
2083.85
2109.94
2116.99
2121.2
2137.78
2141.83
2146.63
2148.01
2177.93
2180.49
2182.25
2182.32
2184.67
2199.86
2190.85
2187.8
2184.97
2196.26
2188.83
2195.17
2189.51
2182.64
2166.87
2154.54
2166.62
2154.2
2160.81
2158.1
2130.14
2139.63
2131.66
2118.2
2115.3
2125.08
2115.04
2127.39
2115.72
2122.45
2123.03
2130.42
2138.69
2131.39
2118.4
2146.57
2175.32
2163.8
2175.79
2201.82
2211.18
2228.11
2252.59
2270.52
2279.07
2289.39
2305.82
2324.76
2362.53
2394.62
2415.62
2446.84
2482.01
2500.14
2535.44
2571.05
2609.87
2635.17
2667.93
2694.47
2715.66
2752.52
2773.03
2777.59
2807.2
2812.23
2824.57
2838.73
2844.75
2855.52
2859.02
2849.21
2854.46
2859.15
2846.97
2815.65
2765.69
2765.28
2739.36
2672.91
2643.33
2607.17
2561.39
2513.14
2474.21
2415.56
2357.21
2321.62
2270.57
2225.16
2176.55
2128.87
2094.82
2055.28
2021.11
1986.55
1966.49
1928.68
1899.1
1868.23
1843.66
1824.49
1819.4
1810.54
1802.48
1785.98
1775.12
1763.73
1766.18
1771.51
1756.09
1752.31
1753.64
1769.09
1757.22
1779.34
1790.22
1799.55
1812.76
1822.89
1840.08
1842.39
1879.96
1875.46
1891.11
1900.42
1935.82
1958.55
1969.19
1990.99
2005.49
2030.16
2048.06
2064.68
2067.25
2088.58
2100.89
2103.09
2122.37
2148.61
2141.87
2149.17
2164.73
2187.88
2195.34
2202.42
2208.44
2206.69
2205.81
2197.56
2187.08
2171.86
2188.84
2201.76
2192.54
2194.45
2193.23
2185.65
2174.09
2203.6
2209.32
2189.01
2205.9
2232.67
2224.04
2245.74
2275.59
2287.58
2319.56
2331.77
2360.42
2384.89
2418.7
2440.23
2458.25
2488.62
2536.13
2569.64
2612.34
2638.47
2678.03
2727.64
2787.31
2832.45
2866.97
2918.09
2948.79
2999.47
3055.04
3107.2
3137.53
3178.65
3248.16
3292.74
3338.93
3374.94
3388.89
3419.54
3459.03
3478.53
3532.77
3522.96
3562.28
3572.27
3558.95
3555.83
3539.79
3511.69
3475.79
3429.34
3380.56
3317.22
3223.07
3155.72
3045.33
2924.12
2798.15
2652.45
2513.77
2368.78
2214.52
2054.87
1906.21
1756.76
1613.02
1470.26
1345.57
1232.83
1126.36
1036.4
944.118
877.087
821.856
762.698
716.833
675.22
628.14
600.985
570.444
541.384
515.211
490.36
475.713
460.418
442.576
430.969
418.866
415.661
416.601
407.162
400.685
407.481
403.036
399.305
401.174
386.689
384.717
384.545
379.791
381.777
378.817
374.528
367.916
371.28
358.662
365.432
367.86
369.124
368.085
366.386
365.843
366.105
367.461
359.833
365.078
363.447
360.205
359.727
358.089
358.141
358.14
360.705
360.42
361.312
363.402
360.842
360.669
357.389
355.096
349.345
351.358
352.01
349.864
355.431
353.353
354.349
352.985
351.566
350.279
351.204
356.315
350.286
354.557
353.363
346.834
349.931
353.172
350.449
348.236
348.862
343.003
348.676
350.78
351.57
347.465
348.998
344.177
351.457
350.828
350.389
346.455
345.756
352.924
346.88
350.979
350.052
347.004
349.122
352.972
352.089
353.065
346.295
346.292
345.477
348.387
349.083
347.056
345.991
343.445
345.497
344.361
345.089
346.342
343.786
349.073
344.514
343.534
341.605
349.103
343.036
342.581
348.267
345.268
341.003
340.534
341.789
340.894
346.61
346.996
340.832
348.942
348.909
347.021
341.52
347.117
347.995
343.427
346.951
344.877
348.466
343.791
337.325
341.776
343.258
343.076
343.219
347.84
346.287
350.62
343.175
341.74
342.452
347.669
349.142
346.33
349.548
350.936
348.628
350.972
343.981
344.487
346.995
344.392
347.442
347.773
343.092
340.181
343.213
347.637
348.914
348.792
345.858
344.533
347.382
350.152
344.032
349.43
344.313
344.871
343.466
347.236
345.057
346.172
347.084
342.588
348.865
342.51
341.268
351.25
343.864
339.854
344.165
346.798
349.616
344.353
353.566
351.017
347.824
344.558
346.339
349.401
349.957
346.848
342.196
351.832
350.391
345.56
341.915
347.743
345.931
345.077
344.545
342.416
342.244
346.184
347.379
347.738
342.447
348.608
346.802
343.308
342.234
345.434
3.06292
Co2pFe2p
FeO
2021
5
12
9
49
25
0
22
Casa Info Follows
0
2
annot text peak Data 646.61 8267.03 RGB(0,0,0) Font(35,34,700,0,Arial)
Co 2p
annot text peak Data 776.81 11907.6 RGB(0,0,0) Font(35,34,700,0,Arial)
Fe 2p
0
0
File = C:/Users/Mark/Downloads/EX495_S779_Fe2O3.sle

Group = Loop 8_800C in UHV, #Treatments: , #Temp:RT, #Pressure:UHV, #Atmosphere:, #Comments:

First of group = 0

Spectrum ID = 57

Analyzer lens = AngleResolvedMode22:1.5kV

Analyzer slit = 4:7x20c\C:mesh

Scan mode = FixedAnalyzerTransmission

Kinetic energy start = 646.61

C:\Users\Mark\Downloads\EX495_S779_FeO 800C.vms
PCA Coefs = 46984.3, 223.8,
C:\Users\Mark\Downloads\EX495_S779_FeO.vms
c:\users\pielsticker\lukas\mpi-cec\projects\deepxps\xpsdeeplearning\data\references\nicofe\ex491-495 fe, ni, co oxide references.vms
Energy offsets:  1:0
XPS
8
Al
1486.61
0
0
0
54.5
180
FAT
20
1
4.1408
0
0
0
0
0
Co2pFe2p

-1
kinetic energy
eV
646.61
0.1
2
counts
d
Transmission
d
pulse counting
1
1
0
0
0
0
2
ESCAPE DEPTH TYPE
d
0
MFP Exponent
d
0
1
8267.03
3.41218
8153.93
3.41138
8136.67
3.41059
8111.33
3.40979
7996.8
3.409
7964.53
3.4082
7914.33
3.40741
7936.97
3.40662
7898.33
3.40583
7851.93
3.40503
7797.87
3.40424
7807.6
3.40345
7805.67
3.40266
7724.5
3.40187
7706.17
3.40108
7568
3.40029
7528.3
3.39951
7404.63
3.39872
7275.13
3.39793
7129.43
3.39715
6950.23
3.39636
6802.57
3.39558
6661.9
3.39479
6484.7
3.39401
6339.27
3.39322
6220.33
3.39244
6091.03
3.39166
5996.77
3.39088
5946.8
3.39009
5900.3
3.38931
5808.47
3.38853
5776
3.38775
5764.8
3.38697
5704.53
3.38619
5640.23
3.38542
5667.73
3.38464
5651.5
3.38386
5566.4
3.38309
5594.57
3.38231
5623.87
3.38153
5573.03
3.38076
5606.1
3.37998
5530.27
3.37921
5515.7
3.37844
5514.43
3.37766
5478.67
3.37689
5471.97
3.37612
5484.7
3.37535
5523.13
3.37458
5505.8
3.37381
5434.47
3.37304
5431.27
3.37227
5440.63
3.3715
5413.53
3.37073
5410.2
3.36996
5395.5
3.3692
5372.63
3.36843
5336.37
3.36766
5361.7
3.3669
5352.73
3.36613
5303.57
3.36537
5303.97
3.36461
5266.93
3.36384
5290.53
3.36308
5245.57
3.36232
5241.67
3.36156
5212.83
3.36079
5227.23
3.36003
5232.9
3.35927
5206
3.35851
5227.87
3.35775
5209.87
3.35699
5229.23
3.35624
5170.47
3.35548
5228
3.35472
5253.57
3.35397
5176.77
3.35321
5213.77
3.35245
5227.3
3.3517
5175.43
3.35094
5177.7
3.35019
5219.73
3.34944
5254
3.34868
5204.8
3.34793
5234.97
3.34718
5250.83
3.34643
5261.17
3.34567
5251.43
3.34492
5196.23
3.34417
5246.2
3.34342
5242.2
3.34268
5264.2
3.34193
5264.73
3.34118
5273.37
3.34043
5259.7
3.33968
5294
3.33894
5261.7
3.33819
5280.27
3.33745
5275.33
3.3367
5306.03
3.33596
5317.8
3.33521
5284.63
3.33447
5337.1
3.33373
5302.03
3.33298
5306.7
3.33224
5317.5
3.3315
5334.8
3.33076
5337.1
3.33002
5325.83
3.32928
5368.6
3.32854
5375.4
3.3278
5363.77
3.32706
5406.07
3.32632
5324.63
3.32558
5378.73
3.32485
5363.83
3.32411
5363.5
3.32337
5404.1
3.32264
5397.9
3.3219
5381.97
3.32117
5397.97
3.32043
5401.47
3.3197
5384.2
3.31897
5368.1
3.31823
5399.6
3.3175
5426.53
3.31677
5401
3.31604
5392.43
3.31531
5407.23
3.31458
5414.77
3.31385
5437.77
3.31312
5446.6
3.31239
5445.5
3.31166
5454.97
3.31093
5418.5
3.31021
5411.4
3.30948
5415.83
3.30875
5434.83
3.30803
5436
3.3073
5427.07
3.30658
5439.13
3.30585
5466
3.30513
5469
3.3044
5504.8
3.30368
5506.77
3.30296
5489.53
3.30224
5569.53
3.30151
5508.83
3.30079
5556.77
3.30007
5558.37
3.29935
5571.2
3.29863
5620.3
3.29791
5674.53
3.29719
5670.47
3.29647
5728.9
3.29576
5761.9
3.29504
5827.4
3.29432
5847.6
3.29361
5890.2
3.29289
5995.33
3.29217
6059.07
3.29146
6061.6
3.29074
6126.33
3.29003
6189.23
3.28932
6278.2
3.2886
6322.57
3.28789
6398.53
3.28718
6445.03
3.28646
6457.87
3.28575
6506.77
3.28504
6514.13
3.28433
6557.4
3.28362
6606.27
3.28291
6630.93
3.2822
6695.27
3.28149
6663.43
3.28079
6708.1
3.28008
6756.43
3.27937
6797.37
3.27866
6832.43
3.27796
6739.23
3.27725
6790.1
3.27655
6877.93
3.27584
6858.4
3.27514
6912.87
3.27443
6972.13
3.27373
6993.03
3.27303
7005.77
3.27232
7025.77
3.27162
7011.7
3.27092
7001.63
3.27022
7024.73
3.26952
6915.23
3.26882
6853.17
3.26812
6747.8
3.26742
6691.8
3.26672
6601.57
3.26602
6473.37
3.26532
6320.93
3.26462
6234.2
3.26392
6057.57
3.26323
5983.8
3.26253
5807.53
3.26184
5741.5
3.26114
5570.2
3.26044
5487.3
3.25975
5456.23
3.25906
5406.83
3.25836
5359.73
3.25767
5353.7
3.25698
5344.67
3.25628
5305.23
3.25559
5268.37
3.2549
5276.73
3.25421
5225.23
3.25352
5255.4
3.25283
5277.83
3.25214
5254
3.25145
5253.93
3.25076
5272.37
3.25007
5283.77
3.24938
5320.53
3.24869
5311.87
3.24801
5334.67
3.24732
5282.3
3.24663
5313.1
3.24595
5340.53
3.24526
5337.73
3.24458
5361.43
3.24389
5367.27
3.24321
5414.97
3.24253
5320.8
3.24184
5361.67
3.24116
5379.6
3.24048
5367.87
3.24002
5334.23
3.23934
5300.6
3.23866
5303.67
3.23798
5256.4
3.2373
5268.67
3.23662
5203.83
3.23594
5081.77
3.23526
5138.53
3.23458
5107.23
3.2339
5048.03
3.23322
5022.73
3.23255
5003.97
3.23187
4997.13
3.23119
4957.53
3.23052
4883.67
3.22984
4919.17
3.22917
4917.47
3.22849
4904.37
3.22782
4902.83
3.22714
4899.1
3.22647
4901.4
3.2258
4860.7
3.22512
4885.37
3.22445
4901.37
3.22378
4908.87
3.22311
4906.07
3.22244
4938.87
3.22176
4896.7
3.22109
4925.73
3.22042
4975.8
3.21976
4956.67
3.21909
4875.07
3.21842
4972.57
3.21775
4944.23
3.21708
4917.87
3.21641
4959.07
3.21575
4998.03
3.21508
5040.53
3.21441
5033.87
3.21375
5044.5
3.21308
5041.53
3.21242
5054.3
3.21175
5035.77
3.21109
5060.37
3.21043
5053.07
3.20976
5048.77
3.2091
5084.23
3.20844
5113.5
3.20778
5108.1
3.20711
5123.07
3.20645
5143.47
3.20579
5125.3
3.20513
5115.17
3.20447
5176.87
3.20381
5159.33
3.20315
5207.5
3.2025
5242.87
3.20184
5171.6
3.20118
5193.3
3.20052
5241.53
3.19986
5209.9
3.19921
5218.03
3.19855
5274.1
3.1979
5283.17
3.19724
5274.8
3.19658
5281.23
3.19593
5311.43
3.19528
5325.13
3.19462
5352.77
3.19397
5332
3.19332
5409.2
3.19266
5325.17
3.19201
5419.3
3.19136
5421.83
3.19071
5416.53
3.19006
5460.5
3.18941
5455.7
3.18876
5419.93
3.18811
5461.67
3.18746
5529.77
3.18681
5504.4
3.18616
5532.23
3.18551
5536.6
3.18486
5542.57
3.18421
5580.37
3.18357
5549.6
3.18292
5576.87
3.18227
5577.2
3.18163
5604.73
3.18098
5546.73
3.18034
5524.93
3.17969
5518.27
3.17905
5510.53
3.1784
5461.47
3.17776
5472.57
3.17712
5460.53
3.17647
5439.9
3.17583
5373.2
3.17519
5432.63
3.17455
5422.03
3.17391
5430.27
3.17327
5456.9
3.17263
5462.13
3.17199
5405.73
3.17135
5472.53
3.17071
5488.03
3.17007
5474.4
3.16943
5440
3.16879
5492.17
3.16815
5552.63
3.16752
5563.83
3.16688
5581.83
3.16624
5611.1
3.16561
5682.03
3.16497
5756.4
3.16434
5783.4
3.1637
5881.03
3.16307
5884.43
3.16243
5953.93
3.1618
6033.97
3.16116
6081.33
3.16053
6174.57
3.1599
6247.67
3.15927
6373.57
3.15863
6472.43
3.158
6570.07
3.15737
6675.57
3.15674
6743.6
3.15611
6916.8
3.15548
7033.13
3.15485
7125.93
3.15422
7160.03
3.15359
7274.17
3.15296
7332.87
3.15233
7283.23
3.15171
7317.23
3.15108
7222.9
3.15045
7180.67
3.14982
7100.47
3.1492
7060.67
3.14857
7050.13
3.14795
7074.83
3.14732
7128.97
3.1467
7155.23
3.14607
7252.63
3.14545
7427.03
3.14482
7596.9
3.1442
7749.2
3.14358
8052.07
3.14295
8333.8
3.14233
8699.57
3.14171
8981.57
3.14109
9243.43
3.14047
9374.1
3.13985
9482.5
3.13923
9497.37
3.13861
9489.9
3.13799
9217.6
3.13737
8811.1
3.13675
8377.13
3.13613
7857.37
3.13551
7417.2
3.13489
6982.73
3.13428
6621.83
3.13366
6330.33
3.13304
6081.63
3.13243
6008.27
3.13181
5879.1
3.13119
5853.63
3.13058
5896.97
3.12996
5967.4
3.12935
6076.3
3.12873
6266.53
3.12812
6334.73
3.12751
6563.97
3.12689
6767.2
3.12628
6890.83
3.12567
7010.3
3.12506
7139.57
3.12445
7292.93
3.12383
7361.47
3.12322
7325.2
3.12261
7296.13
3.122
7314.83
3.12139
7246.97
3.12078
7296.7
3.12017
7413.47
3.11956
7625.27
3.11896
7868.07
3.11835
8134.1
3.11774
8453.77
3.11713
8794.9
3.11653
9291.03
3.11592
9726.97
3.11531
10183.5
3.11471
10595.5
3.1141
11129.8
3.1135
11398.5
3.11289
11775.9
3.11229
11907.6
3.11168
11799.3
3.11108
11431.1
3.11047
10743.6
3.10987
9747.07
3.10927
8379.23
3.10867
6849.57
3.10806
5376.73
3.10746
4109.43
3.10686
3147.06
3.10626
2542.33
3.10566
2093.8
3.10506
1804.61
3.10446
1585.71
3.10386
1436.56
3.10326
1388.67
3.10266
1358.27
3.10206
1337.25
3.10146
1281.82
3.10086
1262.72
3.10027
1237.6
3.09967
1226.2
3.09907
1221.29
3.09848
1224.87
3.09788
1211.49
3.09728
1193.63
3.09669
1202.35
3.09609
1211.34
3.0955
1191.3
3.0949
1171.19
3.09431
1184.77
3.09372
1176.62
3.09312
1170.68
3.09253
1181.86
3.09194
1166.44
3.09134
1160.79
3.09075
1162.25
3.09016
1158.22
3.08957
1171.52
3.08898
1154.85
3.08839
1156.27
3.0878
1156.68
3.08721
1173.63
3.08662
1154.31
3.08603
1163.61
3.08544
1144.82
3.08485
1150.3
3.08426
1163.58
3.08367
1138.68
3.08308
1141.94
3.0825
1136.68
3.08191
1136.31
3.08132
1136.11
3.08074
1156.74
3.08015
1159.98
3.07957
1149.59
3.07898
1124.42
3.0784
1143.59
3.07781
1154.29
3.07723
1139.13
3.07664
1163.81
3.07606
1169.79
3.07547
1146.6
3.07489
1147.97
3.07431
1143.64
3.07373
1158.79
3.07314
1152.86
3.07256
1167.17
3.07198
1147.71
3.0714
1157.45
3.07082
1156.95
3.07024
1141.7
3.06966
1146.21
3.06908
1155.99
3.0685
1178.55
3.06792
1148.53
3.06734
1166.52
3.06676
1172.77
3.06619
1139.72
3.06561
1150.26
3.06503
1140.81
3.06445
1159.13
3.06388
1156.01
3.0633
1151.45
3.06292
end of experiment