File: data/references/Fe_references.vms
VAMAS Surface Chemical Analysis Standard Data Transfer Format 1988 May 4
Not Specified
Not Specified
Not Specified
Not Specified
7
Casa Info Follows CasaXPS Version 2.3.24PR1.0
0
SourceAnalyserAngle: Not Specified
CasaRowLabel:Fe metal
CasaRowLabel:FeO
CasaRowLabel:Fe3O4
CasaRowLabel:Fe2O3
NORM
REGULAR
0
1
Exp Variable
d
0
0
0
0
4
Fe2p
Fe metal
7
2021
5
18
14
57
0
11
Casa Info Follows
0
0
0
0
none
Group: none
Analyzer Lens: none
Analyzer Slit: none
Scan Mode: none
C:\Users\pielsticker\Downloads\utils\test fits\new\Fe2p_Fe_metal_new.vms
XPS
0
Al
1486.61
0
0
0
56.5
180
FAT
20
1
4.1408
0
0
0
0
0
Fe
2p
-1
kinetic energy
eV
716.61
0.05
2
counts
d
Transmission
d
pulse counting
0.1
3
0
0
0
0
2
ESCAPE DEPTH TYPE
d
0
MFP Exponent
d
0
54850.3
12642.4
1
12750.4
1
12676.4
1
12700.3
1
12646.5
1
12687.5
1
12614.1
1
12635.7
1
12593.5
1
12608.5
1
12437.1
1
12508.5
1
12416.5
1
12424
1
12357.8
1
12322.2
1
12280.6
1
12275.5
1
12171.7
1
12193.4
1
12208.3
1
12168.2
1
12150.5
1
12145.5
1
12090.8
1
12104
1
12084.1
1
12059.8
1
12116.2
1
12035
1
12046.4
1
12052.4
1
12064.5
1
12089.1
1
12006.4
1
12001.9
1
12029.8
1
12059.9
1
12041.7
1
11977.4
1
11926.1
1
12045.3
1
12021.8
1
11944.9
1
11976.3
1
12005.9
1
11940.7
1
11965.3
1
11992.9
1
11957.9
1
11966.1
1
11907.1
1
11944.9
1
11968.4
1
11870.4
1
11880.2
1
11905.7
1
11857.1
1
11845
1
11913.2
1
11888.2
1
11882.5
1
11874.5
1
11856.5
1
11903.1
1
11913.6
1
12016.2
1
11940
1
11891.4
1
11927
1
11863.6
1
11969.2
1
11971.6
1
11997.7
1
11940.4
1
11912
1
11966
1
12016.2
1
12085.3
1
12081.2
1
12084.1
1
12145.4
1
12090.8
1
12229.3
1
12157.2
1
12192.2
1
12207.4
1
12235.1
1
12275.3
1
12329.7
1
12315.4
1
12348.7
1
12328.6
1
12369.7
1
12330.2
1
12376.2
1
12369.3
1
12361.3
1
12466.4
1
12486.8
1
12485.2
1
12478.1
1
12577.7
1
12532.4
1
12561.2
1
12682.4
1
12551.3
1
12555.3
1
12643
1
12629.5
1
12749.3
1
12712.9
1
12721.6
1
12831
1
12807
1
12783.4
1
12840.7
1
12869.8
1
12881.8
1
12884.1
1
12886.2
1
12904.8
1
12955.7
1
12980.9
1
12973.6
1
12955.3
1
13036.6
1
13031.7
1
13118.5
1
13066.7
1
13099.4
1
13114.1
1
13081.4
1
13161.4
1
13171.9
1
13220
1
13365.3
1
13261.3
1
13343
1
13451.1
1
13374.1
1
13342.1
1
13457.4
1
13414.5
1
13514.9
1
13494
1
13544.3
1
13599.5
1
13582.6
1
13645.5
1
13643.9
1
13598.2
1
13690.9
1
13757.8
1
13722.4
1
13758.3
1
13746.3
1
13765.4
1
13856.3
1
13861
1
13883.4
1
13904.5
1
13937.1
1
13931.5
1
13995.9
1
14023.3
1
14051.5
1
14015.5
1
14056.5
1
14110.1
1
14224.8
1
14183.7
1
14138.7
1
14116.8
1
14163.8
1
14153.3
1
14191.3
1
14139.3
1
14222.1
1
14255.6
1
14216.3
1
14220.3
1
14342.3
1
14238.6
1
14284.1
1
14261.5
1
14286.9
1
14410.9
1
14308.4
1
14278.5
1
14358.6
1
14367.1
1
14341
1
14340.8
1
14295.7
1
14341.3
1
14328.5
1
14291.4
1
14340.5
1
14392.1
1
14417.5
1
14375
1
14392.8
1
14391
1
14525.7
1
14404.5
1
14401.1
1
14489.6
1
14494.2
1
14530.4
1
14555.1
1
14575.7
1
14591.9
1
14691
1
14651.8
1
14647.3
1
14664.7
1
14790.2
1
14810.4
1
14747.7
1
14771.2
1
14769.4
1
14795.9
1
14871.9
1
14852.9
1
14902
1
14982
1
14951.9
1
14923.9
1
14982.5
1
15109.6
1
15048.8
1
15141.5
1
15176.6
1
15091.2
1
15088.5
1
15189.1
1
15220.7
1
15259.5
1
15273.7
1
15352.2
1
15374.4
1
15374.1
1
15423
1
15402.5
1
15442.1
1
15488.2
1
15608
1
15511.1
1
15510.9
1
15554.8
1
15629.4
1
15665.1
1
15586
1
15745.4
1
15727.9
1
15738.1
1
15748.6
1
15835.5
1
15759.9
1
15797.4
1
15761.5
1
15814
1
15766.8
1
15749.8
1
15749.9
1
15803.9
1
15849.2
1
15772.8
1
15840.8
1
15851.3
1
15824.1
1
15895.5
1
15841.1
1
15785.5
1
15848.7
1
15792.9
1
15839.6
1
15830.3
1
15806.7
1
15883.8
1
15925.7
1
15796.8
1
15877.1
1
15972.4
1
16010.6
1
15956.9
1
15929.7
1
16003.5
1
16000
1
16102.9
1
16000.8
1
16112.7
1
16047.6
1
16168.7
1
16135.1
1
16287.8
1
16271.4
1
16211.9
1
16270.3
1
16288.3
1
16306.6
1
16382.4
1
16412.7
1
16472.5
1
16511.3
1
16562.9
1
16621.3
1
16710.2
1
16866.2
1
17019
1
17142.9
1
17238.3
1
17355.8
1
17630.9
1
17780
1
18036.8
1
18242.2
1
18637.2
1
18770.9
1
19201.4
1
19437.2
1
20069.7
1
20510
1
20983.4
1
21555.6
1
22539.1
1
22993.2
1
24143.9
1
24840.7
1
26517.4
1
27151.7
1
28868
1
29549.9
1
30291.3
1
30164.6
1
29173.8
1
28304.4
1
25545.5
1
23803.8
1
20545.8
1
19139.4
1
17034.7
1
16234.7
1
14947.2
1
14480.4
1
13870.1
1
13490.6
1
13180.3
1
12969.9
1
12681.5
1
12645.3
1
12476.7
1
12419.9
1
12272
1
12252.5
1
12203.9
1
12180.2
1
12116.8
1
12178.1
1
12154.2
1
12190.8
1
12237.1
1
12235.5
1
12248.3
1
12237.4
1
12298.1
1
12431.2
1
12523.5
1
12530
1
12558.9
1
12606.9
1
12733.4
1
12687.6
1
12834.2
1
12862
1
13010.9
1
13035.7
1
13035.2
1
13176.4
1
13193.6
1
13231.7
1
13297.6
1
13236
1
13423.4
1
13532
1
13565.2
1
13626.2
1
13901.9
1
13921
1
14171.8
1
14245.1
1
14473.8
1
14619.5
1
14923.2
1
15012.9
1
15355.2
1
15448.4
1
15766.2
1
15838.5
1
16194.4
1
16367.9
1
16706.1
1
16910.8
1
17420.5
1
17588.4
1
18370.2
1
18677.4
1
19522.2
1
20095.6
1
21272.7
1
22051
1
24161.1
1
25331.1
1
28571.6
1
30392
1
34439.7
1
36369.3
1
39760.3
1
41630.3
1
46923.7
1
50218
1
54850.3
1
54130
1
43614
1
35167
1
19516.7
1
14244.4
1
8352.37
1
6853.27
1
5015.8
1
4427.13
1
3682.03
1
3439.77
1
3029.64
1
2864.95
1
2541.73
1
2435.33
1
2308.28
1
2216.3
1
2074.82
1
2022.23
1
1950.51
1
1896.4
1
1782.96
1
1774.07
1
1703.07
1
1713.04
1
1656.2
1
1633.67
1
1603.28
1
1578.75
1
1547.14
1
1516.6
1
1495.77
1
1474.47
1
1446.33
1
1456.02
1
1394.57
1
1405.32
1
1396.94
1
1398.83
1
1381.98
1
1369.71
1
1336.59
1
1331.06
1
1330.41
1
1317.97
1
1291.27
1
1311.94
1
1293.15
1
1288.66
1
1305.35
1
1297.25
1
1273.18
1
1268.84
1
1284.92
1
1288.28
1
1257.09
1
1279
1
1257.67
1
1258.8
1
1243
1
1256.27
1
1234.7
1
1222.11
1
1229.63
1
1231.92
1
1227.29
1
1240.52
1
1204.78
1
1211.73
1
1215.39
1
1208.48
1
1226.52
1
1206.47
1
1208.39
1
1214.39
1
1204.79
1
1201.14
1
1190.55
1
1190.69
1
1184.72
1
1200.23
1
1155.05
1
1182.92
1
1164.77
1
1152.57
1
1195.59
1
1189.21
1
1162.95
1
1144.88
1
1169.35
1
1159.5
1
1148.89
1
1154.63
1
1181.12
1
1154.61
1
1160.2
1
1163.84
1
1149.26
1
1163.66
1
1149.84
1
1164.1
1
1148.38
1
1153.72
1
1159.29
1
1162.65
1
1147.3
1
1135.94
1
1185.31
1
1154.3
1
1151.42
1
1172.18
1
1178.4
1
1171.79
1
1134.46
1
1168.3
1
1207.68
1
1201.96
1
1212.92
1
1214.79
1
1186.79
1
1195.58
1
1151.71
1
1184.55
1
1193.15
1
1177.95
1
1162.17
1
1165.25
1
1148.32
1
1140.5
1
1155.09
1
1165.48
1
1147.23
1
1149.19
1
1150.9
1
1157.73
1
1160.05
1
1168.93
1
1163.64
1
1168.26
1
1167.16
1
1169.02
1
1174.5
1
1157.26
1
1162.4
1
1
Fe2p
FeO
2012
2021
5
9
41
29
0
11
Casa Info Follows
0
0
0
0
none
Group: none
Analyzer Lens: none
Analyzer Slit: none
Scan Mode: none
C:\Users\pielsticker\Downloads\utils\test fits\new\Fe2p_FeO_new.vms
XPS
0
Al
1486.61
0
0
0
56.5
180
FAT
20
1
4.1408
0
0
0
0
0
Fe
2p
-1
kinetic energy
eV
716.61
0.05
2
counts
d
Transmission
d
pulse counting
0.1
3
0
0
0
0
2
ESCAPE DEPTH TYPE
d
0
MFP Exponent
d
0
11907.6
5360.6
1
5367.87
1
5348
1
5334.23
1
5309.4
1
5300.6
1
5319.83
1
5303.67
1
5238.47
1
5256.4
1
5225.97
1
5268.67
1
5199.93
1
5203.83
1
5144.73
1
5081.77
1
5119.27
1
5138.53
1
5138.93
1
5107.23
1
5046.5
1
5048.03
1
5039.07
1
5022.73
1
4982.77
1
5003.97
1
5002.4
1
4997.13
1
4934.43
1
4957.53
1
4954.97
1
4883.67
1
4923.9
1
4919.17
1
4924.2
1
4917.47
1
4903.87
1
4904.37
1
4895.57
1
4902.83
1
4865
1
4899.1
1
4911.53
1
4901.4
1
4898.23
1
4860.7
1
4895.07
1
4885.37
1
4905.3
1
4901.37
1
4850.6
1
4908.87
1
4922.7
1
4906.07
1
4899.87
1
4938.87
1
4896.13
1
4896.7
1
4886.63
1
4925.73
1
4937.33
1
4975.8
1
4926.2
1
4956.67
1
4920.73
1
4875.07
1
4966.13
1
4972.57
1
4978.6
1
4944.23
1
4984.9
1
4917.87
1
4971.3
1
4959.07
1
4991.13
1
4998.03
1
5011.57
1
5040.53
1
5019.63
1
5033.87
1
5039.07
1
5044.5
1
5038.73
1
5041.53
1
5048.13
1
5054.3
1
5074.4
1
5035.77
1
5051.7
1
5060.37
1
5081.5
1
5053.07
1
5073.63
1
5048.77
1
5082.83
1
5084.23
1
5086.83
1
5113.5
1
5100.3
1
5108.1
1
5125.4
1
5123.07
1
5122.13
1
5143.47
1
5141.17
1
5125.3
1
5145.93
1
5115.17
1
5163.77
1
5176.87
1
5145.77
1
5159.33
1
5199.63
1
5207.5
1
5185.43
1
5242.87
1
5188.57
1
5171.6
1
5217.73
1
5193.3
1
5231.57
1
5241.53
1
5231.67
1
5209.9
1
5193.93
1
5218.03
1
5255.13
1
5274.1
1
5296.1
1
5283.17
1
5294.83
1
5274.8
1
5239.83
1
5281.23
1
5310.27
1
5311.43
1
5315.93
1
5325.13
1
5323.27
1
5352.77
1
5358.9
1
5332
1
5349.43
1
5409.2
1
5373.3
1
5325.17
1
5425.07
1
5419.3
1
5412.3
1
5421.83
1
5402.13
1
5416.53
1
5418.73
1
5460.5
1
5472.67
1
5455.7
1
5433.7
1
5419.93
1
5477.83
1
5461.67
1
5487.43
1
5529.77
1
5489.17
1
5504.4
1
5534.27
1
5532.23
1
5560.47
1
5536.6
1
5562.67
1
5542.57
1
5601.7
1
5580.37
1
5546.47
1
5549.6
1
5581.8
1
5576.87
1
5539.67
1
5577.2
1
5567.97
1
5604.73
1
5539.47
1
5546.73
1
5498.87
1
5524.93
1
5500.83
1
5518.27
1
5509.77
1
5510.53
1
5467.47
1
5461.47
1
5449.93
1
5472.57
1
5443.53
1
5460.53
1
5457.83
1
5439.9
1
5423.8
1
5373.2
1
5417.8
1
5432.63
1
5433.2
1
5422.03
1
5470.87
1
5430.27
1
5456.77
1
5456.9
1
5454.73
1
5462.13
1
5431.07
1
5405.73
1
5462.7
1
5472.53
1
5479.47
1
5488.03
1
5461.9
1
5474.4
1
5474.87
1
5440
1
5481.43
1
5492.17
1
5557.87
1
5552.63
1
5589.27
1
5563.83
1
5604.63
1
5581.83
1
5628.47
1
5611.1
1
5677.47
1
5682.03
1
5695.8
1
5756.4
1
5745.6
1
5783.4
1
5823.5
1
5881.03
1
5855.63
1
5884.43
1
5964.63
1
5953.93
1
6025.17
1
6033.97
1
6071.77
1
6081.33
1
6123.57
1
6174.57
1
6256.77
1
6247.67
1
6317.27
1
6373.57
1
6445.83
1
6472.43
1
6540.53
1
6570.07
1
6646.77
1
6675.57
1
6698.73
1
6743.6
1
6872.13
1
6916.8
1
6946.17
1
7033.13
1
7070.67
1
7125.93
1
7155.43
1
7160.03
1
7268.3
1
7274.17
1
7282.23
1
7332.87
1
7292.67
1
7283.23
1
7296.1
1
7317.23
1
7275.47
1
7222.9
1
7222.07
1
7180.67
1
7193.67
1
7100.47
1
7105.53
1
7060.67
1
7083.6
1
7050.13
1
7052.4
1
7074.83
1
7101.4
1
7128.97
1
7061.33
1
7155.23
1
7212.67
1
7252.63
1
7370.6
1
7427.03
1
7568.4
1
7596.9
1
7686.07
1
7749.2
1
7982.07
1
8052.07
1
8273.37
1
8333.8
1
8570.17
1
8699.57
1
8893.1
1
8981.57
1
9175.07
1
9243.43
1
9357.33
1
9374.1
1
9462.43
1
9482.5
1
9530.07
1
9497.37
1
9530.5
1
9489.9
1
9218.97
1
9217.6
1
8909.7
1
8811.1
1
8537.97
1
8377.13
1
8051.87
1
7857.37
1
7568.57
1
7417.2
1
7096.23
1
6982.73
1
6737.03
1
6621.83
1
6428.93
1
6330.33
1
6145.53
1
6081.63
1
6035.13
1
6008.27
1
5917.07
1
5879.1
1
5905.03
1
5853.63
1
5845.47
1
5896.97
1
5931.13
1
5967.4
1
6042.53
1
6076.3
1
6141.3
1
6266.53
1
6303.7
1
6334.73
1
6528.5
1
6563.97
1
6684.97
1
6767.2
1
6882.27
1
6890.83
1
7002.97
1
7010.3
1
7162.03
1
7139.57
1
7215.77
1
7292.93
1
7341.4
1
7361.47
1
7352.7
1
7325.2
1
7239.53
1
7296.13
1
7308.47
1
7314.83
1
7285.5
1
7246.97
1
7364.4
1
7296.7
1
7442.23
1
7413.47
1
7585.3
1
7625.27
1
7772.57
1
7868.07
1
8062.33
1
8134.1
1
8295.4
1
8453.77
1
8707.8
1
8794.9
1
9092.13
1
9291.03
1
9556.57
1
9726.97
1
9998.23
1
10183.5
1
10458.4
1
10595.5
1
10975.8
1
11129.8
1
11296.3
1
11398.5
1
11595.1
1
11775.9
1
11874.3
1
11907.6
1
11852.8
1
11799.3
1
11586
1
11431.1
1
11057.4
1
10743.6
1
10151.1
1
9747.07
1
8841.5
1
8379.23
1
7381.73
1
6849.57
1
5855.87
1
5376.73
1
4485.23
1
4109.43
1
3454.67
1
3147.06
1
2739.52
1
2542.33
1
2250.73
1
2093.8
1
1901.48
1
1804.61
1
1634.53
1
1585.71
1
1475.25
1
1436.56
1
1385.54
1
1388.67
1
1335.62
1
1358.27
1
1331.02
1
1337.25
1
1282.39
1
1281.82
1
1272.59
1
1262.72
1
1226.39
1
1237.6
1
1218.11
1
1226.2
1
1226.95
1
1221.29
1
1220.35
1
1224.87
1
1216.93
1
1211.49
1
1199.09
1
1193.63
1
1193.8
1
1202.35
1
1204.37
1
1211.34
1
1202.23
1
1191.3
1
1164.48
1
1171.19
1
1166.21
1
1184.77
1
1181.16
1
1176.62
1
1167.6
1
1170.68
1
1167.62
1
1181.86
1
1156.11
1
1166.44
1
1168.16
1
1160.79
1
1143.34
1
1162.25
1
1171.9
1
1158.22
1
1147.26
1
1171.52
1
1167.96
1
1154.85
1
1176.41
1
1156.27
1
1166.84
1
1156.68
1
1176.57
1
1173.63
1
1154.32
1
1154.31
1
1161.29
1
1163.61
1
1153.3
1
1144.82
1
1147.87
1
1150.3
1
1145.95
1
1163.58
1
1145.11
1
1138.68
1
1143.45
1
1141.94
1
1150.89
1
1136.68
1
1139.3
1
1136.31
1
1156.65
1
1136.11
1
1163.03
1
1156.74
1
1157.06
1
1159.98
1
1156.5
1
1149.59
1
1145.97
1
1124.42
1
1144.19
1
1143.59
1
1159.47
1
1154.29
1
1143.92
1
1139.13
1
1158.9
1
1163.81
1
1165.16
1
1169.79
1
1169.91
1
1146.6
1
1156.65
1
1147.97
1
1159.24
1
1143.64
1
1144.04
1
1158.79
1
1162.64
1
1152.86
1
1157.94
1
1167.17
1
1164.77
1
1147.71
1
1144.89
1
1157.45
1
1153.91
1
1156.95
1
1162.88
1
1141.7
1
1170.83
1
1146.21
1
1147.22
1
1155.99
1
1147.84
1
1178.55
1
1159.41
1
1148.53
1
1164.67
1
1166.52
1
1140.65
1
1172.77
1
1151.87
1
1139.72
1
1153.1
1
1150.26
1
1141.39
1
1140.81
1
1157.93
1
1159.13
1
1162.03
1
1156.01
1
1140.78
1
1
Fe2p
Fe3O4
2011
2021
5
5
29
55
0
11
Casa Info Follows
0
0
0
0
none
Group: none
Analyzer Lens: none
Analyzer Slit: none
Scan Mode: none
C:\Users\pielsticker\Downloads\utils\test fits\new\Fe2p_Fe3O4_new.vms
XPS
0
Al
1486.61
0
0
0
56.5
180
FAT
20
1
4.1408
0
0
0
0
0
Fe
2p
-1
kinetic energy
eV
716.61
0.05
2
counts
d
Transmission
d
pulse counting
0.1
3
0
0
0
0
2
ESCAPE DEPTH TYPE
d
0
MFP Exponent
d
0
10850.6
5787.97
1
5759.4
1
5818.43
1
5773.47
1
5744.77
1
5739.03
1
5731.47
1
5736.03
1
5706.9
1
5634.9
1
5685.87
1
5659.6
1
5626.9
1
5624.33
1
5589.4
1
5599.5
1
5547.43
1
5574.43
1
5550
1
5530.93
1
5493.27
1
5460.5
1
5435.83
1
5436.63
1
5426.9
1
5414.47
1
5430.77
1
5360.27
1
5404.77
1
5390.27
1
5363.63
1
5353.87
1
5392.43
1
5368.2
1
5350.93
1
5318.07
1
5344.1
1
5297.73
1
5307.7
1
5354.43
1
5296.27
1
5313.67
1
5276.03
1
5303.3
1
5271.73
1
5269.47
1
5310.87
1
5304.83
1
5295.33
1
5336.03
1
5296.53
1
5313.93
1
5330.03
1
5306.83
1
5322.37
1
5346.53
1
5328.5
1
5313.37
1
5405.17
1
5366.87
1
5352.67
1
5335.67
1
5313.6
1
5362.17
1
5354.13
1
5351.9
1
5408.13
1
5427.6
1
5397.9
1
5416.43
1
5369
1
5375.87
1
5357.7
1
5419.5
1
5436.83
1
5443.87
1
5465.33
1
5416.73
1
5421.93
1
5399.53
1
5457.57
1
5481.13
1
5432.93
1
5463.67
1
5450.13
1
5454.2
1
5514.83
1
5510.57
1
5476.8
1
5504.7
1
5431.2
1
5494.47
1
5508.77
1
5482.9
1
5481
1
5546
1
5481.1
1
5501.57
1
5495.33
1
5495.8
1
5561.17
1
5535.17
1
5563.07
1
5530.03
1
5590.83
1
5583.07
1
5544.97
1
5525.17
1
5564.7
1
5574.73
1
5593.03
1
5596.5
1
5587.63
1
5597.8
1
5613.23
1
5649.03
1
5649.97
1
5594.93
1
5642.73
1
5625.97
1
5611.33
1
5683.2
1
5661.4
1
5652.37
1
5667.13
1
5664
1
5706.03
1
5672.83
1
5719.7
1
5697.83
1
5694.9
1
5729.43
1
5728.57
1
5741.93
1
5720.6
1
5755.27
1
5763.97
1
5794.43
1
5721.4
1
5743
1
5781.23
1
5793.2
1
5790.37
1
5789
1
5840.53
1
5834.9
1
5849.33
1
5807.43
1
5811.5
1
5845.1
1
5858.47
1
5867.8
1
5841.03
1
5827.9
1
5914.03
1
5858.57
1
5896.13
1
5902.87
1
5891.1
1
5895.93
1
5909.47
1
5915.03
1
5959.8
1
5969.87
1
5998.6
1
6013.67
1
6048.87
1
6039.63
1
6040.9
1
6108.73
1
6111.57
1
6089.73
1
6115.13
1
6190.9
1
6101.57
1
6149.1
1
6174.27
1
6172.77
1
6229.93
1
6197.4
1
6146.73
1
6162.27
1
6176.27
1
6142.23
1
6160.67
1
6167.07
1
6144.4
1
6131.7
1
6038
1
6123.83
1
6098.03
1
6097.07
1
6058.67
1
6033.27
1
6033.83
1
6019.47
1
6060.03
1
6018.17
1
6025.73
1
6021.33
1
6054.93
1
6030.93
1
6011.43
1
6051.93
1
6060.07
1
6071.87
1
6068.27
1
6068.7
1
6060.23
1
6103.5
1
6075.13
1
6095.23
1
6136.03
1
6150.17
1
6156.3
1
6203.93
1
6245.23
1
6249.27
1
6214.53
1
6223.23
1
6308.6
1
6286.03
1
6333.9
1
6359.53
1
6434.5
1
6398.77
1
6496.2
1
6459.2
1
6503.97
1
6495.63
1
6565.2
1
6547.1
1
6615.03
1
6616.53
1
6665.57
1
6692.87
1
6714.13
1
6739.07
1
6754.77
1
6790.93
1
6846.93
1
6867.7
1
6880.23
1
6915.83
1
6953
1
6988.53
1
6992.87
1
7017.8
1
7051.57
1
7060.73
1
7170.5
1
7110.33
1
7160.17
1
7238.1
1
7249.57
1
7213.3
1
7302.9
1
7287.5
1
7396.6
1
7410.57
1
7457.97
1
7439.33
1
7541.4
1
7557.17
1
7637.67
1
7708.8
1
7704.73
1
7704.23
1
7725.77
1
7756
1
7729.03
1
7768.4
1
7783.6
1
7786
1
7818.77
1
7804.07
1
7850.13
1
7835.63
1
7904.8
1
7865.77
1
7969.5
1
7818.9
1
7870.7
1
7928.17
1
7948.77
1
7991.3
1
8089.2
1
8108.43
1
8192.9
1
8159.8
1
8304.37
1
8333.57
1
8371.57
1
8441.57
1
8535.07
1
8587.87
1
8652.33
1
8722.07
1
8871.9
1
8934.73
1
9044.67
1
9120.43
1
9202.83
1
9269.47
1
9380.87
1
9388.5
1
9459.77
1
9543.5
1
9669.43
1
9697.53
1
9755.3
1
9773.53
1
9799.3
1
9832.2
1
9809.8
1
9744.03
1
9619.77
1
9556.03
1
9403.13
1
9334.67
1
9162.8
1
8986.27
1
8722.4
1
8570.9
1
8172.03
1
8009.93
1
7746.6
1
7588.27
1
7351.77
1
7208.53
1
7082.53
1
7026.3
1
6911.7
1
6892.5
1
6770.33
1
6802.87
1
6737.5
1
6699.23
1
6686.63
1
6688.17
1
6645.13
1
6651.63
1
6620.03
1
6615.43
1
6642.87
1
6677
1
6718.83
1
6668.4
1
6800.47
1
6776.2
1
6850.97
1
6858.6
1
6887.97
1
6913.07
1
6975.2
1
7024
1
7064.97
1
7027.13
1
7127.6
1
7128.53
1
7223.3
1
7181.17
1
7259.9
1
7248.33
1
7303.4
1
7343.2
1
7350.2
1
7424.1
1
7440.63
1
7487.6
1
7576.67
1
7609.63
1
7713.17
1
7778.07
1
7894.27
1
8048.77
1
8140.33
1
8267.3
1
8380.97
1
8482
1
8621.03
1
8694.07
1
8984.53
1
9088
1
9130.63
1
9220.87
1
9462.33
1
9537.2
1
9766.77
1
9870.9
1
10042
1
10130.7
1
10357.2
1
10489.7
1
10642.7
1
10654.5
1
10702.5
1
10758.2
1
10824
1
10822.9
1
10743.4
1
10749.7
1
10458.1
1
10375.5
1
10105.5
1
9929.87
1
9654.07
1
9482.3
1
9045.27
1
8819.5
1
8226.87
1
7851.7
1
6984.43
1
6519.77
1
5472.33
1
4949.5
1
3995.73
1
3569.4
1
2975.78
1
2739.66
1
2405.54
1
2278.72
1
2078.74
1
2006.69
1
1855.89
1
1758.76
1
1707.24
1
1665.86
1
1588.51
1
1575
1
1530.54
1
1520.24
1
1495.59
1
1494.72
1
1477
1
1470.38
1
1460.95
1
1469.52
1
1439.29
1
1450.64
1
1440.69
1
1411.43
1
1408.86
1
1411.03
1
1440.9
1
1438.95
1
1382.02
1
1386.07
1
1393.22
1
1398.32
1
1363.02
1
1384.04
1
1373.04
1
1382.78
1
1372.17
1
1376.92
1
1386.63
1
1384.82
1
1357.25
1
1372.95
1
1374.47
1
1374.32
1
1361.21
1
1360.51
1
1361.76
1
1363.61
1
1380.14
1
1357.78
1
1363.58
1
1369.2
1
1377.02
1
1343.53
1
1368.24
1
1371.02
1
1375.91
1
1354.4
1
1364.1
1
1351.92
1
1360.4
1
1370.96
1
1366.28
1
1356.92
1
1352.74
1
1360.76
1
1363.61
1
1358.33
1
1374.96
1
1342.2
1
1350.71
1
1368.34
1
1363.03
1
1361.15
1
1378.44
1
1377.21
1
1356.93
1
1348.24
1
1348.15
1
1351.04
1
1360.19
1
1360.32
1
1357.6
1
1328.24
1
1362.59
1
1364.54
1
1357.58
1
1381.03
1
1346.4
1
1338.68
1
1352.42
1
1359.58
1
1366.84
1
1345.58
1
1359.64
1
1375.56
1
1346.83
1
1344.72
1
1364.5
1
1347.22
1
1360.08
1
1358.85
1
1374.27
1
1362.38
1
1346.49
1
1352.78
1
1359.06
1
1370.61
1
1360.17
1
1345.13
1
1340.91
1
1361.07
1
1346.47
1
1360.39
1
1350.7
1
1353.43
1
1336.83
1
1355.59
1
1375.07
1
1352.31
1
1346.21
1
1340.32
1
1379.91
1
1359.5
1
1348.71
1
1340.45
1
1351.09
1
1362.11
1
1371.86
1
1364.54
1
1345.47
1
1379.8
1
1347.04
1
1345.64
1
1351.49
1
1348.38
1
1360.03
1
1370.78
1
1370.46
1
1366.93
1
1354.01
1
1353.18
1
1353.52
1
1359.09
1
1366.82
1
1369.19
1
1352.65
1
1361.25
1
1368.61
1
1
Fe2p
Fe2O3
2010
2021
5
17
51
2
0
11
Casa Info Follows
0
0
0
0
none
Group: none
Analyzer Lens: none
Analyzer Slit: none
Scan Mode: none
C:\Users\pielsticker\Downloads\utils\test fits\new\Fe2p_Fe2O3_new.vms
XPS
0
Al
1486.61
0
0
0
56.5
180
FAT
20
1
4.1408
0
0
0
0
0
Fe
2p
-1
kinetic energy
eV
716.61
0.05
2
counts
d
Transmission
d
pulse counting
0.1
3
0
0
0
0
2
ESCAPE DEPTH TYPE
d
0
MFP Exponent
d
0
11225.4
5792.37
1
5779.4
1
5727.2
1
5772.57
1
5773.43
1
5814.9
1
5682.67
1
5750.2
1
5764.67
1
5680.77
1
5755.93
1
5758.13
1
5605.77
1
5676.5
1
5694
1
5709.13
1
5581.87
1
5573.9
1
5588.97
1
5561.97
1
5507.17
1
5525.1
1
5493.7
1
5458.1
1
5489.3
1
5413.43
1
5439.13
1
5399.67
1
5440.73
1
5411.9
1
5382.97
1
5389.3
1
5417.7
1
5388.63
1
5355.43
1
5365.5
1
5379.27
1
5362.97
1
5434.5
1
5363.53
1
5348.9
1
5322.87
1
5393.63
1
5368.1
1
5356.83
1
5363.03
1
5381.2
1
5384.37
1
5339.47
1
5314.73
1
5389.3
1
5323.53
1
5325.5
1
5324.87
1
5355.03
1
5358.13
1
5329.83
1
5320.9
1
5402.03
1
5251.3
1
5425.83
1
5433.43
1
5328.9
1
5364.13
1
5383.47
1
5342.67
1
5384.53
1
5394.33
1
5347.87
1
5414.03
1
5387.7
1
5460.07
1
5388.63
1
5353.83
1
5456.5
1
5480.07
1
5408.23
1
5350.77
1
5371.87
1
5425.2
1
5539.33
1
5461.03
1
5426.1
1
5422.5
1
5460.73
1
5458.5
1
5483.97
1
5546.5
1
5477.27
1
5496.27
1
5460.93
1
5464.4
1
5482.57
1
5444.77
1
5493.57
1
5561.93
1
5534.23
1
5585
1
5502.43
1
5490.03
1
5534.53
1
5491.9
1
5551.6
1
5445.57
1
5545.5
1
5478.53
1
5543.27
1
5591.03
1
5548.2
1
5502.23
1
5551.63
1
5586.4
1
5572.13
1
5566.67
1
5555.73
1
5623.43
1
5689.4
1
5635
1
5619.3
1
5623.93
1
5600.8
1
5655.27
1
5577.47
1
5619.27
1
5551.7
1
5655.8
1
5586.57
1
5596.07
1
5648.67
1
5667.03
1
5632.23
1
5657.7
1
5679.43
1
5648.43
1
5593.17
1
5663.53
1
5651.37
1
5704.57
1
5654.57
1
5707.47
1
5687.57
1
5688
1
5771.57
1
5731.73
1
5760.47
1
5751.27
1
5777.7
1
5761.57
1
5773.93
1
5808.93
1
5788.5
1
5757.03
1
5767.07
1
5746.8
1
5705.7
1
5732
1
5834.67
1
5830.73
1
5820.7
1
5776.2
1
5761.57
1
5812.87
1
5773.73
1
5770.97
1
5823.13
1
5826.67
1
5867.03
1
5936.6
1
5971.27
1
5942.4
1
5935
1
5996.53
1
6041.47
1
6079.87
1
6140.3
1
6166.87
1
6256.67
1
6196.57
1
6260.43
1
6282.4
1
6277.37
1
6325.6
1
6307.13
1
6303.23
1
6327.63
1
6295.63
1
6389.87
1
6327.9
1
6313.33
1
6305.3
1
6246.57
1
6242.27
1
6180.63
1
6250.03
1
6136.57
1
6104.37
1
6149.27
1
6130.2
1
6093.73
1
6066.57
1
6125.27
1
6150.77
1
6090.4
1
6141.07
1
6027.67
1
6112.3
1
6044.53
1
5958.73
1
6074.67
1
6039.73
1
6045.97
1
6097.27
1
6111.5
1
6109
1
6153.47
1
6183.83
1
6270
1
6256.5
1
6308.03
1
6260.77
1
6299.47
1
6374.3
1
6381.53
1
6381.23
1
6411.07
1
6448.6
1
6461.93
1
6464.4
1
6481.53
1
6513.17
1
6605.4
1
6623.3
1
6655.57
1
6745.77
1
6716.63
1
6719.6
1
6892.2
1
6840.7
1
6945.9
1
7008.87
1
6966.1
1
6994.33
1
7075.9
1
7032.83
1
7123.47
1
7108.83
1
7146.83
1
7141
1
7120
1
7133.57
1
7155
1
7206.1
1
7169.67
1
7177.13
1
7178.4
1
7166.93
1
7113.93
1
7026.87
1
7088.8
1
7066.93
1
7021.77
1
6999.23
1
7004.07
1
6934.8
1
6982.5
1
6934.8
1
6963.63
1
6992.83
1
7005.97
1
7073.77
1
7026.33
1
7023.03
1
7073.2
1
7119.7
1
7210.37
1
7252.7
1
7303.43
1
7307.3
1
7488.83
1
7490.3
1
7543.73
1
7622.4
1
7717.13
1
7767.5
1
7838.23
1
7907.27
1
8152.83
1
8180.5
1
8324.8
1
8305.87
1
8430.57
1
8432.03
1
8639.97
1
8767.73
1
8909.67
1
8903.13
1
9077.23
1
9220.4
1
9315.73
1
9390.17
1
9444.6
1
9600.87
1
9665.23
1
9732.4
1
9780.67
1
9809.07
1
9689.3
1
9677.8
1
9540.07
1
9450.4
1
9184.03
1
9111.2
1
8878.1
1
8795.83
1
8445.03
1
8237.7
1
7626.5
1
7372.87
1
7037.93
1
7005.13
1
6786
1
6714.7
1
6677.87
1
6622.17
1
6617.03
1
6597.6
1
6594.7
1
6632.13
1
6729.83
1
6657.63
1
6766.97
1
6787.2
1
6869.23
1
6875.23
1
6883.73
1
6939.27
1
6906.77
1
6996.1
1
6865.97
1
6922.4
1
6944.03
1
6946.13
1
6947.1
1
6880.4
1
6688
1
6746.27
1
6718.87
1
6633.03
1
6482.37
1
6487.77
1
6394.1
1
6328.63
1
6257
1
6159.37
1
6110.87
1
6048.5
1
6011.6
1
6016.53
1
6025.3
1
5997.53
1
6086.8
1
5970.1
1
5973.57
1
5983.57
1
5976.13
1
6052.73
1
6261.87
1
6227.3
1
6290.5
1
6374.37
1
6574.43
1
6607.6
1
6729.43
1
6858.57
1
7161.23
1
7208.03
1
7470.2
1
7540.17
1
7842.3
1
7944.57
1
8137.1
1
8217.07
1
8634.1
1
8655.47
1
8878.37
1
9008.6
1
9341.7
1
9490.2
1
9931.97
1
10154.5
1
10553.5
1
10808.1
1
10977.3
1
11131
1
11152.4
1
10940.2
1
10729
1
10562.7
1
10414.3
1
10450.1
1
10503.9
1
10446.9
1
9622.73
1
8922.87
1
7023.07
1
5926.4
1
4126.17
1
3421.23
1
2637.1
1
2473.03
1
2149.73
1
2040.86
1
1899.92
1
1883.29
1
1815.61
1
1777
1
1720.75
1
1705.62
1
1707.42
1
1683.39
1
1607.82
1
1595.03
1
1601.63
1
1633.77
1
1648.63
1
1600.68
1
1573.6
1
1526.42
1
1559.18
1
1577.26
1
1523.53
1
1549.88
1
1532.17
1
1576.81
1
1519.92
1
1540.27
1
1511.9
1
1509.72
1
1507.25
1
1488.97
1
1498.56
1
1501.15
1
1466.67
1
1474.97
1
1529.51
1
1535.6
1
1508.64
1
1511.08
1
1495.94
1
1485.17
1
1503.9
1
1453.46
1
1485.99
1
1497.83
1
1486.91
1
1494.86
1
1481.89
1
1510.62
1
1460.15
1
1476.04
1
1457.34
1
1488.35
1
1475.98
1
1436.37
1
1478.05
1
1476.06
1
1467.01
1
1461.68
1
1505.38
1
1472.49
1
1467.19
1
1453.34
1
1461.49
1
1450.25
1
1480.9
1
1457.96
1
1462.52
1
1467.63
1
1450.55
1
1489.94
1
1454.92
1
1476.5
1
1457.59
1
1468.64
1
1459.8
1
1458.08
1
1473.49
1
1456.62
1
1458.66
1
1446.55
1
1480.11
1
1491.09
1
1481.2
1
1497.25
1
1486.95
1
1482.45
1
1501.13
1
1462.77
1
1483.37
1
1469.89
1
1464.3
1
1471.5
1
1487.68
1
1467.23
1
1495.55
1
1458.29
1
1451.04
1
1430.24
1
1442.46
1
1487.61
1
1507.67
1
1484.48
1
1487.25
1
1501.67
1
1435.27
1
1467.9
1
1448.55
1
1453.77
1
1456.26
1
1456.97
1
1467.09
1
1485.52
1
1504.77
1
1500.03
1
1449.01
1
1455.97
1
1496.62
1
1485.01
1
1461.05
1
1473.36
1
1467.79
1
1465.53
1
1482.76
1
1484.56
1
1469.23
1
1482.17
1
1460.27
1
1464.61
1
1489.6
1
1489.78
1
1490.64
1
1475.03
1
1447.07
1
1479.33
1
1501.99
1
1480.26
1
1491.65
1
1489.76
1
1502
1
1477.63
1
1478.62
1
1513.21
1
1487.78
1
1449.76
1
1501.23
1
1489.1
1
1508.9
1
1490.09
1
1476.93
1
1463.08
1
1486.69
1
1484.64
1
1493.43
1
1497.43
1
1464.94
1
1507.82
1
1489.21
1
1
end of experiment