File: data/references/Pd_references.vms
VAMAS Surface Chemical Analysis Standard Data Transfer Format 1988 May 4
Not Specified
Not Specified
Not Specified
Not Specified
5
Casa Info Follows CasaXPS Version 2.3.24PR1.0
0
SourceAnalyserAngle: Not Specified
CasaRowLabel:Pd metal
CasaRowLabel:PdO
NORM
REGULAR
0
1
Exp Variable
d
0
0
0
0
2
Pd 3d
Pd metal
1
2021
6
15
32
52
0
11
Casa Info Follows
0
0
0
0
none
Group: none
Analyzer Lens: none
Analyzer Slit: none
Scan Mode: none
C:\Users\pielsticker\Lukas\MPI-CEC\Projects\deepxps\xpsdeeplearning\data\references\Pd3d_Pd_metal_narrow.txt_new.vms
XPS
0
Al
1486.61
0
0
0
56.5
180
FAT
20
1
4.1408
0
0
0
0
0
Pd
3d
-1
kinetic energy
eV
1136.61
0.05
2
counts
d
Transmission
d
pulse counting
1
1
0
0
0
0
2
ESCAPE DEPTH TYPE
d
0
MFP Exponent
d
0
762
430.988
24252.1
1
1
3030.43
1
3057.78
1
3057.78
1
3057.78
1
3085.13
1
3099.76
1
3099.76
1
3099.76
1
3114.4
1
3138.66
1
3138.66
1
3138.66
1
3162.93
1
3186.47
1
3186.47
1
3186.47
1
3210.03
1
3228.91
1
3228.91
1
3228.91
1
3247.8
1
3282.22
1
3282.22
1
3282.22
1
3316.65
1
3340.78
1
3340.78
1
3340.78
1
3364.9
1
3385.31
1
3385.31
1
3385.31
1
3405.72
1
3438.28
1
3438.28
1
3438.28
1
3470.82
1
3516.1
1
3516.1
1
3516.1
1
3561.38
1
3562.97
1
3562.97
1
3562.97
1
3564.57
1
3601.18
1
3601.18
1
3601.18
1
3637.78
1
3678.22
1
3678.22
1
3678.22
1
3718.68
1
3752.86
1
3752.86
1
3752.86
1
3787.05
1
3839.46
1
3839.46
1
3839.46
1
3891.88
1
3917.71
1
3917.71
1
3917.71
1
3943.55
1
3947.94
1
3947.94
1
3947.94
1
3952.32
1
3945.99
1
3945.99
1
3945.99
1
3939.65
1
3883.97
1
3883.97
1
3883.97
1
3828.3
1
3774.82
1
3774.82
1
3774.82
1
3721.35
1
3678.44
1
3678.44
1
3678.44
1
3635.53
1
3600.65
1
3600.65
1
3600.65
1
3565.78
1
3561.09
1
3561.09
1
3561.09
1
3556.4
1
3548.95
1
3548.95
1
3548.95
1
3541.5
1
3540.14
1
3540.14
1
3540.14
1
3538.78
1
3565.09
1
3565.09
1
3565.09
1
3591.4
1
3650.78
1
3650.78
1
3650.78
1
3710.15
1
3730.54
1
3730.54
1
3730.54
1
3750.93
1
3826.21
1
3826.21
1
3826.21
1
3901.5
1
3929.72
1
3929.72
1
3929.72
1
3957.95
1
4028.35
1
4124.65
1
4109.02
1
4164.95
1
4210.23
1
4196.45
1
4268.13
1
4266.63
1
4305.5
1
4340.4
1
4385.82
1
4398.9
1
4408.98
1
4458.68
1
4514.1
1
4538.25
1
4608.95
1
4592.63
1
4680.45
1
4724.07
1
4787.23
1
4820.77
1
4821.63
1
4878.8
1
4969.45
1
4986.52
1
5078.15
1
5152.8
1
5191.27
1
5238.7
1
5365.25
1
5418.2
1
5484.75
1
5544.9
1
5729.5
1
5759.25
1
5863.8
1
6025.02
1
6109.35
1
6198.68
1
6354.52
1
6552.25
1
6717.7
1
6930.48
1
7069.07
1
7332.55
1
7554.73
1
7703.15
1
7994.15
1
8282.17
1
8621.88
1
9011.45
1
9368.08
1
9682.98
1
10119.6
1
10641.4
1
11130.7
1
11688.8
1
12254.6
1
12795
1
13337.2
1
13982.5
1
14680.6
1
15373.7
1
15885.7
1
16392
1
16924.4
1
17322.8
1
17691
1
18053.5
1
18180.9
1
18002.5
1
17657.9
1
17086
1
16152.9
1
15198.1
1
13810.5
1
12396.6
1
11057.5
1
9748.6
1
8526.6
1
7363.63
1
6422.55
1
5700.1
1
5145.02
1
4595.65
1
4227.9
1
3955.18
1
3779.68
1
3587.4
1
3447.43
1
3348.1
1
3247.1
1
3195.75
1
3105
1
3074.2
1
3008.88
1
3004.35
1
2977.75
1
2925.68
1
2966.25
1
2914.68
1
2915.82
1
2920.28
1
2900.18
1
2943.03
1
2940.45
1
2936.97
1
2931.7
1
2971.85
1
2952.6
1
2937.25
1
3018.85
1
2988.2
1
3006.55
1
3048.13
1
3000.75
1
3064.53
1
3090.8
1
3094.55
1
3190.63
1
3185.15
1
3219.18
1
3219.32
1
3277.4
1
3269.95
1
3341.22
1
3398.2
1
3418.38
1
3446.2
1
3499.68
1
3550.4
1
3662.85
1
3771.45
1
3798.18
1
3886.88
1
3924.43
1
4018.2
1
4103.7
1
4277.95
1
4385.3
1
4486.82
1
4622.38
1
4747.07
1
4939.2
1
5123.85
1
5367.65
1
5606.9
1
5851.73
1
6051.07
1
6353.18
1
6758.35
1
7038.45
1
7449.7
1
7922.15
1
8467.6
1
8841.7
1
9472.27
1
10111
1
10789.1
1
11545.4
1
12295.5
1
13190.5
1
14069.1
1
14979.8
1
16031.9
1
17015.8
1
17979.2
1
19018.3
1
20042.9
1
20980.8
1
21843.3
1
22659.8
1
23292.5
1
24008.3
1
24252.1
1
24131.1
1
23905.6
1
23265.1
1
21995.8
1
20600.9
1
18729.1
1
16643.3
1
14359
1
12122.4
1
10112.3
1
8266.55
1
6671.32
1
5460.7
1
4433
1
3677.22
1
3075.5
1
2612.78
1
2279.53
1
2031.8
1
1814.8
1
1640.2
1
1484.16
1
1383.78
1
1270.04
1
1210.55
1
1128.36
1
1072.89
1
1033.43
1
987.68
1
911.48
1
877.72
1
843.693
1
835.405
1
806.597
1
784.43
1
751.928
1
713.357
1
704.045
1
704.35
1
702.293
1
694.695
1
650.403
1
624.217
1
630.97
1
620.165
1
586.313
1
605.398
1
606.83
1
586.023
1
574.125
1
568.79
1
560.83
1
546.995
1
532.33
1
534.745
1
518.825
1
521.57
1
526.185
1
520.607
1
524.035
1
515.393
1
503.505
1
500.115
1
487.753
1
486.548
1
490.923
1
496.705
1
490.275
1
471.808
1
468.303
1
474.428
1
461.91
1
457.678
1
461.017
1
451.298
1
447.572
1
462.582
1
451.195
1
452.085
1
437.25
1
443.205
1
454.05
1
442.695
1
430.988
1
Pd 3d
PdO
1
2021
6
15
32
52
0
11
Casa Info Follows
0
0
0
0
none
Group: none
Analyzer Lens: none
Analyzer Slit: none
Scan Mode: none
C:\Users\pielsticker\Lukas\MPI-CEC\Projects\deepxps\xpsdeeplearning\data\references\Pd3d_PdO_narrow.txt_new.vms
XPS
0
Al
1486.61
0
0
0
56.5
180
FAT
20
1
4.1408
0
0
0
0
0
Pd
3d
-1
kinetic energy
eV
1136.61
0.05
2
counts
d
Transmission
d
pulse counting
1
1
0
0
0
0
2
ESCAPE DEPTH TYPE
d
0
MFP Exponent
d
0
762
307.257
20303.2
1
1
2197.63
1
2188.82
1
2188.82
1
2188.82
1
2180.02
1
2208.03
1
2208.03
1
2208.03
1
2236.05
1
2235.37
1
2235.37
1
2235.37
1
2234.68
1
2192.28
1
2192.28
1
2192.28
1
2149.87
1
2152.77
1
2152.77
1
2152.77
1
2155.67
1
2114.68
1
2114.68
1
2114.68
1
2073.7
1
2176.8
1
2176.8
1
2176.8
1
2279.9
1
2242.2
1
2242.2
1
2242.2
1
2204.5
1
2228.74
1
2228.74
1
2228.74
1
2252.98
1
2332.55
1
2368.69
1
2475.24
1
2266.42
1
2328.22
1
2374.51
1
2363.7
1
2306.87
1
2343.47
1
2392.33
1
2443.7
1
2422.91
1
2405.28
1
2504.94
1
2468.69
1
2507.03
1
2618.51
1
2556.43
1
2585.41
1
2565.26
1
2554.64
1
2584.63
1
2639.29
1
2579.29
1
2631.47
1
2640.74
1
2627.86
1
2730.43
1
2697.52
1
2721.09
1
2771.1
1
2751.59
1
2746.06
1
2791.74
1
2787.38
1
2773.77
1
2777.43
1
2861.1
1
2854.07
1
2892.19
1
2999.87
1
2961.32
1
2931.4
1
3003.94
1
2966.28
1
3030.46
1
3050.38
1
3060.07
1
3147.73
1
3125.98
1
3136.57
1
3128.72
1
3147.69
1
3154.1
1
3238.56
1
3174.93
1
3233.63
1
3211.42
1
3229.24
1
3103.22
1
3185.35
1
3232.22
1
3239.12
1
3192.1
1
3131.74
1
3112.23
1
3153.47
1
3150.57
1
3094.33
1
3009.53
1
3034.97
1
2983.88
1
2937.74
1
2901.37
1
3022.43
1
2985.67
1
2903.19
1
2924.36
1
2948.82
1
2954.51
1
2959.21
1
2963.15
1
2981.82
1
2977.93
1
3026.61
1
3093.93
1
3111.18
1
3088.87
1
3203.81
1
3339.35
1
3434.43
1
3521.37
1
3660.17
1
3720.76
1
3934.87
1
4071.47
1
4292.5
1
4496.24
1
4723.06
1
4894.24
1
5182.97
1
5568.43
1
5875.63
1
6245.88
1
6487.62
1
7051.17
1
7489.93
1
7787.52
1
8378.33
1
8853.58
1
9242
1
9702.58
1
10147.7
1
10295.8
1
10493.8
1
10814.3
1
10919.3
1
11009.3
1
10846.9
1
10742.4
1
10514.2
1
10223.8
1
9874.33
1
9363.17
1
8788.83
1
8377.25
1
7743.75
1
7207.33
1
6770.73
1
6480.76
1
5961.29
1
5409.02
1
5131.62
1
4746.1
1
4448.18
1
4255.13
1
3843.51
1
3736.36
1
3537.61
1
3405.13
1
3171.43
1
3025.75
1
2934.81
1
2763.26
1
2718.57
1
2677.35
1
2571.56
1
2494.72
1
2477.31
1
2295.79
1
2329.9
1
2293.97
1
2280.76
1
2254.37
1
2294.03
1
2279.69
1
2279.12
1
2312.97
1
2295.67
1
2304.22
1
2403.1
1
2529.5
1
2459.93
1
2528.78
1
2582.18
1
2600.2
1
2620.03
1
2573.45
1
2680.93
1
2686.48
1
2750.77
1
2741.96
1
2590.47
1
2618.72
1
2703.33
1
2563.16
1
2651.78
1
2636.45
1
2517.88
1
2459.29
1
2439.93
1
2460.82
1
2365.59
1
2411.08
1
2299.37
1
2290.32
1
2421.78
1
2363.8
1
2411.57
1
2430.07
1
2454.28
1
2436.69
1
2443.47
1
2493.44
1
2612.7
1
2615.65
1
2755.33
1
2770.37
1
2863.87
1
3039.57
1
3190.32
1
3401.88
1
3603.28
1
3810.72
1
4075.82
1
4495.95
1
4818.37
1
5318.09
1
5816.49
1
6322.59
1
7106.67
1
7881.12
1
8584.75
1
9654.58
1
10530.8
1
11584
1
12819.9
1
13790.2
1
14932.1
1
16205.3
1
17329.3
1
18176.5
1
18892.4
1
19612.7
1
20303.2
1
20233
1
19763.3
1
19224.4
1
18263.2
1
17150.1
1
15664.8
1
14076
1
12465.2
1
10785.7
1
9155
1
7815.25
1
6585.46
1
5510.75
1
4571.4
1
3831.32
1
3292.48
1
2843.35
1
2427.27
1
2117.79
1
1847.53
1
1623.11
1
1444.9
1
1322.11
1
1224.28
1
1154.33
1
1035.72
1
998.075
1
950.733
1
910.483
1
809.87
1
786.79
1
794.795
1
708.003
1
694.123
1
653.437
1
636.866
1
646.489
1
584.881
1
573.482
1
538.603
1
555.145
1
566.058
1
535.354
1
505.261
1
506.248
1
489.879
1
461.141
1
454.582
1
455.534
1
440.819
1
437.626
1
456.598
1
444.005
1
418.868
1
431.231
1
425.892
1
411.276
1
410.563
1
428.758
1
424.108
1
419.803
1
393.612
1
397.052
1
397.986
1
388.638
1
396.083
1
376.361
1
378.586
1
364.729
1
396.717
1
375.137
1
359.262
1
360.153
1
350.459
1
391.632
1
382.886
1
365.986
1
389.053
1
387.068
1
378.602
1
369.072
1
353.892
1
348.553
1
355.742
1
369.232
1
362.997
1
363.095
1
318.993
1
367.734
1
345.293
1
350.444
1
340.623
1
349.982
1
347.978
1
335.687
1
351.904
1
339.345
1
346.197
1
330.462
1
340.036
1
349.267
1
346.913
1
327.198
1
313.187
1
320.789
1
357.823
1
353.642
1
313.175
1
307.257
1
320.483
1
328.227
1
319.029
1
328.503
1
338.752
1
321.619
1
331.68
1
333.668
1
316.447
1
336.34
1
end of experiment