File: src/xpsdeeplearning/data/references/NiCoFe/EX491-495 Fe, Co oxide references.vms
VAMAS Surface Chemical Analysis Standard Data Transfer Format 1988 May 4
Not Specified
Not Specified
Not Specified
Not Specified
39
Casa Info Follows CasaXPS Version 2.3.24PR1.0
0
Created by SpecsLab Prodigy, Version 4.73.2-r95032
SourceAnalyserAngle: Not Specified
CasaRowLabel:Co metal
CasaRowLabel:CoO
CasaRowLabel:Co3O4
CasaRowLabel:Fe metal
CasaRowLabel:FeO
CasaRowLabel:Fe3O4
CasaRowLabel:Fe2O3
CasaRowLabel:Co metal lineshape Tougaard
CasaRowLabel:CoO lineshape Tougaard
CasaRowLabel:Co3O4 lineshape Tougaard
CasaRowLabel:Fe metal lineshape Tougaard
CasaRowLabel:FeO lineshape Tougaard
CasaRowLabel:Fe3O4 lineshape Tougaard
CasaRowLabel:Fe2O3 lineshape Tougaard
CasaRowLabel:Co metal fit Tougaard
CasaRowLabel:CoO fit Tougaard
CasaRowLabel:Co3O4 fit Tougaard
CasaRowLabel:Fe metal fit Tougaard
CasaRowLabel:FeO fit Tougaard
CasaRowLabel:Fe3O4 fit Tougaard
CasaRowLabel:Fe2O3 fit Tougaard
CasaRowLabel:Co metal lineshape min limits
CasaRowLabel:CoO lineshape min limits
CasaRowLabel:Co3O4 lineshape min limits
CasaRowLabel:Fe metal lineshape min limits
CasaRowLabel:FeO lineshape min limits
CasaRowLabel:Fe3O4 lineshape min limits
CasaRowLabel:Fe2O3 lineshape min limits
CasaRowLabel:Co metal fit min limits
CasaRowLabel:CoO fit min limits
CasaRowLabel:Co3O4 fit min limits
CasaRowLabel:Fe metal fit min limits
CasaRowLabel:FeO fit min limits
CasaRowLabel:Fe3O4 fit min limits
CasaRowLabel:Fe2O3 fit min limits
NORM
REGULAR
4
1
Exp Variable
d
0
0
0
0
56
Survey
Co metal
2021
4
27
18
28
6
0
17
Casa Info Follows
0
0
0
0
File = E:/OwnCloud/XPS lab/EX491_S745_Co.sle
Group = RT in vacuum, #Treatments:4h sputter, #Temp:RT , #Pressure:vacuum , #Atmosphere:{:}, #Comments:
First of group = 1
Spectrum ID = 13
Analyzer lens = LargeArea:1.5kV
Analyzer slit = 4:7x20c\C:mesh
Scan mode = FixedAnalyzerTransmission
Kinetic energy start = 286.61
PCA Coefs = 148206, -15288.9, -1023.74, -577.522, -1664.67, 621.197,
C:\Users\Mark\Downloads\EX491_S745_Co (1).vms
c:\users\pielsticker\lukas\mpi-cec\projects\deepxps\xpsdeeplearning\data\references\nicofe\ex491-495 fe, ni, co oxide references.vms
CasaXP1
XPS
1
Al
1486.61
0
0
0
54.5
180
FAT
100
1
4.1408
0
0
0
0
0
Survey

-1
kinetic energy
eV
286.61
1
2
counts
d
Transmission
d
pulse counting
0.1
1
0
0
0
0
2
ESCAPE DEPTH TYPE
d
1
MFP Exponent
d
0
191.047
1
3654.4
3665.99
3654.94
3667.85
3674.77
3692.47
3693.12
3691.98
3710.61
3689.09
3701.53
3719.47
3734.31
3754.87
3758.52
3787.56
3801.82
3780.63
3756.14
3790.89
3824.62
3826.37
3811.29
3827.25
3869.91
3838.93
3863.57
3893.23
3891
3892.39
3949.49
3913.14
3899.41
3912.73
3958.12
3934.23
3952.55
3994.67
3990.13
3956.77
4009.88
4034.72
4009.5
4035.09
4053.12
4067.85
4077.08
4079.16
4068.44
4104.51
4126.88
4128.85
4138.58
4145.27
4186.37
4169.97
4184.22
4184.05
4221.04
4247.74
4283.6
4249.97
4226.58
4251.9
4263.35
4260.5
4318.77
4339.31
4299.72
4309.18
4368.27
4350.77
4364.33
4382.72
4369.89
4408.6
4414.66
4418.66
4402
4440.6
4460.18
4453.55
4484.29
4498.56
4520.6
4528.95
4533.06
4541.35
4544.99
4623.02
4585.29
4601.13
4614.4
4618.05
4629.18
4647.02
4665.98
4646.13
4657.82
4651.47
4748.25
4747.59
4752.53
4746.22
4768.54
4776.47
4830.06
4819.58
4811.26
4825.86
4837.24
4849.53
4879.66
4872.56
4866.39
4887.26
4940.21
4962.44
4940.39
4934.41
4984.2
5019.41
5038.51
5017.83
5013.04
5048.1
5075.72
5112.66
5105.57
5104.38
5109.49
5117.98
5161.86
5187.33
5161.07
5183.74
5193.93
5225.17
5203.14
5229.14
5188.21
5265.5
5255.74
5268.24
5299.46
5337.56
5332.52
5341.09
5344.08
5350.16
5362.57
5369.84
5425.57
5441.55
5450.48
5431.88
5411.7
5461.81
5528.73
5524.64
5496.87
5534.56
5557.05
5546.73
5620.65
5644.82
5658.29
5653.06
5673.48
5715.03
5655.18
5713.16
5744.48
5740.64
5772.6
5769.36
5814.22
5818.28
5817.12
5813.16
5857.57
5830.3
5878.11
5936.11
5914.07
5909.82
5919.48
5976.88
5992.47
6022.47
6039.78
6076.66
6066.87
6003.4
6060.8
6131.99
6155.57
6110.32
6156.22
6176.85
6219.14
6191.25
6251.71
6295.59
6269.98
6286.33
6347.73
6330.13
6405.18
6352.99
6335.43
6398.33
6415
6427.51
6498.98
6545.03
6546.39
6536.73
6565.61
6590.95
6600.58
6640.27
6687.82
6724.71
6777.83
6760.64
6787.22
6829.61
6833.51
6831.2
6812.74
6863.58
6880.36
6912.99
6933.69
6939.4
6962.57
7056.12
7039.22
7063.53
7079.52
7119.52
7115.26
7143.17
7168.91
7198.29
7269.22
7305.13
7281.24
7326.94
7322.62
7388.59
7382.19
7423.56
7442.31
7485.81
7483.42
7511.99
7535.28
7574.7
7607.23
7685.24
7740.52
7736.32
7737.05
7819.2
7879.74
7939.12
8075.72
8098.69
8255.27
8334.44
8382.9
8463.93
8534.18
8583.92
8426.03
8251.34
7990.96
7798.42
7637.86
7558.13
7533.1
7433.38
7385.87
7383.68
7410.21
7371.04
7339.35
7331.6
7337.19
7360.71
7392.48
7446.33
7412.12
7415.78
7473.16
7457.31
7529.4
7513.83
7515.35
7517.1
7603.23
7666.64
7659.34
7674.83
7771.12
7766.63
7767.06
7756.93
7841.18
7908.5
7962.72
8018.89
8044.34
8123.36
8168.43
8180.24
8168.47
8185.84
8198.58
8204.22
8174.16
8192.15
8193.17
8251.11
8323.37
8394.67
8393.76
8507.81
8666.78
8734.52
8731.95
8621.45
8519.29
8411.59
8419.69
8493.03
8534.69
8529.09
8568.18
8623.2
8628.73
8725.79
8727.89
8792.53
8861.61
8922.46
8924.61
9032.5
9129.32
9135.67
9297.43
9311.49
9392.21
9434.44
9627.73
9718.86
9846.65
9991.17
10123.5
10230.1
10255.1
10171.3
10059.4
9901.94
9880.64
9983.55
10116.9
10156
10000.2
9554.12
9141.52
8923.74
8755.1
8683.35
8623.74
8630.12
8613.28
8643.1
8679.97
8763.56
8786.77
8846.32
8853.49
8957.49
9056.24
8969.24
8953.15
9033.04
9092.51
9091.8
9152.22
9216.96
9281.63
9407.43
9452.07
9575.65
9704.29
9803.51
9911.12
10169.2
10482.1
10919.7
11693.5
12849.2
13641.8
12528.7
10346.8
9090.62
8818.29
8784.51
8935.99
9133.74
9385.16
9713.6
10171.4
10654.1
11277.6
12535.4
15804
18922.9
15652.8
9424.02
6553.38
5823.89
5421.47
5228.54
5164.03
4948.19
4667.88
4258.27
3639.85
3126.78
2758.81
2631.65
2557.65
2495.85
2465.68
2415.58
2347.93
2268.23
2274.96
2255.22
2201.01
2142.05
2115.27
2082.85
2045.08
2070.76
2072.96
2070.66
2077.75
2130.73
2195.05
2194.88
2198.19
2222.96
2244.69
2249.03
2277.39
2274.1
2292.76
2311.61
2351.65
2343.22
2340.75
2353.2
2354.48
2377.18
2403.29
2438.15
2481.42
2529.75
2555.55
2613.81
2668.59
2784.65
2911.93
3030.58
3185.38
3433.21
3666.69
4009.35
4497.51
5049.15
5549.36
5639.76
5139.31
4305.06
3314.05
2363.25
1717.26
1428.28
1250.03
1170.38
1158.2
1129.12
1150.64
1182.77
1251.62
1243.96
1248.51
1175.99
1039.46
895.466
776.892
674.097
599.503
559.526
559.709
543.265
525.381
526.795
529.561
514.999
524.398
523.228
520.226
526.769
531.189
517.748
518.934
522.566
525.986
527.829
529.323
521.915
531.696
531.854
534.535
526.934
528.279
525.611
536.872
524.444
519.763
534.741
527.188
519.419
509.445
526.343
512.579
519.502
519.268
521.76
509.058
516.546
525.254
530.123
525.095
516.658
515.852
520.02
526.205
514.695
510.113
522.959
522.737
547.952
526.979
525.8
529.923
535.436
527.744
528.522
534.445
535.098
519.506
537.83
538.531
531.997
527.29
534.998
526.449
536.207
538.438
527.897
527.8
538.712
521.992
535.534
542.301
539.651
546.046
537.05
543.364
544.438
536.828
546.901
556.887
552.049
554.582
544.956
541.448
555.893
560.692
544.389
564.085
559.591
545.531
544.851
560.774
558.498
553.549
564.677
561.035
558.784
563.617
550.625
553.569
570.839
563.729
554.741
555.693
573.792
574.714
584.544
583.153
574.487
584.663
579.575
576.161
597.003
591.355
602.906
600.908
578.017
590.904
590.607
590.75
600.689
604.633
598.115
601.17
596.667
581.036
582.281
581.839
588.233
588.302
586.405
583.06
583.202
581.66
592.625
596.424
594.78
603.309
613.432
588.878
582.931
582.047
596.477
599.582
593.069
594.303
603.577
604.596
615.752
613.867
604.958
577.908
590.642
617.002
625.081
629.309
624.753
687.39
764.409
823.778
781.017
658.113
597.386
607.059
600.901
602.69
607.267
606.058
605.275
604.697
611.554
599.964
600.479
619.373
608.123
612.631
601.097
609.166
610.721
617.094
621.198
612.679
608.786
611.565
608.203
635.71
627.456
630.96
630.72
625.901
625.954
617.409
615.607
636.944
634.651
628.29
638.796
626.753
627.586
631.926
636.935
638.682
641.412
646.972
651.21
644.45
646.895
630.04
637.583
650.07
649.371
649.092
643.296
634.177
653.573
653.148
655.546
655.814
648.847
642.804
652.965
654.433
653.236
662.015
661.954
654.934
641.009
654.043
667.249
671.899
667.588
672.73
669.342
667.92
669.419
665.71
677.07
667.106
678.08
677.225
672.888
668.317
677.243
678.551
670.413
682.689
677.78
681.269
678.269
689.035
700.191
673.616
682.212
680.382
674.603
677.712
681.448
701.351
713.102
703.459
700.742
686.297
679.327
699.405
711.18
682.164
695.408
692.977
687.711
697.041
699.834
703.398
707.349
710.113
718.977
721.231
720.079
720.642
715.141
728.802
723.742
720.64
711.975
711.205
716.186
725.918
733.65
735.522
732.262
735.598
728.572
725.544
729.048
741.72
715.725
733.232
724.529
741.782
741.833
748.006
768.225
751.074
762.502
751.522
738.186
745.351
759.367
750.633
752.114
758.148
760.644
760.902
770.962
769.632
769.384
767.929
762.603
776.326
743.859
763.622
780.537
781.912
766.159
775.02
784.049
788.156
785.525
796.613
780.414
783.694
791.31
784.474
789.094
781.665
798.314
803.008
790.004
787.804
787.986
801.68
811.517
797.595
805.974
810.289
807.188
818.332
812.171
816.416
805.888
802.23
817.115
812.114
811.564
813
818.258
816.461
817.532
813.945
812.649
824.725
824.106
831.763
831.449
830.669
842.872
847.194
866.361
882.475
904.799
922.64
878.911
856.427
861.373
845.287
824.582
825.172
824.634
843.993
832.006
831.51
834.223
848.275
856.773
852.931
863.996
865.091
862.105
857.829
852.442
864.23
849.599
856.562
872.344
879.102
885.161
853.722
875.385
861.237
866.757
869.626
884.536
859.976
866.993
874.822
963.764
1032.88
991.664
898.037
864.341
870.108
861.583
878.525
869.859
881.456
885.535
889.412
886.699
886.88
888.049
889.313
890.33
890.27
914.03
922.894
912.046
910.383
894.695
913.486
898.075
882.752
883.466
885.851
900.318
891.575
894.832
912.485
907.547
904.56
895.005
900.868
904.286
917.162
927.406
941.322
1013.9
1071.16
1119.14
1082.06
987.937
918.319
929.571
905.477
902.206
910.555
902.177
907.359
901.009
904.756
895.054
903.211
907.425
907.134
916.726
916.737
913.938
919.261
936.583
938.896
935.386
936.268
930.597
914.564
924.59
936.089
937.546
951.78
947.368
944.335
963.082
946.816
952.605
963.758
967.221
938.294
944.354
955.79
961.173
956.358
978.055
974.031
976.772
963.877
976.796
998.927
977.069
991.682
980.21
980.423
991.802
997.911
984.253
996.9
1004.33
1015.15
1010.58
1022.68
1011.51
1024.9
1025.24
1010.84
1035.75
1030.49
1022.59
1033.42
1056.78
1040.08
1049.12
1046.64
1056.19
1053.21
1047.76
1052.57
1075.23
1061.4
1063.36
1069.23
1077.19
1060.11
1053.62
1086.08
1098.45
1098.92
1094.76
1094.37
1099.72
1094.73
1098.06
1119.85
1125.56
1135.11
1117.53
1131.02
1152.46
1172.05
1154.37
1150.35
1171.62
1174.21
1177.46
1194.92
1215.87
1212.93
1225.07
1218.86
1241.72
1255.37
1234.65
1267.01
1287.02
1284.76
1303.76
1292.39
1285.9
1293.76
1309.7
1298.48
1289.66
1288.29
1300.94
1305.67
1299.18
1309.89
1339.16
1340.66
1371.39
1375.6
1394.76
1428.43
1467.56
1501.17
1556.66
1617.27
1667.65
1695.71
1762.81
1860.21
2074.53
2268.58
2197.83
1878.15
1549.5
1357.22
1298.04
1258.67
1220.05
1226.65
1233.48
1233.38
1261.56
1254.66
1279.84
1315.58
1287.97
1300.01
1297.29
1320.19
1318.54
1307.86
1301.44
1330.95
1334.2
1360.62
1359.66
1356.04
1355.84
1367.29
1392.41
1442.78
1470.89
1478.99
1470.09
1484.29
1505.84
1563.03
1679.45
1832.93
2091.38
2560.03
3226.88
3574.58
2750.12
1421.84
640.694
410.622
320.521
283.143
251.162
227.784
226.579
213.643
210.612
205.197
206.174
204.779
207.137
200.941
194.32
200.16
206.064
203.343
203.556
214.322
221.484
211.391
223.51
231.1
234.309
232.16
233.194
235.864
234.022
239.678
234.113
238.403
240.424
241.299
242.084
247.903
233.847
224.838
227.064
228.147
228.125
229.101
231.825
246.698
256.166
266.459
288.563
319.164
340.295
375.724
411.318
451.736
534.37
639.108
752.805
866.673
702.726
316.703
1
Co2p
Co metal
2021
4
27
18
36
14
0
18
Casa Info Follows
0
0
1
CASA region (*Co 2p*) (*U 2 Tougaard*) 676.61 716.61 19.16 2 0 0 1438.0209 -650 0 0 (*Co 2p*) 58.9332 0 19.16
0
File = E:/OwnCloud/XPS lab/EX491_S745_Co.sle
Group = RT in vacuum, #Treatments:4h sputter, #Temp:RT , #Pressure:vacuum , #Atmosphere:{:}, #Comments:
First of group = 0
Spectrum ID = 15
Analyzer lens = AngleResolvedMode22:1.5kV
Analyzer slit = 4:7x20c\C:mesh
Scan mode = FixedAnalyzerTransmission
Kinetic energy start = 646.61
PCA Coefs = 117821, -21153.7, -1403.13, 970.754, 1743.34,
C:\Users\Mark\Downloads\EX491_S745_Co (1).vms
c:\users\pielsticker\lukas\mpi-cec\projects\deepxps\xpsdeeplearning\data\references\nicofe\ex491-495 fe, ni, co oxide references.vms
CasaXP1
XPS
1
Al
1486.61
0
0
0
54.5
180
FAT
20
1
4.1408
0
0
0
0
0
Co
2p
-1
kinetic energy
eV
646.61
0.1
2
counts
d
Transmission
d
pulse counting
0.1
2
0
0
0
0
2
ESCAPE DEPTH TYPE
d
1
MFP Exponent
d
0
1402
2120.19
13889.6
1
1
4565.58
1
4573.78
1
4592.52
1
4594.61
1
4589.69
1
4625.72
1
4632.34
1
4631.83
1
4617.53
1
4622.36
1
4628.75
1
4610.33
1
4632.59
1
4652.39
1
4642.18
1
4638.13
1
4638.33
1
4636.05
1
4663.47
1
4659.32
1
4661.18
1
4667.98
1
4662.28
1
4655.87
1
4634.72
1
4634.58
1
4621.88
1
4640.71
1
4643.94
1
4641.59
1
4631.49
1
4605.81
1
4636.11
1
4633.43
1
4611.44
1
4623.11
1
4605.16
1
4584.81
1
4595.82
1
4589.15
1
4578.12
1
4587.29
1
4580.29
1
4540.5
1
4526.17
1
4526.69
1
4532.22
1
4489.65
1
4503.42
1
4509.74
1
4497.77
1
4503.13
1
4497.29
1
4512.85
1
4485.34
1
4494.74
1
4483.6
1
4474.39
1
4469.59
1
4451.37
1
4425.91
1
4467.92
1
4467.25
1
4444.25
1
4463.18
1
4484.65
1
4500.96
1
4465.22
1
4441.89
1
4448.85
1
4476.73
1
4486.37
1
4491.61
1
4511.35
1
4526.53
1
4512.47
1
4515.82
1
4521.5
1
4519.35
1
4519.94
1
4541.25
1
4560.45
1
4612.8
1
4626.28
1
4638.57
1
4605.67
1
4629.09
1
4643.45
1
4655.13
1
4652.27
1
4667.74
1
4654.73
1
4691.46
1
4699.84
1
4681.69
1
4657.73
1
4685.2
1
4652.53
1
4660.02
1
4649.62
1
4616.76
1
4623.6
1
4618.29
1
4610.17
1
4578.82
1
4569.14
1
4515.38
1
4510.69
1
4484.02
1
4465.77
1
4433.52
1
4385.32
1
4354.16
1
4367.07
1
4324.94
1
4286.76
1
4258.85
1
4232.18
1
4189.11
1
4181.66
1
4174.6
1
4162.63
1
4147.71
1
4100.91
1
4083.54
1
4068.67
1
4055.87
1
4063.55
1
4036.66
1
4038.03
1
4002.93
1
4013.89
1
3994.06
1
3977.06
1
3986.67
1
3986.11
1
3961.77
1
3941.76
1
3968.53
1
3960.37
1
3954.85
1
3917.05
1
3915.17
1
3928.73
1
3917.22
1
3947.12
1
3931.18
1
3917.23
1
3902.98
1
3872
1
3911.59
1
3914.28
1
3908.09
1
3940.57
1
3932.52
1
3892.21
1
3920.19
1
3939.9
1
3910.85
1
3890.28
1
3878
1
3907.75
1
3899.35
1
3867.71
1
3884.25
1
3891.64
1
3893.9
1
3913.15
1
3901.38
1
3914.45
1
3882.95
1
3893.55
1
3911.72
1
3884.93
1
3902.85
1
3912.22
1
3885.39
1
3878.58
1
3909.17
1
3928.02
1
3910.91
1
3916.38
1
3923.95
1
3932.93
1
3886.43
1
3887.47
1
3892.57
1
3925.69
1
3912.36
1
3891.64
1
3900.66
1
3902.32
1
3930.83
1
3916.06
1
3909.01
1
3932.12
1
3931.42
1
3899.78
1
3895.55
1
3898.03
1
3918.04
1
3911.14
1
3898.61
1
3916.07
1
3938.36
1
3929.22
1
3925.19
1
3918.33
1
3940.54
1
3972.24
1
3966.15
1
3932.3
1
3921.75
1
3952.09
1
3946.19
1
3953.93
1
3964.75
1
3978.08
1
3943.78
1
3975.15
1
3966.39
1
3953.27
1
3981.42
1
3951.86
1
3978.86
1
3985.28
1
3985.37
1
3973.32
1
3986.93
1
3951.53
1
3955.54
1
3980.08
1
3993.82
1
4006.91
1
4013.88
1
4012.95
1
4004.59
1
3996.62
1
4014.7
1
4018.43
1
4011.66
1
4024.78
1
4008.87
1
4027.81
1
4022.19
1
4028.99
1
4039.46
1
4033.2
1
4063.18
1
4049.45
1
4039.69
1
4061.92
1
4065.55
1
4095.46
1
4069.28
1
4068.61
1
4057.23
1
4059.45
1
4085.93
1
4083.34
1
4055.85
1
4065.13
1
4051.45
1
4058.02
1
4064.88
1
4068.04
1
4055.55
1
4055.36
1
4047.27
1
4053.44
1
4045.58
1
4048.7
1
4022.46
1
4064.16
1
4058.76
1
4031.75
1
4029.82
1
4037.41
1
4010.65
1
4031.14
1
4028.63
1
4022.63
1
4041.42
1
4022.72
1
4043.11
1
4027.42
1
4054.13
1
4028.87
1
4024.91
1
4033.74
1
4041.64
1
4020.82
1
4054.24
1
4054.77
1
4040.36
1
4027.76
1
4036.72
1
4051.28
1
4027.17
1
4038.59
1
4053.37
1
4051.15
1
4053.17
1
4061.02
1
4055.42
1
4048.65
1
4074.19
1
4067.43
1
4091.31
1
4098.42
1
4093.23
1
4056.82
1
4064.68
1
4075.78
1
4089.18
1
4080.15
1
4100.41
1
4073.47
1
4069.8
1
4098.24
1
4089.62
1
4080.22
1
4071.68
1
4090.51
1
4115.9
1
4121.8
1
4112.85
1
4104.45
1
4149.54
1
4124.48
1
4138.13
1
4148.64
1
4170.52
1
4164.72
1
4188.67
1
4180.95
1
4165.31
1
4181.17
1
4187.54
1
4178.91
1
4180.78
1
4170.71
1
4227.2
1
4204.86
1
4202.67
1
4193.58
1
4197.05
1
4206.8
1
4199.6
1
4190.95
1
4209.2
1
4203.65
1
4226.81
1
4216.54
1
4217.43
1
4223.24
1
4229.41
1
4207.41
1
4240.63
1
4227.9
1
4233.24
1
4233.87
1
4252.25
1
4245.27
1
4257.93
1
4271.98
1
4245.85
1
4271.46
1
4273.98
1
4270.29
1
4272.6
1
4269.69
1
4281.04
1
4281.05
1
4311.61
1
4310.13
1
4282.84
1
4300.29
1
4320.27
1
4322.87
1
4341.28
1
4316.74
1
4316.45
1
4353.22
1
4329.21
1
4297.05
1
4319.06
1
4356.98
1
4376.28
1
4332.61
1
4350.19
1
4331.19
1
4359.29
1
4372.86
1
4362.28
1
4350.3
1
4377.97
1
4384.89
1
4408.84
1
4374.81
1
4374.07
1
4391.63
1
4399.03
1
4430.32
1
4450.77
1
4432.11
1
4436.09
1
4435.21
1
4448.8
1
4467.75
1
4474.36
1
4483.76
1
4497.12
1
4507.46
1
4527.36
1
4554.93
1
4544.55
1
4537.73
1
4556.31
1
4579.77
1
4577.42
1
4561.8
1
4623.04
1
4629.61
1
4633.98
1
4655.1
1
4667.86
1
4705.97
1
4730.06
1
4735.01
1
4752.94
1
4762.72
1
4792.45
1
4828.71
1
4828.7
1
4886.79
1
4913.73
1
4912.83
1
4935.49
1
4970.35
1
5023.92
1
5003.6
1
5051.46
1
5095.98
1
5137.54
1
5176.99
1
5229.74
1
5275.57
1
5304.85
1
5395.1
1
5429.72
1
5489.65
1
5540.86
1
5613.38
1
5699.42
1
5753.3
1
5831.5
1
5898.96
1
5980.26
1
6059.09
1
6178.68
1
6314.94
1
6411.18
1
6580.71
1
6699.06
1
6811.43
1
6936.81
1
7019.51
1
7041.27
1
7002.25
1
6864.2
1
6666.02
1
6434.5
1
6160.47
1
5878.15
1
5568.63
1
5279.12
1
5042.33
1
4837.55
1
4678.37
1
4510.26
1
4388.43
1
4303.01
1
4220.3
1
4147.16
1
4148.13
1
4054.21
1
4026.64
1
4015.76
1
4003.33
1
3955.86
1
3933.92
1
3904.73
1
3885.48
1
3875.89
1
3872.25
1
3829.81
1
3833.4
1
3830.76
1
3818.97
1
3824.02
1
3833.07
1
3813.13
1
3829
1
3808.58
1
3816.19
1
3820.59
1
3836.14
1
3851.1
1
3846.77
1
3837.17
1
3852.67
1
3853.64
1
3858.56
1
3896.86
1
3906.7
1
3901.95
1
3898.55
1
3884.65
1
3907.55
1
3933.9
1
3938.84
1
3931.22
1
3945.38
1
3945.76
1
3973.09
1
3988.31
1
3951.12
1
3970.79
1
3978
1
4011.65
1
4007.99
1
4008.87
1
4017.56
1
4024.89
1
4042.1
1
4070.59
1
4075.64
1
4066.28
1
4088.84
1
4091.6
1
4120.27
1
4107.12
1
4119.94
1
4126.51
1
4146.41
1
4135.17
1
4189.59
1
4216.82
1
4203.09
1
4203.86
1
4211.39
1
4242.9
1
4239.47
1
4277.85
1
4321.15
1
4327.86
1
4336.87
1
4344.37
1
4350.66
1
4360.84
1
4415.33
1
4399.67
1
4435.12
1
4454.85
1
4492.73
1
4494.65
1
4496.45
1
4550.34
1
4589.65
1
4615.25
1
4643.2
1
4683.1
1
4683.46
1
4720.65
1
4736.58
1
4789.94
1
4824.6
1
4822.89
1
4823.44
1
4875.44
1
4914.05
1
4888.3
1
4912.45
1
4905.75
1
4944.81
1
4961.19
1
4943.26
1
4970.8
1
5034.78
1
5025.78
1
5072.26
1
5151.96
1
5199.74
1
5242.44
1
5270.47
1
5403.71
1
5465.66
1
5529.36
1
5661.11
1
5744.31
1
5868.5
1
5997.12
1
6158.41
1
6342.74
1
6468.35
1
6720.09
1
6931.28
1
7225.09
1
7534.2
1
7946.21
1
8467.86
1
9085.86
1
9874.31
1
10799.3
1
11826.9
1
12812.9
1
13570.3
1
13923.1
1
13602.9
1
12656.8
1
11198.9
1
9520.84
1
7833.75
1
6439.82
1
5397.08
1
4667.5
1
4182.13
1
3815.72
1
3572.46
1
3406.33
1
3281.26
1
3175.14
1
3117.13
1
3049.81
1
2975.06
1
2948.42
1
2919.17
1
2884.24
1
2855.6
1
2843.81
1
2808.89
1
2803.59
1
2775.38
1
2766.78
1
2740.08
1
2693.98
1
2668.73
1
2657.65
1
2618.4
1
2593.98
1
2578.61
1
2536.15
1
2501.95
1
2483.01
1
2464.76
1
2433.08
1
2389.5
1
2370.49
1
2349.62
1
2376.13
1
2339.65
1
2307.94
1
2300.04
1
2282.35
1
2290.45
1
2300.01
1
2269.94
1
2253.01
1
2262.6
1
2265.68
1
2273.46
1
2271.7
1
2273.8
1
2264.05
1
2274.8
1
2272.8
1
2267.31
1
2259.87
1
2260.94
1
2283.3
1
2301.67
1
2283.84
1
2283.05
1
2300.14
1
2298.28
1
2283.51
1
2277.61
1
2288.35
1
2286.29
1
2286.73
1
2266.66
1
2255.9
1
2258.2
1
2230.89
1
2209.46
1
2186.02
1
2179.3
1
2177.35
1
2160.91
1
2138.65
1
Fe2p
Co metal
2021
4
27
18
40
49
0
17
Casa Info Follows
0
0
0
0
File = E:/OwnCloud/XPS lab/EX491_S745_Co.sle
Group = RT in vacuum, #Treatments:4h sputter, #Temp:RT , #Pressure:vacuum , #Atmosphere:{:}, #Comments:
First of group = 0
Spectrum ID = 16
Analyzer lens = AngleResolvedMode22:1.5kV
Analyzer slit = 4:7x20c\C:mesh
Scan mode = FixedAnalyzerTransmission
Kinetic energy start = 716.61
PCA Coefs = 32468.6, -4575.75, -244.522, -299.101, -116.521,
C:\Users\Mark\Downloads\EX491_S745_Co (1).vms
c:\users\pielsticker\lukas\mpi-cec\projects\deepxps\xpsdeeplearning\data\references\nicofe\ex491-495 fe, ni, co oxide references.vms
CasaXP1
XPS
1
Al
1486.61
0
0
0
54.5
180
FAT
20
1
4.1408
0
0
0
0
0
Fe
2p
-1
kinetic energy
eV
716.61
0.1
2
counts
d
Transmission
d
pulse counting
0.1
2
0
0
0
0
2
ESCAPE DEPTH TYPE
d
1
MFP Exponent
d
0
1402
456.429
2662.14
1
1
2140.53
1
2131.21
1
2109.54
1
2096
1
2065.13
1
2053.15
1
2021.2
1
2017.9
1
2009.73
1
2002.16
1
1981.63
1
1956.09
1
1933.75
1
1928.91
1
1910.74
1
1905.49
1
1869.03
1
1837.99
1
1820.09
1
1806.02
1
1768.19
1
1726.17
1
1719.76
1
1682.45
1
1651.12
1
1615.9
1
1571.98
1
1529.59
1
1463.78
1
1426.97
1
1422.98
1
1379.69
1
1336.62
1
1324.51
1
1310.13
1
1288.63
1
1275.87
1
1260.23
1
1250.77
1
1250.04
1
1218.06
1
1206.2
1
1194.8
1
1197.15
1
1187.36
1
1189.48
1
1188.26
1
1172.11
1
1165.7
1
1172.87
1
1144.17
1
1147.09
1
1142.97
1
1144.71
1
1152.02
1
1141.8
1
1130.13
1
1134.49
1
1112.53
1
1102.93
1
1119.01
1
1114.99
1
1127.56
1
1116.24
1
1114.68
1
1115.82
1
1126.54
1
1105.33
1
1112.07
1
1123.2
1
1115.62
1
1102.12
1
1099.57
1
1098.32
1
1099.03
1
1111.54
1
1101.76
1
1087.1
1
1105.14
1
1099.8
1
1092.48
1
1106.65
1
1100.67
1
1089.12
1
1084.06
1
1090.69
1
1073.32
1
1077.38
1
1066.33
1
1062.08
1
1062.54
1
1070.22
1
1080.35
1
1062.94
1
1041.95
1
1044.98
1
1039.84
1
1058.39
1
1034.44
1
1041.55
1
1035.14
1
1029.66
1
1033.41
1
1026.4
1
1029.16
1
1023.73
1
1024.47
1
1016.57
1
1009.26
1
1022.87
1
1029.28
1
1011.82
1
1015.67
1
1011.27
1
1009.61
1
1014.57
1
1014.92
1
1012.28
1
1002
1
1016.98
1
1014.8
1
1007.84
1
1002.26
1
1004.54
1
1018.41
1
1002.44
1
994.94
1
999.388
1
1017.16
1
999.341
1
1001.83
1
1005.56
1
1004.65
1
1000.93
1
991.912
1
979.865
1
985.128
1
992.411
1
982.657
1
979.025
1
977.279
1
970.328
1
963.504
1
963.691
1
972.368
1
978.404
1
967.248
1
959.555
1
974.27
1
970.972
1
956.026
1
948.589
1
959.419
1
955.681
1
961.695
1
966.944
1
955.549
1
956.384
1
945.082
1
946.793
1
938.427
1
954.227
1
941.446
1
945.397
1
938.483
1
927.654
1
919.285
1
925.872
1
919.757
1
928.298
1
934.552
1
934.637
1
929.24
1
931.049
1
934.51
1
912.673
1
932.236
1
930.432
1
921.434
1
913.014
1
917.637
1
914.497
1
930.409
1
914.45
1
921.121
1
916.844
1
913.034
1
918.97
1
910.936
1
923.565
1
908.762
1
910.664
1
918.98
1
922.909
1
925.014
1
927.011
1
913.975
1
907.785
1
915.953
1
923.341
1
909.059
1
909.584
1
910.44
1
912.214
1
919.64
1
934.855
1
925.394
1
915.058
1
919.619
1
921.508
1
923.018
1
927.242
1
917.056
1
916.812
1
924.435
1
925.261
1
928.2
1
932.729
1
941.634
1
940.97
1
933.522
1
923.866
1
932.265
1
931.072
1
939.554
1
930.523
1
930.699
1
937.96
1
943.823
1
944.617
1
941.64
1
937.598
1
943.283
1
945.979
1
943.162
1
954.204
1
943.863
1
954.782
1
955.293
1
948.699
1
945.933
1
951.834
1
945.544
1
939.918
1
948.565
1
950.391
1
965.006
1
953.385
1
952.308
1
961.048
1
954.759
1
960.627
1
970.886
1
958.535
1
961.16
1
957.771
1
970.402
1
964.418
1
960.138
1
988.215
1
975.569
1
960.269
1
967.542
1
967.158
1
960.022
1
981.135
1
981.227
1
962.688
1
971.552
1
990.269
1
993.502
1
986.246
1
979.084
1
974.118
1
993.933
1
1000.8
1
983.012
1
994.972
1
974.657
1
978.773
1
991.763
1
981.033
1
977.451
1
991.752
1
994.873
1
1002.33
1
990.923
1
997.405
1
998.32
1
1006.77
1
1009.52
1
1013.8
1
1003.03
1
1004.72
1
1010.4
1
1001.37
1
997.397
1
1007.62
1
1011.12
1
1011.27
1
1003.32
1
1008.97
1
1015.94
1
1013.07
1
1023.94
1
1012.23
1
1010.51
1
1016.75
1
1023.8
1
1023.49
1
1019.16
1
1027.58
1
1017.52
1
1014.72
1
1016.94
1
1008.64
1
1025.66
1
1026.76
1
1027.12
1
1015.99
1
1008.06
1
1019.08
1
1015.39
1
1018.99
1
1035.81
1
1038.86
1
1040.78
1
1023.45
1
1023.63
1
1028.81
1
1017.57
1
1038.12
1
1036.83
1
1041.31
1
1042.21
1
1026.59
1
1022.7
1
1041.58
1
1030.98
1
1020.88
1
1040.14
1
1048.28
1
1030.99
1
1033.39
1
1040.33
1
1042.98
1
1054.05
1
1040.76
1
1048.49
1
1022.74
1
1025.84
1
1039.23
1
1035.64
1
1040.81
1
1036.95
1
1035.24
1
1034.43
1
1039.27
1
1030.27
1
1031.04
1
1033.66
1
1032.48
1
1041.62
1
1037.05
1
1051.81
1
1049.03
1
1045.34
1
1050.93
1
1052.63
1
1025.83
1
1044.79
1
1041.21
1
1042.44
1
1038.83
1
1045.03
1
1041.51
1
1051.38
1
1048.92
1
1052.96
1
1051.2
1
1038.53
1
1040.8
1
1054.18
1
1039.92
1
1045.32
1
1055.25
1
1040.9
1
1044.98
1
1042.32
1
1045.96
1
1033.7
1
1050.84
1
1048.04
1
1045.33
1
1035.02
1
1058.01
1
1060.71
1
1056.67
1
1047.53
1
1052.05
1
1052.2
1
1057.68
1
1049.71
1
1048.92
1
1056.05
1
1039.29
1
1063.28
1
1062.93
1
1054.84
1
1060.05
1
1045.18
1
1056.2
1
1080.66
1
1061.19
1
1060.65
1
1066.86
1
1051.38
1
1064.39
1
1069.32
1
1072.14
1
1075.49
1
1070.07
1
1080
1
1076.51
1
1086.13
1
1077.88
1
1084.61
1
1070.92
1
1074.32
1
1080.67
1
1077.08
1
1081.57
1
1088.27
1
1090.86
1
1095.86
1
1086.43
1
1091.09
1
1079.32
1
1082.11
1
1093.73
1
1103.53
1
1098.23
1
1109.11
1
1103.71
1
1102.22
1
1105.16
1
1109.19
1
1104.21
1
1106.34
1
1105.8
1
1094.67
1
1109.73
1
1123.61
1
1114.88
1
1105.07
1
1107.03
1
1129.18
1
1137.34
1
1131.76
1
1132.34
1
1139.04
1
1138.43
1
1131.73
1
1133.14
1
1152.37
1
1141.58
1
1157.26
1
1148.6
1
1159.46
1
1180.33
1
1180.05
1
1178.86
1
1181.53
1
1190.77
1
1187.16
1
1196.91
1
1201.42
1
1206.11
1
1215.63
1
1209.97
1
1217.04
1
1229.06
1
1230.71
1
1244.64
1
1252.19
1
1266.94
1
1272.12
1
1260.09
1
1259.46
1
1281.63
1
1291.4
1
1293.37
1
1303.3
1
1295.71
1
1320.9
1
1309.9
1
1316.78
1
1323.91
1
1348.66
1
1353.61
1
1359.37
1
1369.58
1
1378.61
1
1371.39
1
1381.32
1
1389.05
1
1399.62
1
1406.27
1
1406.72
1
1399.17
1
1426.73
1
1424.8
1
1448.17
1
1456
1
1465.22
1
1457.77
1
1462.34
1
1487.76
1
1500.13
1
1510.32
1
1509.88
1
1528.65
1
1553.7
1
1550.71
1
1550.56
1
1572.71
1
1587.86
1
1597.52
1
1624.9
1
1608.86
1
1622.64
1
1660.36
1
1671.42
1
1694.73
1
1738.22
1
1728.39
1
1741.78
1
1761.19
1
1782.25
1
1797.59
1
1826.48
1
1865.22
1
1882.16
1
1898.18
1
1918.66
1
1941.49
1
1975.39
1
2007.45
1
2028.5
1
2049.87
1
2066.86
1
2108.56
1
2159.33
1
2149.79
1
2206.4
1
2234.44
1
2253.55
1
2298.42
1
2341.53
1
2368.34
1
2387.15
1
2436.61
1
2462.48
1
2471.49
1
2500.52
1
2523.84
1
2557.32
1
2585.42
1
2559.09
1
2577.79
1
2605.04
1
2603.91
1
2600
1
2618.01
1
2599.89
1
2561.97
1
2549.71
1
2542.1
1
2508.34
1
2506.75
1
2480.92
1
2447.59
1
2397.78
1
2378.3
1
2348.97
1
2306.69
1
2252.97
1
2223.31
1
2181.96
1
2139.57
1
2102.35
1
2069.4
1
2036.98
1
1982.55
1
1950.56
1
1900.52
1
1854.31
1
1814.31
1
1781.17
1
1758.77
1
1722.21
1
1656.26
1
1604.01
1
1553.56
1
1515.2
1
1463.79
1
1396.7
1
1347.78
1
1284.06
1
1228.76
1
1178.25
1
1112.57
1
1055.94
1
999.328
1
946.701
1
898.101
1
852.352
1
817.286
1
790.446
1
762.028
1
729.467
1
710.709
1
691.222
1
662.927
1
657.163
1
659.52
1
633.558
1
620.657
1
608.151
1
615.575
1
600.193
1
583.58
1
578.848
1
573.072
1
568.931
1
547.742
1
545.557
1
551.515
1
541.729
1
529.967
1
526.843
1
519.711
1
515.581
1
515.406
1
507.036
1
506.607
1
501.278
1
501.052
1
500.958
1
487.25
1
494.196
1
494.728
1
490.08
1
492.067
1
497.708
1
486.664
1
476.664
1
492.234
1
478.305
1
481.379
1
481.793
1
477.812
1
482.264
1
481.966
1
472.184
1
474.246
1
471.404
1
478.376
1
477.404
1
483.154
1
492.513
1
479.769
1
486.975
1
478.334
1
480.94
1
469.67
1
473.645
1
480.502
1
480.367
1
467.232
1
478.512
1
485.738
1
488.947
1
486.938
1
479.459
1
487.088
1
477.312
1
473.748
1
473.759
1
484.465
1
493.059
1
496.375
1
491.781
1
498.19
1
504.439
1
494.887
1
504.26
1
493.987
1
504.661
1
499.737
1
517.897
1
O1s
Co metal
2021
4
27
18
43
3
0
17
Casa Info Follows
0
0
0
0
File = E:/OwnCloud/XPS lab/EX491_S745_Co.sle
Group = RT in vacuum, #Treatments:4h sputter, #Temp:RT , #Pressure:vacuum , #Atmosphere:{:}, #Comments:
First of group = 0
Spectrum ID = 17
Analyzer lens = AngleResolvedMode22:1.5kV
Analyzer slit = 4:7x20c\C:mesh
Scan mode = FixedAnalyzerTransmission
Kinetic energy start = 926.61
PCA Coefs = 3893.53, 1858.99, -3657.86, -17.8739, 208.516, -19.2583, 6.26844,
C:\Users\Mark\Downloads\EX491_S745_Co (1).vms
c:\users\pielsticker\lukas\mpi-cec\projects\deepxps\xpsdeeplearning\data\references\nicofe\ex491-495 fe, ni, co oxide references.vms
CasaXP1
XPS
1
Al
1486.61
0
0
0
54.5
180
FAT
20
1
4.1408
0
0
0
0
0
O
1s
-1
kinetic energy
eV
926.61
0.1
2
counts
d
Transmission
d
pulse counting
0.1
2
0
0
0
0
2
ESCAPE DEPTH TYPE
d
1
MFP Exponent
d
0
1002
208.107
375.515
1
1
249.835
1
248.774
1
250.052
1
248.861
1
246.135
1
246.397
1
244.911
1
245.919
1
246.072
1
243.053
1
248.117
1
249.367
1
242.761
1
248.729
1
248.82
1
244.94
1
242.52
1
239.378
1
244.853
1
249.178
1
242.68
1
242.083
1
246.078
1
241.731
1
243.484
1
243.262
1
245.645
1
245.781
1
246.831
1
243.301
1
242.959
1
239.097
1
244.563
1
243.862
1
247.239
1
247.384
1
245.103
1
245.56
1
245.829
1
246.514
1
249.707
1
242.64
1
238.411
1
246.881
1
247.34
1
246.291
1
248.114
1
245.704
1
248.724
1
252.39
1
250.569
1
243.416
1
241.87
1
245.972
1
244.638
1
248.297
1
245.517
1
247.445
1
247.905
1
248.318
1
248.67
1
252.101
1
248.424
1
250.557
1
246.01
1
248.95
1
247.573
1
246.839
1
246.032
1
250.958
1
251.305
1
254.589
1
249.114
1
253.757
1
250.753
1
244.888
1
244.231
1
250.146
1
240.211
1
248.42
1
246.5
1
244.59
1
249.537
1
256.371
1
251.225
1
249.588
1
254.165
1
251.076
1
250.552
1
249.823
1
245.463
1
245.047
1
245.51
1
247.346
1
250.924
1
247.514
1
248.667
1
249.348
1
252.979
1
249.296
1
245.278
1
248.823
1
247.644
1
249.238
1
247.622
1
249.794
1
248.699
1
247.007
1
249.837
1
242.937
1
249.085
1
250.306
1
251.724
1
250.69
1
249.494
1
250.01
1
250.229
1
246.641
1
245.103
1
250.331
1
250.946
1
250.403
1
250.876
1
248.319
1
245.939
1
252.308
1
249.613
1
247.351
1
245.24
1
246.318
1
247.913
1
244.072
1
249.124
1
251.424
1
244.707
1
240.872
1
245.223
1
250.696
1
245.634
1
252.755
1
247.227
1
248.946
1
250.396
1
250.086
1
248.173
1
248.437
1
253.357
1
246.688
1
249.224
1
254.833
1
252.089
1
251.577
1
253.772
1
251.194
1
248.673
1
250.045
1
246.495
1
244.946
1
249.729
1
250.535
1
251.075
1
255.239
1
250.158
1
251.454
1
248.859
1
248.589
1
251.524
1
247.166
1
243.981
1
248.084
1
246.396
1
248.705
1
247.234
1
249.567
1
250.671
1
250.065
1
251.043
1
249.845
1
247.157
1
243.886
1
252.093
1
251.152
1
245.877
1
252.16
1
247.902
1
247.402
1
250.764
1
251.337
1
245.798
1
246.18
1
248.952
1
252.206
1
250.841
1
251.903
1
244.64
1
253.634
1
248.401
1
248.398
1
250.413
1
247.192
1
249.473
1
250.738
1
248.907
1
254.785
1
251.848
1
245.812
1
251.362
1
251.806
1
249.268
1
248.548
1
249.167
1
255.803
1
253.159
1
247.923
1
248.98
1
254.241
1
250.475
1
245.422
1
246.303
1
246.845
1
249.49
1
258.354
1
252.091
1
247.249
1
248.355
1
249.815
1
250.743
1
246.274
1
249.439
1
247.958
1
244.221
1
248.154
1
248.745
1
252.994
1
250.938
1
248.76
1
249.124
1
247.908
1
248.039
1
248.553
1
256.004
1
250.9
1
254.738
1
249.443
1
247.138
1
251.775
1
252.193
1
253.789
1
246.243
1
251.472
1
248.553
1
254.187
1
250.154
1
251.778
1
248.937
1
252.924
1
252.704
1
249.474
1
256.947
1
257.676
1
255.725
1
253.5
1
256.552
1
254.515
1
254.467
1
256.564
1
257.577
1
259.567
1
262.929
1
256.942
1
263.125
1
261.777
1
267.64
1
269.76
1
272.988
1
275.101
1
281.216
1
282.603
1
282.327
1
291.697
1
288.381
1
294.125
1
302.064
1
305.329
1
296.764
1
303.692
1
308.113
1
300.982
1
304.83
1
310.129
1
314.928
1
313.727
1
316.98
1
321.934
1
322.831
1
323.855
1
335.238
1
343.497
1
350.942
1
356.707
1
358.338
1
357.863
1
355.617
1
350.633
1
337.718
1
315.769
1
307.128
1
291.222
1
280.324
1
268.211
1
257.41
1
253.041
1
255.305
1
247.233
1
242.942
1
242.682
1
243.535
1
245.77
1
243.271
1
236.591
1
241.803
1
243.018
1
241.961
1
244.739
1
238.96
1
244.058
1
244.031
1
244.047
1
245.941
1
248.533
1
247.711
1
243.019
1
242.294
1
243.78
1
240.328
1
243.026
1
241.994
1
243.482
1
245.924
1
244.508
1
243.672
1
243.503
1
242.351
1
246.233
1
244.303
1
242.043
1
240.786
1
239.249
1
244.636
1
244.928
1
242.055
1
240.046
1
241.117
1
243.901
1
243.222
1
248.535
1
251.155
1
247.582
1
244.203
1
244.651
1
242.669
1
244.12
1
242.867
1
239.501
1
246.353
1
241.68
1
248.405
1
243.171
1
243.277
1
246.019
1
247.194
1
245.683
1
245.848
1
243.801
1
245.98
1
244.238
1
248.143
1
243.572
1
240.673
1
241.441
1
246.28
1
247.422
1
243.751
1
242.698
1
247.999
1
243.183
1
244.002
1
247.815
1
248.169
1
241.331
1
242.29
1
245.062
1
247.215
1
249.056
1
249.411
1
243.351
1
247.357
1
242.561
1
242.475
1
241.185
1
244.573
1
245.824
1
244.105
1
241.852
1
244.811
1
253.521
1
248.085
1
241.776
1
240.743
1
245.099
1
245.588
1
247.469
1
243.068
1
243.65
1
246.706
1
247.424
1
245.666
1
247.153
1
245.972
1
243.209
1
247.317
1
246.742
1
247.389
1
241.361
1
242.821
1
245.997
1
249.289
1
246.975
1
245.353
1
242.289
1
248.064
1
245.074
1
242.548
1
247.25
1
243.493
1
240.772
1
246.033
1
246.198
1
246.665
1
246.19
1
246.811
1
246.21
1
237.647
1
243.111
1
250.706
1
247.527
1
243.081
1
248.561
1
244.799
1
245.79
1
244.725
1
245.539
1
247.585
1
248.312
1
247.142
1
248.469
1
244.202
1
243.367
1
243.47
1
245.321
1
244.9
1
245.745
1
245.597
1
248.51
1
247.13
1
248.155
1
249.444
1
249.266
1
246.577
1
247.073
1
245.739
1
249.272
1
250.871
1
248.562
1
243.525
1
243.551
1
244.413
1
243.339
1
245.97
1
244.089
1
246.523
1
243.961
1
245.169
1
248.998
1
245.762
1
246.237
1
250.984
1
247.96
1
244.164
1
244.792
1
245.776
1
250.354
1
249.962
1
250.028
1
249.052
1
248.671
1
252.994
1
246.871
1
254.003
1
252.092
1
248.417
1
Survey
CoO
2021
4
29
9
42
10
0
17
Casa Info Follows
0
0
0
0
File = E:/OwnCloud/XPS lab/EX491_S745_Co.sle
Group = Loop 11_ RT in vacuum, #Treatments: , #Temp:RT , #Pressure:vacuum , #Atmosphere: , #Comments:
First of group = 1
Spectrum ID = 59
Analyzer lens = LargeArea:1.5kV
Analyzer slit = 4:7x20c\C:mesh
Scan mode = FixedAnalyzerTransmission
Kinetic energy start = 286.61
PCA Coefs = 132265, 6885.64, -7079.42, 2674.3, 605.159, -187.616,
C:\Users\Mark\Downloads\EX491_S745_Co (1).vms
c:\users\pielsticker\lukas\mpi-cec\projects\deepxps\xpsdeeplearning\data\references\nicofe\ex491-495 fe, ni, co oxide references.vms
CasaXP1
XPS
8
Al
1486.61
0
0
0
54.5
180
FAT
100
1
4.1408
0
0
0
0
0
Survey

-1
kinetic energy
eV
286.61
1
2
counts
d
Transmission
d
pulse counting
0.1
1
0
0
0
0
2
ESCAPE DEPTH TYPE
d
1
MFP Exponent
d
0
41.074
1
3306.37
3323.28
3318.23
3337.25
3318.74
3306.32
3354.64
3365.58
3364.12
3382.52
3408.28
3422.08
3433.42
3395.64
3426.36
3470.75
3467.78
3453.94
3457.74
3451.1
3472.81
3499.1
3529
3503.99
3538.85
3548.53
3570.8
3613.85
3581.6
3594.41
3602.63
3601.63
3647.43
3642.65
3630.14
3673.3
3693.61
3712.25
3711.32
3727.17
3725.9
3731.28
3755.98
3751.18
3788.75
3800.98
3775.52
3800.84
3787.42
3806.17
3839.91
3874.21
3884.59
3870.39
3864.41
3879.29
3904.79
3901.88
3906.69
3933.61
3908.01
3943.48
3945
3976.09
3986.88
4038.7
4009.74
4024.93
4008.45
4021.42
4036.14
4091.24
4095.44
4091.26
4130.48
4147.29
4097.29
4120.51
4165.45
4158.4
4183.26
4173.19
4192
4223.11
4228.46
4248.12
4279.75
4236.34
4245.74
4262.7
4299.67
4334.71
4361.67
4327.89
4368
4355.42
4371.14
4393.4
4434.33
4425.56
4445.27
4455.5
4500.16
4485
4471.5
4505.06
4509.95
4531.33
4550.62
4546.73
4555.32
4564.1
4546.71
4561.08
4629.94
4676.55
4687.16
4663.97
4670.45
4654.18
4682.46
4705.25
4723.02
4735.99
4758.86
4770.15
4788.01
4816.94
4840.63
4844.34
4839.34
4839.15
4880.2
4882.51
4874.23
4877.38
4915.27
4953.04
4979.28
4982.97
5010.03
5016.23
5017.74
4999.77
5016.79
5042.37
5085.45
5081.61
5138.59
5104.11
5096.34
5127.76
5179.29
5181.98
5141.18
5194.54
5233.71
5240.32
5269.47
5217.16
5288.04
5312.26
5322.48
5323.09
5293.88
5307.76
5349.3
5399.31
5415.84
5431.79
5433.54
5414.24
5449.61
5421.96
5499.67
5509.87
5542.52
5538.1
5579.06
5602.84
5632.35
5650.69
5663.34
5664.63
5719.64
5756.23
5747.63
5762.26
5766.71
5805.01
5825.11
5865.03
5832.28
5859.94
5849.32
5854.65
5827.53
5899.75
5899.23
5914.55
5974.59
6060.48
6179.46
6229.59
6317.87
6368.01
6317.32
6226.84
6132.76
6117.56
6112.6
6154.8
6173.45
6152.36
6148.16
6140.34
6166.16
6162.87
6203.65
6229.88
6362.2
6514.76
6787.72
7096.87
7324.18
7326.89
7104.87
6868.5
6711.92
6614.2
6585.52
6500.24
6412.21
6355.6
6361.97
6268.9
6263.64
6250.28
6219.01
6168
6159.31
6198.51
6228.38
6201.52
6270.89
6263.82
6282.87
6306.4
6315.68
6318.1
6343.91
6373.12
6383.33
6389.57
6403.26
6436.72
6407.65
6488.72
6525.85
6617.11
6649.47
6778.65
6831.89
6929.89
7003.49
7061.7
7199
7333.41
7390.98
7388.3
7441.18
7522.38
7583.3
7518.94
7378.74
7220.97
7019.2
6866.31
6796.01
6646.31
6571.74
6509.31
6462.74
6437.39
6430.4
6414.02
6476.33
6452.19
6448.81
6401.47
6445.04
6486.36
6477.13
6466.77
6466.88
6537.18
6512.18
6587.55
6570.62
6554.31
6539.41
6621.64
6646.44
6646.49
6681.44
6701.76
6713.43
6760.64
6866.55
6858.31
6876.56
6918.48
6959.16
6966.97
7008.83
7029.64
7031.32
7046.58
7071.2
7059.25
7030.74
7067.64
7054.52
7102.74
7113.36
7153.44
7177.53
7301.19
7354.97
7345.59
7320.25
7321.19
7285.04
7234.15
7211.48
7180.94
7185.25
7195.01
7247.92
7244.65
7259.9
7305.96
7353.38
7376.32
7455.81
7494.08
7513.51
7615.83
7668.58
7786.38
7901.53
8029.16
8057.4
8105.77
8115.73
8145.43
8179.21
8319.58
8450.54
8443.62
8437.49
8492.42
8480.44
8464.23
8435.79
8512.1
8523.56
8442.97
8267.54
8016.72
7730.95
7534.09
7349.58
7275.83
7236.31
7216.88
7224.54
7230.73
7275.58
7269
7233.17
7221.94
7215.18
7100.37
7065.66
6943.42
6801.12
6707.81
6630.57
6603.67
6634.17
6730.37
7033.05
7333.23
7789.03
8499.03
9165.52
9343.93
8942.45
8394.03
8380.41
9005.55
9974.78
10451.4
9918.12
8568.28
7345.01
6963.06
7216.95
7661.26
8275.72
9158.84
9954.45
10397.4
10366.2
10282.7
10900.8
12261.2
13709.1
14295.5
12576.8
9136.15
6303.8
5267.22
4912.56
4707.54
4540.57
4396.63
4240.93
4036.59
3697.94
3332.2
3034.43
2850.1
2708.96
2614.71
2554.41
2506.06
2449.66
2420.08
2339.79
2330.24
2311.06
2264.21
2190.43
2169.42
2135.73
2097.57
2077.6
2050.64
2062.49
2078.81
2090.81
2098.42
2105.08
2107.71
2131.57
2133.07
2145.05
2169.24
2186.44
2186.16
2226.95
2241.06
2240.74
2273.89
2249
2270.7
2279.84
2264.01
2244.13
2237.99
2263.58
2293.27
2371.92
2472.63
2605.8
2774.91
3044.11
3330.12
3562.83
3709.58
3786.9
3821.51
3895.47
3971.1
4017.57
3964.45
3794.2
3469.39
2991.52
2448.26
2039.66
1773.57
1664.79
1648.73
1647.84
1627.2
1648.36
1664.07
1671.99
1663.31
1616.14
1537.46
1406.38
1238.94
1096.64
1008.1
975.627
974.73
961.504
973.061
962.471
939.61
964.199
996.271
971.697
967.167
954.501
934.827
947.427
953.762
977.667
952.12
948.64
948.898
967.36
965.17
963.709
970.437
966.896
971.883
949.874
961.397
981.997
969.172
978.68
964.671
959.871
969.566
957.973
972.071
969.151
963.844
979.67
987.598
994.338
991.706
999.479
980.148
992.315
989.474
1004.73
1022.28
1002.53
997.818
1007.8
1013.77
1022.09
1022.34
1035.43
1008.58
1015.23
1025.71
1028.51
1023.78
1027.42
1031.69
1057.18
1044.01
1038.08
1035.75
1017.89
1034.76
1039.76
1038.77
1049.43
1069.52
1055.91
1054.9
1049.96
1060.66
1070.74
1077.39
1067.74
1076.21
1084.78
1083.2
1094.99
1091.85
1089.23
1084.07
1074.86
1074.23
1090.47
1095.39
1091.63
1105.38
1115.74
1107.61
1145.99
1132.08
1145.67
1144.95
1152.75
1168.05
1160.7
1165.63
1164.15
1157.49
1147.03
1142.41
1130.02
1124.42
1142.17
1154.15
1153.88
1154.58
1185.48
1185.93
1174.56
1175.07
1208.3
1214.99
1214.88
1254.53
1240.92
1224.78
1235.24
1240.18
1246.88
1243.59
1251.65
1228.19
1228.81
1230.94
1211.29
1201.04
1198.04
1177.64
1175.44
1179.51
1209.09
1234.38
1305.04
1384.91
1482.05
1524.04
1480.43
1424.48
1394.85
1327.87
1268.03
1205.24
1157.99
1111.87
1053.32
1003.07
980.141
959.883
949.171
927.652
917.752
918.968
903.394
896.481
1063.68
1607.07
3339.04
6921.87
7230.61
3574.49
1079.25
693.539
604.139
568.531
552.539
526.022
536.811
531.239
527.594
519.698
524.157
525.082
510.989
526.181
520.924
515.212
516.692
523.411
534.474
536.014
525.553
525.202
526.129
535.964
537.293
542.309
531.463
542.164
535.161
541.589
546.602
539.808
532.336
528.41
529.786
538.986
546.05
537.545
540.14
542.439
542.796
542.612
558.8
552.029
543.827
540.691
556.023
553.905
545.438
549.242
557.483
553.532
555.784
556.82
547.512
548.487
553.848
545.998
565.129
567.276
564.663
571.73
568.494
555.54
543.655
568.966
563.502
562.122
565.001
563.778
568.975
568.994
571.245
[...]
1749.39
1756.69
1765.33
1779.84
1789.39
1786.18
1787.57
1807.55
1810.19
1821.89
1821.53
1824.4
1833.59
1837.07
1852.37
1860.42
1877.03
1874.3
1890.69
1895.18
1912.07
1908.45
1933.75
1941.73
1948.68
1962.16
1971.02
1978.55
1994.03
2002.67
2018.19
2009.62
2023.08
2044.89
2061.64
2075.04
2084.14
2083.85
2109.94
2116.99
2121.2
2137.78
2141.83
2146.63
2148.01
2177.93
2180.49
2182.25
2182.32
2184.67
2199.86
2190.85
2187.8
2184.97
2196.26
2188.83
2195.17
2189.51
2182.64
2166.87
2154.54
2166.62
2154.2
2160.81
2158.1
2130.14
2139.63
2131.66
2118.2
2115.3
2125.08
2115.04
2127.39
2115.72
2122.45
2123.03
2130.42
2138.69
2131.39
2118.4
2146.57
2175.32
2163.8
2175.79
2201.82
2211.18
2228.11
2252.59
2270.52
2279.07
2289.39
2305.82
2324.76
2362.53
2394.62
2415.62
2446.84
2482.01
2500.14
2535.44
2571.05
2609.87
2635.17
2667.93
2694.47
2715.66
2752.52
2773.03
2777.59
2807.2
2812.23
2824.57
2838.73
2844.75
2855.52
2859.02
2849.21
2854.46
2859.15
2846.97
2815.65
2765.69
2765.28
2739.36
2672.91
2643.33
2607.17
2561.39
2513.14
2474.21
2415.56
2357.21
2321.62
2270.57
2225.16
2176.55
2128.87
2094.82
2055.28
2021.11
1986.55
1966.49
1928.68
1899.1
1868.23
1843.66
1824.49
1819.4
1810.54
1802.48
1785.98
1775.12
1763.73
1766.18
1771.51
1756.09
1752.31
1753.64
1769.09
1757.22
1779.34
1790.22
1799.55
1812.76
1822.89
1840.08
1842.39
1879.96
1875.46
1891.11
1900.42
1935.82
1958.55
1969.19
1990.99
2005.49
2030.16
2048.06
2064.68
2067.25
2088.58
2100.89
2103.09
2122.37
2148.61
2141.87
2149.17
2164.73
2187.88
2195.34
2202.42
2208.44
2206.69
2205.81
2197.56
2187.08
2171.86
2188.84
2201.76
2192.54
2194.45
2193.23
2185.65
2174.09
2203.6
2209.32
2189.01
2205.9
2232.67
2224.04
2245.74
2275.59
2287.58
2319.56
2331.77
2360.42
2384.89
2418.7
2440.23
2458.25
2488.62
2536.13
2569.64
2612.34
2638.47
2678.03
2727.64
2787.31
2832.45
2866.97
2918.09
2948.79
2999.47
3055.04
3107.2
3137.53
3178.65
3248.16
3292.74
3338.93
3374.94
3388.89
3419.54
3459.03
3478.53
3532.77
3522.96
3562.28
3572.27
3558.95
3555.83
3539.79
3511.69
3475.79
3429.34
3380.56
3317.22
3223.07
3155.72
3045.33
2924.12
2798.15
2652.45
2513.77
2368.78
2214.52
2054.87
1906.21
1756.76
1613.02
1470.26
1345.57
1232.83
1126.36
1036.4
944.118
877.087
821.856
762.698
716.833
675.22
628.14
600.985
570.444
541.384
515.211
490.36
475.713
460.418
442.576
430.969
418.866
415.661
416.601
407.162
400.685
407.481
403.036
399.305
401.174
386.689
384.717
384.545
379.791
381.777
378.817
374.528
367.916
371.28
358.662
365.432
367.86
369.124
368.085
366.386
365.843
366.105
367.461
359.833
365.078
363.447
360.205
359.727
358.089
358.141
358.14
360.705
360.42
361.312
363.402
360.842
360.669
357.389
355.096
349.345
351.358
352.01
349.864
355.431
353.353
354.349
352.985
351.566
350.279
351.204
356.315
350.286
354.557
353.363
346.834
349.931
353.172
350.449
348.236
348.862
343.003
348.676
350.78
351.57
347.465
348.998
344.177
351.457
350.828
350.389
346.455
345.756
352.924
346.88
350.979
350.052
347.004
349.122
352.972
352.089
353.065
346.295
346.292
345.477
348.387
349.083
347.056
345.991
343.445
345.497
344.361
345.089
346.342
343.786
349.073
344.514
343.534
341.605
349.103
343.036
342.581
348.267
345.268
341.003
340.534
341.789
340.894
346.61
346.996
340.832
348.942
348.909
347.021
341.52
347.117
347.995
343.427
346.951
344.877
348.466
343.791
337.325
341.776
343.258
343.076
343.219
347.84
346.287
350.62
343.175
341.74
342.452
347.669
349.142
346.33
349.548
350.936
348.628
350.972
343.981
344.487
346.995
344.392
347.442
347.773
343.092
340.181
343.213
347.637
348.914
348.792
345.858
344.533
347.382
350.152
344.032
349.43
344.313
344.871
343.466
347.236
345.057
346.172
347.084
342.588
348.865
342.51
341.268
351.25
343.864
339.854
344.165
346.798
349.616
344.353
353.566
351.017
347.824
344.558
346.339
349.401
349.957
346.848
342.196
351.832
350.391
345.56
341.915
347.743
345.931
345.077
344.545
342.416
342.244
346.184
347.379
347.738
342.447
348.608
346.802
343.308
342.234
345.434
3.06292
Fe2p
Fe3O4 fit min limits
2021
5
11
5
29
55
0
21
Casa Info Follows
0
0
1
CASA region (*Fe3O4*) (*Min Limits*) 736.61 791.61 16.42 2 0 0 1370.3777 -650 0 0 (*Fe 2p*) 55.8458 0 16.42
1
CASA comp (*Fe 2p*) (*&FE3O4*) Area 3.3390118 0 1575218 -1 1 MFWHM 1 1 1 -1 1 Position 755.91076 755.41 756.41 -1 1 RSF 16.42 MASS 55.8458 INDEX 2 (*fe3o4*) CONST (**) UNCORRECTEDRSF 16.42
File = E:/OwnCloud/XPS lab/EX495_S779_Fe2O3.sle
Group = Loop 5_450C in UHV, #Treatments: , #Temp:450C, #Pressure:UHV, #Atmosphere:, #Comments:
First of group = 0
Spectrum ID = 38
Analyzer lens = AngleResolvedMode22:1.5kV
Analyzer slit = 4:7x20c\C:mesh
Scan mode = FixedAnalyzerTransmission
Kinetic energy start = 716.61
PCA Coefs = 52201.2, -2129.68, -308.73, -185.423,
c:\users\mark\downloads\ex495_s779_fe2o3.vms
c:\users\pielsticker\lukas\mpi-cec\projects\deepxps\xpsdeeplearning\data\references\nicofe\ex491-495 fe, ni, co oxide references.vms
CasaXP1
CasaXP1
C:\Users\pielsticker\Lukas\MPI-CEC\Projects\deepxps\xpsdeeplearning\data\references\NiCoFe\EX491-495 Fe, Co oxide references.vms
XPS
30
Al
1486.61
0
0
0
54.5
180
FAT
20
1
4.1408
0
0
0
0
0
Fe
2p
-1
kinetic energy
eV
716.61
0.1
2
counts
d
Transmission
d
pulse counting
0.1
3
0
0
0
0
3
ESCAPE DEPTH TYPE
d
1
MFP Exponent
d
0
PROPAGATION_CONVERGED
d
1
366.288
3.06292
1736.39
1727.82
1731.83
1745.53
1732.04
1729.06
1723.43
1721.71
1723.72
1719.44
1720.81
1727.19
1712.07
1690.47
1695.44
1705.76
1697.88
1686.2
1688.07
1687.3
1687.76
1676.82
1679.85
1663.29
1664.23
1672.33
1662.6
1665
1659.28
1650.81
1647.98
1638.15
1640.05
1630.75
1630.99
1635.12
1628.07
1624.34
1623.34
1629.23
1608.08
1603.89
1621.43
1617.08
1607.13
1609.09
1606.16
1611.8
1617.73
1610.46
1598.74
1605.28
1595.42
1598.45
1603.23
1589.32
1589.33
1592.31
1606.33
1593.65
1588.88
1594.1
1588.42
1582.81
1590.99
1597.06
1581.52
1580.84
1578.83
1593.26
1591.45
1594.67
1588.6
1600.81
1601.23
1588.96
1594.18
1596.66
1599.01
1592.05
1601.71
1596.71
1603.96
1606.67
1598.55
1594.01
1614.38
1621.55
1610.06
1608.83
1605.8
1600.7
1608.32
1594.08
1608.65
1604.97
1606.24
1605.57
1609.1
1622.44
1628.28
1622.03
1619.37
1624.93
1624.24
1610.7
1612.76
1609.92
1607.31
1625.85
1626.33
1631.05
1633.16
1641.78
1639.6
1625.02
1627.44
1626.58
1619.86
1623.42
1637.27
1644.34
1622.2
1629.88
1639.1
1635.11
1635.04
1636.26
1637.61
1654.45
1653.17
1640.37
1643.04
1651.41
1644.94
1629.36
1648.34
1654.81
1652.63
1644.87
1644.36
1644.3
1663.8
1647.08
1644.33
1650.47
1665.07
1648.6
1648.74
1658.17
1668.35
1660.55
1656.37
1668.92
1659.01
1671.25
1677.25
1674.92
1677.45
1663.49
1657.55
1675.28
1669.41
1672.42
1680.44
1677.91
1678.95
1678.35
1676.29
1679.34
1683.66
1683.97
1694.71
1697.28
1694.99
1678.48
1692.87
1692.82
1687.79
1694.86
1683.4
1704.96
1704.08
1698.42
1695.71
1700.93
1700.14
1699.2
1696.98
1711.81
1701.85
1705.87
1715.91
1709.35
1720.21
1708.47
1718.83
1717.91
1718.57
1722.58
1702.22
1716.18
1726.58
1720.67
1729.19
1738.33
1723.03
1716.42
1722.9
1718.28
1734.37
1737.96
1740.51
1737.11
1736.7
1749.08
1752.16
1750.47
1757.06
1754.8
1742.23
1734.15
1743.45
1753.53
1758.13
1757.54
1760.34
1755.82
1752.31
1748.37
1766.76
1774.21
1757.57
1749
1768.84
1770.86
1773.57
1767.33
1768.78
1765.87
1772.84
1774.51
1778.44
1787.94
1790.96
1804.48
1799.58
1804.1
1808.84
1814.66
1811.89
1806.02
1812.27
1832.62
1821.68
1833.47
1826.92
1830.95
1834.54
1857.27
1854.81
1830.47
1844.73
1851.06
1852.28
1851.83
1863.18
1868.98
1859.22
1865.12
1844.02
1848.68
1863.42
1852.88
1842.67
1835.94
1848.2
1850.12
1855.43
1843.32
1839.51
1826.07
1811.4
1837.15
1834.8
1829.41
1829.12
1813.76
1817.6
1809.98
1807.2
1810.15
1805.84
1805.95
1818.01
1805.45
1794.53
1807.72
1806.4
1803.43
1816.48
1809.28
1804.4
1803.43
1815.58
1816.31
1818.02
1821.56
1806.77
1820.48
1820.61
1837.08
1818.07
1831.05
1837.4
1822.54
1828.57
1846.64
1840.81
1845.05
1828.81
1846.89
1861.18
1855.48
1873.57
1874.78
1874.03
1864.36
1866.97
1880.87
1892.58
1885.81
1890.7
1900.17
1907.86
1929.22
1930.35
1919.63
1947.04
1948.86
1937.76
1934.6
1951.19
1948.69
1968.75
1969.56
1964.13
1985.54
1984.51
1984.96
1997.17
1999.67
2007.86
2011.93
2014.24
2021.72
2024.51
2026.43
2037.28
2058.19
2054.08
2060.31
2073.97
2064.07
2074.75
2093.07
2085.9
2096.56
2086.08
2097.86
2105.34
2110.1
2115.47
2118.22
2138.69
2151.15
2133.1
2147.15
2148.05
2171.43
2164.83
2174.87
2163.99
2198.92
2190.87
2186.25
2203.36
2218.98
2223.17
2236.15
2237.39
2231.8
2248.38
2262.42
2267.15
2290.15
2291.3
2312.64
2303.36
2311.42
2311.27
2320.88
2317.73
2326.8
2334.93
2318.71
2330.52
2344.29
2335.08
2335.8
2346.79
2345.63
2341.22
2334.69
2355.04
2350.69
2347.32
2371.44
2359.73
2376.68
2390.85
2345.67
2356.01
2361.21
2378.45
2398.36
2384.63
2397.39
2398.37
2426.76
2432.53
2425.93
2457.87
2447.94
2465.22
2491.31
2500.07
2516.57
2511.47
2532.47
2539.73
2560.52
2576.36
2580.76
2595.7
2616.62
2627.9
2661.57
2680.42
2694.27
2713.4
2736.13
2733.77
2760.85
2780.84
2795.59
2814.26
2816.55
2821.25
2837.93
2863.05
2890.52
2900.83
2909.26
2917.57
2926.59
2932.06
2944.03
2939.79
2949.66
2946.59
2942.94
2923.21
2911.53
2885.93
2866.81
2854.24
2820.94
2800.4
2777.02
2748.84
2695.88
2667.19
2616.72
2571.27
2519
2451.61
2402.98
2365.25
2323.98
2276.48
2230.25
2205.53
2162.56
2132.4
2124.76
2107.89
2073.88
2073.51
2067.75
2052.88
2031.1
2040.86
2030.26
2021.25
2009.77
2002.57
2005.99
2006.45
1986.55
1993.54
1995.49
1989.43
1986.01
1984.63
1987.51
1992.86
2003.1
2007.38
2015.65
2000.52
2022.67
2040.14
2032.86
2035.39
2055.29
2057.58
2062.13
2066.39
2073.92
2090.02
2092.56
2107.2
2137.7
2119.49
2108.14
2124.89
2138.28
2138.56
2152.76
2166.99
2154.35
2167.08
2177.97
2174.5
2185.78
2191.02
2202.96
2196.08
2205.06
2227.23
2221.78
2232.19
2246.28
2269.67
2273
2282.89
2307.07
2313.95
2333.42
2346.85
2368.28
2414.63
2435.01
2442.1
2480.19
2488.3
2514.29
2544.6
2557.16
2586.31
2608.22
2647.61
2695.36
2726.4
2737.5
2739.19
2766.26
2808.27
2838.7
2861.16
2898.36
2930.03
2961.27
2997.08
3012.6
3039.22
3083.48
3107.17
3146.91
3157.95
3192.81
3196.35
3193.11
3210.76
3227.45
3235.32
3247.21
3246.87
3255.17
3223.02
3224.91
3182.21
3137.43
3112.64
3071.14
3031.65
2978.96
2943.69
2896.22
2844.69
2777.1
2713.58
2645.85
2553.09
2468.06
2355.51
2219.83
2095.33
1955.93
1794
1641.7
1484.85
1330.55
1198.72
1070.82
972.317
892.735
821.899
765.278
721.661
683.617
653.115
623.621
602.007
577.727
556.767
527.627
524.016
512.172
499.757
479.916
476.552
472.501
471.441
459.161
456.073
451.65
448.678
448.416
444.248
443.1
441.114
443.688
438.284
440.855
427.191
431.788
435.191
433.793
432.207
423.429
419.385
422.658
423.308
425.922
432.27
431.684
419.03
414.605
415.821
423.536
417.965
419.496
413.006
408.906
415.213
413.344
411.912
414.834
418.029
411.651
413.075
408.144
415.99
415.447
409.435
407.176
411.884
410.287
412.342
412.296
409.839
408.364
408.152
402.611
408.529
409.082
408.751
414.041
407.335
402.278
409.075
410.76
410.286
413.106
403.058
412.746
410.473
411.306
411.94
412.773
406.319
408.314
409.231
405.576
408.697
408.12
411.287
411.949
409.883
407.075
401.015
405.822
408.227
404.523
409.083
407.498
413.467
412.487
402.661
406.34
405.213
410.503
404.974
408.91
408.344
405.94
413.533
413.163
410.037
407.078
404.472
406.783
404.445
405.313
400.348
408.056
408.097
410.621
407.28
398.471
407.752
408.776
409.363
409.831
407.274
414.308
405.601
403.92
401.605
407.282
405.727
407.873
412.059
410.051
403.674
409.343
407.893
412.668
407.247
404.05
403.416
408.094
409.351
404.165
399.062
408.025
407.655
406.024
412.281
408.713
412.69
403.946
405.835
405.683
407.719
411.182
405.12
408.051
403.538
402.662
402.274
408.32
406.549
403.94
408.116
409.919
405.209
406.03
404.523
401.05
406.677
407.207
412.522
405.694
405.866
403.864
402.096
404.356
413.973
407.85
407.429
404.614
402.135
406.705
405.326
408.634
405.368
411.558
409.363
402.211
403.64
413.939
410.873
404.111
403.691
408.729
405.446
404.514
408.004
408.01
411.233
410.711
411.137
410.078
404.296
406.204
405.953
408.494
406.055
407.726
408.31
410.045
410.756
405.904
405.796
408.376
411.627
410.583
413.12
3.06292
Fe2p
Fe2O3 fit min limits
2021
5
10
17
51
2
0
21
Casa Info Follows
0
0
1
CASA region (*Fe2O3*) (*Min Limits*) 736.61 791.61 16.42 2 0 0 1370.3777 -650 0 0 (*Fe 2p*) 55.8458 0 16.42
1
CASA comp (*Fe 2p*) (*&FE2O3*) Area 3.3330425 0 1575218 -1 1 MFWHM 1 1 1 -1 1 Position 754.70999 754.21 755.21 -1 1 RSF 16.42 MASS 55.8458 INDEX 2 (*fe203*) CONST (**) UNCORRECTEDRSF 16.42
File = E:/OwnCloud/XPS lab/EX495_S779_Fe2O3.sle
Group = Loop 3_RT in UHV, #Treatments: , #Temp:RT, #Pressure:UHV, #Atmosphere:, #Comments:
First of group = 0
Spectrum ID = 29
Analyzer lens = AngleResolvedMode22:1.5kV
Analyzer slit = 4:7x20c\C:mesh
Scan mode = FixedAnalyzerTransmission
Kinetic energy start = 716.61
PCA Coefs = 49819.3, 5040.47, -1408.81, -111.072,
c:\users\mark\downloads\ex495_s779_fe2o3.vms
c:\users\pielsticker\lukas\mpi-cec\projects\deepxps\xpsdeeplearning\data\references\nicofe\ex491-495 fe, ni, co oxide references.vms
CasaXP1
CasaXP1
C:\Users\pielsticker\Lukas\MPI-CEC\Projects\deepxps\xpsdeeplearning\data\references\NiCoFe\EX491-495 Fe, Co oxide references.vms
XPS
7
Al
1486.61
0
0
0
54.5
180
FAT
20
1
4.1408
0
0
0
0
0
Fe
2p
-1
kinetic energy
eV
716.61
0.1
2
counts
d
Transmission
d
pulse counting
0.1
3
0
0
0
0
3
ESCAPE DEPTH TYPE
d
1
MFP Exponent
d
0
PROPAGATION_CONVERGED
d
1
388.373
3.06292
1737.71
1733.82
1733.9
1718.16
1731.77
1731.68
1732.03
1744.47
1727.7
1704.8
1725.06
1723.75
1729.4
1704.23
1708.72
1726.78
1727.44
1686.72
1681.73
1702.95
1724.96
1708.2
1712.74
1689.58
1674.56
1672.17
1667.4
1676.69
1668.59
1660.87
1652.15
1657.53
1648.65
1648.11
1637.43
1644.41
1646.79
1624.03
1649.75
1631.74
1619.9
1626.21
1632.22
1623.57
1614.58
1614.89
1616.79
1611.48
1625.31
1616.59
1601.56
1606.63
1609.65
1613.4
1613.78
1608.89
1603.82
1630.35
1609.06
1607.5
1604.67
1596.86
1613.66
1618.09
1610.43
1594.92
1607.05
1608.91
1615.11
1614.36
1615.31
1601.33
1601.84
1594.42
1602.73
1616.79
1597.06
1587.04
1597.65
1597.46
1598.24
1606.51
1607.44
1617.52
1598.95
1596.27
1623.54
1620.61
1575.39
1605.47
1627.75
1630.03
1592.1
1598.67
1609.24
1603.48
1615.04
1602.8
1605.09
1615.36
1618.3
1626.84
1604.36
1624.21
1624.21
1616.31
1638.02
1618.61
1616.59
1606.15
1612.78
1636.95
1644.02
1643.93
1622.47
1605.23
1622.54
1611.56
1627.56
1646.43
1661.8
1638.31
1630.13
1627.83
1626.75
1627.76
1638.22
1637.55
1650.27
1645.19
1663.95
1639.49
1643.18
1648.88
1632.36
1638.28
1639.32
1641.98
1644.77
1633.43
1656.56
1648.07
1668.58
1647.41
1660.27
1675.5
1654.69
1650.73
1647.01
1660.92
1660.36
1647.57
1649.16
1665.48
1633.67
1645.97
1663.65
1643.56
1643.78
1662.98
1677.31
1669.65
1664.46
1650.67
1666.88
1665.49
1675.92
1663.58
1671.64
1670
1669.36
1666.72
1687.03
1680.31
1706.82
1690.5
1671.36
1685.79
1687.18
1673.73
1680.24
1696.58
1695.29
1673.24
1685.78
1690.88
1665.51
1696.74
1680.46
1675.97
1678.82
1711.02
1694.6
1700.11
1701.3
1689.67
1697.31
1711.86
1703.83
1694.53
1675.81
1677.95
1699.06
1694.13
1695.41
1711.37
1702.4
1696.37
1712.24
1697.19
1706.27
1706.4
1721.84
1731.47
1719.52
1717.28
1728.14
1725.38
1733.99
1733.31
1728.47
1715.24
1732.18
1742.68
1730.24
1736.55
1727.11
1749.63
1730.12
1724.04
1711.56
1711.71
1719.6
1728.93
1750.4
1749.22
1749.74
1746.21
1732.86
1722.11
1728.47
1743.86
1732.96
1732.12
1731.29
1751.01
1746.94
1748
1764.59
1760.11
1780.98
1781.66
1791.38
1782.72
1786.33
1780.5
1798.96
1796.19
1812.44
1823.96
1840.93
1842.09
1850.06
1861.13
1877
1858.97
1881.26
1878.13
1884.72
1883.83
1883.21
1897.68
1887.18
1892.14
1890.97
1894.25
1898.29
1888.69
1905.6
1916.96
1898.37
1898.04
1894
1891.59
1870.8
1873.97
1872.68
1875.96
1854.19
1875.01
1876.46
1840.97
1831.31
1852.63
1844.78
1839.06
1829.57
1828.12
1819.97
1808.58
1837.58
1845.23
1832.02
1827.12
1842.32
1807.27
1808.3
1833.69
1818.57
1813.36
1787.62
1803.45
1822.4
1811.92
1837.14
1813.79
1829.18
1861.62
1833.45
1832.7
1828.29
1846.04
1855.15
1859.99
1881
1876.95
1873.53
1892.41
1878.23
1882.63
1889.84
1912.29
1916.34
1914.46
1914.37
1936.77
1923.32
1934.58
1940.18
1938.58
1939.32
1938.28
1944.46
1953.95
1958.62
1981.62
1986.99
2011.64
1996.67
2023.73
2013.59
2014.99
2015.88
2046.94
2067.66
2052.21
2074.68
2083.77
2102.66
2086.9
2089.83
2098.3
2116.19
2122.77
2109.85
2149.51
2137.04
2132.65
2123.2
2144.05
2142.3
2139.18
2136
2140.07
2162.3
2146.5
2161.83
2174.98
2150.9
2153.14
2154.26
2153.52
2150.08
2138.19
2134.18
2108.06
2125.32
2126.64
2120.08
2106.58
2106.53
2099.77
2117.5
2101.22
2080.44
2092.01
2094.75
2080.44
2111.14
2089.09
2097.85
2123.02
2101.79
2122.13
2104.75
2107.9
2106.91
2113.25
2121.96
2135.91
2146.46
2163.11
2175.81
2179.12
2191.03
2192.19
2217.42
2246.65
2247.09
2272.37
2263.12
2286.72
2303.58
2315.14
2330.25
2361.77
2351.47
2372.18
2431.12
2445.85
2454.15
2473.93
2497.44
2491.76
2514.69
2529.17
2529.61
2579.89
2591.99
2630.32
2651.48
2672.9
2670.94
2716.46
2723.17
2766.12
2771.18
2794.72
2817.05
2823.14
2833.38
2880.26
2901.05
2899.57
2919.72
2929.48
2934.2
2942.72
2919.35
2906.79
2903.34
2901.8
2862.02
2835.12
2797.76
2755.21
2733.36
2707.15
2663.43
2638.75
2580.88
2533.51
2471.31
2381.45
2287.95
2211.86
2169.32
2111.38
2101.54
2072.42
2035.8
2014.41
2009.31
2003.36
1986.65
1976.74
1985.11
1979.28
1970.62
1978.41
1989.64
1992.82
2018.95
1997.29
2008.17
2030.09
2036.16
2047.88
2060.77
2062.57
2068.43
2065.12
2081.78
2063.29
2072.03
2098.83
2081.8
2059.79
2076.72
2067.68
2083.21
2083.84
2069.77
2084.13
2064.12
2035.51
2006.4
2023.88
2009.24
2015.66
1989.91
1975.7
1944.71
1946.33
1919.08
1918.23
1898.59
1906.57
1877.1
1847.81
1852.86
1833.26
1814.55
1827.19
1803.48
1804.96
1799.87
1807.59
1799.26
1791.32
1826.04
1791.03
1791.41
1792.07
1795.07
1782.9
1792.84
1815.82
1849.62
1878.56
1868.19
1855.52
1887.15
1912.31
1941.06
1972.33
1982.28
2010.04
2018.83
2057.57
2103.76
2148.37
2162.41
2202.77
2241.06
2262.05
2288.1
2352.69
2383.37
2422.55
2441.13
2465.12
2526.76
2590.23
2596.64
2636.22
2663.51
2702.58
2742.73
2802.51
2847.06
2927.34
2979.59
3046.35
3122.24
3166.06
3242.43
3275.19
3293.18
3339.31
3367.61
3345.71
3282.06
3253.74
3218.7
3168.8
3124.84
3124.3
3135.04
3157.97
3151.16
3134.08
3042.37
2886.82
2676.86
2425.09
2106.92
1777.92
1473.2
1237.85
1026.37
876.123
791.13
741.908
687.949
644.92
612.258
593.803
569.977
564.986
558.198
544.683
533.101
519.558
516.224
511.685
519.302
512.227
505.017
493.244
482.346
478.51
485.755
480.488
490.13
481.296
494.59
480.204
469.643
472.08
457.925
466.882
467.754
473.178
473.71
457.06
464.963
468.494
459.651
473.044
457.528
455.975
462.082
445.929
453.57
452.917
464.338
452.174
446.692
447.142
449.568
450.344
443.935
440
442.49
451.366
458.852
460.679
457.994
452.592
453.324
443.609
448.783
445.55
446.561
451.171
436.038
449.365
445.796
449.35
450.045
446.074
448.459
442.081
444.567
453.185
446.684
438.045
442.812
440.313
437.202
446.506
447.236
442.793
430.912
441.927
443.415
442.818
440.18
440.102
438.505
446.045
451.614
441.746
436.53
440.156
436.003
432.499
438.446
435.076
438.11
444.269
437.387
439.133
438.757
440.29
440.664
435.166
446.983
440.011
436.475
442.95
441.605
437.276
440.591
433.167
437.939
437.425
447.999
442.047
436.987
431.991
437.597
433.964
434.402
444.032
447.326
434.453
444.361
449.174
445.101
446.086
444.736
446.181
450.34
438.832
443.335
445.012
440.966
444.058
439.291
441.449
442.914
446.304
440.17
458.188
448.666
437.486
433.408
435.311
429.073
426.118
432.739
446.282
444.137
452.302
445.345
447.33
446.174
450.501
451.942
430.582
440.371
436.466
434.564
436.132
434.846
436.879
437.091
447.704
440.128
445.657
453.373
451.43
450.009
441.07
434.703
436.792
438.844
448.985
445.503
440.411
438.315
442.008
435.341
440.336
439.659
449.923
444.828
445.369
445.269
440.768
444.652
438.516
438.08
439.382
438.559
446.88
446.933
439.201
447.191
442.509
434.664
434.122
443.798
451.687
450.597
444.077
446.393
447.495
446.927
444.531
450.6
443.289
449.544
443.586
453.963
443.286
446.333
434.929
452.563
450.368
446.729
436.623
452.669
447.027
446.544
443.078
438.923
438.566
446.007
445.393
454.891
448.028
449.23
444.187
439.482
452.345
449.335
446.762
452.392
3.06292
end of experiment