File: src/xpsdeeplearning/data/references/NiCoFe/Fe2p_Fe_metal.vms
VAMAS Surface Chemical Analysis Standard Data Transfer Format 1988 May 4
Not Specified
Not Specified
Not Specified
Not Specified
5
Casa Info Follows CasaXPS Version 2.3.24PR1.0
0
Created by SpecsLab Prodigy, Version 4.73.2-r95032
SourceAnalyserAngle: Not Specified
CasaRowLabel:Fe metal
NORM
REGULAR
0
1
Exp Variable
d
0
0
0
0
1
Fe2p
Fe metal
2021
5
7
18
14
57
0
17
Casa Info Follows
0
0
0
0
File = E:/OwnCloud/XPS lab/EX494_S778_Fe metal.sle
Group = RT in UHV, #Treatments: , #Temp:RT , #Pressure:UHV, #Atmosphere: , #Comments:
First of group = 0
Spectrum ID = 54
Analyzer lens = AngleResolvedMode22:1.5kV
Analyzer slit = 4:7x20c\C:mesh
Scan mode = FixedAnalyzerTransmission
Kinetic energy start = 716.61
PCA Coefs = 124235, -421.933, -624.314,
c:\users\mark\downloads\ex494_s778_fe metal.vms
c:\users\mark\downloads\ex494_fe metal.vms
C:\Users\pielsticker\Lukas\MPI-CEC\Projects\deepxps\xpsdeeplearning\data\references\NiCoFe\EX491-495 Fe, Ni, Co oxide references.vms
XPS
2
Al
1486.61
0
0
0
54.5
180
FAT
20
1
4.1408
0
0
0
0
0
Fe
2p
-1
kinetic energy
eV
716.61
0.1
2
counts
d
Transmission
d
pulse counting
0.1
3
0
0
0
0
2
ESCAPE DEPTH TYPE
d
1
MFP Exponent
d
0
323.951
3.06292
3792.71
3825.12
3824.11
3802.93
3810.09
3796.89
3793.94
3806.25
3798.68
3784.24
3790.72
3773.41
3778.05
3782.55
3754.88
3731.12
3752.55
3748.22
3724.94
3727.19
3732.2
3707.35
3696.67
3680.79
3684.17
3682.64
3684.61
3651.5
3658.03
3651.65
3662.5
3650.47
3653.65
3645.15
3643.65
3626.84
3627.24
3631.2
3615.61
3625.24
3617.95
3604.73
3634.87
3610.51
3612.08
3613.92
3615.72
3612.1
3619.35
3626.72
3619.04
3601.93
3600.58
3594.47
3608.95
3617.96
3597.74
3612.52
3593.23
3602.37
3577.84
3613.58
3612.19
3606.54
3583.46
3580.16
3592.89
3601.76
3596.43
3582.21
3589.6
3599.35
3597.88
3587.36
3574.78
3589.84
3572.13
3552.43
3583.47
3590.53
3570.14
3561.11
3564.05
3578.48
3571.72
3557.13
3565.59
3553.51
3573.97
3571.24
3566.46
3564.75
3588.27
3562.36
3556.94
3558.14
3570.94
3574.09
3580.21
3604.87
3582.01
3574.11
3567.41
3578.11
3573.98
3559.09
3590.76
3567.15
3591.48
3599.31
3586.65
3582.13
3573.61
3596.12
3589.81
3604.85
3623.94
3625.58
3624.35
3626.26
3625.22
3643.62
3653.98
3627.25
3668.8
3663.28
3647.17
3657.66
3656.22
3662.21
3670.53
3652.28
3682.59
3698.91
3678.65
3694.62
3704.6
3699.28
3698.57
3710.91
3710.45
3699.05
3712.87
3711.76
3710.78
3708.38
3732.62
3739.93
3746.05
3734.77
3745.55
3743.44
3771.28
3773.3
3759.73
3774.56
3768.36
3804.71
3800.9
3765.39
3766.59
3787.1
3792.91
3788.85
3800.84
3824.79
3813.88
3816.63
3816.47
3849.3
3836.82
3842.11
3835.02
3846.95
3852.21
3860.94
3850.09
3864.54
3865.24
3866.95
3865.87
3871.44
3888.96
3886.7
3894.27
3906.62
3892.07
3886.6
3895.67
3910.98
3909.51
3936.19
3935.54
3920.02
3917.49
3929.82
3934.23
3947.11
3924.42
3948.43
3974.03
3951.56
3965.99
3989.68
4009.6
3978.4
3985.73
4002.89
4035.32
4012.88
4012.23
4002.63
4008.94
4037.21
4024.34
4050.23
4054.46
4048.19
4045.22
4063.29
4079.84
4066.22
4074.77
4093.66
4092.94
4093.18
4079.45
4078.02
4107.26
4127.34
4119.21
4116.72
4127.49
4117.45
4123.88
4129.63
4157.65
4156.88
4158.29
4166.65
4165.03
4171.34
4171.03
4181.13
4179.44
4175.73
4198.78
4207
4202.86
4215.46
4204.64
4203.19
4216.95
4233.02
4238.17
4267.44
4255.11
4235.57
4241.62
4235.03
4236.82
4249.15
4245.98
4261.51
4257.4
4241.79
4267.98
4266.62
4276.69
4286.17
4264.88
4266.1
4275.46
4302.69
4271.59
4269.71
4285.23
4278.45
4278.93
4286.06
4323.27
4300.94
4292.53
4283.55
4287.1
4307.57
4310.12
4292.32
4302.3
4302.23
4289.51
4288.72
4302.4
4301.96
4298.55
4287.43
4316.32
4302.15
4317.63
4309.67
4325.25
4312.49
4317.15
4317.83
4317.29
4318.41
4357.72
4321.36
4320.68
4320.33
4346.87
4352.63
4348.27
4359.11
4371.5
4366.52
4372.7
4366.16
4377.58
4407.29
4392.37
4395.53
4394.2
4407.29
4399.41
4437.06
4435.76
4443.12
4424.3
4437.07
4431.35
4430.81
4451.31
4438.76
4461.58
4450.41
4455.86
4470.61
4477.93
4494.59
4485.56
4486.9
4477.18
4494.76
4529.9
4532.89
4514.64
4515.27
4542.46
4552.99
4542.74
4527.35
4526.54
4560.16
4556.72
4566.21
4580.26
4577.86
4582.1
4586.88
4605.65
4612.31
4610.87
4612.24
4626.91
4628.2
4620.75
4632.63
4629.6
4646.47
4682.4
4686.17
4653.34
4653.28
4678.06
4666.44
4688.83
4708.95
4699.54
4675.8
4713.69
4723.62
4718.36
4720.88
4721.43
4724.57
4722.61
4750.65
4727.98
4721.94
4739.23
4728.45
4735.23
4744.2
4730.05
4745.76
4724.93
4724.98
4721.48
4741.17
4754.75
4762.73
4731.85
4752.25
4753.35
4755.4
4747.22
4741.09
4768.66
4752.32
4770.93
4735.66
4754.61
4738.72
4737.87
4751.88
4744.68
4749.1
4742.02
4753.61
4765.14
4777.72
4775.3
4739.05
4763.13
4780.89
4791.72
4803.18
4798.22
4787.08
4778.91
4794.27
4801.04
4800.01
4791.48
4830.87
4800.25
4801.76
4833.81
4814.28
4834.95
4850.61
4840.53
4847.2
4886.34
4881.42
4885.8
4863.56
4881.09
4892.54
4886.48
4891.98
4907.35
4914.73
4923.82
4952.85
4941.74
4953.4
4966.1
4968.88
4986.39
4985.95
5013.07
5059.85
5063.49
5105.69
5142.87
5169.33
5171.5
5206.74
5237.23
5289.27
5334.01
5373.96
5411.05
5472.66
5530.12
5591.16
5631.26
5715.9
5760.42
5831.16
5935.4
6020.91
6153.01
6213.98
6295.02
6466.67
6600.44
6761.72
6897.97
7042.98
7243.16
7452.2
7684.96
7955.21
8145.51
8404.54
8660.39
8864.96
9005.56
9087.38
9049.39
8965.17
8752.13
8491.31
8092.59
7663.64
7141.13
6632.09
6163.74
5741.83
5389.96
5110.41
4870.41
4659.06
4484.17
4344.13
4248.98
4161.03
4047.18
4004.89
3954.1
3890.98
3850.56
3804.46
3793.59
3769.1
3743
3725.97
3693.43
3681.6
3675.74
3656.51
3661.17
3654.05
3643.03
3635.05
3653.42
3658.56
3646.27
3657.24
3656.17
3671.13
3670.66
3685.79
3674.48
3671.22
3691.1
3689.42
3729.37
3732.6
3757.04
3759.01
3763.05
3767.68
3782.06
3795.69
3820.01
3806.29
3832.53
3850.26
3858.6
3882.95
3903.27
3910.72
3907.47
3910.56
3952.93
3948.41
3958.07
3969.52
3985.49
3989.28
3970.79
4008.41
4027.02
4059.59
4078.86
4069.57
4087.87
4143.24
4170.57
4176.3
4202
4251.55
4273.54
4302.02
4342.14
4385.85
4443.75
4476.97
4503.88
4571.03
4606.55
4634.53
4662.71
4729.86
4751.54
4818.86
4858.33
4910.38
4976.86
5011.82
5073.23
5150.34
5226.16
5276.51
5377.93
5511.07
5603.23
5706.17
5856.65
6028.68
6195.03
6381.81
6615.31
6926.18
7248.32
7599.32
8007.52
8571.49
9117.59
9702.72
10331.9
10910.8
11440.1
11928.1
12489.1
13223.5
14077.1
15065.4
15962.8
16455.1
16239
15074.4
13084.2
10550.1
8016.14
5855.01
4273.32
3197.39
2505.71
2055.98
1734.96
1504.74
1328.14
1204.72
1104.61
1031.93
966.562
908.891
859.484
808.579
762.518
730.599
712.672
692.485
664.89
647.694
622.447
606.669
598.578
585.153
568.919
550.346
534.889
532.222
519.736
510.921
513.912
496.677
496.859
490.102
480.908
480.985
473.624
471.188
464.142
454.98
452.692
448.731
442.342
438.984
433.898
436.807
427.533
418.371
421.597
415.603
419.083
419.649
418.208
414.593
410.913
406.118
400.976
399.317
405.606
399.124
395.392
390.778
387.382
393.581
393.045
387.946
386.599
385.747
391.606
389.175
382.926
381.955
380.651
384.365
385.475
386.485
385.694
377.127
383.7
376.968
377.302
377.639
376.698
372.901
376.882
364.403
370.409
366.634
369.513
368.889
369.577
368.134
368.186
372.155
367.473
361.435
363.518
367.619
364.616
362.545
366.932
367.957
361.94
357.379
362.516
364.316
362.677
361.437
360.341
361.18
357.166
357.208
356.901
355.416
360.069
352.878
346.514
354.877
357.099
349.432
345.77
347.442
358.678
356.764
351.647
348.885
343.464
341.176
350.804
347.849
350.305
344.668
346.388
347.208
354.337
346.383
348.368
348.059
349.153
347.357
344.779
349.099
353.921
344.951
349.23
342.259
344.514
346.117
349.295
347.788
348.794
353.215
344.191
340.781
349.284
355.594
346.291
341.093
345.426
351.653
350.366
353.521
351.537
351.621
340.338
350.491
351.171
362.305
360.589
355.255
363.877
364.437
350.675
356.037
358.674
349.016
345.512
355.365
352.105
357.946
353.385
355.225
348.652
349.576
346.531
344.496
342.149
348.156
346.528
349.645
350.02
344.168
344.756
351.633
345.271
347.319
347.093
348.016
350.68
344.407
349.091
350.479
351.67
350.148
350.705
346.856
352.35
347.179
348.244
348.719
355.053
3.06292
end of experiment